[2024-02-01 00:51:45,283] 	INFO 	20 	id_data.py 	<module>() 	ID Data Started
[2024-02-01 00:51:45,855] 	INFO 	31 	id_data.py 	<module>() 	ID Data Ended
[2024-02-01 00:51:46,624] 	INFO 	24 	day_data.py 	<module>() 	Day Data Fusion Started
[2024-02-01 00:51:49,104] 	INFO 	71 	day_data.py 	<module>() 	Day Data Fusion Ended
[2024-02-01 00:51:50,726] 	INFO 	35 	pair_data.py 	<module>() 	Pair Data Fusion Started
[2024-02-01 00:52:03,189] 	INFO 	101 	pair_data.py 	<module>() 	Pair Data Fusion Ended
[2024-02-01 00:52:04,015] 	INFO 	36 	bribe_data.py 	<module>() 	Bribe Data Started
[2024-02-01 00:54:50,971] 	INFO 	157 	bribe_data.py 	<module>() 	Bribe Data Ended
[2024-02-01 00:54:51,754] 	INFO 	36 	fee_data.py 	<module>() 	Fee Data Started
[2024-02-01 00:57:01,229] 	INFO 	157 	fee_data.py 	<module>() 	Fee Data Ended
[2024-02-01 00:57:02,016] 	INFO 	37 	vote_data.py 	<module>() 	Vote Data Started
[2024-02-01 00:57:12,220] 	INFO 	116 	vote_data.py 	<module>() 	Vote Data Ended
[2024-02-01 00:57:13,031] 	INFO 	30 	revenue_data.py 	<module>() 	Revenue Data Started
[2024-02-01 00:57:22,233] 	INFO 	150 	revenue_data.py 	<module>() 	Revenue Data Ended
[2024-02-01 00:57:22,989] 	INFO 	20 	pool_data.py 	<module>() 	Pool Data Started
[2024-02-01 00:57:33,774] 	ERROR 	82 	pool_data.py 	<module>() 	Error occurred during Pool Data process. Error: {'code': -32000, 'message': 'execution aborted (timeout = 5s)'}
Traceback (most recent call last):
  File "pool_data.py", line 53, in <module>
    pool_data = contract_instance.functions.getActivePoolDistributions(pool_address).call()
  File "/opt/hostedtoolcache/Python/3.8.18/x64/lib/python3.8/site-packages/web3/contract.py", line 970, in call
    return call_contract_function(
  File "/opt/hostedtoolcache/Python/3.8.18/x64/lib/python3.8/site-packages/web3/contract.py", line 1525, in call_contract_function
    return_data = web3.eth.call(
  File "/opt/hostedtoolcache/Python/3.8.18/x64/lib/python3.8/site-packages/web3/module.py", line 57, in caller
    result = w3.manager.request_blocking(method_str,
  File "/opt/hostedtoolcache/Python/3.8.18/x64/lib/python3.8/site-packages/web3/manager.py", line 198, in request_blocking
    return self.formatted_response(response,
  File "/opt/hostedtoolcache/Python/3.8.18/x64/lib/python3.8/site-packages/web3/manager.py", line 171, in formatted_response
    raise ValueError(response["error"])
ValueError: {'code': -32000, 'message': 'execution aborted (timeout = 5s)'}
[2024-02-01 01:10:23,166] 	INFO 	26 	emissions_data.py 	<module>() 	Emissions Data Started
[2024-02-01 01:10:32,111] 	INFO 	131 	emissions_data.py 	<module>() 	Emissions Data Ended
[2024-02-01 01:50:23,341] 	INFO 	20 	id_data.py 	<module>() 	ID Data Started
[2024-02-01 01:50:23,778] 	INFO 	31 	id_data.py 	<module>() 	ID Data Ended
[2024-02-01 01:50:24,405] 	INFO 	24 	day_data.py 	<module>() 	Day Data Fusion Started
[2024-02-01 01:50:26,098] 	INFO 	71 	day_data.py 	<module>() 	Day Data Fusion Ended
[2024-02-01 01:50:27,169] 	INFO 	35 	pair_data.py 	<module>() 	Pair Data Fusion Started
[2024-02-01 01:50:41,559] 	INFO 	101 	pair_data.py 	<module>() 	Pair Data Fusion Ended
[2024-02-01 01:50:42,385] 	INFO 	36 	bribe_data.py 	<module>() 	Bribe Data Started
[2024-02-01 01:53:34,195] 	INFO 	157 	bribe_data.py 	<module>() 	Bribe Data Ended
[2024-02-01 01:53:35,065] 	INFO 	36 	fee_data.py 	<module>() 	Fee Data Started
[2024-02-01 01:55:34,528] 	INFO 	157 	fee_data.py 	<module>() 	Fee Data Ended
[2024-02-01 01:55:35,397] 	INFO 	37 	vote_data.py 	<module>() 	Vote Data Started
[2024-02-01 01:55:46,157] 	INFO 	116 	vote_data.py 	<module>() 	Vote Data Ended
[2024-02-01 01:55:47,038] 	INFO 	30 	revenue_data.py 	<module>() 	Revenue Data Started
[2024-02-01 01:55:58,494] 	INFO 	150 	revenue_data.py 	<module>() 	Revenue Data Ended
[2024-02-01 01:55:59,269] 	INFO 	20 	pool_data.py 	<module>() 	Pool Data Started
[2024-02-01 01:56:07,906] 	ERROR 	82 	pool_data.py 	<module>() 	Error occurred during Pool Data process. Error: {'code': -32000, 'message': 'execution aborted (timeout = 5s)'}
Traceback (most recent call last):
  File "pool_data.py", line 53, in <module>
    pool_data = contract_instance.functions.getActivePoolDistributions(pool_address).call()
  File "/opt/hostedtoolcache/Python/3.8.18/x64/lib/python3.8/site-packages/web3/contract.py", line 970, in call
    return call_contract_function(
  File "/opt/hostedtoolcache/Python/3.8.18/x64/lib/python3.8/site-packages/web3/contract.py", line 1525, in call_contract_function
    return_data = web3.eth.call(
  File "/opt/hostedtoolcache/Python/3.8.18/x64/lib/python3.8/site-packages/web3/module.py", line 57, in caller
    result = w3.manager.request_blocking(method_str,
  File "/opt/hostedtoolcache/Python/3.8.18/x64/lib/python3.8/site-packages/web3/manager.py", line 198, in request_blocking
    return self.formatted_response(response,
  File "/opt/hostedtoolcache/Python/3.8.18/x64/lib/python3.8/site-packages/web3/manager.py", line 171, in formatted_response
    raise ValueError(response["error"])
ValueError: {'code': -32000, 'message': 'execution aborted (timeout = 5s)'}
[2024-02-01 02:20:51,943] 	INFO 	20 	id_data.py 	<module>() 	ID Data Started
[2024-02-01 02:20:52,265] 	INFO 	31 	id_data.py 	<module>() 	ID Data Ended
[2024-02-01 02:20:52,801] 	INFO 	24 	day_data.py 	<module>() 	Day Data Fusion Started
[2024-02-01 02:20:54,853] 	INFO 	71 	day_data.py 	<module>() 	Day Data Fusion Ended
[2024-02-01 02:20:55,689] 	INFO 	35 	pair_data.py 	<module>() 	Pair Data Fusion Started
[2024-02-01 02:21:10,826] 	INFO 	101 	pair_data.py 	<module>() 	Pair Data Fusion Ended
[2024-02-01 02:21:11,651] 	INFO 	36 	bribe_data.py 	<module>() 	Bribe Data Started
[2024-02-01 02:23:34,213] 	INFO 	157 	bribe_data.py 	<module>() 	Bribe Data Ended
[2024-02-01 02:23:35,021] 	INFO 	36 	fee_data.py 	<module>() 	Fee Data Started
[2024-02-01 02:25:31,168] 	INFO 	157 	fee_data.py 	<module>() 	Fee Data Ended
[2024-02-01 02:25:31,998] 	INFO 	37 	vote_data.py 	<module>() 	Vote Data Started
[2024-02-01 02:25:40,496] 	INFO 	116 	vote_data.py 	<module>() 	Vote Data Ended
[2024-02-01 02:25:41,323] 	INFO 	30 	revenue_data.py 	<module>() 	Revenue Data Started
[2024-02-01 02:25:56,372] 	INFO 	150 	revenue_data.py 	<module>() 	Revenue Data Ended
[2024-02-01 02:25:57,102] 	INFO 	20 	pool_data.py 	<module>() 	Pool Data Started
[2024-02-01 02:26:08,138] 	ERROR 	82 	pool_data.py 	<module>() 	Error occurred during Pool Data process. Error: {'code': -32000, 'message': 'execution aborted (timeout = 5s)'}
Traceback (most recent call last):
  File "pool_data.py", line 53, in <module>
    pool_data = contract_instance.functions.getActivePoolDistributions(pool_address).call()
  File "/opt/hostedtoolcache/Python/3.8.18/x64/lib/python3.8/site-packages/web3/contract.py", line 970, in call
    return call_contract_function(
  File "/opt/hostedtoolcache/Python/3.8.18/x64/lib/python3.8/site-packages/web3/contract.py", line 1525, in call_contract_function
    return_data = web3.eth.call(
  File "/opt/hostedtoolcache/Python/3.8.18/x64/lib/python3.8/site-packages/web3/module.py", line 57, in caller
    result = w3.manager.request_blocking(method_str,
  File "/opt/hostedtoolcache/Python/3.8.18/x64/lib/python3.8/site-packages/web3/manager.py", line 198, in request_blocking
    return self.formatted_response(response,
  File "/opt/hostedtoolcache/Python/3.8.18/x64/lib/python3.8/site-packages/web3/manager.py", line 171, in formatted_response
    raise ValueError(response["error"])
ValueError: {'code': -32000, 'message': 'execution aborted (timeout = 5s)'}
[2024-02-01 02:27:07,700] 	INFO 	29 	partner_data.py 	<module>() 	Partner Vote Data Started
[2024-02-01 02:27:24,138] 	INFO 	196 	partner_data.py 	<module>() 	Partner Vote Data Ended
[2024-02-01 02:27:24,931] 	INFO 	24 	apr_data.py 	<module>() 	APR Data Started
[2024-02-01 02:27:26,807] 	INFO 	101 	apr_data.py 	<module>() 	APR Data Ended
[2024-02-01 02:37:10,683] 	INFO 	20 	id_data.py 	<module>() 	ID Data Started
[2024-02-01 02:37:11,249] 	INFO 	31 	id_data.py 	<module>() 	ID Data Ended
[2024-02-01 02:37:11,781] 	INFO 	24 	day_data.py 	<module>() 	Day Data Fusion Started
[2024-02-01 02:37:15,189] 	INFO 	71 	day_data.py 	<module>() 	Day Data Fusion Ended
[2024-02-01 02:37:16,237] 	INFO 	35 	pair_data.py 	<module>() 	Pair Data Fusion Started
[2024-02-01 02:37:33,446] 	INFO 	101 	pair_data.py 	<module>() 	Pair Data Fusion Ended
[2024-02-01 02:37:34,251] 	INFO 	36 	bribe_data.py 	<module>() 	Bribe Data Started
[2024-02-01 02:39:55,328] 	INFO 	157 	bribe_data.py 	<module>() 	Bribe Data Ended
[2024-02-01 02:39:56,129] 	INFO 	36 	fee_data.py 	<module>() 	Fee Data Started
[2024-02-01 02:45:41,041] 	INFO 	157 	fee_data.py 	<module>() 	Fee Data Ended
[2024-02-01 02:45:41,840] 	INFO 	37 	vote_data.py 	<module>() 	Vote Data Started
[2024-02-01 02:45:51,494] 	INFO 	116 	vote_data.py 	<module>() 	Vote Data Ended
[2024-02-01 02:45:52,340] 	INFO 	30 	revenue_data.py 	<module>() 	Revenue Data Started
[2024-02-01 02:46:05,679] 	INFO 	150 	revenue_data.py 	<module>() 	Revenue Data Ended
[2024-02-01 02:46:06,411] 	INFO 	20 	pool_data.py 	<module>() 	Pool Data Started
[2024-02-01 02:46:17,564] 	ERROR 	82 	pool_data.py 	<module>() 	Error occurred during Pool Data process. Error: {'code': -32000, 'message': 'execution aborted (timeout = 5s)'}
Traceback (most recent call last):
  File "pool_data.py", line 53, in <module>
    pool_data = contract_instance.functions.getActivePoolDistributions(pool_address).call()
  File "/opt/hostedtoolcache/Python/3.8.18/x64/lib/python3.8/site-packages/web3/contract.py", line 970, in call
    return call_contract_function(
  File "/opt/hostedtoolcache/Python/3.8.18/x64/lib/python3.8/site-packages/web3/contract.py", line 1525, in call_contract_function
    return_data = web3.eth.call(
  File "/opt/hostedtoolcache/Python/3.8.18/x64/lib/python3.8/site-packages/web3/module.py", line 57, in caller
    result = w3.manager.request_blocking(method_str,
  File "/opt/hostedtoolcache/Python/3.8.18/x64/lib/python3.8/site-packages/web3/manager.py", line 198, in request_blocking
    return self.formatted_response(response,
  File "/opt/hostedtoolcache/Python/3.8.18/x64/lib/python3.8/site-packages/web3/manager.py", line 171, in formatted_response
    raise ValueError(response["error"])
ValueError: {'code': -32000, 'message': 'execution aborted (timeout = 5s)'}
[2024-02-01 02:49:28,377] 	INFO 	20 	id_data.py 	<module>() 	ID Data Started
[2024-02-01 02:49:28,639] 	INFO 	31 	id_data.py 	<module>() 	ID Data Ended
[2024-02-01 02:49:29,294] 	INFO 	24 	day_data.py 	<module>() 	Day Data Fusion Started
[2024-02-01 02:49:32,655] 	INFO 	71 	day_data.py 	<module>() 	Day Data Fusion Ended
[2024-02-01 02:49:33,786] 	INFO 	35 	pair_data.py 	<module>() 	Pair Data Fusion Started
[2024-02-01 02:49:45,576] 	INFO 	101 	pair_data.py 	<module>() 	Pair Data Fusion Ended
[2024-02-01 02:49:46,356] 	INFO 	36 	bribe_data.py 	<module>() 	Bribe Data Started
[2024-02-01 02:52:20,284] 	INFO 	157 	bribe_data.py 	<module>() 	Bribe Data Ended
[2024-02-01 02:52:21,052] 	INFO 	36 	fee_data.py 	<module>() 	Fee Data Started
[2024-02-01 02:54:21,212] 	INFO 	157 	fee_data.py 	<module>() 	Fee Data Ended
[2024-02-01 02:54:21,981] 	INFO 	37 	vote_data.py 	<module>() 	Vote Data Started
[2024-02-01 02:54:31,633] 	INFO 	116 	vote_data.py 	<module>() 	Vote Data Ended
[2024-02-01 02:54:32,415] 	INFO 	30 	revenue_data.py 	<module>() 	Revenue Data Started
[2024-02-01 02:54:38,112] 	INFO 	150 	revenue_data.py 	<module>() 	Revenue Data Ended
[2024-02-01 02:54:38,795] 	INFO 	20 	pool_data.py 	<module>() 	Pool Data Started
[2024-02-01 02:54:44,130] 	ERROR 	82 	pool_data.py 	<module>() 	Error occurred during Pool Data process. Error: execution reverted
Traceback (most recent call last):
  File "pool_data.py", line 53, in <module>
    pool_data = contract_instance.functions.getActivePoolDistributions(pool_address).call()
  File "/opt/hostedtoolcache/Python/3.8.18/x64/lib/python3.8/site-packages/web3/contract.py", line 970, in call
    return call_contract_function(
  File "/opt/hostedtoolcache/Python/3.8.18/x64/lib/python3.8/site-packages/web3/contract.py", line 1525, in call_contract_function
    return_data = web3.eth.call(
  File "/opt/hostedtoolcache/Python/3.8.18/x64/lib/python3.8/site-packages/web3/module.py", line 57, in caller
    result = w3.manager.request_blocking(method_str,
  File "/opt/hostedtoolcache/Python/3.8.18/x64/lib/python3.8/site-packages/web3/manager.py", line 198, in request_blocking
    return self.formatted_response(response,
  File "/opt/hostedtoolcache/Python/3.8.18/x64/lib/python3.8/site-packages/web3/manager.py", line 170, in formatted_response
    apply_error_formatters(error_formatters, response)
  File "/opt/hostedtoolcache/Python/3.8.18/x64/lib/python3.8/site-packages/web3/manager.py", line 70, in apply_error_formatters
    formatted_resp = pipe(response, error_formatters)
  File "cytoolz/functoolz.pyx", line 680, in cytoolz.functoolz.pipe
  File "cytoolz/functoolz.pyx", line 655, in cytoolz.functoolz.c_pipe
  File "/opt/hostedtoolcache/Python/3.8.18/x64/lib/python3.8/site-packages/web3/_utils/method_formatters.py", line 580, in raise_solidity_error_on_revert
    raise ContractLogicError('execution reverted')
web3.exceptions.ContractLogicError: execution reverted
[2024-02-01 03:12:17,278] 	INFO 	20 	id_data.py 	<module>() 	ID Data Started
[2024-02-01 03:12:17,535] 	INFO 	31 	id_data.py 	<module>() 	ID Data Ended
[2024-02-01 03:12:18,181] 	INFO 	24 	day_data.py 	<module>() 	Day Data Fusion Started
[2024-02-01 03:12:22,012] 	INFO 	71 	day_data.py 	<module>() 	Day Data Fusion Ended
[2024-02-01 03:12:23,063] 	INFO 	35 	pair_data.py 	<module>() 	Pair Data Fusion Started
[2024-02-01 03:12:53,226] 	INFO 	101 	pair_data.py 	<module>() 	Pair Data Fusion Ended
[2024-02-01 03:12:54,059] 	INFO 	36 	bribe_data.py 	<module>() 	Bribe Data Started
[2024-02-01 03:14:58,865] 	INFO 	157 	bribe_data.py 	<module>() 	Bribe Data Ended
[2024-02-01 03:14:59,676] 	INFO 	36 	fee_data.py 	<module>() 	Fee Data Started
[2024-02-01 03:17:11,496] 	INFO 	157 	fee_data.py 	<module>() 	Fee Data Ended
[2024-02-01 03:17:12,302] 	INFO 	37 	vote_data.py 	<module>() 	Vote Data Started
[2024-02-01 03:17:21,987] 	INFO 	116 	vote_data.py 	<module>() 	Vote Data Ended
[2024-02-01 03:17:22,792] 	INFO 	30 	revenue_data.py 	<module>() 	Revenue Data Started
[2024-02-01 03:17:38,506] 	INFO 	150 	revenue_data.py 	<module>() 	Revenue Data Ended
[2024-02-01 03:17:39,210] 	INFO 	20 	pool_data.py 	<module>() 	Pool Data Started
[2024-02-01 03:17:47,273] 	ERROR 	82 	pool_data.py 	<module>() 	Error occurred during Pool Data process. Error: execution reverted
Traceback (most recent call last):
  File "pool_data.py", line 53, in <module>
    pool_data = contract_instance.functions.getActivePoolDistributions(pool_address).call()
  File "/opt/hostedtoolcache/Python/3.8.18/x64/lib/python3.8/site-packages/web3/contract.py", line 970, in call
    return call_contract_function(
  File "/opt/hostedtoolcache/Python/3.8.18/x64/lib/python3.8/site-packages/web3/contract.py", line 1525, in call_contract_function
    return_data = web3.eth.call(
  File "/opt/hostedtoolcache/Python/3.8.18/x64/lib/python3.8/site-packages/web3/module.py", line 57, in caller
    result = w3.manager.request_blocking(method_str,
  File "/opt/hostedtoolcache/Python/3.8.18/x64/lib/python3.8/site-packages/web3/manager.py", line 198, in request_blocking
    return self.formatted_response(response,
  File "/opt/hostedtoolcache/Python/3.8.18/x64/lib/python3.8/site-packages/web3/manager.py", line 170, in formatted_response
    apply_error_formatters(error_formatters, response)
  File "/opt/hostedtoolcache/Python/3.8.18/x64/lib/python3.8/site-packages/web3/manager.py", line 70, in apply_error_formatters
    formatted_resp = pipe(response, error_formatters)
  File "cytoolz/functoolz.pyx", line 680, in cytoolz.functoolz.pipe
  File "cytoolz/functoolz.pyx", line 655, in cytoolz.functoolz.c_pipe
  File "/opt/hostedtoolcache/Python/3.8.18/x64/lib/python3.8/site-packages/web3/_utils/method_formatters.py", line 580, in raise_solidity_error_on_revert
    raise ContractLogicError('execution reverted')
web3.exceptions.ContractLogicError: execution reverted
[2024-02-01 03:23:55,802] 	INFO 	20 	id_data.py 	<module>() 	ID Data Started
[2024-02-01 03:23:56,283] 	INFO 	31 	id_data.py 	<module>() 	ID Data Ended
[2024-02-01 03:23:56,812] 	INFO 	24 	day_data.py 	<module>() 	Day Data Fusion Started
[2024-02-01 03:23:58,569] 	INFO 	71 	day_data.py 	<module>() 	Day Data Fusion Ended
[2024-02-01 03:23:59,407] 	INFO 	35 	pair_data.py 	<module>() 	Pair Data Fusion Started
[2024-02-01 03:24:13,272] 	INFO 	101 	pair_data.py 	<module>() 	Pair Data Fusion Ended
[2024-02-01 03:24:14,064] 	INFO 	36 	bribe_data.py 	<module>() 	Bribe Data Started
[2024-02-01 03:27:18,804] 	INFO 	157 	bribe_data.py 	<module>() 	Bribe Data Ended
[2024-02-01 03:27:19,652] 	INFO 	36 	fee_data.py 	<module>() 	Fee Data Started
[2024-02-01 03:29:03,482] 	INFO 	157 	fee_data.py 	<module>() 	Fee Data Ended
[2024-02-01 03:29:04,288] 	INFO 	37 	vote_data.py 	<module>() 	Vote Data Started
[2024-02-01 03:29:13,016] 	INFO 	116 	vote_data.py 	<module>() 	Vote Data Ended
[2024-02-01 03:29:13,842] 	INFO 	30 	revenue_data.py 	<module>() 	Revenue Data Started
[2024-02-01 03:29:27,833] 	INFO 	150 	revenue_data.py 	<module>() 	Revenue Data Ended
[2024-02-01 03:29:28,571] 	INFO 	20 	pool_data.py 	<module>() 	Pool Data Started
[2024-02-01 03:29:37,848] 	ERROR 	82 	pool_data.py 	<module>() 	Error occurred during Pool Data process. Error: {'code': -32000, 'message': 'execution aborted (timeout = 5s)'}
Traceback (most recent call last):
  File "pool_data.py", line 53, in <module>
    pool_data = contract_instance.functions.getActivePoolDistributions(pool_address).call()
  File "/opt/hostedtoolcache/Python/3.8.18/x64/lib/python3.8/site-packages/web3/contract.py", line 970, in call
    return call_contract_function(
  File "/opt/hostedtoolcache/Python/3.8.18/x64/lib/python3.8/site-packages/web3/contract.py", line 1525, in call_contract_function
    return_data = web3.eth.call(
  File "/opt/hostedtoolcache/Python/3.8.18/x64/lib/python3.8/site-packages/web3/module.py", line 57, in caller
    result = w3.manager.request_blocking(method_str,
  File "/opt/hostedtoolcache/Python/3.8.18/x64/lib/python3.8/site-packages/web3/manager.py", line 198, in request_blocking
    return self.formatted_response(response,
  File "/opt/hostedtoolcache/Python/3.8.18/x64/lib/python3.8/site-packages/web3/manager.py", line 171, in formatted_response
    raise ValueError(response["error"])
ValueError: {'code': -32000, 'message': 'execution aborted (timeout = 5s)'}
[2024-02-01 03:35:47,746] 	INFO 	20 	id_data.py 	<module>() 	ID Data Started
[2024-02-01 03:35:48,605] 	INFO 	31 	id_data.py 	<module>() 	ID Data Ended
[2024-02-01 03:35:49,284] 	INFO 	24 	day_data.py 	<module>() 	Day Data Fusion Started
[2024-02-01 03:35:51,007] 	INFO 	71 	day_data.py 	<module>() 	Day Data Fusion Ended
[2024-02-01 03:35:52,140] 	INFO 	35 	pair_data.py 	<module>() 	Pair Data Fusion Started
[2024-02-01 03:36:06,578] 	INFO 	101 	pair_data.py 	<module>() 	Pair Data Fusion Ended
[2024-02-01 03:36:07,413] 	INFO 	36 	bribe_data.py 	<module>() 	Bribe Data Started
[2024-02-01 03:38:37,357] 	INFO 	157 	bribe_data.py 	<module>() 	Bribe Data Ended
[2024-02-01 03:38:38,147] 	INFO 	36 	fee_data.py 	<module>() 	Fee Data Started
[2024-02-01 03:40:45,203] 	INFO 	157 	fee_data.py 	<module>() 	Fee Data Ended
[2024-02-01 03:40:46,019] 	INFO 	37 	vote_data.py 	<module>() 	Vote Data Started
[2024-02-01 03:40:55,314] 	INFO 	116 	vote_data.py 	<module>() 	Vote Data Ended
[2024-02-01 03:40:56,126] 	INFO 	30 	revenue_data.py 	<module>() 	Revenue Data Started
[2024-02-01 03:41:09,878] 	INFO 	150 	revenue_data.py 	<module>() 	Revenue Data Ended
[2024-02-01 03:41:10,576] 	INFO 	20 	pool_data.py 	<module>() 	Pool Data Started
[2024-02-01 03:41:19,289] 	ERROR 	82 	pool_data.py 	<module>() 	Error occurred during Pool Data process. Error: {'code': -32000, 'message': 'execution aborted (timeout = 5s)'}
Traceback (most recent call last):
  File "pool_data.py", line 53, in <module>
    pool_data = contract_instance.functions.getActivePoolDistributions(pool_address).call()
  File "/opt/hostedtoolcache/Python/3.8.18/x64/lib/python3.8/site-packages/web3/contract.py", line 970, in call
    return call_contract_function(
  File "/opt/hostedtoolcache/Python/3.8.18/x64/lib/python3.8/site-packages/web3/contract.py", line 1525, in call_contract_function
    return_data = web3.eth.call(
  File "/opt/hostedtoolcache/Python/3.8.18/x64/lib/python3.8/site-packages/web3/module.py", line 57, in caller
    result = w3.manager.request_blocking(method_str,
  File "/opt/hostedtoolcache/Python/3.8.18/x64/lib/python3.8/site-packages/web3/manager.py", line 198, in request_blocking
    return self.formatted_response(response,
  File "/opt/hostedtoolcache/Python/3.8.18/x64/lib/python3.8/site-packages/web3/manager.py", line 171, in formatted_response
    raise ValueError(response["error"])
ValueError: {'code': -32000, 'message': 'execution aborted (timeout = 5s)'}
[2024-02-01 03:49:10,308] 	INFO 	20 	id_data.py 	<module>() 	ID Data Started
[2024-02-01 03:49:10,646] 	INFO 	31 	id_data.py 	<module>() 	ID Data Ended
[2024-02-01 03:49:11,283] 	INFO 	24 	day_data.py 	<module>() 	Day Data Fusion Started
[2024-02-01 03:49:13,109] 	INFO 	71 	day_data.py 	<module>() 	Day Data Fusion Ended
[2024-02-01 03:49:14,265] 	INFO 	35 	pair_data.py 	<module>() 	Pair Data Fusion Started
[2024-02-01 03:49:28,042] 	INFO 	101 	pair_data.py 	<module>() 	Pair Data Fusion Ended
[2024-02-01 03:49:28,882] 	INFO 	36 	bribe_data.py 	<module>() 	Bribe Data Started
[2024-02-01 03:51:59,120] 	INFO 	157 	bribe_data.py 	<module>() 	Bribe Data Ended
[2024-02-01 03:51:59,917] 	INFO 	36 	fee_data.py 	<module>() 	Fee Data Started
[2024-02-01 03:54:01,075] 	INFO 	157 	fee_data.py 	<module>() 	Fee Data Ended
[2024-02-01 03:54:01,854] 	INFO 	37 	vote_data.py 	<module>() 	Vote Data Started
[2024-02-01 03:54:40,391] 	INFO 	116 	vote_data.py 	<module>() 	Vote Data Ended
[2024-02-01 03:54:41,192] 	INFO 	30 	revenue_data.py 	<module>() 	Revenue Data Started
[2024-02-01 03:54:53,610] 	INFO 	150 	revenue_data.py 	<module>() 	Revenue Data Ended
[2024-02-01 03:54:54,326] 	INFO 	20 	pool_data.py 	<module>() 	Pool Data Started
[2024-02-01 03:55:00,138] 	ERROR 	82 	pool_data.py 	<module>() 	Error occurred during Pool Data process. Error: {'code': -32000, 'message': 'execution aborted (timeout = 5s)'}
Traceback (most recent call last):
  File "pool_data.py", line 53, in <module>
    pool_data = contract_instance.functions.getActivePoolDistributions(pool_address).call()
  File "/opt/hostedtoolcache/Python/3.8.18/x64/lib/python3.8/site-packages/web3/contract.py", line 970, in call
    return call_contract_function(
  File "/opt/hostedtoolcache/Python/3.8.18/x64/lib/python3.8/site-packages/web3/contract.py", line 1525, in call_contract_function
    return_data = web3.eth.call(
  File "/opt/hostedtoolcache/Python/3.8.18/x64/lib/python3.8/site-packages/web3/module.py", line 57, in caller
    result = w3.manager.request_blocking(method_str,
  File "/opt/hostedtoolcache/Python/3.8.18/x64/lib/python3.8/site-packages/web3/manager.py", line 198, in request_blocking
    return self.formatted_response(response,
  File "/opt/hostedtoolcache/Python/3.8.18/x64/lib/python3.8/site-packages/web3/manager.py", line 171, in formatted_response
    raise ValueError(response["error"])
ValueError: {'code': -32000, 'message': 'execution aborted (timeout = 5s)'}
