[2024-02-01 00:51:45,283] 	INFO 	20 	id_data.py 	<module>() 	ID Data Started
[2024-02-01 00:51:45,855] 	INFO 	31 	id_data.py 	<module>() 	ID Data Ended
[2024-02-01 00:51:46,624] 	INFO 	24 	day_data.py 	<module>() 	Day Data Fusion Started
[2024-02-01 00:51:49,104] 	INFO 	71 	day_data.py 	<module>() 	Day Data Fusion Ended
[2024-02-01 00:51:50,726] 	INFO 	35 	pair_data.py 	<module>() 	Pair Data Fusion Started
[2024-02-01 00:52:03,189] 	INFO 	101 	pair_data.py 	<module>() 	Pair Data Fusion Ended
[2024-02-01 00:52:04,015] 	INFO 	36 	bribe_data.py 	<module>() 	Bribe Data Started
[2024-02-01 00:54:50,971] 	INFO 	157 	bribe_data.py 	<module>() 	Bribe Data Ended
[2024-02-01 00:54:51,754] 	INFO 	36 	fee_data.py 	<module>() 	Fee Data Started
[2024-02-01 00:57:01,229] 	INFO 	157 	fee_data.py 	<module>() 	Fee Data Ended
[2024-02-01 00:57:02,016] 	INFO 	37 	vote_data.py 	<module>() 	Vote Data Started
[2024-02-01 00:57:12,220] 	INFO 	116 	vote_data.py 	<module>() 	Vote Data Ended
[2024-02-01 00:57:13,031] 	INFO 	30 	revenue_data.py 	<module>() 	Revenue Data Started
[2024-02-01 00:57:22,233] 	INFO 	150 	revenue_data.py 	<module>() 	Revenue Data Ended
[2024-02-01 00:57:22,989] 	INFO 	20 	pool_data.py 	<module>() 	Pool Data Started
[2024-02-01 00:57:33,774] 	ERROR 	82 	pool_data.py 	<module>() 	Error occurred during Pool Data process. Error: {'code': -32000, 'message': 'execution aborted (timeout = 5s)'}
Traceback (most recent call last):
  File "pool_data.py", line 53, in <module>
    pool_data = contract_instance.functions.getActivePoolDistributions(pool_address).call()
  File "/opt/hostedtoolcache/Python/3.8.18/x64/lib/python3.8/site-packages/web3/contract.py", line 970, in call
    return call_contract_function(
  File "/opt/hostedtoolcache/Python/3.8.18/x64/lib/python3.8/site-packages/web3/contract.py", line 1525, in call_contract_function
    return_data = web3.eth.call(
  File "/opt/hostedtoolcache/Python/3.8.18/x64/lib/python3.8/site-packages/web3/module.py", line 57, in caller
    result = w3.manager.request_blocking(method_str,
  File "/opt/hostedtoolcache/Python/3.8.18/x64/lib/python3.8/site-packages/web3/manager.py", line 198, in request_blocking
    return self.formatted_response(response,
  File "/opt/hostedtoolcache/Python/3.8.18/x64/lib/python3.8/site-packages/web3/manager.py", line 171, in formatted_response
    raise ValueError(response["error"])
ValueError: {'code': -32000, 'message': 'execution aborted (timeout = 5s)'}
[2024-02-01 01:10:23,166] 	INFO 	26 	emissions_data.py 	<module>() 	Emissions Data Started
[2024-02-01 01:10:32,111] 	INFO 	131 	emissions_data.py 	<module>() 	Emissions Data Ended
[2024-02-01 01:50:23,341] 	INFO 	20 	id_data.py 	<module>() 	ID Data Started
[2024-02-01 01:50:23,778] 	INFO 	31 	id_data.py 	<module>() 	ID Data Ended
[2024-02-01 01:50:24,405] 	INFO 	24 	day_data.py 	<module>() 	Day Data Fusion Started
[2024-02-01 01:50:26,098] 	INFO 	71 	day_data.py 	<module>() 	Day Data Fusion Ended
[2024-02-01 01:50:27,169] 	INFO 	35 	pair_data.py 	<module>() 	Pair Data Fusion Started
[2024-02-01 01:50:41,559] 	INFO 	101 	pair_data.py 	<module>() 	Pair Data Fusion Ended
[2024-02-01 01:50:42,385] 	INFO 	36 	bribe_data.py 	<module>() 	Bribe Data Started
[2024-02-01 01:53:34,195] 	INFO 	157 	bribe_data.py 	<module>() 	Bribe Data Ended
[2024-02-01 01:53:35,065] 	INFO 	36 	fee_data.py 	<module>() 	Fee Data Started
[2024-02-01 01:55:34,528] 	INFO 	157 	fee_data.py 	<module>() 	Fee Data Ended
[2024-02-01 01:55:35,397] 	INFO 	37 	vote_data.py 	<module>() 	Vote Data Started
[2024-02-01 01:55:46,157] 	INFO 	116 	vote_data.py 	<module>() 	Vote Data Ended
[2024-02-01 01:55:47,038] 	INFO 	30 	revenue_data.py 	<module>() 	Revenue Data Started
[2024-02-01 01:55:58,494] 	INFO 	150 	revenue_data.py 	<module>() 	Revenue Data Ended
[2024-02-01 01:55:59,269] 	INFO 	20 	pool_data.py 	<module>() 	Pool Data Started
[2024-02-01 01:56:07,906] 	ERROR 	82 	pool_data.py 	<module>() 	Error occurred during Pool Data process. Error: {'code': -32000, 'message': 'execution aborted (timeout = 5s)'}
Traceback (most recent call last):
  File "pool_data.py", line 53, in <module>
    pool_data = contract_instance.functions.getActivePoolDistributions(pool_address).call()
  File "/opt/hostedtoolcache/Python/3.8.18/x64/lib/python3.8/site-packages/web3/contract.py", line 970, in call
    return call_contract_function(
  File "/opt/hostedtoolcache/Python/3.8.18/x64/lib/python3.8/site-packages/web3/contract.py", line 1525, in call_contract_function
    return_data = web3.eth.call(
  File "/opt/hostedtoolcache/Python/3.8.18/x64/lib/python3.8/site-packages/web3/module.py", line 57, in caller
    result = w3.manager.request_blocking(method_str,
  File "/opt/hostedtoolcache/Python/3.8.18/x64/lib/python3.8/site-packages/web3/manager.py", line 198, in request_blocking
    return self.formatted_response(response,
  File "/opt/hostedtoolcache/Python/3.8.18/x64/lib/python3.8/site-packages/web3/manager.py", line 171, in formatted_response
    raise ValueError(response["error"])
ValueError: {'code': -32000, 'message': 'execution aborted (timeout = 5s)'}
[2024-02-01 02:20:51,943] 	INFO 	20 	id_data.py 	<module>() 	ID Data Started
[2024-02-01 02:20:52,265] 	INFO 	31 	id_data.py 	<module>() 	ID Data Ended
[2024-02-01 02:20:52,801] 	INFO 	24 	day_data.py 	<module>() 	Day Data Fusion Started
[2024-02-01 02:20:54,853] 	INFO 	71 	day_data.py 	<module>() 	Day Data Fusion Ended
[2024-02-01 02:20:55,689] 	INFO 	35 	pair_data.py 	<module>() 	Pair Data Fusion Started
[2024-02-01 02:21:10,826] 	INFO 	101 	pair_data.py 	<module>() 	Pair Data Fusion Ended
[2024-02-01 02:21:11,651] 	INFO 	36 	bribe_data.py 	<module>() 	Bribe Data Started
[2024-02-01 02:23:34,213] 	INFO 	157 	bribe_data.py 	<module>() 	Bribe Data Ended
[2024-02-01 02:23:35,021] 	INFO 	36 	fee_data.py 	<module>() 	Fee Data Started
[2024-02-01 02:25:31,168] 	INFO 	157 	fee_data.py 	<module>() 	Fee Data Ended
[2024-02-01 02:25:31,998] 	INFO 	37 	vote_data.py 	<module>() 	Vote Data Started
[2024-02-01 02:25:40,496] 	INFO 	116 	vote_data.py 	<module>() 	Vote Data Ended
[2024-02-01 02:25:41,323] 	INFO 	30 	revenue_data.py 	<module>() 	Revenue Data Started
[2024-02-01 02:25:56,372] 	INFO 	150 	revenue_data.py 	<module>() 	Revenue Data Ended
[2024-02-01 02:25:57,102] 	INFO 	20 	pool_data.py 	<module>() 	Pool Data Started
[2024-02-01 02:26:08,138] 	ERROR 	82 	pool_data.py 	<module>() 	Error occurred during Pool Data process. Error: {'code': -32000, 'message': 'execution aborted (timeout = 5s)'}
Traceback (most recent call last):
  File "pool_data.py", line 53, in <module>
    pool_data = contract_instance.functions.getActivePoolDistributions(pool_address).call()
  File "/opt/hostedtoolcache/Python/3.8.18/x64/lib/python3.8/site-packages/web3/contract.py", line 970, in call
    return call_contract_function(
  File "/opt/hostedtoolcache/Python/3.8.18/x64/lib/python3.8/site-packages/web3/contract.py", line 1525, in call_contract_function
    return_data = web3.eth.call(
  File "/opt/hostedtoolcache/Python/3.8.18/x64/lib/python3.8/site-packages/web3/module.py", line 57, in caller
    result = w3.manager.request_blocking(method_str,
  File "/opt/hostedtoolcache/Python/3.8.18/x64/lib/python3.8/site-packages/web3/manager.py", line 198, in request_blocking
    return self.formatted_response(response,
  File "/opt/hostedtoolcache/Python/3.8.18/x64/lib/python3.8/site-packages/web3/manager.py", line 171, in formatted_response
    raise ValueError(response["error"])
ValueError: {'code': -32000, 'message': 'execution aborted (timeout = 5s)'}
[2024-02-01 02:27:07,700] 	INFO 	29 	partner_data.py 	<module>() 	Partner Vote Data Started
[2024-02-01 02:27:24,138] 	INFO 	196 	partner_data.py 	<module>() 	Partner Vote Data Ended
[2024-02-01 02:27:24,931] 	INFO 	24 	apr_data.py 	<module>() 	APR Data Started
[2024-02-01 02:27:26,807] 	INFO 	101 	apr_data.py 	<module>() 	APR Data Ended
[2024-02-01 02:37:10,683] 	INFO 	20 	id_data.py 	<module>() 	ID Data Started
[2024-02-01 02:37:11,249] 	INFO 	31 	id_data.py 	<module>() 	ID Data Ended
[2024-02-01 02:37:11,781] 	INFO 	24 	day_data.py 	<module>() 	Day Data Fusion Started
[2024-02-01 02:37:15,189] 	INFO 	71 	day_data.py 	<module>() 	Day Data Fusion Ended
[2024-02-01 02:37:16,237] 	INFO 	35 	pair_data.py 	<module>() 	Pair Data Fusion Started
[2024-02-01 02:37:33,446] 	INFO 	101 	pair_data.py 	<module>() 	Pair Data Fusion Ended
[2024-02-01 02:37:34,251] 	INFO 	36 	bribe_data.py 	<module>() 	Bribe Data Started
[2024-02-01 02:39:55,328] 	INFO 	157 	bribe_data.py 	<module>() 	Bribe Data Ended
[2024-02-01 02:39:56,129] 	INFO 	36 	fee_data.py 	<module>() 	Fee Data Started
[2024-02-01 02:45:41,041] 	INFO 	157 	fee_data.py 	<module>() 	Fee Data Ended
[2024-02-01 02:45:41,840] 	INFO 	37 	vote_data.py 	<module>() 	Vote Data Started
[2024-02-01 02:45:51,494] 	INFO 	116 	vote_data.py 	<module>() 	Vote Data Ended
[2024-02-01 02:45:52,340] 	INFO 	30 	revenue_data.py 	<module>() 	Revenue Data Started
[2024-02-01 02:46:05,679] 	INFO 	150 	revenue_data.py 	<module>() 	Revenue Data Ended
[2024-02-01 02:46:06,411] 	INFO 	20 	pool_data.py 	<module>() 	Pool Data Started
[2024-02-01 02:46:17,564] 	ERROR 	82 	pool_data.py 	<module>() 	Error occurred during Pool Data process. Error: {'code': -32000, 'message': 'execution aborted (timeout = 5s)'}
Traceback (most recent call last):
  File "pool_data.py", line 53, in <module>
    pool_data = contract_instance.functions.getActivePoolDistributions(pool_address).call()
  File "/opt/hostedtoolcache/Python/3.8.18/x64/lib/python3.8/site-packages/web3/contract.py", line 970, in call
    return call_contract_function(
  File "/opt/hostedtoolcache/Python/3.8.18/x64/lib/python3.8/site-packages/web3/contract.py", line 1525, in call_contract_function
    return_data = web3.eth.call(
  File "/opt/hostedtoolcache/Python/3.8.18/x64/lib/python3.8/site-packages/web3/module.py", line 57, in caller
    result = w3.manager.request_blocking(method_str,
  File "/opt/hostedtoolcache/Python/3.8.18/x64/lib/python3.8/site-packages/web3/manager.py", line 198, in request_blocking
    return self.formatted_response(response,
  File "/opt/hostedtoolcache/Python/3.8.18/x64/lib/python3.8/site-packages/web3/manager.py", line 171, in formatted_response
    raise ValueError(response["error"])
ValueError: {'code': -32000, 'message': 'execution aborted (timeout = 5s)'}
[2024-02-01 02:49:28,377] 	INFO 	20 	id_data.py 	<module>() 	ID Data Started
[2024-02-01 02:49:28,639] 	INFO 	31 	id_data.py 	<module>() 	ID Data Ended
[2024-02-01 02:49:29,294] 	INFO 	24 	day_data.py 	<module>() 	Day Data Fusion Started
[2024-02-01 02:49:32,655] 	INFO 	71 	day_data.py 	<module>() 	Day Data Fusion Ended
[2024-02-01 02:49:33,786] 	INFO 	35 	pair_data.py 	<module>() 	Pair Data Fusion Started
[2024-02-01 02:49:45,576] 	INFO 	101 	pair_data.py 	<module>() 	Pair Data Fusion Ended
[2024-02-01 02:49:46,356] 	INFO 	36 	bribe_data.py 	<module>() 	Bribe Data Started
[2024-02-01 02:52:20,284] 	INFO 	157 	bribe_data.py 	<module>() 	Bribe Data Ended
[2024-02-01 02:52:21,052] 	INFO 	36 	fee_data.py 	<module>() 	Fee Data Started
[2024-02-01 02:54:21,212] 	INFO 	157 	fee_data.py 	<module>() 	Fee Data Ended
[2024-02-01 02:54:21,981] 	INFO 	37 	vote_data.py 	<module>() 	Vote Data Started
[2024-02-01 02:54:31,633] 	INFO 	116 	vote_data.py 	<module>() 	Vote Data Ended
[2024-02-01 02:54:32,415] 	INFO 	30 	revenue_data.py 	<module>() 	Revenue Data Started
[2024-02-01 02:54:38,112] 	INFO 	150 	revenue_data.py 	<module>() 	Revenue Data Ended
[2024-02-01 02:54:38,795] 	INFO 	20 	pool_data.py 	<module>() 	Pool Data Started
[2024-02-01 02:54:44,130] 	ERROR 	82 	pool_data.py 	<module>() 	Error occurred during Pool Data process. Error: execution reverted
Traceback (most recent call last):
  File "pool_data.py", line 53, in <module>
    pool_data = contract_instance.functions.getActivePoolDistributions(pool_address).call()
  File "/opt/hostedtoolcache/Python/3.8.18/x64/lib/python3.8/site-packages/web3/contract.py", line 970, in call
    return call_contract_function(
  File "/opt/hostedtoolcache/Python/3.8.18/x64/lib/python3.8/site-packages/web3/contract.py", line 1525, in call_contract_function
    return_data = web3.eth.call(
  File "/opt/hostedtoolcache/Python/3.8.18/x64/lib/python3.8/site-packages/web3/module.py", line 57, in caller
    result = w3.manager.request_blocking(method_str,
  File "/opt/hostedtoolcache/Python/3.8.18/x64/lib/python3.8/site-packages/web3/manager.py", line 198, in request_blocking
    return self.formatted_response(response,
  File "/opt/hostedtoolcache/Python/3.8.18/x64/lib/python3.8/site-packages/web3/manager.py", line 170, in formatted_response
    apply_error_formatters(error_formatters, response)
  File "/opt/hostedtoolcache/Python/3.8.18/x64/lib/python3.8/site-packages/web3/manager.py", line 70, in apply_error_formatters
    formatted_resp = pipe(response, error_formatters)
  File "cytoolz/functoolz.pyx", line 680, in cytoolz.functoolz.pipe
  File "cytoolz/functoolz.pyx", line 655, in cytoolz.functoolz.c_pipe
  File "/opt/hostedtoolcache/Python/3.8.18/x64/lib/python3.8/site-packages/web3/_utils/method_formatters.py", line 580, in raise_solidity_error_on_revert
    raise ContractLogicError('execution reverted')
web3.exceptions.ContractLogicError: execution reverted
[2024-02-01 03:12:17,278] 	INFO 	20 	id_data.py 	<module>() 	ID Data Started
[2024-02-01 03:12:17,535] 	INFO 	31 	id_data.py 	<module>() 	ID Data Ended
[2024-02-01 03:12:18,181] 	INFO 	24 	day_data.py 	<module>() 	Day Data Fusion Started
[2024-02-01 03:12:22,012] 	INFO 	71 	day_data.py 	<module>() 	Day Data Fusion Ended
[2024-02-01 03:12:23,063] 	INFO 	35 	pair_data.py 	<module>() 	Pair Data Fusion Started
[2024-02-01 03:12:53,226] 	INFO 	101 	pair_data.py 	<module>() 	Pair Data Fusion Ended
[2024-02-01 03:12:54,059] 	INFO 	36 	bribe_data.py 	<module>() 	Bribe Data Started
[2024-02-01 03:14:58,865] 	INFO 	157 	bribe_data.py 	<module>() 	Bribe Data Ended
[2024-02-01 03:14:59,676] 	INFO 	36 	fee_data.py 	<module>() 	Fee Data Started
[2024-02-01 03:17:11,496] 	INFO 	157 	fee_data.py 	<module>() 	Fee Data Ended
[2024-02-01 03:17:12,302] 	INFO 	37 	vote_data.py 	<module>() 	Vote Data Started
[2024-02-01 03:17:21,987] 	INFO 	116 	vote_data.py 	<module>() 	Vote Data Ended
[2024-02-01 03:17:22,792] 	INFO 	30 	revenue_data.py 	<module>() 	Revenue Data Started
[2024-02-01 03:17:38,506] 	INFO 	150 	revenue_data.py 	<module>() 	Revenue Data Ended
[2024-02-01 03:17:39,210] 	INFO 	20 	pool_data.py 	<module>() 	Pool Data Started
[2024-02-01 03:17:47,273] 	ERROR 	82 	pool_data.py 	<module>() 	Error occurred during Pool Data process. Error: execution reverted
Traceback (most recent call last):
  File "pool_data.py", line 53, in <module>
    pool_data = contract_instance.functions.getActivePoolDistributions(pool_address).call()
  File "/opt/hostedtoolcache/Python/3.8.18/x64/lib/python3.8/site-packages/web3/contract.py", line 970, in call
    return call_contract_function(
  File "/opt/hostedtoolcache/Python/3.8.18/x64/lib/python3.8/site-packages/web3/contract.py", line 1525, in call_contract_function
    return_data = web3.eth.call(
  File "/opt/hostedtoolcache/Python/3.8.18/x64/lib/python3.8/site-packages/web3/module.py", line 57, in caller
    result = w3.manager.request_blocking(method_str,
  File "/opt/hostedtoolcache/Python/3.8.18/x64/lib/python3.8/site-packages/web3/manager.py", line 198, in request_blocking
    return self.formatted_response(response,
  File "/opt/hostedtoolcache/Python/3.8.18/x64/lib/python3.8/site-packages/web3/manager.py", line 170, in formatted_response
    apply_error_formatters(error_formatters, response)
  File "/opt/hostedtoolcache/Python/3.8.18/x64/lib/python3.8/site-packages/web3/manager.py", line 70, in apply_error_formatters
    formatted_resp = pipe(response, error_formatters)
  File "cytoolz/functoolz.pyx", line 680, in cytoolz.functoolz.pipe
  File "cytoolz/functoolz.pyx", line 655, in cytoolz.functoolz.c_pipe
  File "/opt/hostedtoolcache/Python/3.8.18/x64/lib/python3.8/site-packages/web3/_utils/method_formatters.py", line 580, in raise_solidity_error_on_revert
    raise ContractLogicError('execution reverted')
web3.exceptions.ContractLogicError: execution reverted
[2024-02-01 03:23:55,802] 	INFO 	20 	id_data.py 	<module>() 	ID Data Started
[2024-02-01 03:23:56,283] 	INFO 	31 	id_data.py 	<module>() 	ID Data Ended
[2024-02-01 03:23:56,812] 	INFO 	24 	day_data.py 	<module>() 	Day Data Fusion Started
[2024-02-01 03:23:58,569] 	INFO 	71 	day_data.py 	<module>() 	Day Data Fusion Ended
[2024-02-01 03:23:59,407] 	INFO 	35 	pair_data.py 	<module>() 	Pair Data Fusion Started
[2024-02-01 03:24:13,272] 	INFO 	101 	pair_data.py 	<module>() 	Pair Data Fusion Ended
[2024-02-01 03:24:14,064] 	INFO 	36 	bribe_data.py 	<module>() 	Bribe Data Started
[2024-02-01 03:27:18,804] 	INFO 	157 	bribe_data.py 	<module>() 	Bribe Data Ended
[2024-02-01 03:27:19,652] 	INFO 	36 	fee_data.py 	<module>() 	Fee Data Started
[2024-02-01 03:29:03,482] 	INFO 	157 	fee_data.py 	<module>() 	Fee Data Ended
[2024-02-01 03:29:04,288] 	INFO 	37 	vote_data.py 	<module>() 	Vote Data Started
[2024-02-01 03:29:13,016] 	INFO 	116 	vote_data.py 	<module>() 	Vote Data Ended
[2024-02-01 03:29:13,842] 	INFO 	30 	revenue_data.py 	<module>() 	Revenue Data Started
[2024-02-01 03:29:27,833] 	INFO 	150 	revenue_data.py 	<module>() 	Revenue Data Ended
[2024-02-01 03:29:28,571] 	INFO 	20 	pool_data.py 	<module>() 	Pool Data Started
[2024-02-01 03:29:37,848] 	ERROR 	82 	pool_data.py 	<module>() 	Error occurred during Pool Data process. Error: {'code': -32000, 'message': 'execution aborted (timeout = 5s)'}
Traceback (most recent call last):
  File "pool_data.py", line 53, in <module>
    pool_data = contract_instance.functions.getActivePoolDistributions(pool_address).call()
  File "/opt/hostedtoolcache/Python/3.8.18/x64/lib/python3.8/site-packages/web3/contract.py", line 970, in call
    return call_contract_function(
  File "/opt/hostedtoolcache/Python/3.8.18/x64/lib/python3.8/site-packages/web3/contract.py", line 1525, in call_contract_function
    return_data = web3.eth.call(
  File "/opt/hostedtoolcache/Python/3.8.18/x64/lib/python3.8/site-packages/web3/module.py", line 57, in caller
    result = w3.manager.request_blocking(method_str,
  File "/opt/hostedtoolcache/Python/3.8.18/x64/lib/python3.8/site-packages/web3/manager.py", line 198, in request_blocking
    return self.formatted_response(response,
  File "/opt/hostedtoolcache/Python/3.8.18/x64/lib/python3.8/site-packages/web3/manager.py", line 171, in formatted_response
    raise ValueError(response["error"])
ValueError: {'code': -32000, 'message': 'execution aborted (timeout = 5s)'}
[2024-02-01 03:35:47,746] 	INFO 	20 	id_data.py 	<module>() 	ID Data Started
[2024-02-01 03:35:48,605] 	INFO 	31 	id_data.py 	<module>() 	ID Data Ended
[2024-02-01 03:35:49,284] 	INFO 	24 	day_data.py 	<module>() 	Day Data Fusion Started
[2024-02-01 03:35:51,007] 	INFO 	71 	day_data.py 	<module>() 	Day Data Fusion Ended
[2024-02-01 03:35:52,140] 	INFO 	35 	pair_data.py 	<module>() 	Pair Data Fusion Started
[2024-02-01 03:36:06,578] 	INFO 	101 	pair_data.py 	<module>() 	Pair Data Fusion Ended
[2024-02-01 03:36:07,413] 	INFO 	36 	bribe_data.py 	<module>() 	Bribe Data Started
[2024-02-01 03:38:37,357] 	INFO 	157 	bribe_data.py 	<module>() 	Bribe Data Ended
[2024-02-01 03:38:38,147] 	INFO 	36 	fee_data.py 	<module>() 	Fee Data Started
[2024-02-01 03:40:45,203] 	INFO 	157 	fee_data.py 	<module>() 	Fee Data Ended
[2024-02-01 03:40:46,019] 	INFO 	37 	vote_data.py 	<module>() 	Vote Data Started
[2024-02-01 03:40:55,314] 	INFO 	116 	vote_data.py 	<module>() 	Vote Data Ended
[2024-02-01 03:40:56,126] 	INFO 	30 	revenue_data.py 	<module>() 	Revenue Data Started
[2024-02-01 03:41:09,878] 	INFO 	150 	revenue_data.py 	<module>() 	Revenue Data Ended
[2024-02-01 03:41:10,576] 	INFO 	20 	pool_data.py 	<module>() 	Pool Data Started
[2024-02-01 03:41:19,289] 	ERROR 	82 	pool_data.py 	<module>() 	Error occurred during Pool Data process. Error: {'code': -32000, 'message': 'execution aborted (timeout = 5s)'}
Traceback (most recent call last):
  File "pool_data.py", line 53, in <module>
    pool_data = contract_instance.functions.getActivePoolDistributions(pool_address).call()
  File "/opt/hostedtoolcache/Python/3.8.18/x64/lib/python3.8/site-packages/web3/contract.py", line 970, in call
    return call_contract_function(
  File "/opt/hostedtoolcache/Python/3.8.18/x64/lib/python3.8/site-packages/web3/contract.py", line 1525, in call_contract_function
    return_data = web3.eth.call(
  File "/opt/hostedtoolcache/Python/3.8.18/x64/lib/python3.8/site-packages/web3/module.py", line 57, in caller
    result = w3.manager.request_blocking(method_str,
  File "/opt/hostedtoolcache/Python/3.8.18/x64/lib/python3.8/site-packages/web3/manager.py", line 198, in request_blocking
    return self.formatted_response(response,
  File "/opt/hostedtoolcache/Python/3.8.18/x64/lib/python3.8/site-packages/web3/manager.py", line 171, in formatted_response
    raise ValueError(response["error"])
ValueError: {'code': -32000, 'message': 'execution aborted (timeout = 5s)'}
[2024-02-01 03:49:10,308] 	INFO 	20 	id_data.py 	<module>() 	ID Data Started
[2024-02-01 03:49:10,646] 	INFO 	31 	id_data.py 	<module>() 	ID Data Ended
[2024-02-01 03:49:11,283] 	INFO 	24 	day_data.py 	<module>() 	Day Data Fusion Started
[2024-02-01 03:49:13,109] 	INFO 	71 	day_data.py 	<module>() 	Day Data Fusion Ended
[2024-02-01 03:49:14,265] 	INFO 	35 	pair_data.py 	<module>() 	Pair Data Fusion Started
[2024-02-01 03:49:28,042] 	INFO 	101 	pair_data.py 	<module>() 	Pair Data Fusion Ended
[2024-02-01 03:49:28,882] 	INFO 	36 	bribe_data.py 	<module>() 	Bribe Data Started
[2024-02-01 03:51:59,120] 	INFO 	157 	bribe_data.py 	<module>() 	Bribe Data Ended
[2024-02-01 03:51:59,917] 	INFO 	36 	fee_data.py 	<module>() 	Fee Data Started
[2024-02-01 03:54:01,075] 	INFO 	157 	fee_data.py 	<module>() 	Fee Data Ended
[2024-02-01 03:54:01,854] 	INFO 	37 	vote_data.py 	<module>() 	Vote Data Started
[2024-02-01 03:54:40,391] 	INFO 	116 	vote_data.py 	<module>() 	Vote Data Ended
[2024-02-01 03:54:41,192] 	INFO 	30 	revenue_data.py 	<module>() 	Revenue Data Started
[2024-02-01 03:54:53,610] 	INFO 	150 	revenue_data.py 	<module>() 	Revenue Data Ended
[2024-02-01 03:54:54,326] 	INFO 	20 	pool_data.py 	<module>() 	Pool Data Started
[2024-02-01 03:55:00,138] 	ERROR 	82 	pool_data.py 	<module>() 	Error occurred during Pool Data process. Error: {'code': -32000, 'message': 'execution aborted (timeout = 5s)'}
Traceback (most recent call last):
  File "pool_data.py", line 53, in <module>
    pool_data = contract_instance.functions.getActivePoolDistributions(pool_address).call()
  File "/opt/hostedtoolcache/Python/3.8.18/x64/lib/python3.8/site-packages/web3/contract.py", line 970, in call
    return call_contract_function(
  File "/opt/hostedtoolcache/Python/3.8.18/x64/lib/python3.8/site-packages/web3/contract.py", line 1525, in call_contract_function
    return_data = web3.eth.call(
  File "/opt/hostedtoolcache/Python/3.8.18/x64/lib/python3.8/site-packages/web3/module.py", line 57, in caller
    result = w3.manager.request_blocking(method_str,
  File "/opt/hostedtoolcache/Python/3.8.18/x64/lib/python3.8/site-packages/web3/manager.py", line 198, in request_blocking
    return self.formatted_response(response,
  File "/opt/hostedtoolcache/Python/3.8.18/x64/lib/python3.8/site-packages/web3/manager.py", line 171, in formatted_response
    raise ValueError(response["error"])
ValueError: {'code': -32000, 'message': 'execution aborted (timeout = 5s)'}
[2024-02-01 04:14:35,661] 	INFO 	20 	id_data.py 	<module>() 	ID Data Started
[2024-02-01 04:14:36,118] 	INFO 	31 	id_data.py 	<module>() 	ID Data Ended
[2024-02-01 04:14:36,808] 	INFO 	24 	day_data.py 	<module>() 	Day Data Fusion Started
[2024-02-01 04:14:40,164] 	INFO 	71 	day_data.py 	<module>() 	Day Data Fusion Ended
[2024-02-01 04:14:41,309] 	INFO 	35 	pair_data.py 	<module>() 	Pair Data Fusion Started
[2024-02-01 04:14:56,860] 	INFO 	101 	pair_data.py 	<module>() 	Pair Data Fusion Ended
[2024-02-01 04:14:57,666] 	INFO 	36 	bribe_data.py 	<module>() 	Bribe Data Started
[2024-02-01 04:17:01,585] 	INFO 	157 	bribe_data.py 	<module>() 	Bribe Data Ended
[2024-02-01 04:17:02,363] 	INFO 	36 	fee_data.py 	<module>() 	Fee Data Started
[2024-02-01 04:18:43,887] 	INFO 	157 	fee_data.py 	<module>() 	Fee Data Ended
[2024-02-01 04:18:44,667] 	INFO 	37 	vote_data.py 	<module>() 	Vote Data Started
[2024-02-01 04:18:53,898] 	INFO 	116 	vote_data.py 	<module>() 	Vote Data Ended
[2024-02-01 04:18:54,689] 	INFO 	30 	revenue_data.py 	<module>() 	Revenue Data Started
[2024-02-01 04:19:07,822] 	INFO 	150 	revenue_data.py 	<module>() 	Revenue Data Ended
[2024-02-01 04:19:08,517] 	INFO 	20 	pool_data.py 	<module>() 	Pool Data Started
[2024-02-01 04:19:19,254] 	ERROR 	82 	pool_data.py 	<module>() 	Error occurred during Pool Data process. Error: {'code': -32000, 'message': 'execution aborted (timeout = 5s)'}
Traceback (most recent call last):
  File "pool_data.py", line 53, in <module>
    pool_data = contract_instance.functions.getActivePoolDistributions(pool_address).call()
  File "/opt/hostedtoolcache/Python/3.8.18/x64/lib/python3.8/site-packages/web3/contract.py", line 970, in call
    return call_contract_function(
  File "/opt/hostedtoolcache/Python/3.8.18/x64/lib/python3.8/site-packages/web3/contract.py", line 1525, in call_contract_function
    return_data = web3.eth.call(
  File "/opt/hostedtoolcache/Python/3.8.18/x64/lib/python3.8/site-packages/web3/module.py", line 57, in caller
    result = w3.manager.request_blocking(method_str,
  File "/opt/hostedtoolcache/Python/3.8.18/x64/lib/python3.8/site-packages/web3/manager.py", line 198, in request_blocking
    return self.formatted_response(response,
  File "/opt/hostedtoolcache/Python/3.8.18/x64/lib/python3.8/site-packages/web3/manager.py", line 171, in formatted_response
    raise ValueError(response["error"])
ValueError: {'code': -32000, 'message': 'execution aborted (timeout = 5s)'}
[2024-02-01 04:28:58,477] 	INFO 	20 	id_data.py 	<module>() 	ID Data Started
[2024-02-01 04:28:58,853] 	INFO 	31 	id_data.py 	<module>() 	ID Data Ended
[2024-02-01 04:28:59,356] 	INFO 	24 	day_data.py 	<module>() 	Day Data Fusion Started
[2024-02-01 04:29:00,816] 	INFO 	71 	day_data.py 	<module>() 	Day Data Fusion Ended
[2024-02-01 04:29:01,673] 	INFO 	35 	pair_data.py 	<module>() 	Pair Data Fusion Started
[2024-02-01 04:29:24,468] 	INFO 	101 	pair_data.py 	<module>() 	Pair Data Fusion Ended
[2024-02-01 04:29:25,255] 	INFO 	36 	bribe_data.py 	<module>() 	Bribe Data Started
[2024-02-01 04:31:45,180] 	INFO 	157 	bribe_data.py 	<module>() 	Bribe Data Ended
[2024-02-01 04:31:45,973] 	INFO 	36 	fee_data.py 	<module>() 	Fee Data Started
[2024-02-01 04:33:30,163] 	INFO 	157 	fee_data.py 	<module>() 	Fee Data Ended
[2024-02-01 04:33:30,956] 	INFO 	37 	vote_data.py 	<module>() 	Vote Data Started
[2024-02-01 04:33:38,986] 	INFO 	116 	vote_data.py 	<module>() 	Vote Data Ended
[2024-02-01 04:33:39,790] 	INFO 	30 	revenue_data.py 	<module>() 	Revenue Data Started
[2024-02-01 04:33:44,228] 	INFO 	150 	revenue_data.py 	<module>() 	Revenue Data Ended
[2024-02-01 04:33:44,921] 	INFO 	20 	pool_data.py 	<module>() 	Pool Data Started
[2024-02-01 04:33:50,750] 	ERROR 	82 	pool_data.py 	<module>() 	Error occurred during Pool Data process. Error: {'code': -32000, 'message': 'execution aborted (timeout = 5s)'}
Traceback (most recent call last):
  File "pool_data.py", line 53, in <module>
    pool_data = contract_instance.functions.getActivePoolDistributions(pool_address).call()
  File "/opt/hostedtoolcache/Python/3.8.18/x64/lib/python3.8/site-packages/web3/contract.py", line 970, in call
    return call_contract_function(
  File "/opt/hostedtoolcache/Python/3.8.18/x64/lib/python3.8/site-packages/web3/contract.py", line 1525, in call_contract_function
    return_data = web3.eth.call(
  File "/opt/hostedtoolcache/Python/3.8.18/x64/lib/python3.8/site-packages/web3/module.py", line 57, in caller
    result = w3.manager.request_blocking(method_str,
  File "/opt/hostedtoolcache/Python/3.8.18/x64/lib/python3.8/site-packages/web3/manager.py", line 198, in request_blocking
    return self.formatted_response(response,
  File "/opt/hostedtoolcache/Python/3.8.18/x64/lib/python3.8/site-packages/web3/manager.py", line 171, in formatted_response
    raise ValueError(response["error"])
ValueError: {'code': -32000, 'message': 'execution aborted (timeout = 5s)'}
[2024-02-01 04:37:48,357] 	INFO 	20 	id_data.py 	<module>() 	ID Data Started
[2024-02-01 04:37:48,679] 	INFO 	31 	id_data.py 	<module>() 	ID Data Ended
[2024-02-01 04:37:49,289] 	INFO 	24 	day_data.py 	<module>() 	Day Data Fusion Started
[2024-02-01 04:37:50,849] 	INFO 	71 	day_data.py 	<module>() 	Day Data Fusion Ended
[2024-02-01 04:37:51,735] 	INFO 	35 	pair_data.py 	<module>() 	Pair Data Fusion Started
[2024-02-01 04:38:04,852] 	INFO 	101 	pair_data.py 	<module>() 	Pair Data Fusion Ended
[2024-02-01 04:38:05,642] 	INFO 	36 	bribe_data.py 	<module>() 	Bribe Data Started
[2024-02-01 04:40:12,639] 	INFO 	157 	bribe_data.py 	<module>() 	Bribe Data Ended
[2024-02-01 04:40:13,437] 	INFO 	36 	fee_data.py 	<module>() 	Fee Data Started
[2024-02-01 04:41:44,261] 	INFO 	157 	fee_data.py 	<module>() 	Fee Data Ended
[2024-02-01 04:41:45,054] 	INFO 	37 	vote_data.py 	<module>() 	Vote Data Started
[2024-02-01 04:41:53,137] 	INFO 	116 	vote_data.py 	<module>() 	Vote Data Ended
[2024-02-01 04:41:53,950] 	INFO 	30 	revenue_data.py 	<module>() 	Revenue Data Started
[2024-02-01 04:41:57,719] 	INFO 	150 	revenue_data.py 	<module>() 	Revenue Data Ended
[2024-02-01 04:41:58,416] 	INFO 	20 	pool_data.py 	<module>() 	Pool Data Started
[2024-02-01 04:42:04,022] 	ERROR 	82 	pool_data.py 	<module>() 	Error occurred during Pool Data process. Error: {'code': -32000, 'message': 'execution aborted (timeout = 5s)'}
Traceback (most recent call last):
  File "pool_data.py", line 53, in <module>
    pool_data = contract_instance.functions.getActivePoolDistributions(pool_address).call()
  File "/opt/hostedtoolcache/Python/3.8.18/x64/lib/python3.8/site-packages/web3/contract.py", line 970, in call
    return call_contract_function(
  File "/opt/hostedtoolcache/Python/3.8.18/x64/lib/python3.8/site-packages/web3/contract.py", line 1525, in call_contract_function
    return_data = web3.eth.call(
  File "/opt/hostedtoolcache/Python/3.8.18/x64/lib/python3.8/site-packages/web3/module.py", line 57, in caller
    result = w3.manager.request_blocking(method_str,
  File "/opt/hostedtoolcache/Python/3.8.18/x64/lib/python3.8/site-packages/web3/manager.py", line 198, in request_blocking
    return self.formatted_response(response,
  File "/opt/hostedtoolcache/Python/3.8.18/x64/lib/python3.8/site-packages/web3/manager.py", line 171, in formatted_response
    raise ValueError(response["error"])
ValueError: {'code': -32000, 'message': 'execution aborted (timeout = 5s)'}
[2024-02-01 04:49:12,555] 	INFO 	20 	id_data.py 	<module>() 	ID Data Started
[2024-02-01 04:49:12,880] 	INFO 	31 	id_data.py 	<module>() 	ID Data Ended
[2024-02-01 04:49:13,633] 	INFO 	24 	day_data.py 	<module>() 	Day Data Fusion Started
[2024-02-01 04:49:15,601] 	INFO 	71 	day_data.py 	<module>() 	Day Data Fusion Ended
[2024-02-01 04:49:16,879] 	INFO 	35 	pair_data.py 	<module>() 	Pair Data Fusion Started
[2024-02-01 04:49:30,933] 	INFO 	101 	pair_data.py 	<module>() 	Pair Data Fusion Ended
[2024-02-01 04:49:31,736] 	INFO 	36 	bribe_data.py 	<module>() 	Bribe Data Started
[2024-02-01 04:51:45,287] 	INFO 	157 	bribe_data.py 	<module>() 	Bribe Data Ended
[2024-02-01 04:51:46,104] 	INFO 	36 	fee_data.py 	<module>() 	Fee Data Started
[2024-02-01 04:53:29,458] 	INFO 	157 	fee_data.py 	<module>() 	Fee Data Ended
[2024-02-01 04:53:30,302] 	INFO 	37 	vote_data.py 	<module>() 	Vote Data Started
[2024-02-01 04:53:38,418] 	INFO 	116 	vote_data.py 	<module>() 	Vote Data Ended
[2024-02-01 04:53:39,256] 	INFO 	30 	revenue_data.py 	<module>() 	Revenue Data Started
[2024-02-01 04:53:43,851] 	INFO 	150 	revenue_data.py 	<module>() 	Revenue Data Ended
[2024-02-01 04:53:44,578] 	INFO 	20 	pool_data.py 	<module>() 	Pool Data Started
[2024-02-01 04:53:53,012] 	ERROR 	82 	pool_data.py 	<module>() 	Error occurred during Pool Data process. Error: {'code': -32000, 'message': 'execution aborted (timeout = 5s)'}
Traceback (most recent call last):
  File "pool_data.py", line 53, in <module>
    pool_data = contract_instance.functions.getActivePoolDistributions(pool_address).call()
  File "/opt/hostedtoolcache/Python/3.8.18/x64/lib/python3.8/site-packages/web3/contract.py", line 970, in call
    return call_contract_function(
  File "/opt/hostedtoolcache/Python/3.8.18/x64/lib/python3.8/site-packages/web3/contract.py", line 1525, in call_contract_function
    return_data = web3.eth.call(
  File "/opt/hostedtoolcache/Python/3.8.18/x64/lib/python3.8/site-packages/web3/module.py", line 57, in caller
    result = w3.manager.request_blocking(method_str,
  File "/opt/hostedtoolcache/Python/3.8.18/x64/lib/python3.8/site-packages/web3/manager.py", line 198, in request_blocking
    return self.formatted_response(response,
  File "/opt/hostedtoolcache/Python/3.8.18/x64/lib/python3.8/site-packages/web3/manager.py", line 171, in formatted_response
    raise ValueError(response["error"])
ValueError: {'code': -32000, 'message': 'execution aborted (timeout = 5s)'}
[2024-02-01 05:10:26,422] 	INFO 	20 	id_data.py 	<module>() 	ID Data Started
[2024-02-01 05:10:26,832] 	INFO 	31 	id_data.py 	<module>() 	ID Data Ended
[2024-02-01 05:10:27,420] 	INFO 	24 	day_data.py 	<module>() 	Day Data Fusion Started
[2024-02-01 05:10:29,169] 	INFO 	71 	day_data.py 	<module>() 	Day Data Fusion Ended
[2024-02-01 05:10:30,105] 	INFO 	35 	pair_data.py 	<module>() 	Pair Data Fusion Started
[2024-02-01 05:10:44,004] 	INFO 	101 	pair_data.py 	<module>() 	Pair Data Fusion Ended
[2024-02-01 05:10:44,790] 	INFO 	36 	bribe_data.py 	<module>() 	Bribe Data Started
[2024-02-01 05:12:42,369] 	INFO 	157 	bribe_data.py 	<module>() 	Bribe Data Ended
[2024-02-01 05:12:43,166] 	INFO 	36 	fee_data.py 	<module>() 	Fee Data Started
[2024-02-01 05:14:23,155] 	INFO 	157 	fee_data.py 	<module>() 	Fee Data Ended
[2024-02-01 05:14:23,948] 	INFO 	37 	vote_data.py 	<module>() 	Vote Data Started
[2024-02-01 05:14:30,948] 	INFO 	116 	vote_data.py 	<module>() 	Vote Data Ended
[2024-02-01 05:14:31,755] 	INFO 	30 	revenue_data.py 	<module>() 	Revenue Data Started
[2024-02-01 05:14:38,857] 	INFO 	150 	revenue_data.py 	<module>() 	Revenue Data Ended
[2024-02-01 05:14:39,586] 	INFO 	20 	pool_data.py 	<module>() 	Pool Data Started
[2024-02-01 05:14:50,215] 	ERROR 	82 	pool_data.py 	<module>() 	Error occurred during Pool Data process. Error: {'code': -32000, 'message': 'execution aborted (timeout = 5s)'}
Traceback (most recent call last):
  File "pool_data.py", line 53, in <module>
    pool_data = contract_instance.functions.getActivePoolDistributions(pool_address).call()
  File "/opt/hostedtoolcache/Python/3.8.18/x64/lib/python3.8/site-packages/web3/contract.py", line 970, in call
    return call_contract_function(
  File "/opt/hostedtoolcache/Python/3.8.18/x64/lib/python3.8/site-packages/web3/contract.py", line 1525, in call_contract_function
    return_data = web3.eth.call(
  File "/opt/hostedtoolcache/Python/3.8.18/x64/lib/python3.8/site-packages/web3/module.py", line 57, in caller
    result = w3.manager.request_blocking(method_str,
  File "/opt/hostedtoolcache/Python/3.8.18/x64/lib/python3.8/site-packages/web3/manager.py", line 198, in request_blocking
    return self.formatted_response(response,
  File "/opt/hostedtoolcache/Python/3.8.18/x64/lib/python3.8/site-packages/web3/manager.py", line 171, in formatted_response
    raise ValueError(response["error"])
ValueError: {'code': -32000, 'message': 'execution aborted (timeout = 5s)'}
[2024-02-01 05:26:52,246] 	INFO 	20 	id_data.py 	<module>() 	ID Data Started
[2024-02-01 05:26:52,971] 	INFO 	31 	id_data.py 	<module>() 	ID Data Ended
[2024-02-01 05:26:53,537] 	INFO 	24 	day_data.py 	<module>() 	Day Data Fusion Started
[2024-02-01 05:26:55,305] 	INFO 	71 	day_data.py 	<module>() 	Day Data Fusion Ended
[2024-02-01 05:26:56,228] 	INFO 	35 	pair_data.py 	<module>() 	Pair Data Fusion Started
[2024-02-01 05:27:11,479] 	INFO 	101 	pair_data.py 	<module>() 	Pair Data Fusion Ended
[2024-02-01 05:27:12,267] 	INFO 	36 	bribe_data.py 	<module>() 	Bribe Data Started
[2024-02-01 05:29:25,686] 	INFO 	157 	bribe_data.py 	<module>() 	Bribe Data Ended
[2024-02-01 05:29:26,456] 	INFO 	36 	fee_data.py 	<module>() 	Fee Data Started
[2024-02-01 05:31:07,307] 	INFO 	157 	fee_data.py 	<module>() 	Fee Data Ended
[2024-02-01 05:31:08,080] 	INFO 	37 	vote_data.py 	<module>() 	Vote Data Started
[2024-02-01 05:31:17,450] 	INFO 	116 	vote_data.py 	<module>() 	Vote Data Ended
[2024-02-01 05:31:18,231] 	INFO 	30 	revenue_data.py 	<module>() 	Revenue Data Started
[2024-02-01 05:31:22,802] 	INFO 	150 	revenue_data.py 	<module>() 	Revenue Data Ended
[2024-02-01 05:31:23,484] 	INFO 	20 	pool_data.py 	<module>() 	Pool Data Started
[2024-02-01 05:31:29,167] 	ERROR 	82 	pool_data.py 	<module>() 	Error occurred during Pool Data process. Error: {'code': -32000, 'message': 'execution aborted (timeout = 5s)'}
Traceback (most recent call last):
  File "pool_data.py", line 53, in <module>
    pool_data = contract_instance.functions.getActivePoolDistributions(pool_address).call()
  File "/opt/hostedtoolcache/Python/3.8.18/x64/lib/python3.8/site-packages/web3/contract.py", line 970, in call
    return call_contract_function(
  File "/opt/hostedtoolcache/Python/3.8.18/x64/lib/python3.8/site-packages/web3/contract.py", line 1525, in call_contract_function
    return_data = web3.eth.call(
  File "/opt/hostedtoolcache/Python/3.8.18/x64/lib/python3.8/site-packages/web3/module.py", line 57, in caller
    result = w3.manager.request_blocking(method_str,
  File "/opt/hostedtoolcache/Python/3.8.18/x64/lib/python3.8/site-packages/web3/manager.py", line 198, in request_blocking
    return self.formatted_response(response,
  File "/opt/hostedtoolcache/Python/3.8.18/x64/lib/python3.8/site-packages/web3/manager.py", line 171, in formatted_response
    raise ValueError(response["error"])
ValueError: {'code': -32000, 'message': 'execution aborted (timeout = 5s)'}
[2024-02-01 05:36:23,421] 	INFO 	20 	id_data.py 	<module>() 	ID Data Started
[2024-02-01 05:36:24,029] 	INFO 	31 	id_data.py 	<module>() 	ID Data Ended
[2024-02-01 05:36:24,658] 	INFO 	24 	day_data.py 	<module>() 	Day Data Fusion Started
[2024-02-01 05:36:27,227] 	INFO 	71 	day_data.py 	<module>() 	Day Data Fusion Ended
[2024-02-01 05:36:28,312] 	INFO 	35 	pair_data.py 	<module>() 	Pair Data Fusion Started
[2024-02-01 05:36:41,990] 	INFO 	101 	pair_data.py 	<module>() 	Pair Data Fusion Ended
[2024-02-01 05:36:42,802] 	INFO 	36 	bribe_data.py 	<module>() 	Bribe Data Started
[2024-02-01 05:38:52,089] 	INFO 	157 	bribe_data.py 	<module>() 	Bribe Data Ended
[2024-02-01 05:38:52,874] 	INFO 	36 	fee_data.py 	<module>() 	Fee Data Started
[2024-02-01 05:40:29,638] 	INFO 	157 	fee_data.py 	<module>() 	Fee Data Ended
[2024-02-01 05:40:30,432] 	INFO 	37 	vote_data.py 	<module>() 	Vote Data Started
[2024-02-01 05:40:38,536] 	INFO 	116 	vote_data.py 	<module>() 	Vote Data Ended
[2024-02-01 05:40:39,338] 	INFO 	30 	revenue_data.py 	<module>() 	Revenue Data Started
[2024-02-01 05:40:43,564] 	INFO 	150 	revenue_data.py 	<module>() 	Revenue Data Ended
[2024-02-01 05:40:44,257] 	INFO 	20 	pool_data.py 	<module>() 	Pool Data Started
[2024-02-01 05:40:54,991] 	ERROR 	82 	pool_data.py 	<module>() 	Error occurred during Pool Data process. Error: {'code': -32000, 'message': 'execution aborted (timeout = 5s)'}
Traceback (most recent call last):
  File "pool_data.py", line 53, in <module>
    pool_data = contract_instance.functions.getActivePoolDistributions(pool_address).call()
  File "/opt/hostedtoolcache/Python/3.8.18/x64/lib/python3.8/site-packages/web3/contract.py", line 970, in call
    return call_contract_function(
  File "/opt/hostedtoolcache/Python/3.8.18/x64/lib/python3.8/site-packages/web3/contract.py", line 1525, in call_contract_function
    return_data = web3.eth.call(
  File "/opt/hostedtoolcache/Python/3.8.18/x64/lib/python3.8/site-packages/web3/module.py", line 57, in caller
    result = w3.manager.request_blocking(method_str,
  File "/opt/hostedtoolcache/Python/3.8.18/x64/lib/python3.8/site-packages/web3/manager.py", line 198, in request_blocking
    return self.formatted_response(response,
  File "/opt/hostedtoolcache/Python/3.8.18/x64/lib/python3.8/site-packages/web3/manager.py", line 171, in formatted_response
    raise ValueError(response["error"])
ValueError: {'code': -32000, 'message': 'execution aborted (timeout = 5s)'}
[2024-02-01 05:49:16,371] 	INFO 	20 	id_data.py 	<module>() 	ID Data Started
[2024-02-01 05:49:16,815] 	INFO 	31 	id_data.py 	<module>() 	ID Data Ended
[2024-02-01 05:49:17,372] 	INFO 	24 	day_data.py 	<module>() 	Day Data Fusion Started
[2024-02-01 05:49:19,804] 	INFO 	71 	day_data.py 	<module>() 	Day Data Fusion Ended
[2024-02-01 05:49:20,865] 	INFO 	35 	pair_data.py 	<module>() 	Pair Data Fusion Started
[2024-02-01 05:49:35,230] 	INFO 	101 	pair_data.py 	<module>() 	Pair Data Fusion Ended
[2024-02-01 05:49:36,000] 	INFO 	36 	bribe_data.py 	<module>() 	Bribe Data Started
[2024-02-01 05:51:52,973] 	INFO 	157 	bribe_data.py 	<module>() 	Bribe Data Ended
[2024-02-01 05:51:53,782] 	INFO 	36 	fee_data.py 	<module>() 	Fee Data Started
[2024-02-01 05:53:30,739] 	INFO 	157 	fee_data.py 	<module>() 	Fee Data Ended
[2024-02-01 05:53:31,517] 	INFO 	37 	vote_data.py 	<module>() 	Vote Data Started
[2024-02-01 05:53:39,649] 	INFO 	116 	vote_data.py 	<module>() 	Vote Data Ended
[2024-02-01 05:53:40,434] 	INFO 	30 	revenue_data.py 	<module>() 	Revenue Data Started
[2024-02-01 05:53:44,675] 	INFO 	150 	revenue_data.py 	<module>() 	Revenue Data Ended
[2024-02-01 05:53:45,357] 	INFO 	20 	pool_data.py 	<module>() 	Pool Data Started
[2024-02-01 05:53:56,010] 	ERROR 	82 	pool_data.py 	<module>() 	Error occurred during Pool Data process. Error: {'code': -32000, 'message': 'execution aborted (timeout = 5s)'}
Traceback (most recent call last):
  File "pool_data.py", line 53, in <module>
    pool_data = contract_instance.functions.getActivePoolDistributions(pool_address).call()
  File "/opt/hostedtoolcache/Python/3.8.18/x64/lib/python3.8/site-packages/web3/contract.py", line 970, in call
    return call_contract_function(
  File "/opt/hostedtoolcache/Python/3.8.18/x64/lib/python3.8/site-packages/web3/contract.py", line 1525, in call_contract_function
    return_data = web3.eth.call(
  File "/opt/hostedtoolcache/Python/3.8.18/x64/lib/python3.8/site-packages/web3/module.py", line 57, in caller
    result = w3.manager.request_blocking(method_str,
  File "/opt/hostedtoolcache/Python/3.8.18/x64/lib/python3.8/site-packages/web3/manager.py", line 198, in request_blocking
    return self.formatted_response(response,
  File "/opt/hostedtoolcache/Python/3.8.18/x64/lib/python3.8/site-packages/web3/manager.py", line 171, in formatted_response
    raise ValueError(response["error"])
ValueError: {'code': -32000, 'message': 'execution aborted (timeout = 5s)'}
[2024-02-01 06:14:37,460] 	INFO 	20 	id_data.py 	<module>() 	ID Data Started
[2024-02-01 06:14:38,033] 	INFO 	31 	id_data.py 	<module>() 	ID Data Ended
[2024-02-01 06:14:38,577] 	INFO 	24 	day_data.py 	<module>() 	Day Data Fusion Started
[2024-02-01 06:14:41,339] 	INFO 	71 	day_data.py 	<module>() 	Day Data Fusion Ended
[2024-02-01 06:14:42,343] 	INFO 	35 	pair_data.py 	<module>() 	Pair Data Fusion Started
[2024-02-01 06:14:58,755] 	INFO 	101 	pair_data.py 	<module>() 	Pair Data Fusion Ended
[2024-02-01 06:14:59,527] 	INFO 	36 	bribe_data.py 	<module>() 	Bribe Data Started
[2024-02-01 06:17:04,371] 	INFO 	157 	bribe_data.py 	<module>() 	Bribe Data Ended
[2024-02-01 06:17:05,148] 	INFO 	36 	fee_data.py 	<module>() 	Fee Data Started
[2024-02-01 06:18:43,462] 	INFO 	157 	fee_data.py 	<module>() 	Fee Data Ended
[2024-02-01 06:18:44,243] 	INFO 	37 	vote_data.py 	<module>() 	Vote Data Started
[2024-02-01 06:18:52,377] 	INFO 	116 	vote_data.py 	<module>() 	Vote Data Ended
[2024-02-01 06:18:53,167] 	INFO 	30 	revenue_data.py 	<module>() 	Revenue Data Started
[2024-02-01 06:18:59,751] 	INFO 	150 	revenue_data.py 	<module>() 	Revenue Data Ended
[2024-02-01 06:19:00,445] 	INFO 	20 	pool_data.py 	<module>() 	Pool Data Started
[2024-02-01 06:19:03,496] 	ERROR 	82 	pool_data.py 	<module>() 	Error occurred during Pool Data process. Error: execution reverted
Traceback (most recent call last):
  File "pool_data.py", line 53, in <module>
    pool_data = contract_instance.functions.getActivePoolDistributions(pool_address).call()
  File "/opt/hostedtoolcache/Python/3.8.18/x64/lib/python3.8/site-packages/web3/contract.py", line 970, in call
    return call_contract_function(
  File "/opt/hostedtoolcache/Python/3.8.18/x64/lib/python3.8/site-packages/web3/contract.py", line 1525, in call_contract_function
    return_data = web3.eth.call(
  File "/opt/hostedtoolcache/Python/3.8.18/x64/lib/python3.8/site-packages/web3/module.py", line 57, in caller
    result = w3.manager.request_blocking(method_str,
  File "/opt/hostedtoolcache/Python/3.8.18/x64/lib/python3.8/site-packages/web3/manager.py", line 198, in request_blocking
    return self.formatted_response(response,
  File "/opt/hostedtoolcache/Python/3.8.18/x64/lib/python3.8/site-packages/web3/manager.py", line 170, in formatted_response
    apply_error_formatters(error_formatters, response)
  File "/opt/hostedtoolcache/Python/3.8.18/x64/lib/python3.8/site-packages/web3/manager.py", line 70, in apply_error_formatters
    formatted_resp = pipe(response, error_formatters)
  File "cytoolz/functoolz.pyx", line 680, in cytoolz.functoolz.pipe
  File "cytoolz/functoolz.pyx", line 655, in cytoolz.functoolz.c_pipe
  File "/opt/hostedtoolcache/Python/3.8.18/x64/lib/python3.8/site-packages/web3/_utils/method_formatters.py", line 580, in raise_solidity_error_on_revert
    raise ContractLogicError('execution reverted')
web3.exceptions.ContractLogicError: execution reverted
[2024-02-01 06:29:20,743] 	INFO 	20 	id_data.py 	<module>() 	ID Data Started
[2024-02-01 06:29:21,292] 	INFO 	31 	id_data.py 	<module>() 	ID Data Ended
[2024-02-01 06:29:21,858] 	INFO 	24 	day_data.py 	<module>() 	Day Data Fusion Started
[2024-02-01 06:29:23,768] 	INFO 	71 	day_data.py 	<module>() 	Day Data Fusion Ended
[2024-02-01 06:29:24,583] 	INFO 	35 	pair_data.py 	<module>() 	Pair Data Fusion Started
[2024-02-01 06:29:39,402] 	INFO 	101 	pair_data.py 	<module>() 	Pair Data Fusion Ended
[2024-02-01 06:29:40,201] 	INFO 	36 	bribe_data.py 	<module>() 	Bribe Data Started
[2024-02-01 06:31:48,773] 	INFO 	157 	bribe_data.py 	<module>() 	Bribe Data Ended
[2024-02-01 06:31:49,565] 	INFO 	36 	fee_data.py 	<module>() 	Fee Data Started
[2024-02-01 06:33:24,256] 	INFO 	157 	fee_data.py 	<module>() 	Fee Data Ended
[2024-02-01 06:33:25,037] 	INFO 	37 	vote_data.py 	<module>() 	Vote Data Started
[2024-02-01 06:33:32,933] 	INFO 	116 	vote_data.py 	<module>() 	Vote Data Ended
[2024-02-01 06:33:33,725] 	INFO 	30 	revenue_data.py 	<module>() 	Revenue Data Started
[2024-02-01 06:33:38,700] 	INFO 	150 	revenue_data.py 	<module>() 	Revenue Data Ended
[2024-02-01 06:33:39,396] 	INFO 	20 	pool_data.py 	<module>() 	Pool Data Started
[2024-02-01 06:33:49,987] 	ERROR 	82 	pool_data.py 	<module>() 	Error occurred during Pool Data process. Error: {'code': -32000, 'message': 'execution aborted (timeout = 5s)'}
Traceback (most recent call last):
  File "pool_data.py", line 53, in <module>
    pool_data = contract_instance.functions.getActivePoolDistributions(pool_address).call()
  File "/opt/hostedtoolcache/Python/3.8.18/x64/lib/python3.8/site-packages/web3/contract.py", line 970, in call
    return call_contract_function(
  File "/opt/hostedtoolcache/Python/3.8.18/x64/lib/python3.8/site-packages/web3/contract.py", line 1525, in call_contract_function
    return_data = web3.eth.call(
  File "/opt/hostedtoolcache/Python/3.8.18/x64/lib/python3.8/site-packages/web3/module.py", line 57, in caller
    result = w3.manager.request_blocking(method_str,
  File "/opt/hostedtoolcache/Python/3.8.18/x64/lib/python3.8/site-packages/web3/manager.py", line 198, in request_blocking
    return self.formatted_response(response,
  File "/opt/hostedtoolcache/Python/3.8.18/x64/lib/python3.8/site-packages/web3/manager.py", line 171, in formatted_response
    raise ValueError(response["error"])
ValueError: {'code': -32000, 'message': 'execution aborted (timeout = 5s)'}
[2024-02-01 06:38:43,734] 	INFO 	20 	id_data.py 	<module>() 	ID Data Started
[2024-02-01 06:38:44,179] 	INFO 	31 	id_data.py 	<module>() 	ID Data Ended
[2024-02-01 06:38:45,033] 	INFO 	24 	day_data.py 	<module>() 	Day Data Fusion Started
[2024-02-01 06:38:46,517] 	INFO 	71 	day_data.py 	<module>() 	Day Data Fusion Ended
[2024-02-01 06:38:47,712] 	INFO 	35 	pair_data.py 	<module>() 	Pair Data Fusion Started
[2024-02-01 06:39:01,765] 	INFO 	101 	pair_data.py 	<module>() 	Pair Data Fusion Ended
[2024-02-01 06:39:02,540] 	INFO 	36 	bribe_data.py 	<module>() 	Bribe Data Started
[2024-02-01 06:41:11,845] 	INFO 	157 	bribe_data.py 	<module>() 	Bribe Data Ended
[2024-02-01 06:41:12,620] 	INFO 	36 	fee_data.py 	<module>() 	Fee Data Started
[2024-02-01 06:42:50,656] 	INFO 	157 	fee_data.py 	<module>() 	Fee Data Ended
[2024-02-01 06:42:51,433] 	INFO 	37 	vote_data.py 	<module>() 	Vote Data Started
[2024-02-01 06:42:58,932] 	INFO 	116 	vote_data.py 	<module>() 	Vote Data Ended
[2024-02-01 06:42:59,720] 	INFO 	30 	revenue_data.py 	<module>() 	Revenue Data Started
[2024-02-01 06:43:04,432] 	INFO 	150 	revenue_data.py 	<module>() 	Revenue Data Ended
[2024-02-01 06:43:05,117] 	INFO 	20 	pool_data.py 	<module>() 	Pool Data Started
[2024-02-01 06:43:15,750] 	ERROR 	82 	pool_data.py 	<module>() 	Error occurred during Pool Data process. Error: {'code': -32000, 'message': 'execution aborted (timeout = 5s)'}
Traceback (most recent call last):
  File "pool_data.py", line 53, in <module>
    pool_data = contract_instance.functions.getActivePoolDistributions(pool_address).call()
  File "/opt/hostedtoolcache/Python/3.8.18/x64/lib/python3.8/site-packages/web3/contract.py", line 970, in call
    return call_contract_function(
  File "/opt/hostedtoolcache/Python/3.8.18/x64/lib/python3.8/site-packages/web3/contract.py", line 1525, in call_contract_function
    return_data = web3.eth.call(
  File "/opt/hostedtoolcache/Python/3.8.18/x64/lib/python3.8/site-packages/web3/module.py", line 57, in caller
    result = w3.manager.request_blocking(method_str,
  File "/opt/hostedtoolcache/Python/3.8.18/x64/lib/python3.8/site-packages/web3/manager.py", line 198, in request_blocking
    return self.formatted_response(response,
  File "/opt/hostedtoolcache/Python/3.8.18/x64/lib/python3.8/site-packages/web3/manager.py", line 171, in formatted_response
    raise ValueError(response["error"])
ValueError: {'code': -32000, 'message': 'execution aborted (timeout = 5s)'}
[2024-02-01 06:49:18,656] 	INFO 	20 	id_data.py 	<module>() 	ID Data Started
[2024-02-01 06:49:19,256] 	INFO 	31 	id_data.py 	<module>() 	ID Data Ended
[2024-02-01 06:49:19,816] 	INFO 	24 	day_data.py 	<module>() 	Day Data Fusion Started
[2024-02-01 06:49:22,074] 	INFO 	71 	day_data.py 	<module>() 	Day Data Fusion Ended
[2024-02-01 06:49:22,875] 	INFO 	35 	pair_data.py 	<module>() 	Pair Data Fusion Started
[2024-02-01 06:49:33,616] 	INFO 	101 	pair_data.py 	<module>() 	Pair Data Fusion Ended
[2024-02-01 06:49:34,397] 	INFO 	36 	bribe_data.py 	<module>() 	Bribe Data Started
[2024-02-01 06:51:50,274] 	INFO 	157 	bribe_data.py 	<module>() 	Bribe Data Ended
[2024-02-01 06:51:51,090] 	INFO 	36 	fee_data.py 	<module>() 	Fee Data Started
[2024-02-01 06:53:29,577] 	INFO 	157 	fee_data.py 	<module>() 	Fee Data Ended
[2024-02-01 06:53:30,363] 	INFO 	37 	vote_data.py 	<module>() 	Vote Data Started
[2024-02-01 06:53:39,265] 	INFO 	116 	vote_data.py 	<module>() 	Vote Data Ended
[2024-02-01 06:53:40,074] 	INFO 	30 	revenue_data.py 	<module>() 	Revenue Data Started
[2024-02-01 06:53:47,356] 	INFO 	150 	revenue_data.py 	<module>() 	Revenue Data Ended
[2024-02-01 06:53:48,049] 	INFO 	20 	pool_data.py 	<module>() 	Pool Data Started
[2024-02-01 06:53:53,863] 	ERROR 	82 	pool_data.py 	<module>() 	Error occurred during Pool Data process. Error: execution reverted
Traceback (most recent call last):
  File "pool_data.py", line 53, in <module>
    pool_data = contract_instance.functions.getActivePoolDistributions(pool_address).call()
  File "/opt/hostedtoolcache/Python/3.8.18/x64/lib/python3.8/site-packages/web3/contract.py", line 970, in call
    return call_contract_function(
  File "/opt/hostedtoolcache/Python/3.8.18/x64/lib/python3.8/site-packages/web3/contract.py", line 1525, in call_contract_function
    return_data = web3.eth.call(
  File "/opt/hostedtoolcache/Python/3.8.18/x64/lib/python3.8/site-packages/web3/module.py", line 57, in caller
    result = w3.manager.request_blocking(method_str,
  File "/opt/hostedtoolcache/Python/3.8.18/x64/lib/python3.8/site-packages/web3/manager.py", line 198, in request_blocking
    return self.formatted_response(response,
  File "/opt/hostedtoolcache/Python/3.8.18/x64/lib/python3.8/site-packages/web3/manager.py", line 170, in formatted_response
    apply_error_formatters(error_formatters, response)
  File "/opt/hostedtoolcache/Python/3.8.18/x64/lib/python3.8/site-packages/web3/manager.py", line 70, in apply_error_formatters
    formatted_resp = pipe(response, error_formatters)
  File "cytoolz/functoolz.pyx", line 680, in cytoolz.functoolz.pipe
  File "cytoolz/functoolz.pyx", line 655, in cytoolz.functoolz.c_pipe
  File "/opt/hostedtoolcache/Python/3.8.18/x64/lib/python3.8/site-packages/web3/_utils/method_formatters.py", line 580, in raise_solidity_error_on_revert
    raise ContractLogicError('execution reverted')
web3.exceptions.ContractLogicError: execution reverted
[2024-02-01 07:11:07,227] 	INFO 	20 	id_data.py 	<module>() 	ID Data Started
[2024-02-01 07:11:07,716] 	INFO 	31 	id_data.py 	<module>() 	ID Data Ended
[2024-02-01 07:11:08,404] 	INFO 	24 	day_data.py 	<module>() 	Day Data Fusion Started
[2024-02-01 07:11:10,372] 	INFO 	71 	day_data.py 	<module>() 	Day Data Fusion Ended
[2024-02-01 07:11:11,491] 	INFO 	35 	pair_data.py 	<module>() 	Pair Data Fusion Started
[2024-02-01 07:11:25,279] 	INFO 	101 	pair_data.py 	<module>() 	Pair Data Fusion Ended
[2024-02-01 07:11:26,048] 	INFO 	36 	bribe_data.py 	<module>() 	Bribe Data Started
[2024-02-01 07:13:41,212] 	INFO 	157 	bribe_data.py 	<module>() 	Bribe Data Ended
[2024-02-01 07:13:41,985] 	INFO 	36 	fee_data.py 	<module>() 	Fee Data Started
[2024-02-01 07:15:22,079] 	INFO 	157 	fee_data.py 	<module>() 	Fee Data Ended
[2024-02-01 07:15:22,854] 	INFO 	37 	vote_data.py 	<module>() 	Vote Data Started
[2024-02-01 07:15:31,370] 	INFO 	116 	vote_data.py 	<module>() 	Vote Data Ended
[2024-02-01 07:15:32,157] 	INFO 	30 	revenue_data.py 	<module>() 	Revenue Data Started
[2024-02-01 07:15:36,983] 	INFO 	150 	revenue_data.py 	<module>() 	Revenue Data Ended
[2024-02-01 07:15:37,668] 	INFO 	20 	pool_data.py 	<module>() 	Pool Data Started
[2024-02-01 07:15:43,458] 	ERROR 	82 	pool_data.py 	<module>() 	Error occurred during Pool Data process. Error: {'code': -32000, 'message': 'execution aborted (timeout = 5s)'}
Traceback (most recent call last):
  File "pool_data.py", line 53, in <module>
    pool_data = contract_instance.functions.getActivePoolDistributions(pool_address).call()
  File "/opt/hostedtoolcache/Python/3.8.18/x64/lib/python3.8/site-packages/web3/contract.py", line 970, in call
    return call_contract_function(
  File "/opt/hostedtoolcache/Python/3.8.18/x64/lib/python3.8/site-packages/web3/contract.py", line 1525, in call_contract_function
    return_data = web3.eth.call(
  File "/opt/hostedtoolcache/Python/3.8.18/x64/lib/python3.8/site-packages/web3/module.py", line 57, in caller
    result = w3.manager.request_blocking(method_str,
  File "/opt/hostedtoolcache/Python/3.8.18/x64/lib/python3.8/site-packages/web3/manager.py", line 198, in request_blocking
    return self.formatted_response(response,
  File "/opt/hostedtoolcache/Python/3.8.18/x64/lib/python3.8/site-packages/web3/manager.py", line 171, in formatted_response
    raise ValueError(response["error"])
ValueError: {'code': -32000, 'message': 'execution aborted (timeout = 5s)'}
[2024-02-01 07:21:20,456] 	INFO 	20 	id_data.py 	<module>() 	ID Data Started
[2024-02-01 07:21:21,237] 	INFO 	31 	id_data.py 	<module>() 	ID Data Ended
[2024-02-01 07:21:21,867] 	INFO 	24 	day_data.py 	<module>() 	Day Data Fusion Started
[2024-02-01 07:21:24,751] 	INFO 	71 	day_data.py 	<module>() 	Day Data Fusion Ended
[2024-02-01 07:21:25,725] 	INFO 	35 	pair_data.py 	<module>() 	Pair Data Fusion Started
[2024-02-01 07:21:42,942] 	INFO 	101 	pair_data.py 	<module>() 	Pair Data Fusion Ended
[2024-02-01 07:21:43,760] 	INFO 	36 	bribe_data.py 	<module>() 	Bribe Data Started
[2024-02-01 07:23:50,385] 	INFO 	157 	bribe_data.py 	<module>() 	Bribe Data Ended
[2024-02-01 07:23:51,165] 	INFO 	36 	fee_data.py 	<module>() 	Fee Data Started
[2024-02-01 07:25:27,178] 	INFO 	157 	fee_data.py 	<module>() 	Fee Data Ended
[2024-02-01 07:25:27,960] 	INFO 	37 	vote_data.py 	<module>() 	Vote Data Started
[2024-02-01 07:25:35,948] 	INFO 	116 	vote_data.py 	<module>() 	Vote Data Ended
[2024-02-01 07:25:36,726] 	INFO 	30 	revenue_data.py 	<module>() 	Revenue Data Started
[2024-02-01 07:25:43,226] 	INFO 	150 	revenue_data.py 	<module>() 	Revenue Data Ended
[2024-02-01 07:25:43,910] 	INFO 	20 	pool_data.py 	<module>() 	Pool Data Started
[2024-02-01 07:25:51,109] 	ERROR 	82 	pool_data.py 	<module>() 	Error occurred during Pool Data process. Error: execution reverted
Traceback (most recent call last):
  File "pool_data.py", line 53, in <module>
    pool_data = contract_instance.functions.getActivePoolDistributions(pool_address).call()
  File "/opt/hostedtoolcache/Python/3.8.18/x64/lib/python3.8/site-packages/web3/contract.py", line 970, in call
    return call_contract_function(
  File "/opt/hostedtoolcache/Python/3.8.18/x64/lib/python3.8/site-packages/web3/contract.py", line 1525, in call_contract_function
    return_data = web3.eth.call(
  File "/opt/hostedtoolcache/Python/3.8.18/x64/lib/python3.8/site-packages/web3/module.py", line 57, in caller
    result = w3.manager.request_blocking(method_str,
  File "/opt/hostedtoolcache/Python/3.8.18/x64/lib/python3.8/site-packages/web3/manager.py", line 198, in request_blocking
    return self.formatted_response(response,
  File "/opt/hostedtoolcache/Python/3.8.18/x64/lib/python3.8/site-packages/web3/manager.py", line 170, in formatted_response
    apply_error_formatters(error_formatters, response)
  File "/opt/hostedtoolcache/Python/3.8.18/x64/lib/python3.8/site-packages/web3/manager.py", line 70, in apply_error_formatters
    formatted_resp = pipe(response, error_formatters)
  File "cytoolz/functoolz.pyx", line 680, in cytoolz.functoolz.pipe
  File "cytoolz/functoolz.pyx", line 655, in cytoolz.functoolz.c_pipe
  File "/opt/hostedtoolcache/Python/3.8.18/x64/lib/python3.8/site-packages/web3/_utils/method_formatters.py", line 580, in raise_solidity_error_on_revert
    raise ContractLogicError('execution reverted')
web3.exceptions.ContractLogicError: execution reverted
[2024-02-01 07:34:24,157] 	INFO 	20 	id_data.py 	<module>() 	ID Data Started
[2024-02-01 07:34:24,677] 	INFO 	31 	id_data.py 	<module>() 	ID Data Ended
[2024-02-01 07:34:25,186] 	INFO 	24 	day_data.py 	<module>() 	Day Data Fusion Started
[2024-02-01 07:34:27,546] 	INFO 	71 	day_data.py 	<module>() 	Day Data Fusion Ended
[2024-02-01 07:34:28,371] 	INFO 	35 	pair_data.py 	<module>() 	Pair Data Fusion Started
[2024-02-01 07:34:42,483] 	INFO 	101 	pair_data.py 	<module>() 	Pair Data Fusion Ended
[2024-02-01 07:34:43,257] 	INFO 	36 	bribe_data.py 	<module>() 	Bribe Data Started
[2024-02-01 07:36:58,502] 	INFO 	157 	bribe_data.py 	<module>() 	Bribe Data Ended
[2024-02-01 07:36:59,308] 	INFO 	36 	fee_data.py 	<module>() 	Fee Data Started
[2024-02-01 07:38:48,354] 	INFO 	157 	fee_data.py 	<module>() 	Fee Data Ended
[2024-02-01 07:38:49,186] 	INFO 	37 	vote_data.py 	<module>() 	Vote Data Started
[2024-02-01 07:38:57,105] 	INFO 	116 	vote_data.py 	<module>() 	Vote Data Ended
[2024-02-01 07:38:57,955] 	INFO 	30 	revenue_data.py 	<module>() 	Revenue Data Started
[2024-02-01 07:39:03,271] 	INFO 	150 	revenue_data.py 	<module>() 	Revenue Data Ended
[2024-02-01 07:39:04,026] 	INFO 	20 	pool_data.py 	<module>() 	Pool Data Started
[2024-02-01 07:39:09,701] 	ERROR 	82 	pool_data.py 	<module>() 	Error occurred during Pool Data process. Error: {'code': -32000, 'message': 'execution aborted (timeout = 5s)'}
Traceback (most recent call last):
  File "pool_data.py", line 53, in <module>
    pool_data = contract_instance.functions.getActivePoolDistributions(pool_address).call()
  File "/opt/hostedtoolcache/Python/3.8.18/x64/lib/python3.8/site-packages/web3/contract.py", line 970, in call
    return call_contract_function(
  File "/opt/hostedtoolcache/Python/3.8.18/x64/lib/python3.8/site-packages/web3/contract.py", line 1525, in call_contract_function
    return_data = web3.eth.call(
  File "/opt/hostedtoolcache/Python/3.8.18/x64/lib/python3.8/site-packages/web3/module.py", line 57, in caller
    result = w3.manager.request_blocking(method_str,
  File "/opt/hostedtoolcache/Python/3.8.18/x64/lib/python3.8/site-packages/web3/manager.py", line 198, in request_blocking
    return self.formatted_response(response,
  File "/opt/hostedtoolcache/Python/3.8.18/x64/lib/python3.8/site-packages/web3/manager.py", line 171, in formatted_response
    raise ValueError(response["error"])
ValueError: {'code': -32000, 'message': 'execution aborted (timeout = 5s)'}
[2024-02-01 07:49:13,544] 	INFO 	20 	id_data.py 	<module>() 	ID Data Started
[2024-02-01 07:49:13,755] 	INFO 	31 	id_data.py 	<module>() 	ID Data Ended
[2024-02-01 07:49:14,337] 	INFO 	24 	day_data.py 	<module>() 	Day Data Fusion Started
[2024-02-01 07:49:16,077] 	INFO 	71 	day_data.py 	<module>() 	Day Data Fusion Ended
[2024-02-01 07:49:17,023] 	INFO 	35 	pair_data.py 	<module>() 	Pair Data Fusion Started
[2024-02-01 07:49:31,813] 	INFO 	101 	pair_data.py 	<module>() 	Pair Data Fusion Ended
[2024-02-01 07:49:32,618] 	INFO 	36 	bribe_data.py 	<module>() 	Bribe Data Started
[2024-02-01 07:51:41,236] 	INFO 	157 	bribe_data.py 	<module>() 	Bribe Data Ended
[2024-02-01 07:51:42,048] 	INFO 	36 	fee_data.py 	<module>() 	Fee Data Started
[2024-02-01 07:53:20,904] 	INFO 	157 	fee_data.py 	<module>() 	Fee Data Ended
[2024-02-01 07:53:21,723] 	INFO 	37 	vote_data.py 	<module>() 	Vote Data Started
[2024-02-01 07:53:30,021] 	INFO 	116 	vote_data.py 	<module>() 	Vote Data Ended
[2024-02-01 07:53:30,848] 	INFO 	30 	revenue_data.py 	<module>() 	Revenue Data Started
[2024-02-01 07:53:39,556] 	INFO 	150 	revenue_data.py 	<module>() 	Revenue Data Ended
[2024-02-01 07:53:40,279] 	INFO 	20 	pool_data.py 	<module>() 	Pool Data Started
[2024-02-01 07:53:45,973] 	ERROR 	82 	pool_data.py 	<module>() 	Error occurred during Pool Data process. Error: {'code': -32000, 'message': 'execution aborted (timeout = 5s)'}
Traceback (most recent call last):
  File "pool_data.py", line 53, in <module>
    pool_data = contract_instance.functions.getActivePoolDistributions(pool_address).call()
  File "/opt/hostedtoolcache/Python/3.8.18/x64/lib/python3.8/site-packages/web3/contract.py", line 970, in call
    return call_contract_function(
  File "/opt/hostedtoolcache/Python/3.8.18/x64/lib/python3.8/site-packages/web3/contract.py", line 1525, in call_contract_function
    return_data = web3.eth.call(
  File "/opt/hostedtoolcache/Python/3.8.18/x64/lib/python3.8/site-packages/web3/module.py", line 57, in caller
    result = w3.manager.request_blocking(method_str,
  File "/opt/hostedtoolcache/Python/3.8.18/x64/lib/python3.8/site-packages/web3/manager.py", line 198, in request_blocking
    return self.formatted_response(response,
  File "/opt/hostedtoolcache/Python/3.8.18/x64/lib/python3.8/site-packages/web3/manager.py", line 171, in formatted_response
    raise ValueError(response["error"])
ValueError: {'code': -32000, 'message': 'execution aborted (timeout = 5s)'}
[2024-02-01 08:13:37,876] 	INFO 	20 	id_data.py 	<module>() 	ID Data Started
[2024-02-01 08:13:38,167] 	INFO 	31 	id_data.py 	<module>() 	ID Data Ended
[2024-02-01 08:13:38,684] 	INFO 	24 	day_data.py 	<module>() 	Day Data Fusion Started
[2024-02-01 08:13:41,103] 	INFO 	71 	day_data.py 	<module>() 	Day Data Fusion Ended
[2024-02-01 08:13:42,150] 	INFO 	35 	pair_data.py 	<module>() 	Pair Data Fusion Started
[2024-02-01 08:13:56,892] 	INFO 	101 	pair_data.py 	<module>() 	Pair Data Fusion Ended
[2024-02-01 08:13:57,679] 	INFO 	36 	bribe_data.py 	<module>() 	Bribe Data Started
[2024-02-01 08:16:06,035] 	INFO 	157 	bribe_data.py 	<module>() 	Bribe Data Ended
[2024-02-01 08:16:06,822] 	INFO 	36 	fee_data.py 	<module>() 	Fee Data Started
[2024-02-01 08:17:45,515] 	INFO 	157 	fee_data.py 	<module>() 	Fee Data Ended
[2024-02-01 08:17:46,307] 	INFO 	37 	vote_data.py 	<module>() 	Vote Data Started
[2024-02-01 08:17:53,948] 	INFO 	116 	vote_data.py 	<module>() 	Vote Data Ended
[2024-02-01 08:17:54,771] 	INFO 	30 	revenue_data.py 	<module>() 	Revenue Data Started
[2024-02-01 08:18:02,792] 	INFO 	150 	revenue_data.py 	<module>() 	Revenue Data Ended
[2024-02-01 08:18:03,494] 	INFO 	20 	pool_data.py 	<module>() 	Pool Data Started
[2024-02-01 08:18:14,193] 	ERROR 	82 	pool_data.py 	<module>() 	Error occurred during Pool Data process. Error: {'code': -32000, 'message': 'execution aborted (timeout = 5s)'}
Traceback (most recent call last):
  File "pool_data.py", line 53, in <module>
    pool_data = contract_instance.functions.getActivePoolDistributions(pool_address).call()
  File "/opt/hostedtoolcache/Python/3.8.18/x64/lib/python3.8/site-packages/web3/contract.py", line 970, in call
    return call_contract_function(
  File "/opt/hostedtoolcache/Python/3.8.18/x64/lib/python3.8/site-packages/web3/contract.py", line 1525, in call_contract_function
    return_data = web3.eth.call(
  File "/opt/hostedtoolcache/Python/3.8.18/x64/lib/python3.8/site-packages/web3/module.py", line 57, in caller
    result = w3.manager.request_blocking(method_str,
  File "/opt/hostedtoolcache/Python/3.8.18/x64/lib/python3.8/site-packages/web3/manager.py", line 198, in request_blocking
    return self.formatted_response(response,
  File "/opt/hostedtoolcache/Python/3.8.18/x64/lib/python3.8/site-packages/web3/manager.py", line 171, in formatted_response
    raise ValueError(response["error"])
ValueError: {'code': -32000, 'message': 'execution aborted (timeout = 5s)'}
[2024-02-01 08:27:40,652] 	INFO 	20 	id_data.py 	<module>() 	ID Data Started
[2024-02-01 08:27:41,039] 	INFO 	31 	id_data.py 	<module>() 	ID Data Ended
[2024-02-01 08:27:41,671] 	INFO 	24 	day_data.py 	<module>() 	Day Data Fusion Started
[2024-02-01 08:27:44,324] 	INFO 	71 	day_data.py 	<module>() 	Day Data Fusion Ended
[2024-02-01 08:27:45,354] 	INFO 	35 	pair_data.py 	<module>() 	Pair Data Fusion Started
[2024-02-01 08:27:56,947] 	INFO 	101 	pair_data.py 	<module>() 	Pair Data Fusion Ended
[2024-02-01 08:27:57,851] 	INFO 	36 	bribe_data.py 	<module>() 	Bribe Data Started
[2024-02-01 08:30:16,857] 	INFO 	157 	bribe_data.py 	<module>() 	Bribe Data Ended
[2024-02-01 08:30:17,647] 	INFO 	36 	fee_data.py 	<module>() 	Fee Data Started
[2024-02-01 08:32:01,178] 	INFO 	157 	fee_data.py 	<module>() 	Fee Data Ended
[2024-02-01 08:32:01,959] 	INFO 	37 	vote_data.py 	<module>() 	Vote Data Started
[2024-02-01 08:32:10,047] 	INFO 	116 	vote_data.py 	<module>() 	Vote Data Ended
[2024-02-01 08:32:10,831] 	INFO 	30 	revenue_data.py 	<module>() 	Revenue Data Started
[2024-02-01 08:32:15,753] 	INFO 	150 	revenue_data.py 	<module>() 	Revenue Data Ended
[2024-02-01 08:32:16,438] 	INFO 	20 	pool_data.py 	<module>() 	Pool Data Started
[2024-02-01 08:32:22,140] 	ERROR 	82 	pool_data.py 	<module>() 	Error occurred during Pool Data process. Error: {'code': -32000, 'message': 'execution aborted (timeout = 5s)'}
Traceback (most recent call last):
  File "pool_data.py", line 53, in <module>
    pool_data = contract_instance.functions.getActivePoolDistributions(pool_address).call()
  File "/opt/hostedtoolcache/Python/3.8.18/x64/lib/python3.8/site-packages/web3/contract.py", line 970, in call
    return call_contract_function(
  File "/opt/hostedtoolcache/Python/3.8.18/x64/lib/python3.8/site-packages/web3/contract.py", line 1525, in call_contract_function
    return_data = web3.eth.call(
  File "/opt/hostedtoolcache/Python/3.8.18/x64/lib/python3.8/site-packages/web3/module.py", line 57, in caller
    result = w3.manager.request_blocking(method_str,
  File "/opt/hostedtoolcache/Python/3.8.18/x64/lib/python3.8/site-packages/web3/manager.py", line 198, in request_blocking
    return self.formatted_response(response,
  File "/opt/hostedtoolcache/Python/3.8.18/x64/lib/python3.8/site-packages/web3/manager.py", line 171, in formatted_response
    raise ValueError(response["error"])
ValueError: {'code': -32000, 'message': 'execution aborted (timeout = 5s)'}
[2024-02-01 08:36:59,316] 	INFO 	20 	id_data.py 	<module>() 	ID Data Started
[2024-02-01 08:36:59,570] 	INFO 	31 	id_data.py 	<module>() 	ID Data Ended
[2024-02-01 08:37:00,191] 	INFO 	24 	day_data.py 	<module>() 	Day Data Fusion Started
[2024-02-01 08:37:02,716] 	INFO 	71 	day_data.py 	<module>() 	Day Data Fusion Ended
[2024-02-01 08:37:03,634] 	INFO 	35 	pair_data.py 	<module>() 	Pair Data Fusion Started
[2024-02-01 08:37:18,932] 	INFO 	101 	pair_data.py 	<module>() 	Pair Data Fusion Ended
[2024-02-01 08:37:19,743] 	INFO 	36 	bribe_data.py 	<module>() 	Bribe Data Started
[2024-02-01 08:39:25,286] 	INFO 	157 	bribe_data.py 	<module>() 	Bribe Data Ended
[2024-02-01 08:39:26,117] 	INFO 	36 	fee_data.py 	<module>() 	Fee Data Started
[2024-02-01 08:40:53,879] 	INFO 	157 	fee_data.py 	<module>() 	Fee Data Ended
[2024-02-01 08:40:54,681] 	INFO 	37 	vote_data.py 	<module>() 	Vote Data Started
[2024-02-01 08:41:02,636] 	INFO 	116 	vote_data.py 	<module>() 	Vote Data Ended
[2024-02-01 08:41:03,441] 	INFO 	30 	revenue_data.py 	<module>() 	Revenue Data Started
[2024-02-01 08:41:08,814] 	INFO 	150 	revenue_data.py 	<module>() 	Revenue Data Ended
[2024-02-01 08:41:09,521] 	INFO 	20 	pool_data.py 	<module>() 	Pool Data Started
[2024-02-01 08:41:23,429] 	ERROR 	82 	pool_data.py 	<module>() 	Error occurred during Pool Data process. Error: {'code': -32000, 'message': 'execution aborted (timeout = 5s)'}
Traceback (most recent call last):
  File "pool_data.py", line 53, in <module>
    pool_data = contract_instance.functions.getActivePoolDistributions(pool_address).call()
  File "/opt/hostedtoolcache/Python/3.8.18/x64/lib/python3.8/site-packages/web3/contract.py", line 970, in call
    return call_contract_function(
  File "/opt/hostedtoolcache/Python/3.8.18/x64/lib/python3.8/site-packages/web3/contract.py", line 1525, in call_contract_function
    return_data = web3.eth.call(
  File "/opt/hostedtoolcache/Python/3.8.18/x64/lib/python3.8/site-packages/web3/module.py", line 57, in caller
    result = w3.manager.request_blocking(method_str,
  File "/opt/hostedtoolcache/Python/3.8.18/x64/lib/python3.8/site-packages/web3/manager.py", line 198, in request_blocking
    return self.formatted_response(response,
  File "/opt/hostedtoolcache/Python/3.8.18/x64/lib/python3.8/site-packages/web3/manager.py", line 171, in formatted_response
    raise ValueError(response["error"])
ValueError: {'code': -32000, 'message': 'execution aborted (timeout = 5s)'}
[2024-02-01 08:49:15,424] 	INFO 	20 	id_data.py 	<module>() 	ID Data Started
[2024-02-01 08:49:15,796] 	INFO 	31 	id_data.py 	<module>() 	ID Data Ended
[2024-02-01 08:49:16,379] 	INFO 	24 	day_data.py 	<module>() 	Day Data Fusion Started
[2024-02-01 08:49:19,158] 	INFO 	71 	day_data.py 	<module>() 	Day Data Fusion Ended
[2024-02-01 08:49:20,206] 	INFO 	35 	pair_data.py 	<module>() 	Pair Data Fusion Started
[2024-02-01 08:49:37,296] 	INFO 	101 	pair_data.py 	<module>() 	Pair Data Fusion Ended
[2024-02-01 08:49:38,102] 	INFO 	36 	bribe_data.py 	<module>() 	Bribe Data Started
[2024-02-01 08:51:40,749] 	INFO 	157 	bribe_data.py 	<module>() 	Bribe Data Ended
[2024-02-01 08:51:41,550] 	INFO 	36 	fee_data.py 	<module>() 	Fee Data Started
[2024-02-01 08:53:11,215] 	INFO 	157 	fee_data.py 	<module>() 	Fee Data Ended
[2024-02-01 08:53:12,068] 	INFO 	37 	vote_data.py 	<module>() 	Vote Data Started
[2024-02-01 08:53:21,950] 	INFO 	116 	vote_data.py 	<module>() 	Vote Data Ended
[2024-02-01 08:53:22,806] 	INFO 	30 	revenue_data.py 	<module>() 	Revenue Data Started
[2024-02-01 08:53:28,564] 	INFO 	150 	revenue_data.py 	<module>() 	Revenue Data Ended
[2024-02-01 08:53:29,276] 	INFO 	20 	pool_data.py 	<module>() 	Pool Data Started
[2024-02-01 08:53:34,127] 	ERROR 	82 	pool_data.py 	<module>() 	Error occurred during Pool Data process. Error: execution reverted
Traceback (most recent call last):
  File "pool_data.py", line 53, in <module>
    pool_data = contract_instance.functions.getActivePoolDistributions(pool_address).call()
  File "/opt/hostedtoolcache/Python/3.8.18/x64/lib/python3.8/site-packages/web3/contract.py", line 970, in call
    return call_contract_function(
  File "/opt/hostedtoolcache/Python/3.8.18/x64/lib/python3.8/site-packages/web3/contract.py", line 1525, in call_contract_function
    return_data = web3.eth.call(
  File "/opt/hostedtoolcache/Python/3.8.18/x64/lib/python3.8/site-packages/web3/module.py", line 57, in caller
    result = w3.manager.request_blocking(method_str,
  File "/opt/hostedtoolcache/Python/3.8.18/x64/lib/python3.8/site-packages/web3/manager.py", line 198, in request_blocking
    return self.formatted_response(response,
  File "/opt/hostedtoolcache/Python/3.8.18/x64/lib/python3.8/site-packages/web3/manager.py", line 170, in formatted_response
    apply_error_formatters(error_formatters, response)
  File "/opt/hostedtoolcache/Python/3.8.18/x64/lib/python3.8/site-packages/web3/manager.py", line 70, in apply_error_formatters
    formatted_resp = pipe(response, error_formatters)
  File "cytoolz/functoolz.pyx", line 680, in cytoolz.functoolz.pipe
  File "cytoolz/functoolz.pyx", line 655, in cytoolz.functoolz.c_pipe
  File "/opt/hostedtoolcache/Python/3.8.18/x64/lib/python3.8/site-packages/web3/_utils/method_formatters.py", line 580, in raise_solidity_error_on_revert
    raise ContractLogicError('execution reverted')
web3.exceptions.ContractLogicError: execution reverted
[2024-02-01 09:11:48,246] 	INFO 	20 	id_data.py 	<module>() 	ID Data Started
[2024-02-01 09:11:48,714] 	INFO 	31 	id_data.py 	<module>() 	ID Data Ended
[2024-02-01 09:11:49,238] 	INFO 	24 	day_data.py 	<module>() 	Day Data Fusion Started
[2024-02-01 09:11:50,618] 	INFO 	71 	day_data.py 	<module>() 	Day Data Fusion Ended
[2024-02-01 09:11:51,519] 	INFO 	35 	pair_data.py 	<module>() 	Pair Data Fusion Started
[2024-02-01 09:12:07,062] 	INFO 	101 	pair_data.py 	<module>() 	Pair Data Fusion Ended
[2024-02-01 09:12:07,846] 	INFO 	36 	bribe_data.py 	<module>() 	Bribe Data Started
[2024-02-01 09:14:19,879] 	INFO 	157 	bribe_data.py 	<module>() 	Bribe Data Ended
[2024-02-01 09:14:20,667] 	INFO 	36 	fee_data.py 	<module>() 	Fee Data Started
[2024-02-01 09:16:00,665] 	INFO 	157 	fee_data.py 	<module>() 	Fee Data Ended
[2024-02-01 09:16:01,441] 	INFO 	37 	vote_data.py 	<module>() 	Vote Data Started
[2024-02-01 09:16:09,920] 	INFO 	116 	vote_data.py 	<module>() 	Vote Data Ended
[2024-02-01 09:16:10,758] 	INFO 	30 	revenue_data.py 	<module>() 	Revenue Data Started
[2024-02-01 09:16:15,925] 	INFO 	150 	revenue_data.py 	<module>() 	Revenue Data Ended
[2024-02-01 09:16:16,620] 	INFO 	20 	pool_data.py 	<module>() 	Pool Data Started
[2024-02-01 09:16:23,471] 	ERROR 	82 	pool_data.py 	<module>() 	Error occurred during Pool Data process. Error: execution reverted
Traceback (most recent call last):
  File "pool_data.py", line 53, in <module>
    pool_data = contract_instance.functions.getActivePoolDistributions(pool_address).call()
  File "/opt/hostedtoolcache/Python/3.8.18/x64/lib/python3.8/site-packages/web3/contract.py", line 970, in call
    return call_contract_function(
  File "/opt/hostedtoolcache/Python/3.8.18/x64/lib/python3.8/site-packages/web3/contract.py", line 1525, in call_contract_function
    return_data = web3.eth.call(
  File "/opt/hostedtoolcache/Python/3.8.18/x64/lib/python3.8/site-packages/web3/module.py", line 57, in caller
    result = w3.manager.request_blocking(method_str,
  File "/opt/hostedtoolcache/Python/3.8.18/x64/lib/python3.8/site-packages/web3/manager.py", line 198, in request_blocking
    return self.formatted_response(response,
  File "/opt/hostedtoolcache/Python/3.8.18/x64/lib/python3.8/site-packages/web3/manager.py", line 170, in formatted_response
    apply_error_formatters(error_formatters, response)
  File "/opt/hostedtoolcache/Python/3.8.18/x64/lib/python3.8/site-packages/web3/manager.py", line 70, in apply_error_formatters
    formatted_resp = pipe(response, error_formatters)
  File "cytoolz/functoolz.pyx", line 680, in cytoolz.functoolz.pipe
  File "cytoolz/functoolz.pyx", line 655, in cytoolz.functoolz.c_pipe
  File "/opt/hostedtoolcache/Python/3.8.18/x64/lib/python3.8/site-packages/web3/_utils/method_formatters.py", line 580, in raise_solidity_error_on_revert
    raise ContractLogicError('execution reverted')
web3.exceptions.ContractLogicError: execution reverted
[2024-02-01 09:23:40,493] 	INFO 	20 	id_data.py 	<module>() 	ID Data Started
[2024-02-01 09:23:40,729] 	INFO 	31 	id_data.py 	<module>() 	ID Data Ended
[2024-02-01 09:23:41,296] 	INFO 	24 	day_data.py 	<module>() 	Day Data Fusion Started
[2024-02-01 09:23:42,589] 	INFO 	71 	day_data.py 	<module>() 	Day Data Fusion Ended
[2024-02-01 09:23:43,659] 	INFO 	35 	pair_data.py 	<module>() 	Pair Data Fusion Started
[2024-02-01 09:23:58,504] 	INFO 	101 	pair_data.py 	<module>() 	Pair Data Fusion Ended
[2024-02-01 09:23:59,285] 	INFO 	36 	bribe_data.py 	<module>() 	Bribe Data Started
[2024-02-01 09:26:08,621] 	INFO 	157 	bribe_data.py 	<module>() 	Bribe Data Ended
[2024-02-01 09:26:09,395] 	INFO 	36 	fee_data.py 	<module>() 	Fee Data Started
[2024-02-01 09:27:48,730] 	INFO 	157 	fee_data.py 	<module>() 	Fee Data Ended
[2024-02-01 09:27:49,577] 	INFO 	37 	vote_data.py 	<module>() 	Vote Data Started
[2024-02-01 09:27:58,663] 	INFO 	116 	vote_data.py 	<module>() 	Vote Data Ended
[2024-02-01 09:27:59,491] 	INFO 	30 	revenue_data.py 	<module>() 	Revenue Data Started
[2024-02-01 09:28:04,369] 	INFO 	150 	revenue_data.py 	<module>() 	Revenue Data Ended
[2024-02-01 09:28:05,095] 	INFO 	20 	pool_data.py 	<module>() 	Pool Data Started
[2024-02-01 09:28:15,900] 	ERROR 	82 	pool_data.py 	<module>() 	Error occurred during Pool Data process. Error: {'code': -32000, 'message': 'execution aborted (timeout = 5s)'}
Traceback (most recent call last):
  File "pool_data.py", line 53, in <module>
    pool_data = contract_instance.functions.getActivePoolDistributions(pool_address).call()
  File "/opt/hostedtoolcache/Python/3.8.18/x64/lib/python3.8/site-packages/web3/contract.py", line 970, in call
    return call_contract_function(
  File "/opt/hostedtoolcache/Python/3.8.18/x64/lib/python3.8/site-packages/web3/contract.py", line 1525, in call_contract_function
    return_data = web3.eth.call(
  File "/opt/hostedtoolcache/Python/3.8.18/x64/lib/python3.8/site-packages/web3/module.py", line 57, in caller
    result = w3.manager.request_blocking(method_str,
  File "/opt/hostedtoolcache/Python/3.8.18/x64/lib/python3.8/site-packages/web3/manager.py", line 198, in request_blocking
    return self.formatted_response(response,
  File "/opt/hostedtoolcache/Python/3.8.18/x64/lib/python3.8/site-packages/web3/manager.py", line 171, in formatted_response
    raise ValueError(response["error"])
ValueError: {'code': -32000, 'message': 'execution aborted (timeout = 5s)'}
[2024-02-01 09:35:14,478] 	INFO 	20 	id_data.py 	<module>() 	ID Data Started
[2024-02-01 09:35:14,952] 	INFO 	31 	id_data.py 	<module>() 	ID Data Ended
[2024-02-01 09:35:15,575] 	INFO 	24 	day_data.py 	<module>() 	Day Data Fusion Started
[2024-02-01 09:35:18,050] 	INFO 	71 	day_data.py 	<module>() 	Day Data Fusion Ended
[2024-02-01 09:35:18,917] 	INFO 	35 	pair_data.py 	<module>() 	Pair Data Fusion Started
[2024-02-01 09:35:31,054] 	INFO 	101 	pair_data.py 	<module>() 	Pair Data Fusion Ended
[2024-02-01 09:35:31,842] 	INFO 	36 	bribe_data.py 	<module>() 	Bribe Data Started
[2024-02-01 09:37:42,713] 	INFO 	157 	bribe_data.py 	<module>() 	Bribe Data Ended
[2024-02-01 09:37:43,533] 	INFO 	36 	fee_data.py 	<module>() 	Fee Data Started
[2024-02-01 09:39:26,706] 	INFO 	157 	fee_data.py 	<module>() 	Fee Data Ended
[2024-02-01 09:39:27,544] 	INFO 	37 	vote_data.py 	<module>() 	Vote Data Started
[2024-02-01 09:39:35,596] 	INFO 	116 	vote_data.py 	<module>() 	Vote Data Ended
[2024-02-01 09:39:36,417] 	INFO 	30 	revenue_data.py 	<module>() 	Revenue Data Started
[2024-02-01 09:39:40,948] 	INFO 	150 	revenue_data.py 	<module>() 	Revenue Data Ended
[2024-02-01 09:39:41,665] 	INFO 	20 	pool_data.py 	<module>() 	Pool Data Started
[2024-02-01 09:39:51,132] 	ERROR 	82 	pool_data.py 	<module>() 	Error occurred during Pool Data process. Error: execution reverted
Traceback (most recent call last):
  File "pool_data.py", line 53, in <module>
    pool_data = contract_instance.functions.getActivePoolDistributions(pool_address).call()
  File "/opt/hostedtoolcache/Python/3.8.18/x64/lib/python3.8/site-packages/web3/contract.py", line 970, in call
    return call_contract_function(
  File "/opt/hostedtoolcache/Python/3.8.18/x64/lib/python3.8/site-packages/web3/contract.py", line 1525, in call_contract_function
    return_data = web3.eth.call(
  File "/opt/hostedtoolcache/Python/3.8.18/x64/lib/python3.8/site-packages/web3/module.py", line 57, in caller
    result = w3.manager.request_blocking(method_str,
  File "/opt/hostedtoolcache/Python/3.8.18/x64/lib/python3.8/site-packages/web3/manager.py", line 198, in request_blocking
    return self.formatted_response(response,
  File "/opt/hostedtoolcache/Python/3.8.18/x64/lib/python3.8/site-packages/web3/manager.py", line 170, in formatted_response
    apply_error_formatters(error_formatters, response)
  File "/opt/hostedtoolcache/Python/3.8.18/x64/lib/python3.8/site-packages/web3/manager.py", line 70, in apply_error_formatters
    formatted_resp = pipe(response, error_formatters)
  File "cytoolz/functoolz.pyx", line 680, in cytoolz.functoolz.pipe
  File "cytoolz/functoolz.pyx", line 655, in cytoolz.functoolz.c_pipe
  File "/opt/hostedtoolcache/Python/3.8.18/x64/lib/python3.8/site-packages/web3/_utils/method_formatters.py", line 580, in raise_solidity_error_on_revert
    raise ContractLogicError('execution reverted')
web3.exceptions.ContractLogicError: execution reverted
[2024-02-01 09:49:17,062] 	INFO 	20 	id_data.py 	<module>() 	ID Data Started
[2024-02-01 09:49:17,254] 	INFO 	31 	id_data.py 	<module>() 	ID Data Ended
[2024-02-01 09:49:17,974] 	INFO 	24 	day_data.py 	<module>() 	Day Data Fusion Started
[2024-02-01 09:49:19,331] 	INFO 	71 	day_data.py 	<module>() 	Day Data Fusion Ended
[2024-02-01 09:49:20,648] 	INFO 	35 	pair_data.py 	<module>() 	Pair Data Fusion Started
[2024-02-01 09:49:34,468] 	INFO 	101 	pair_data.py 	<module>() 	Pair Data Fusion Ended
[2024-02-01 09:49:35,240] 	INFO 	36 	bribe_data.py 	<module>() 	Bribe Data Started
[2024-02-01 09:51:36,828] 	INFO 	157 	bribe_data.py 	<module>() 	Bribe Data Ended
[2024-02-01 09:51:37,605] 	INFO 	36 	fee_data.py 	<module>() 	Fee Data Started
[2024-02-01 09:53:10,029] 	INFO 	157 	fee_data.py 	<module>() 	Fee Data Ended
[2024-02-01 09:53:10,804] 	INFO 	37 	vote_data.py 	<module>() 	Vote Data Started
[2024-02-01 09:53:18,647] 	INFO 	116 	vote_data.py 	<module>() 	Vote Data Ended
[2024-02-01 09:53:19,437] 	INFO 	30 	revenue_data.py 	<module>() 	Revenue Data Started
[2024-02-01 09:53:25,473] 	INFO 	150 	revenue_data.py 	<module>() 	Revenue Data Ended
[2024-02-01 09:53:26,155] 	INFO 	20 	pool_data.py 	<module>() 	Pool Data Started
[2024-02-01 09:53:31,818] 	ERROR 	82 	pool_data.py 	<module>() 	Error occurred during Pool Data process. Error: {'code': -32000, 'message': 'execution aborted (timeout = 5s)'}
Traceback (most recent call last):
  File "pool_data.py", line 53, in <module>
    pool_data = contract_instance.functions.getActivePoolDistributions(pool_address).call()
  File "/opt/hostedtoolcache/Python/3.8.18/x64/lib/python3.8/site-packages/web3/contract.py", line 970, in call
    return call_contract_function(
  File "/opt/hostedtoolcache/Python/3.8.18/x64/lib/python3.8/site-packages/web3/contract.py", line 1525, in call_contract_function
    return_data = web3.eth.call(
  File "/opt/hostedtoolcache/Python/3.8.18/x64/lib/python3.8/site-packages/web3/module.py", line 57, in caller
    result = w3.manager.request_blocking(method_str,
  File "/opt/hostedtoolcache/Python/3.8.18/x64/lib/python3.8/site-packages/web3/manager.py", line 198, in request_blocking
    return self.formatted_response(response,
  File "/opt/hostedtoolcache/Python/3.8.18/x64/lib/python3.8/site-packages/web3/manager.py", line 171, in formatted_response
    raise ValueError(response["error"])
ValueError: {'code': -32000, 'message': 'execution aborted (timeout = 5s)'}
[2024-02-01 10:12:14,867] 	INFO 	20 	id_data.py 	<module>() 	ID Data Started
[2024-02-01 10:12:15,541] 	INFO 	31 	id_data.py 	<module>() 	ID Data Ended
[2024-02-01 10:12:16,144] 	INFO 	24 	day_data.py 	<module>() 	Day Data Fusion Started
[2024-02-01 10:12:18,350] 	INFO 	71 	day_data.py 	<module>() 	Day Data Fusion Ended
[2024-02-01 10:12:19,334] 	INFO 	35 	pair_data.py 	<module>() 	Pair Data Fusion Started
[2024-02-01 10:12:31,246] 	INFO 	101 	pair_data.py 	<module>() 	Pair Data Fusion Ended
[2024-02-01 10:12:32,025] 	INFO 	36 	bribe_data.py 	<module>() 	Bribe Data Started
[2024-02-01 10:14:42,480] 	INFO 	157 	bribe_data.py 	<module>() 	Bribe Data Ended
[2024-02-01 10:14:43,255] 	INFO 	36 	fee_data.py 	<module>() 	Fee Data Started
[2024-02-01 10:16:24,526] 	INFO 	157 	fee_data.py 	<module>() 	Fee Data Ended
[2024-02-01 10:16:25,315] 	INFO 	37 	vote_data.py 	<module>() 	Vote Data Started
[2024-02-01 10:16:33,611] 	INFO 	116 	vote_data.py 	<module>() 	Vote Data Ended
[2024-02-01 10:16:34,401] 	INFO 	30 	revenue_data.py 	<module>() 	Revenue Data Started
[2024-02-01 10:16:39,121] 	INFO 	150 	revenue_data.py 	<module>() 	Revenue Data Ended
[2024-02-01 10:16:39,808] 	INFO 	20 	pool_data.py 	<module>() 	Pool Data Started
[2024-02-01 10:16:50,399] 	ERROR 	82 	pool_data.py 	<module>() 	Error occurred during Pool Data process. Error: {'code': -32000, 'message': 'execution aborted (timeout = 5s)'}
Traceback (most recent call last):
  File "pool_data.py", line 53, in <module>
    pool_data = contract_instance.functions.getActivePoolDistributions(pool_address).call()
  File "/opt/hostedtoolcache/Python/3.8.18/x64/lib/python3.8/site-packages/web3/contract.py", line 970, in call
    return call_contract_function(
  File "/opt/hostedtoolcache/Python/3.8.18/x64/lib/python3.8/site-packages/web3/contract.py", line 1525, in call_contract_function
    return_data = web3.eth.call(
  File "/opt/hostedtoolcache/Python/3.8.18/x64/lib/python3.8/site-packages/web3/module.py", line 57, in caller
    result = w3.manager.request_blocking(method_str,
  File "/opt/hostedtoolcache/Python/3.8.18/x64/lib/python3.8/site-packages/web3/manager.py", line 198, in request_blocking
    return self.formatted_response(response,
  File "/opt/hostedtoolcache/Python/3.8.18/x64/lib/python3.8/site-packages/web3/manager.py", line 171, in formatted_response
    raise ValueError(response["error"])
ValueError: {'code': -32000, 'message': 'execution aborted (timeout = 5s)'}
[2024-02-01 10:28:58,832] 	INFO 	20 	id_data.py 	<module>() 	ID Data Started
[2024-02-01 10:28:59,251] 	INFO 	31 	id_data.py 	<module>() 	ID Data Ended
[2024-02-01 10:28:59,885] 	INFO 	24 	day_data.py 	<module>() 	Day Data Fusion Started
[2024-02-01 10:29:01,048] 	INFO 	71 	day_data.py 	<module>() 	Day Data Fusion Ended
[2024-02-01 10:29:02,346] 	INFO 	35 	pair_data.py 	<module>() 	Pair Data Fusion Started
[2024-02-01 10:29:16,193] 	INFO 	101 	pair_data.py 	<module>() 	Pair Data Fusion Ended
[2024-02-01 10:29:16,972] 	INFO 	36 	bribe_data.py 	<module>() 	Bribe Data Started
[2024-02-01 10:31:27,253] 	INFO 	157 	bribe_data.py 	<module>() 	Bribe Data Ended
[2024-02-01 10:31:28,025] 	INFO 	36 	fee_data.py 	<module>() 	Fee Data Started
[2024-02-01 10:33:04,813] 	INFO 	157 	fee_data.py 	<module>() 	Fee Data Ended
[2024-02-01 10:33:05,592] 	INFO 	37 	vote_data.py 	<module>() 	Vote Data Started
[2024-02-01 10:33:13,500] 	INFO 	116 	vote_data.py 	<module>() 	Vote Data Ended
[2024-02-01 10:33:14,286] 	INFO 	30 	revenue_data.py 	<module>() 	Revenue Data Started
[2024-02-01 10:33:50,436] 	ERROR 	152 	revenue_data.py 	<module>() 	Error occurred during Revenue Data process. Error: {'code': 500, 'message': 'Internal error encountered.', 'status': 'INTERNAL'}
Traceback (most recent call last):
  File "revenue_data.py", line 137, in <module>
    gs = gc.open_by_key(sheetkey)
  File "/opt/hostedtoolcache/Python/3.8.18/x64/lib/python3.8/site-packages/gspread/client.py", line 170, in open_by_key
    return Spreadsheet(self, {"id": key})
  File "/opt/hostedtoolcache/Python/3.8.18/x64/lib/python3.8/site-packages/gspread/spreadsheet.py", line 34, in __init__
    metadata = self.fetch_sheet_metadata()
  File "/opt/hostedtoolcache/Python/3.8.18/x64/lib/python3.8/site-packages/gspread/spreadsheet.py", line 254, in fetch_sheet_metadata
    r = self.client.request("get", url, params=params)
  File "/opt/hostedtoolcache/Python/3.8.18/x64/lib/python3.8/site-packages/gspread/client.py", line 92, in request
    raise APIError(response)
gspread.exceptions.APIError: {'code': 500, 'message': 'Internal error encountered.', 'status': 'INTERNAL'}
[2024-02-01 10:33:51,120] 	INFO 	20 	pool_data.py 	<module>() 	Pool Data Started
[2024-02-01 10:33:59,367] 	ERROR 	82 	pool_data.py 	<module>() 	Error occurred during Pool Data process. Error: execution reverted
Traceback (most recent call last):
  File "pool_data.py", line 53, in <module>
    pool_data = contract_instance.functions.getActivePoolDistributions(pool_address).call()
  File "/opt/hostedtoolcache/Python/3.8.18/x64/lib/python3.8/site-packages/web3/contract.py", line 970, in call
    return call_contract_function(
  File "/opt/hostedtoolcache/Python/3.8.18/x64/lib/python3.8/site-packages/web3/contract.py", line 1525, in call_contract_function
    return_data = web3.eth.call(
  File "/opt/hostedtoolcache/Python/3.8.18/x64/lib/python3.8/site-packages/web3/module.py", line 57, in caller
    result = w3.manager.request_blocking(method_str,
  File "/opt/hostedtoolcache/Python/3.8.18/x64/lib/python3.8/site-packages/web3/manager.py", line 198, in request_blocking
    return self.formatted_response(response,
  File "/opt/hostedtoolcache/Python/3.8.18/x64/lib/python3.8/site-packages/web3/manager.py", line 170, in formatted_response
    apply_error_formatters(error_formatters, response)
  File "/opt/hostedtoolcache/Python/3.8.18/x64/lib/python3.8/site-packages/web3/manager.py", line 70, in apply_error_formatters
    formatted_resp = pipe(response, error_formatters)
  File "cytoolz/functoolz.pyx", line 680, in cytoolz.functoolz.pipe
  File "cytoolz/functoolz.pyx", line 655, in cytoolz.functoolz.c_pipe
  File "/opt/hostedtoolcache/Python/3.8.18/x64/lib/python3.8/site-packages/web3/_utils/method_formatters.py", line 580, in raise_solidity_error_on_revert
    raise ContractLogicError('execution reverted')
web3.exceptions.ContractLogicError: execution reverted
