[2025-06-01 02:29:52,756] 	INFO 	20 	id_data.py 	<module>() 	ID Data Started
[2025-06-01 02:30:12,337] 	ERROR 	33 	id_data.py 	<module>() 	Error occurred during ID Data process. Error: Expecting value: line 1 column 1 (char 0)
Traceback (most recent call last):
  File "/opt/hostedtoolcache/Python/3.8.18/x64/lib/python3.8/site-packages/requests/models.py", line 971, in json
    return complexjson.loads(self.text, **kwargs)
  File "/opt/hostedtoolcache/Python/3.8.18/x64/lib/python3.8/json/__init__.py", line 357, in loads
    return _default_decoder.decode(s)
  File "/opt/hostedtoolcache/Python/3.8.18/x64/lib/python3.8/json/decoder.py", line 337, in decode
    obj, end = self.raw_decode(s, idx=_w(s, 0).end())
  File "/opt/hostedtoolcache/Python/3.8.18/x64/lib/python3.8/json/decoder.py", line 355, in raw_decode
    raise JSONDecodeError("Expecting value", s, err.value) from None
json.decoder.JSONDecodeError: Expecting value: line 1 column 1 (char 0)

During handling of the above exception, another exception occurred:

Traceback (most recent call last):
  File "id_data.py", line 27, in <module>
    data = response.json()["data"]
  File "/opt/hostedtoolcache/Python/3.8.18/x64/lib/python3.8/site-packages/requests/models.py", line 975, in json
    raise RequestsJSONDecodeError(e.msg, e.doc, e.pos)
requests.exceptions.JSONDecodeError: Expecting value: line 1 column 1 (char 0)
[2025-06-01 02:30:12,858] 	INFO 	24 	day_data.py 	<module>() 	Day Data Fusion Started
[2025-06-01 02:30:13,101] 	ERROR 	73 	day_data.py 	<module>() 	Error occurred during Day Data Fusion process. Error: 'data'
Traceback (most recent call last):
  File "day_data.py", line 41, in <module>
    data = response.json()["data"]["uniswapDayDatas"]
KeyError: 'data'
[2025-06-01 02:30:13,949] 	INFO 	35 	pair_data.py 	<module>() 	Pair Data Fusion Started
[2025-06-01 02:30:14,235] 	ERROR 	63 	pair_data.py 	<module>() 	Error occurred during Pair Data Fusion process. Pair: sAMM-USDC.e/USDT, Address: 0xB38245b7fE8D594d883A27DB1055bf67926F6B27, Error: 'data'
[2025-06-01 02:30:14,337] 	ERROR 	63 	pair_data.py 	<module>() 	Error occurred during Pair Data Fusion process. Pair: vAMM-WPOL/elRETRO, Address: 0x90a09fE272540Ecd34661B91252f2aB4b7f7A4CE, Error: 'data'
[2025-06-01 02:30:14,450] 	ERROR 	63 	pair_data.py 	<module>() 	Error occurred during Pair Data Fusion process. Pair: sAMM-oRETRO/elRETRO, Address: 0xc58Eb718892Da5D519587A3ec87063A8a46c9feb, Error: 'data'
[2025-06-01 02:30:14,555] 	ERROR 	63 	pair_data.py 	<module>() 	Error occurred during Pair Data Fusion process. Pair: WPOL/WETH (0.05%), Address: 0x1a34EaBbe928Bf431B679959379b2225d60D9cdA, Error: 'data'
[2025-06-01 02:30:14,648] 	ERROR 	63 	pair_data.py 	<module>() 	Error occurred during Pair Data Fusion process. Pair: WPOL/USDC.e (0.05%), Address: 0xEC15624FBB314eb05BaaD4cA49b7904C0Cb6b645, Error: 'data'
[2025-06-01 02:30:14,739] 	ERROR 	63 	pair_data.py 	<module>() 	Error occurred during Pair Data Fusion process. Pair: USDC.e/WETH (0.05%), Address: 0xCE67850420c82dB45eb7fEeCcD2d181300D2BDB3, Error: 'data'
[2025-06-01 02:30:14,834] 	ERROR 	63 	pair_data.py 	<module>() 	Error occurred during Pair Data Fusion process. Pair: WBTC/WETH (0.05%), Address: 0xb694E3bdd4BCdF843510983D257679D1E627C474, Error: 'data'
[2025-06-01 02:30:14,926] 	ERROR 	63 	pair_data.py 	<module>() 	Error occurred during Pair Data Fusion process. Pair: WPOL/USDT (0.05%), Address: 0xB580229645b240A368768ec3E88cb67A41eBBC5B, Error: 'data'
[2025-06-01 02:30:15,028] 	ERROR 	63 	pair_data.py 	<module>() 	Error occurred during Pair Data Fusion process. Pair: WPOL/CASH (0.05%), Address: 0x63ca6ED3D390C725b7FEb617BAdcab78a61038E8, Error: 'data'
[2025-06-01 02:30:15,135] 	ERROR 	63 	pair_data.py 	<module>() 	Error occurred during Pair Data Fusion process. Pair: CASH/WETH (0.05%), Address: 0x0A46B0712974F201BeD15c2458a023EbED25eF4F, Error: 'data'
[2025-06-01 02:30:15,243] 	ERROR 	63 	pair_data.py 	<module>() 	Error occurred during Pair Data Fusion process. Pair: USDC.e/CASH (0.01%), Address: 0x619259F699839dD1498FFC22297044462483bD27, Error: 'data'
[2025-06-01 02:30:15,353] 	ERROR 	63 	pair_data.py 	<module>() 	Error occurred during Pair Data Fusion process. Pair: CASH/USDT (0.01%), Address: 0x160FBF00AB5fbF0200c0Cd4929aEaa2AdD25FB5b, Error: 'data'
[2025-06-01 02:30:15,461] 	ERROR 	63 	pair_data.py 	<module>() 	Error occurred during Pair Data Fusion process. Pair: CASH/DAI (0.01%), Address: 0x1e683586fCB45a769ef2C7d9d7b1803E9C1AEE79, Error: 'data'
[2025-06-01 02:30:15,561] 	ERROR 	63 	pair_data.py 	<module>() 	Error occurred during Pair Data Fusion process. Pair: CASH/miMATIC (0.01%), Address: 0xeB80047F7d5D4C4A3BC6319250d6b1b8aEe2d0D2, Error: 'data'
[2025-06-01 02:30:15,670] 	ERROR 	63 	pair_data.py 	<module>() 	Error occurred during Pair Data Fusion process. Pair: CASH/MaticX (0.05%), Address: 0xb98F8DF0DC6750A3e54540A1e094186C8bED780a, Error: 'data'
[2025-06-01 02:30:15,766] 	ERROR 	63 	pair_data.py 	<module>() 	Error occurred during Pair Data Fusion process. Pair: USDC.e/EURA (0.05%), Address: 0xC2CB03a819F785bD8eb8D628BAD41Cd7c1C71F4B, Error: 'data'
[2025-06-01 02:30:15,878] 	ERROR 	63 	pair_data.py 	<module>() 	Error occurred during Pair Data Fusion process. Pair: FRAX/CASH (0.01%), Address: 0x72289129Dc4937a5d406d1ECeD8b2A17d007A650, Error: 'data'
[2025-06-01 02:30:15,992] 	ERROR 	63 	pair_data.py 	<module>() 	Error occurred during Pair Data Fusion process. Pair: CASH/RETRO (1%), Address: 0xb47A07966cE6812702C0567d03725F1b37E27877, Error: 'data'
[2025-06-01 02:30:16,100] 	ERROR 	63 	pair_data.py 	<module>() 	Error occurred during Pair Data Fusion process. Pair: WETH/RETRO (1%), Address: 0x35394eED0Be676ec6470fE6531daD809265310ff, Error: 'data'
[2025-06-01 02:30:16,218] 	ERROR 	63 	pair_data.py 	<module>() 	Error occurred during Pair Data Fusion process. Pair: WPOL/RETRO (1%), Address: 0x547FD24AA2ED09d86dAC02E36b8Ce84A59fD644F, Error: 'data'
[2025-06-01 02:30:16,330] 	ERROR 	63 	pair_data.py 	<module>() 	Error occurred during Pair Data Fusion process. Pair: WBTC/RETRO (1%), Address: 0x0F73E719a76947752E4b26A2c3FC80a580e68fB4, Error: 'data'
[2025-06-01 02:30:16,420] 	ERROR 	63 	pair_data.py 	<module>() 	Error occurred during Pair Data Fusion process. Pair: stMATIC/RETRO (1%), Address: 0x0973698BB6399c39d628698f9300430C4e7c9bf9, Error: 'data'
[2025-06-01 02:30:16,534] 	ERROR 	63 	pair_data.py 	<module>() 	Error occurred during Pair Data Fusion process. Pair: USDC.e/RETRO (1%), Address: 0xc7d8B9c270D0E31A6a0Cf4496fe019766Be42E15, Error: 'data'
[2025-06-01 02:30:16,626] 	ERROR 	63 	pair_data.py 	<module>() 	Error occurred during Pair Data Fusion process. Pair: RETRO/USDT (1%), Address: 0x69dCAE97A1286B112a8BD75bD9147bD0a3207756, Error: 'data'
[2025-06-01 02:30:16,726] 	ERROR 	63 	pair_data.py 	<module>() 	Error occurred during Pair Data Fusion process. Pair: miMATIC/RETRO (1%), Address: 0xd98eEf295f78ddDd104a8645854C7F8714B39B88, Error: 'data'
[2025-06-01 02:30:16,845] 	ERROR 	63 	pair_data.py 	<module>() 	Error occurred during Pair Data Fusion process. Pair: LINK/RETRO (1%), Address: 0x7761c7233924C3D72F27Fae6a81B074C0152e03a, Error: 'data'
[2025-06-01 02:30:16,960] 	ERROR 	63 	pair_data.py 	<module>() 	Error occurred during Pair Data Fusion process. Pair: RETRO/EURA (1%), Address: 0x15949526fF03fE6ab5f49dA6a86749c20141b3f1, Error: 'data'
[2025-06-01 02:30:17,175] 	ERROR 	63 	pair_data.py 	<module>() 	Error occurred during Pair Data Fusion process. Pair: USDC.e/USDT (0.01%), Address: 0x772510189425ac63f9a5A5eF2fd0C7FDA58CBFC7, Error: 'data'
[2025-06-01 02:30:17,281] 	ERROR 	63 	pair_data.py 	<module>() 	Error occurred during Pair Data Fusion process. Pair: USDC.e/DAI (0.01%), Address: 0x219116F23BDC11EB25e4D0FbE92eD0972d86BE20, Error: 'data'
[2025-06-01 02:30:17,394] 	ERROR 	63 	pair_data.py 	<module>() 	Error occurred during Pair Data Fusion process. Pair: WPOL/MaticX (0.01%), Address: 0x9aa18301055091e9da7C57b81633632Fa33B9a80, Error: 'data'
[2025-06-01 02:30:17,492] 	ERROR 	63 	pair_data.py 	<module>() 	Error occurred during Pair Data Fusion process. Pair: wstETH/WETH (0.01%), Address: 0xa9439Db1D7025Ce4aAc513Baf5eee5220172126C, Error: 'data'
[2025-06-01 02:30:17,595] 	ERROR 	63 	pair_data.py 	<module>() 	Error occurred during Pair Data Fusion process. Pair: WPOL/stMATIC (0.01%), Address: 0x2d623c33673248E95C7a1C26aE7065eb7A7Ac0Ea, Error: 'data'
[2025-06-01 02:30:17,721] 	ERROR 	63 	pair_data.py 	<module>() 	Error occurred during Pair Data Fusion process. Pair: WETH/frxETH (0.01%), Address: 0xe5069a75Bdfe8F676B778B0aaDCcC597841F819B, Error: 'data'
[2025-06-01 02:30:17,845] 	ERROR 	63 	pair_data.py 	<module>() 	Error occurred during Pair Data Fusion process. Pair: FRAX/frxETH (0.05%), Address: 0x38df0c93bf69a9EfB3d3647fF459eF27235A8968, Error: 'data'
[2025-06-01 02:30:17,938] 	ERROR 	63 	pair_data.py 	<module>() 	Error occurred during Pair Data Fusion process. Pair: WPOL/frxETH (0.05%), Address: 0x44AAE81BE8435b6998A66d9642f66DE57DD03FC2, Error: 'data'
[2025-06-01 02:30:18,040] 	ERROR 	63 	pair_data.py 	<module>() 	Error occurred during Pair Data Fusion process. Pair: xbb-t-USD/CASH (0.01%), Address: 0x07dBf448cCC68cA64247da04F2E24643eCf57385, Error: 'data'
[2025-06-01 02:30:18,157] 	ERROR 	63 	pair_data.py 	<module>() 	Error occurred during Pair Data Fusion process. Pair: LINK/LUCHA (0.3%), Address: 0x91248C85DD408BD216254C3cFb51fc326290cF7e, Error: 'data'
[2025-06-01 02:30:18,248] 	ERROR 	63 	pair_data.py 	<module>() 	Error occurred during Pair Data Fusion process. Pair: CASH/LUCHA (0.3%), Address: 0xc666c4b402Bd797185EA419261D22a8f22DDFce6, Error: 'data'
[2025-06-01 02:30:18,365] 	ERROR 	63 	pair_data.py 	<module>() 	Error occurred during Pair Data Fusion process. Pair: USDC.e/miMATIC (0.3%), Address: 0xb090BE2D2F02646057d4DF997A7A983dFb265de0, Error: 'data'
[2025-06-01 02:30:18,470] 	ERROR 	63 	pair_data.py 	<module>() 	Error occurred during Pair Data Fusion process. Pair: FRAX/miMATIC (0.3%), Address: 0xdeB25Dd2d5D168Fd6f80F154d96a2Dab81d61845, Error: 'data'
[2025-06-01 02:30:18,586] 	ERROR 	63 	pair_data.py 	<module>() 	Error occurred during Pair Data Fusion process. Pair: WPOL/miMATIC (0.3%), Address: 0xC571445Fc93666e1E4FaE2E84A7b74FE6ed3978D, Error: 'data'
[2025-06-01 02:30:18,699] 	ERROR 	63 	pair_data.py 	<module>() 	Error occurred during Pair Data Fusion process. Pair: CASH/ERN (0.3%), Address: 0x777a87889f42C33f9A1E5c117774694bbd857075, Error: 'data'
[2025-06-01 02:30:18,840] 	ERROR 	63 	pair_data.py 	<module>() 	Error occurred during Pair Data Fusion process. Pair: ICHI/RETRO (1%), Address: 0xC26E1a0cDab4Bf5141530C49F3360f162C5Db5Db, Error: 'data'
[2025-06-01 02:30:18,942] 	ERROR 	63 	pair_data.py 	<module>() 	Error occurred during Pair Data Fusion process. Pair: WPOL/ICHI (0.3%), Address: 0x13d5e61838D93F7962C52dc921FD7C0Ccc092E35, Error: 'data'
[2025-06-01 02:30:19,043] 	ERROR 	63 	pair_data.py 	<module>() 	Error occurred during Pair Data Fusion process. Pair: SD/MaticX (0.3%), Address: 0xB97c62834e096858BD0B996b758942dd43d7B5eE, Error: 'data'
[2025-06-01 02:30:19,132] 	ERROR 	63 	pair_data.py 	<module>() 	Error occurred during Pair Data Fusion process. Pair: stERN/ERN (1%), Address: 0x99583057951987beD85CE6934473160bFD4921b9, Error: 'data'
[2025-06-01 02:30:19,225] 	ERROR 	63 	pair_data.py 	<module>() 	Error occurred during Pair Data Fusion process. Pair: tUSDC/STAR (0.05%), Address: 0x53C49b9308c3DB176d351d7914Cec0Fb5D7f1129, Error: 'data'
[2025-06-01 02:30:19,327] 	ERROR 	63 	pair_data.py 	<module>() 	Error occurred during Pair Data Fusion process. Pair: WPOL/LUCHA (0.3%), Address: 0x52BeedA850A7048e9D543668BF54E0d9E1B667E0, Error: 'data'
[2025-06-01 02:30:19,424] 	ERROR 	63 	pair_data.py 	<module>() 	Error occurred during Pair Data Fusion process. Pair: LUCHA/WETH (0.3%), Address: 0x13136EA148331a07497087bfc31fBCcD9b99123c, Error: 'data'
[2025-06-01 02:30:19,539] 	ERROR 	63 	pair_data.py 	<module>() 	Error occurred during Pair Data Fusion process. Pair: JRT/WETH (0.3%), Address: 0xAE107e52ebdF151E61d9Fb4Bd800C86c31741465, Error: 'data'
[2025-06-01 02:30:19,646] 	ERROR 	63 	pair_data.py 	<module>() 	Error occurred during Pair Data Fusion process. Pair: axlLqdr/CASH (0.3%), Address: 0x22c10e61A05a03bcd8BF61a7E648f2330ecdA270, Error: 'data'
[2025-06-01 02:30:19,766] 	ERROR 	63 	pair_data.py 	<module>() 	Error occurred during Pair Data Fusion process. Pair: XOC/jMXN (0.01%), Address: 0xccE01e3615785771b84Eb5F88EC612AC6704FdE2, Error: 'data'
[2025-06-01 02:30:19,875] 	ERROR 	63 	pair_data.py 	<module>() 	Error occurred during Pair Data Fusion process. Pair: ICHI/CASH (1%), Address: 0x8ceD58A2dE3C2ea5D3cED3eb4331158c8cf985Fb, Error: 'data'
[2025-06-01 02:30:19,977] 	ERROR 	63 	pair_data.py 	<module>() 	Error occurred during Pair Data Fusion process. Pair: wUSDR/CASH (0.3%), Address: 0x3baEa49B71461DEaB46E6F42548D0005359ff629, Error: 'data'
[2025-06-01 02:30:20,072] 	ERROR 	63 	pair_data.py 	<module>() 	Error occurred during Pair Data Fusion process. Pair: CASH/STAR (0.05%), Address: 0x88C522E526E5Eea8d636fd6805cA7fEB488780D0, Error: 'data'
[2025-06-01 02:30:20,162] 	ERROR 	63 	pair_data.py 	<module>() 	Error occurred during Pair Data Fusion process. Pair: USDC.e/STAR (0.01%), Address: 0x6De0CA91Ef19A6ce9f02A423ae2dF89Fe09Bff0F, Error: 'data'
[2025-06-01 02:30:20,262] 	ERROR 	63 	pair_data.py 	<module>() 	Error occurred during Pair Data Fusion process. Pair: tUSDC/STAR (1%), Address: 0xaC44f57eEF260eB6E0f896b61984Da8d86FeE9ed, Error: 'data'
[2025-06-01 02:30:20,366] 	ERROR 	63 	pair_data.py 	<module>() 	Error occurred during Pair Data Fusion process. Pair: tUSDC/CASH (1%), Address: 0x4FcdB2DCc4Ce156c723aD541dba8B39d47284FC5, Error: 'data'
[2025-06-01 02:30:20,458] 	ERROR 	63 	pair_data.py 	<module>() 	Error occurred during Pair Data Fusion process. Pair: WPOL/USDC.e (0.3%), Address: 0x8c862d100B94d95a49D91958c9e8C2c348d00F04, Error: 'data'
[2025-06-01 02:30:20,551] 	ERROR 	63 	pair_data.py 	<module>() 	Error occurred during Pair Data Fusion process. Pair: WPOL/WETH (0.3%), Address: 0xB8dD18F9b7C3Ad4bDd4B94cB819eda3bd4465119, Error: 'data'
[2025-06-01 02:30:20,652] 	ERROR 	63 	pair_data.py 	<module>() 	Error occurred during Pair Data Fusion process. Pair: USDC.e/WETH (0.3%), Address: 0x058F5330Fef74445878110e201B04F36f8a51c9b, Error: 'data'
[2025-06-01 02:30:20,735] 	ERROR 	63 	pair_data.py 	<module>() 	Error occurred during Pair Data Fusion process. Pair: WBTC/WETH (0.3%), Address: 0x11275C625A7DEE3532E062Eef6915f00af85C3B5, Error: 'data'
[2025-06-01 02:30:20,874] 	ERROR 	63 	pair_data.py 	<module>() 	Error occurred during Pair Data Fusion process. Pair: LINK/WETH (0.3%), Address: 0x555eABEEfe6a047747071525A2c0fFd96d945f69, Error: 'data'
[2025-06-01 02:30:20,975] 	ERROR 	63 	pair_data.py 	<module>() 	Error occurred during Pair Data Fusion process. Pair: WBTC/CASH (0.3%), Address: 0x2C8F7d92Dc7A414D343CbFB687E31a11F525d29e, Error: 'data'
[2025-06-01 02:30:21,077] 	ERROR 	63 	pair_data.py 	<module>() 	Error occurred during Pair Data Fusion process. Pair: WPOL/DEUS (1%), Address: 0xB5cB765e44Eca4bc5a434fFaf6Bf7De235Bc60a5, Error: 'data'
[2025-06-01 02:30:21,176] 	ERROR 	63 	pair_data.py 	<module>() 	Error occurred during Pair Data Fusion process. Pair: WPOL/WBTC (0.3%), Address: 0x2981A1f699eA7149aa08121A07F000cf82846A9e, Error: 'data'
[2025-06-01 02:30:21,284] 	ERROR 	63 	pair_data.py 	<module>() 	Error occurred during Pair Data Fusion process. Pair: FRAX/STAR (0.05%), Address: 0x7D480cBf5Aee75E72eF26F223937f3981d67a860, Error: 'data'
[2025-06-01 02:30:21,382] 	ERROR 	63 	pair_data.py 	<module>() 	Error occurred during Pair Data Fusion process. Pair: CASH/TAROT (0.3%), Address: 0x217aEb0667b79584FBf6265B74a8cD22E1245fdC, Error: 'data'
[2025-06-01 02:30:21,486] 	ERROR 	63 	pair_data.py 	<module>() 	Error occurred during Pair Data Fusion process. Pair: CASH/fxDOLA (0.05%), Address: 0x4b4B895a0dD744B4893aA4370A8F7eDbde5Fd90e, Error: 'data'
[2025-06-01 02:30:21,583] 	ERROR 	63 	pair_data.py 	<module>() 	Error occurred during Pair Data Fusion process. Pair: RETRO/liveRetro (1%), Address: 0x6333BB8b6f1DDa6f929d70eDEB9e31c8148dC9ef, Error: 'data'
[2025-06-01 02:30:21,692] 	ERROR 	63 	pair_data.py 	<module>() 	Error occurred during Pair Data Fusion process. Pair: MVX/WETH (1%), Address: 0xCC72276de3BCc1b159F1B60A86B0211116022B42, Error: 'data'
[2025-06-01 02:30:21,804] 	ERROR 	63 	pair_data.py 	<module>() 	Error occurred during Pair Data Fusion process. Pair: WPOL/elRETRO (1%), Address: 0x6794Db07e2efE1307b8594FBbBFad78E50eC76fa, Error: 'data'
[2025-06-01 02:30:21,894] 	ERROR 	63 	pair_data.py 	<module>() 	Error occurred during Pair Data Fusion process. Pair: OATH/WETH (1%), Address: 0x0c74834d67c4bf5e6a44D18b2BAc767cddB4CdBf, Error: 'data'
[2025-06-01 02:30:21,993] 	ERROR 	63 	pair_data.py 	<module>() 	Error occurred during Pair Data Fusion process. Pair: USDC.e/IBEX (1%), Address: 0x53D8c25B3d130D2810591cDc7A41Bd848bF79B63, Error: 'data'
[2025-06-01 02:30:22,118] 	ERROR 	63 	pair_data.py 	<module>() 	Error occurred during Pair Data Fusion process. Pair: USDC.e/fxDOLA (0.3%), Address: 0x896ffE2cd28Ba13ddDa98103a3B66E82bb36BeE3, Error: 'data'
[2025-06-01 02:30:22,219] 	ERROR 	63 	pair_data.py 	<module>() 	Error occurred during Pair Data Fusion process. Pair: USDC.e/FRAX (0.3%), Address: 0x091236A16952BC9e4bB817FFA7aB40263183f658, Error: 'data'
[2025-06-01 02:30:22,337] 	ERROR 	63 	pair_data.py 	<module>() 	Error occurred during Pair Data Fusion process. Pair: WBTC/USDC.e (0.3%), Address: 0x459F42C788E6F8faCe4854DDD59C81a6Ad8BB1Aa, Error: 'data'
[2025-06-01 02:30:22,429] 	ERROR 	63 	pair_data.py 	<module>() 	Error occurred during Pair Data Fusion process. Pair: WETH/ERN (0.3%), Address: 0xCF2093da3CeBb8731747EEaCbd486A7fcE2Db901, Error: 'data'
[2025-06-01 02:30:22,523] 	ERROR 	63 	pair_data.py 	<module>() 	Error occurred during Pair Data Fusion process. Pair: WETH/JARVIS (0.3%), Address: 0xf310d505B85E0378790Af9fDB9b79b40736f7b4D, Error: 'data'
[2025-06-01 02:30:22,611] 	ERROR 	63 	pair_data.py 	<module>() 	Error occurred during Pair Data Fusion process. Pair: jEUR/CASH (0.05%), Address: 0x65E6b7C7DfE071E52D6923E4079E3C0FcBeaA401, Error: 'data'
[2025-06-01 02:30:22,713] 	ERROR 	63 	pair_data.py 	<module>() 	Error occurred during Pair Data Fusion process. Pair: USDC.e/USDC (0.01%), Address: 0x1e0aa3f6C3130294845B8e162d838e221d170016, Error: 'data'
[2025-06-01 02:30:22,801] 	ERROR 	63 	pair_data.py 	<module>() 	Error occurred during Pair Data Fusion process. Pair: LUCHA/WETH (1%), Address: 0x098c1e4BB34DEcDF49D5966014B5153Af326E766, Error: 'data'
[2025-06-01 02:30:22,900] 	ERROR 	63 	pair_data.py 	<module>() 	Error occurred during Pair Data Fusion process. Pair: WPOL/LUCHA (1%), Address: 0xde4C8898CD50EBE9C167313b312D147D10d1C898, Error: 'data'
[2025-06-01 02:30:22,988] 	ERROR 	63 	pair_data.py 	<module>() 	Error occurred during Pair Data Fusion process. Pair: LINK/LUCHA (1%), Address: 0xA97B2b9AcA65aab57A6b0840B45777bd66fbcf33, Error: 'data'
[2025-06-01 02:30:23,083] 	ERROR 	63 	pair_data.py 	<module>() 	Error occurred during Pair Data Fusion process. Pair: CASH/LUCHA (1%), Address: 0x5c09352B1aa703d18dbcF48c98655BFA19d07FBB, Error: 'data'
[2025-06-01 02:30:23,419] 	ERROR 	103 	pair_data.py 	<module>() 	Error occurred during Pair Data Fusion process. Error: 'date'
Traceback (most recent call last):
  File "/opt/hostedtoolcache/Python/3.8.18/x64/lib/python3.8/site-packages/pandas/core/indexes/base.py", line 3802, in get_loc
    return self._engine.get_loc(casted_key)
  File "pandas/_libs/index.pyx", line 138, in pandas._libs.index.IndexEngine.get_loc
  File "pandas/_libs/index.pyx", line 165, in pandas._libs.index.IndexEngine.get_loc
  File "pandas/_libs/hashtable_class_helper.pxi", line 5745, in pandas._libs.hashtable.PyObjectHashTable.get_item
  File "pandas/_libs/hashtable_class_helper.pxi", line 5753, in pandas._libs.hashtable.PyObjectHashTable.get_item
KeyError: 'date'

The above exception was the direct cause of the following exception:

Traceback (most recent call last):
  File "pair_data.py", line 68, in <module>
    pairdata_fusion_df["date"] = pairdata_fusion_df["date"].apply(lambda timestamp: datetime.utcfromtimestamp(timestamp).date())
  File "/opt/hostedtoolcache/Python/3.8.18/x64/lib/python3.8/site-packages/pandas/core/frame.py", line 3807, in __getitem__
    indexer = self.columns.get_loc(key)
  File "/opt/hostedtoolcache/Python/3.8.18/x64/lib/python3.8/site-packages/pandas/core/indexes/base.py", line 3804, in get_loc
    raise KeyError(key) from err
KeyError: 'date'
[2025-06-01 02:30:24,262] 	INFO 	36 	bribe_data.py 	<module>() 	Bribe Data Started
[2025-06-01 02:30:24,862] 	ERROR 	159 	bribe_data.py 	<module>() 	Error occurred during Bribe Data process. Error: 403 Client Error: Forbidden for url: https://rpc.ankr.com/polygon
Traceback (most recent call last):
  File "bribe_data.py", line 71, in <module>
    rewardsListLength = contract_instance.functions.rewardsListLength().call()
  File "/opt/hostedtoolcache/Python/3.8.18/x64/lib/python3.8/site-packages/web3/contract.py", line 970, in call
    return call_contract_function(
  File "/opt/hostedtoolcache/Python/3.8.18/x64/lib/python3.8/site-packages/web3/contract.py", line 1525, in call_contract_function
    return_data = web3.eth.call(
  File "/opt/hostedtoolcache/Python/3.8.18/x64/lib/python3.8/site-packages/web3/module.py", line 57, in caller
    result = w3.manager.request_blocking(method_str,
  File "/opt/hostedtoolcache/Python/3.8.18/x64/lib/python3.8/site-packages/web3/manager.py", line 197, in request_blocking
    response = self._make_request(method, params)
  File "/opt/hostedtoolcache/Python/3.8.18/x64/lib/python3.8/site-packages/web3/manager.py", line 150, in _make_request
    return request_func(method, params)
  File "/opt/hostedtoolcache/Python/3.8.18/x64/lib/python3.8/site-packages/web3/middleware/formatting.py", line 94, in middleware
    response = make_request(method, params)
  File "/opt/hostedtoolcache/Python/3.8.18/x64/lib/python3.8/site-packages/web3/middleware/gas_price_strategy.py", line 90, in middleware
    return make_request(method, params)
  File "/opt/hostedtoolcache/Python/3.8.18/x64/lib/python3.8/site-packages/web3/middleware/formatting.py", line 94, in middleware
    response = make_request(method, params)
  File "/opt/hostedtoolcache/Python/3.8.18/x64/lib/python3.8/site-packages/web3/middleware/attrdict.py", line 33, in middleware
    response = make_request(method, params)
  File "/opt/hostedtoolcache/Python/3.8.18/x64/lib/python3.8/site-packages/web3/middleware/formatting.py", line 94, in middleware
    response = make_request(method, params)
  File "/opt/hostedtoolcache/Python/3.8.18/x64/lib/python3.8/site-packages/web3/middleware/formatting.py", line 94, in middleware
    response = make_request(method, params)
  File "/opt/hostedtoolcache/Python/3.8.18/x64/lib/python3.8/site-packages/web3/middleware/formatting.py", line 94, in middleware
    response = make_request(method, params)
  File "/opt/hostedtoolcache/Python/3.8.18/x64/lib/python3.8/site-packages/web3/middleware/buffered_gas_estimate.py", line 40, in middleware
    return make_request(method, params)
  File "/opt/hostedtoolcache/Python/3.8.18/x64/lib/python3.8/site-packages/web3/middleware/exception_retry_request.py", line 105, in middleware
    return make_request(method, params)
  File "/opt/hostedtoolcache/Python/3.8.18/x64/lib/python3.8/site-packages/web3/providers/rpc.py", line 88, in make_request
    raw_response = make_post_request(
  File "/opt/hostedtoolcache/Python/3.8.18/x64/lib/python3.8/site-packages/web3/_utils/request.py", line 113, in make_post_request
    response.raise_for_status()
  File "/opt/hostedtoolcache/Python/3.8.18/x64/lib/python3.8/site-packages/requests/models.py", line 1021, in raise_for_status
    raise HTTPError(http_error_msg, response=self)
requests.exceptions.HTTPError: 403 Client Error: Forbidden for url: https://rpc.ankr.com/polygon
[2025-06-01 02:30:25,703] 	INFO 	36 	fee_data.py 	<module>() 	Fee Data Started
[2025-06-01 02:30:25,824] 	ERROR 	159 	fee_data.py 	<module>() 	Error occurred during Fee Data process. Error: 403 Client Error: Forbidden for url: https://rpc.ankr.com/polygon
Traceback (most recent call last):
  File "fee_data.py", line 71, in <module>
    rewardsListLength = contract_instance.functions.rewardsListLength().call()
  File "/opt/hostedtoolcache/Python/3.8.18/x64/lib/python3.8/site-packages/web3/contract.py", line 970, in call
    return call_contract_function(
  File "/opt/hostedtoolcache/Python/3.8.18/x64/lib/python3.8/site-packages/web3/contract.py", line 1525, in call_contract_function
    return_data = web3.eth.call(
  File "/opt/hostedtoolcache/Python/3.8.18/x64/lib/python3.8/site-packages/web3/module.py", line 57, in caller
    result = w3.manager.request_blocking(method_str,
  File "/opt/hostedtoolcache/Python/3.8.18/x64/lib/python3.8/site-packages/web3/manager.py", line 197, in request_blocking
    response = self._make_request(method, params)
  File "/opt/hostedtoolcache/Python/3.8.18/x64/lib/python3.8/site-packages/web3/manager.py", line 150, in _make_request
    return request_func(method, params)
  File "/opt/hostedtoolcache/Python/3.8.18/x64/lib/python3.8/site-packages/web3/middleware/formatting.py", line 94, in middleware
    response = make_request(method, params)
  File "/opt/hostedtoolcache/Python/3.8.18/x64/lib/python3.8/site-packages/web3/middleware/gas_price_strategy.py", line 90, in middleware
    return make_request(method, params)
  File "/opt/hostedtoolcache/Python/3.8.18/x64/lib/python3.8/site-packages/web3/middleware/formatting.py", line 94, in middleware
    response = make_request(method, params)
  File "/opt/hostedtoolcache/Python/3.8.18/x64/lib/python3.8/site-packages/web3/middleware/attrdict.py", line 33, in middleware
    response = make_request(method, params)
  File "/opt/hostedtoolcache/Python/3.8.18/x64/lib/python3.8/site-packages/web3/middleware/formatting.py", line 94, in middleware
    response = make_request(method, params)
  File "/opt/hostedtoolcache/Python/3.8.18/x64/lib/python3.8/site-packages/web3/middleware/formatting.py", line 94, in middleware
    response = make_request(method, params)
  File "/opt/hostedtoolcache/Python/3.8.18/x64/lib/python3.8/site-packages/web3/middleware/formatting.py", line 94, in middleware
    response = make_request(method, params)
  File "/opt/hostedtoolcache/Python/3.8.18/x64/lib/python3.8/site-packages/web3/middleware/buffered_gas_estimate.py", line 40, in middleware
    return make_request(method, params)
  File "/opt/hostedtoolcache/Python/3.8.18/x64/lib/python3.8/site-packages/web3/middleware/exception_retry_request.py", line 105, in middleware
    return make_request(method, params)
  File "/opt/hostedtoolcache/Python/3.8.18/x64/lib/python3.8/site-packages/web3/providers/rpc.py", line 88, in make_request
    raw_response = make_post_request(
  File "/opt/hostedtoolcache/Python/3.8.18/x64/lib/python3.8/site-packages/web3/_utils/request.py", line 113, in make_post_request
    response.raise_for_status()
  File "/opt/hostedtoolcache/Python/3.8.18/x64/lib/python3.8/site-packages/requests/models.py", line 1021, in raise_for_status
    raise HTTPError(http_error_msg, response=self)
requests.exceptions.HTTPError: 403 Client Error: Forbidden for url: https://rpc.ankr.com/polygon
[2025-06-01 02:30:26,673] 	INFO 	37 	vote_data.py 	<module>() 	Vote Data Started
[2025-06-01 02:30:46,278] 	ERROR 	118 	vote_data.py 	<module>() 	Error occurred during Vote Data process. Error: Expecting value: line 1 column 1 (char 0)
Traceback (most recent call last):
  File "/opt/hostedtoolcache/Python/3.8.18/x64/lib/python3.8/site-packages/requests/models.py", line 971, in json
    return complexjson.loads(self.text, **kwargs)
  File "/opt/hostedtoolcache/Python/3.8.18/x64/lib/python3.8/json/__init__.py", line 357, in loads
    return _default_decoder.decode(s)
  File "/opt/hostedtoolcache/Python/3.8.18/x64/lib/python3.8/json/decoder.py", line 337, in decode
    obj, end = self.raw_decode(s, idx=_w(s, 0).end())
  File "/opt/hostedtoolcache/Python/3.8.18/x64/lib/python3.8/json/decoder.py", line 355, in raw_decode
    raise JSONDecodeError("Expecting value", s, err.value) from None
json.decoder.JSONDecodeError: Expecting value: line 1 column 1 (char 0)

During handling of the above exception, another exception occurred:

Traceback (most recent call last):
  File "vote_data.py", line 64, in <module>
    RETRO_price = jmespath.search("data[?name == 'RETRO'].price", response.json())[0]
  File "/opt/hostedtoolcache/Python/3.8.18/x64/lib/python3.8/site-packages/requests/models.py", line 975, in json
    raise RequestsJSONDecodeError(e.msg, e.doc, e.pos)
requests.exceptions.JSONDecodeError: Expecting value: line 1 column 1 (char 0)
[2025-06-01 02:30:47,114] 	INFO 	30 	revenue_data.py 	<module>() 	Revenue Data Started
[2025-06-01 02:31:12,030] 	ERROR 	152 	revenue_data.py 	<module>() 	Error occurred during Revenue Data process. Error: Expecting value: line 1 column 1 (char 0)
Traceback (most recent call last):
  File "/opt/hostedtoolcache/Python/3.8.18/x64/lib/python3.8/site-packages/requests/models.py", line 971, in json
    return complexjson.loads(self.text, **kwargs)
  File "/opt/hostedtoolcache/Python/3.8.18/x64/lib/python3.8/json/__init__.py", line 357, in loads
    return _default_decoder.decode(s)
  File "/opt/hostedtoolcache/Python/3.8.18/x64/lib/python3.8/json/decoder.py", line 337, in decode
    obj, end = self.raw_decode(s, idx=_w(s, 0).end())
  File "/opt/hostedtoolcache/Python/3.8.18/x64/lib/python3.8/json/decoder.py", line 355, in raw_decode
    raise JSONDecodeError("Expecting value", s, err.value) from None
json.decoder.JSONDecodeError: Expecting value: line 1 column 1 (char 0)

During handling of the above exception, another exception occurred:

Traceback (most recent call last):
  File "revenue_data.py", line 66, in <module>
    RETRO_price = jmespath.search("data[?name == 'RETRO'].price", response.json())[0]
  File "/opt/hostedtoolcache/Python/3.8.18/x64/lib/python3.8/site-packages/requests/models.py", line 975, in json
    raise RequestsJSONDecodeError(e.msg, e.doc, e.pos)
requests.exceptions.JSONDecodeError: Expecting value: line 1 column 1 (char 0)
[2025-06-01 03:49:58,776] 	INFO 	20 	id_data.py 	<module>() 	ID Data Started
[2025-06-01 03:50:18,490] 	ERROR 	33 	id_data.py 	<module>() 	Error occurred during ID Data process. Error: Expecting value: line 1 column 1 (char 0)
Traceback (most recent call last):
  File "/opt/hostedtoolcache/Python/3.8.18/x64/lib/python3.8/site-packages/requests/models.py", line 971, in json
    return complexjson.loads(self.text, **kwargs)
  File "/opt/hostedtoolcache/Python/3.8.18/x64/lib/python3.8/json/__init__.py", line 357, in loads
    return _default_decoder.decode(s)
  File "/opt/hostedtoolcache/Python/3.8.18/x64/lib/python3.8/json/decoder.py", line 337, in decode
    obj, end = self.raw_decode(s, idx=_w(s, 0).end())
  File "/opt/hostedtoolcache/Python/3.8.18/x64/lib/python3.8/json/decoder.py", line 355, in raw_decode
    raise JSONDecodeError("Expecting value", s, err.value) from None
json.decoder.JSONDecodeError: Expecting value: line 1 column 1 (char 0)

During handling of the above exception, another exception occurred:

Traceback (most recent call last):
  File "id_data.py", line 27, in <module>
    data = response.json()["data"]
  File "/opt/hostedtoolcache/Python/3.8.18/x64/lib/python3.8/site-packages/requests/models.py", line 975, in json
    raise RequestsJSONDecodeError(e.msg, e.doc, e.pos)
requests.exceptions.JSONDecodeError: Expecting value: line 1 column 1 (char 0)
[2025-06-01 03:50:19,023] 	INFO 	24 	day_data.py 	<module>() 	Day Data Fusion Started
[2025-06-01 03:50:19,224] 	ERROR 	73 	day_data.py 	<module>() 	Error occurred during Day Data Fusion process. Error: 'data'
Traceback (most recent call last):
  File "day_data.py", line 41, in <module>
    data = response.json()["data"]["uniswapDayDatas"]
KeyError: 'data'
[2025-06-01 03:50:20,088] 	INFO 	35 	pair_data.py 	<module>() 	Pair Data Fusion Started
[2025-06-01 03:50:20,315] 	ERROR 	63 	pair_data.py 	<module>() 	Error occurred during Pair Data Fusion process. Pair: sAMM-USDC.e/USDT, Address: 0xB38245b7fE8D594d883A27DB1055bf67926F6B27, Error: 'data'
[2025-06-01 03:50:20,425] 	ERROR 	63 	pair_data.py 	<module>() 	Error occurred during Pair Data Fusion process. Pair: vAMM-WPOL/elRETRO, Address: 0x90a09fE272540Ecd34661B91252f2aB4b7f7A4CE, Error: 'data'
[2025-06-01 03:50:20,524] 	ERROR 	63 	pair_data.py 	<module>() 	Error occurred during Pair Data Fusion process. Pair: sAMM-oRETRO/elRETRO, Address: 0xc58Eb718892Da5D519587A3ec87063A8a46c9feb, Error: 'data'
[2025-06-01 03:50:20,625] 	ERROR 	63 	pair_data.py 	<module>() 	Error occurred during Pair Data Fusion process. Pair: WPOL/WETH (0.05%), Address: 0x1a34EaBbe928Bf431B679959379b2225d60D9cdA, Error: 'data'
[2025-06-01 03:50:20,721] 	ERROR 	63 	pair_data.py 	<module>() 	Error occurred during Pair Data Fusion process. Pair: WPOL/USDC.e (0.05%), Address: 0xEC15624FBB314eb05BaaD4cA49b7904C0Cb6b645, Error: 'data'
[2025-06-01 03:50:20,812] 	ERROR 	63 	pair_data.py 	<module>() 	Error occurred during Pair Data Fusion process. Pair: USDC.e/WETH (0.05%), Address: 0xCE67850420c82dB45eb7fEeCcD2d181300D2BDB3, Error: 'data'
[2025-06-01 03:50:20,903] 	ERROR 	63 	pair_data.py 	<module>() 	Error occurred during Pair Data Fusion process. Pair: WBTC/WETH (0.05%), Address: 0xb694E3bdd4BCdF843510983D257679D1E627C474, Error: 'data'
[2025-06-01 03:50:20,998] 	ERROR 	63 	pair_data.py 	<module>() 	Error occurred during Pair Data Fusion process. Pair: WPOL/USDT (0.05%), Address: 0xB580229645b240A368768ec3E88cb67A41eBBC5B, Error: 'data'
[2025-06-01 03:50:21,097] 	ERROR 	63 	pair_data.py 	<module>() 	Error occurred during Pair Data Fusion process. Pair: WPOL/CASH (0.05%), Address: 0x63ca6ED3D390C725b7FEb617BAdcab78a61038E8, Error: 'data'
[2025-06-01 03:50:21,193] 	ERROR 	63 	pair_data.py 	<module>() 	Error occurred during Pair Data Fusion process. Pair: CASH/WETH (0.05%), Address: 0x0A46B0712974F201BeD15c2458a023EbED25eF4F, Error: 'data'
[2025-06-01 03:50:21,294] 	ERROR 	63 	pair_data.py 	<module>() 	Error occurred during Pair Data Fusion process. Pair: USDC.e/CASH (0.01%), Address: 0x619259F699839dD1498FFC22297044462483bD27, Error: 'data'
[2025-06-01 03:50:21,381] 	ERROR 	63 	pair_data.py 	<module>() 	Error occurred during Pair Data Fusion process. Pair: CASH/USDT (0.01%), Address: 0x160FBF00AB5fbF0200c0Cd4929aEaa2AdD25FB5b, Error: 'data'
[2025-06-01 03:50:21,480] 	ERROR 	63 	pair_data.py 	<module>() 	Error occurred during Pair Data Fusion process. Pair: CASH/DAI (0.01%), Address: 0x1e683586fCB45a769ef2C7d9d7b1803E9C1AEE79, Error: 'data'
[2025-06-01 03:50:21,574] 	ERROR 	63 	pair_data.py 	<module>() 	Error occurred during Pair Data Fusion process. Pair: CASH/miMATIC (0.01%), Address: 0xeB80047F7d5D4C4A3BC6319250d6b1b8aEe2d0D2, Error: 'data'
[2025-06-01 03:50:21,668] 	ERROR 	63 	pair_data.py 	<module>() 	Error occurred during Pair Data Fusion process. Pair: CASH/MaticX (0.05%), Address: 0xb98F8DF0DC6750A3e54540A1e094186C8bED780a, Error: 'data'
[2025-06-01 03:50:21,768] 	ERROR 	63 	pair_data.py 	<module>() 	Error occurred during Pair Data Fusion process. Pair: USDC.e/EURA (0.05%), Address: 0xC2CB03a819F785bD8eb8D628BAD41Cd7c1C71F4B, Error: 'data'
[2025-06-01 03:50:21,863] 	ERROR 	63 	pair_data.py 	<module>() 	Error occurred during Pair Data Fusion process. Pair: FRAX/CASH (0.01%), Address: 0x72289129Dc4937a5d406d1ECeD8b2A17d007A650, Error: 'data'
[2025-06-01 03:50:21,954] 	ERROR 	63 	pair_data.py 	<module>() 	Error occurred during Pair Data Fusion process. Pair: CASH/RETRO (1%), Address: 0xb47A07966cE6812702C0567d03725F1b37E27877, Error: 'data'
[2025-06-01 03:50:22,056] 	ERROR 	63 	pair_data.py 	<module>() 	Error occurred during Pair Data Fusion process. Pair: WETH/RETRO (1%), Address: 0x35394eED0Be676ec6470fE6531daD809265310ff, Error: 'data'
[2025-06-01 03:50:22,150] 	ERROR 	63 	pair_data.py 	<module>() 	Error occurred during Pair Data Fusion process. Pair: WPOL/RETRO (1%), Address: 0x547FD24AA2ED09d86dAC02E36b8Ce84A59fD644F, Error: 'data'
[2025-06-01 03:50:22,244] 	ERROR 	63 	pair_data.py 	<module>() 	Error occurred during Pair Data Fusion process. Pair: WBTC/RETRO (1%), Address: 0x0F73E719a76947752E4b26A2c3FC80a580e68fB4, Error: 'data'
[2025-06-01 03:50:22,348] 	ERROR 	63 	pair_data.py 	<module>() 	Error occurred during Pair Data Fusion process. Pair: stMATIC/RETRO (1%), Address: 0x0973698BB6399c39d628698f9300430C4e7c9bf9, Error: 'data'
[2025-06-01 03:50:22,448] 	ERROR 	63 	pair_data.py 	<module>() 	Error occurred during Pair Data Fusion process. Pair: USDC.e/RETRO (1%), Address: 0xc7d8B9c270D0E31A6a0Cf4496fe019766Be42E15, Error: 'data'
[2025-06-01 03:50:22,541] 	ERROR 	63 	pair_data.py 	<module>() 	Error occurred during Pair Data Fusion process. Pair: RETRO/USDT (1%), Address: 0x69dCAE97A1286B112a8BD75bD9147bD0a3207756, Error: 'data'
[2025-06-01 03:50:22,639] 	ERROR 	63 	pair_data.py 	<module>() 	Error occurred during Pair Data Fusion process. Pair: miMATIC/RETRO (1%), Address: 0xd98eEf295f78ddDd104a8645854C7F8714B39B88, Error: 'data'
[2025-06-01 03:50:22,736] 	ERROR 	63 	pair_data.py 	<module>() 	Error occurred during Pair Data Fusion process. Pair: LINK/RETRO (1%), Address: 0x7761c7233924C3D72F27Fae6a81B074C0152e03a, Error: 'data'
[2025-06-01 03:50:22,839] 	ERROR 	63 	pair_data.py 	<module>() 	Error occurred during Pair Data Fusion process. Pair: RETRO/EURA (1%), Address: 0x15949526fF03fE6ab5f49dA6a86749c20141b3f1, Error: 'data'
[2025-06-01 03:50:22,940] 	ERROR 	63 	pair_data.py 	<module>() 	Error occurred during Pair Data Fusion process. Pair: USDC.e/USDT (0.01%), Address: 0x772510189425ac63f9a5A5eF2fd0C7FDA58CBFC7, Error: 'data'
[2025-06-01 03:50:23,035] 	ERROR 	63 	pair_data.py 	<module>() 	Error occurred during Pair Data Fusion process. Pair: USDC.e/DAI (0.01%), Address: 0x219116F23BDC11EB25e4D0FbE92eD0972d86BE20, Error: 'data'
[2025-06-01 03:50:23,135] 	ERROR 	63 	pair_data.py 	<module>() 	Error occurred during Pair Data Fusion process. Pair: WPOL/MaticX (0.01%), Address: 0x9aa18301055091e9da7C57b81633632Fa33B9a80, Error: 'data'
[2025-06-01 03:50:23,242] 	ERROR 	63 	pair_data.py 	<module>() 	Error occurred during Pair Data Fusion process. Pair: wstETH/WETH (0.01%), Address: 0xa9439Db1D7025Ce4aAc513Baf5eee5220172126C, Error: 'data'
[2025-06-01 03:50:23,339] 	ERROR 	63 	pair_data.py 	<module>() 	Error occurred during Pair Data Fusion process. Pair: WPOL/stMATIC (0.01%), Address: 0x2d623c33673248E95C7a1C26aE7065eb7A7Ac0Ea, Error: 'data'
[2025-06-01 03:50:23,442] 	ERROR 	63 	pair_data.py 	<module>() 	Error occurred during Pair Data Fusion process. Pair: WETH/frxETH (0.01%), Address: 0xe5069a75Bdfe8F676B778B0aaDCcC597841F819B, Error: 'data'
[2025-06-01 03:50:23,546] 	ERROR 	63 	pair_data.py 	<module>() 	Error occurred during Pair Data Fusion process. Pair: FRAX/frxETH (0.05%), Address: 0x38df0c93bf69a9EfB3d3647fF459eF27235A8968, Error: 'data'
[2025-06-01 03:50:23,646] 	ERROR 	63 	pair_data.py 	<module>() 	Error occurred during Pair Data Fusion process. Pair: WPOL/frxETH (0.05%), Address: 0x44AAE81BE8435b6998A66d9642f66DE57DD03FC2, Error: 'data'
[2025-06-01 03:50:23,743] 	ERROR 	63 	pair_data.py 	<module>() 	Error occurred during Pair Data Fusion process. Pair: xbb-t-USD/CASH (0.01%), Address: 0x07dBf448cCC68cA64247da04F2E24643eCf57385, Error: 'data'
[2025-06-01 03:50:23,839] 	ERROR 	63 	pair_data.py 	<module>() 	Error occurred during Pair Data Fusion process. Pair: LINK/LUCHA (0.3%), Address: 0x91248C85DD408BD216254C3cFb51fc326290cF7e, Error: 'data'
[2025-06-01 03:50:23,933] 	ERROR 	63 	pair_data.py 	<module>() 	Error occurred during Pair Data Fusion process. Pair: CASH/LUCHA (0.3%), Address: 0xc666c4b402Bd797185EA419261D22a8f22DDFce6, Error: 'data'
[2025-06-01 03:50:24,030] 	ERROR 	63 	pair_data.py 	<module>() 	Error occurred during Pair Data Fusion process. Pair: USDC.e/miMATIC (0.3%), Address: 0xb090BE2D2F02646057d4DF997A7A983dFb265de0, Error: 'data'
[2025-06-01 03:50:24,133] 	ERROR 	63 	pair_data.py 	<module>() 	Error occurred during Pair Data Fusion process. Pair: FRAX/miMATIC (0.3%), Address: 0xdeB25Dd2d5D168Fd6f80F154d96a2Dab81d61845, Error: 'data'
[2025-06-01 03:50:24,233] 	ERROR 	63 	pair_data.py 	<module>() 	Error occurred during Pair Data Fusion process. Pair: WPOL/miMATIC (0.3%), Address: 0xC571445Fc93666e1E4FaE2E84A7b74FE6ed3978D, Error: 'data'
[2025-06-01 03:50:24,326] 	ERROR 	63 	pair_data.py 	<module>() 	Error occurred during Pair Data Fusion process. Pair: CASH/ERN (0.3%), Address: 0x777a87889f42C33f9A1E5c117774694bbd857075, Error: 'data'
[2025-06-01 03:50:24,430] 	ERROR 	63 	pair_data.py 	<module>() 	Error occurred during Pair Data Fusion process. Pair: ICHI/RETRO (1%), Address: 0xC26E1a0cDab4Bf5141530C49F3360f162C5Db5Db, Error: 'data'
[2025-06-01 03:50:24,526] 	ERROR 	63 	pair_data.py 	<module>() 	Error occurred during Pair Data Fusion process. Pair: WPOL/ICHI (0.3%), Address: 0x13d5e61838D93F7962C52dc921FD7C0Ccc092E35, Error: 'data'
[2025-06-01 03:50:24,622] 	ERROR 	63 	pair_data.py 	<module>() 	Error occurred during Pair Data Fusion process. Pair: SD/MaticX (0.3%), Address: 0xB97c62834e096858BD0B996b758942dd43d7B5eE, Error: 'data'
[2025-06-01 03:50:24,724] 	ERROR 	63 	pair_data.py 	<module>() 	Error occurred during Pair Data Fusion process. Pair: stERN/ERN (1%), Address: 0x99583057951987beD85CE6934473160bFD4921b9, Error: 'data'
[2025-06-01 03:50:24,817] 	ERROR 	63 	pair_data.py 	<module>() 	Error occurred during Pair Data Fusion process. Pair: tUSDC/STAR (0.05%), Address: 0x53C49b9308c3DB176d351d7914Cec0Fb5D7f1129, Error: 'data'
[2025-06-01 03:50:24,918] 	ERROR 	63 	pair_data.py 	<module>() 	Error occurred during Pair Data Fusion process. Pair: WPOL/LUCHA (0.3%), Address: 0x52BeedA850A7048e9D543668BF54E0d9E1B667E0, Error: 'data'
[2025-06-01 03:50:25,010] 	ERROR 	63 	pair_data.py 	<module>() 	Error occurred during Pair Data Fusion process. Pair: LUCHA/WETH (0.3%), Address: 0x13136EA148331a07497087bfc31fBCcD9b99123c, Error: 'data'
[2025-06-01 03:50:25,105] 	ERROR 	63 	pair_data.py 	<module>() 	Error occurred during Pair Data Fusion process. Pair: JRT/WETH (0.3%), Address: 0xAE107e52ebdF151E61d9Fb4Bd800C86c31741465, Error: 'data'
[2025-06-01 03:50:25,197] 	ERROR 	63 	pair_data.py 	<module>() 	Error occurred during Pair Data Fusion process. Pair: axlLqdr/CASH (0.3%), Address: 0x22c10e61A05a03bcd8BF61a7E648f2330ecdA270, Error: 'data'
[2025-06-01 03:50:25,296] 	ERROR 	63 	pair_data.py 	<module>() 	Error occurred during Pair Data Fusion process. Pair: XOC/jMXN (0.01%), Address: 0xccE01e3615785771b84Eb5F88EC612AC6704FdE2, Error: 'data'
[2025-06-01 03:50:25,394] 	ERROR 	63 	pair_data.py 	<module>() 	Error occurred during Pair Data Fusion process. Pair: ICHI/CASH (1%), Address: 0x8ceD58A2dE3C2ea5D3cED3eb4331158c8cf985Fb, Error: 'data'
[2025-06-01 03:50:25,494] 	ERROR 	63 	pair_data.py 	<module>() 	Error occurred during Pair Data Fusion process. Pair: wUSDR/CASH (0.3%), Address: 0x3baEa49B71461DEaB46E6F42548D0005359ff629, Error: 'data'
[2025-06-01 03:50:25,596] 	ERROR 	63 	pair_data.py 	<module>() 	Error occurred during Pair Data Fusion process. Pair: CASH/STAR (0.05%), Address: 0x88C522E526E5Eea8d636fd6805cA7fEB488780D0, Error: 'data'
[2025-06-01 03:50:25,692] 	ERROR 	63 	pair_data.py 	<module>() 	Error occurred during Pair Data Fusion process. Pair: USDC.e/STAR (0.01%), Address: 0x6De0CA91Ef19A6ce9f02A423ae2dF89Fe09Bff0F, Error: 'data'
[2025-06-01 03:50:25,795] 	ERROR 	63 	pair_data.py 	<module>() 	Error occurred during Pair Data Fusion process. Pair: tUSDC/STAR (1%), Address: 0xaC44f57eEF260eB6E0f896b61984Da8d86FeE9ed, Error: 'data'
[2025-06-01 03:50:25,884] 	ERROR 	63 	pair_data.py 	<module>() 	Error occurred during Pair Data Fusion process. Pair: tUSDC/CASH (1%), Address: 0x4FcdB2DCc4Ce156c723aD541dba8B39d47284FC5, Error: 'data'
[2025-06-01 03:50:25,983] 	ERROR 	63 	pair_data.py 	<module>() 	Error occurred during Pair Data Fusion process. Pair: WPOL/USDC.e (0.3%), Address: 0x8c862d100B94d95a49D91958c9e8C2c348d00F04, Error: 'data'
[2025-06-01 03:50:26,079] 	ERROR 	63 	pair_data.py 	<module>() 	Error occurred during Pair Data Fusion process. Pair: WPOL/WETH (0.3%), Address: 0xB8dD18F9b7C3Ad4bDd4B94cB819eda3bd4465119, Error: 'data'
[2025-06-01 03:50:26,178] 	ERROR 	63 	pair_data.py 	<module>() 	Error occurred during Pair Data Fusion process. Pair: USDC.e/WETH (0.3%), Address: 0x058F5330Fef74445878110e201B04F36f8a51c9b, Error: 'data'
[2025-06-01 03:50:26,278] 	ERROR 	63 	pair_data.py 	<module>() 	Error occurred during Pair Data Fusion process. Pair: WBTC/WETH (0.3%), Address: 0x11275C625A7DEE3532E062Eef6915f00af85C3B5, Error: 'data'
[2025-06-01 03:50:26,379] 	ERROR 	63 	pair_data.py 	<module>() 	Error occurred during Pair Data Fusion process. Pair: LINK/WETH (0.3%), Address: 0x555eABEEfe6a047747071525A2c0fFd96d945f69, Error: 'data'
[2025-06-01 03:50:26,480] 	ERROR 	63 	pair_data.py 	<module>() 	Error occurred during Pair Data Fusion process. Pair: WBTC/CASH (0.3%), Address: 0x2C8F7d92Dc7A414D343CbFB687E31a11F525d29e, Error: 'data'
[2025-06-01 03:50:26,572] 	ERROR 	63 	pair_data.py 	<module>() 	Error occurred during Pair Data Fusion process. Pair: WPOL/DEUS (1%), Address: 0xB5cB765e44Eca4bc5a434fFaf6Bf7De235Bc60a5, Error: 'data'
[2025-06-01 03:50:26,665] 	ERROR 	63 	pair_data.py 	<module>() 	Error occurred during Pair Data Fusion process. Pair: WPOL/WBTC (0.3%), Address: 0x2981A1f699eA7149aa08121A07F000cf82846A9e, Error: 'data'
[2025-06-01 03:50:26,760] 	ERROR 	63 	pair_data.py 	<module>() 	Error occurred during Pair Data Fusion process. Pair: FRAX/STAR (0.05%), Address: 0x7D480cBf5Aee75E72eF26F223937f3981d67a860, Error: 'data'
[2025-06-01 03:50:26,864] 	ERROR 	63 	pair_data.py 	<module>() 	Error occurred during Pair Data Fusion process. Pair: CASH/TAROT (0.3%), Address: 0x217aEb0667b79584FBf6265B74a8cD22E1245fdC, Error: 'data'
[2025-06-01 03:50:26,960] 	ERROR 	63 	pair_data.py 	<module>() 	Error occurred during Pair Data Fusion process. Pair: CASH/fxDOLA (0.05%), Address: 0x4b4B895a0dD744B4893aA4370A8F7eDbde5Fd90e, Error: 'data'
[2025-06-01 03:50:27,048] 	ERROR 	63 	pair_data.py 	<module>() 	Error occurred during Pair Data Fusion process. Pair: RETRO/liveRetro (1%), Address: 0x6333BB8b6f1DDa6f929d70eDEB9e31c8148dC9ef, Error: 'data'
[2025-06-01 03:50:27,145] 	ERROR 	63 	pair_data.py 	<module>() 	Error occurred during Pair Data Fusion process. Pair: MVX/WETH (1%), Address: 0xCC72276de3BCc1b159F1B60A86B0211116022B42, Error: 'data'
[2025-06-01 03:50:27,242] 	ERROR 	63 	pair_data.py 	<module>() 	Error occurred during Pair Data Fusion process. Pair: WPOL/elRETRO (1%), Address: 0x6794Db07e2efE1307b8594FBbBFad78E50eC76fa, Error: 'data'
[2025-06-01 03:50:27,343] 	ERROR 	63 	pair_data.py 	<module>() 	Error occurred during Pair Data Fusion process. Pair: OATH/WETH (1%), Address: 0x0c74834d67c4bf5e6a44D18b2BAc767cddB4CdBf, Error: 'data'
[2025-06-01 03:50:27,434] 	ERROR 	63 	pair_data.py 	<module>() 	Error occurred during Pair Data Fusion process. Pair: USDC.e/IBEX (1%), Address: 0x53D8c25B3d130D2810591cDc7A41Bd848bF79B63, Error: 'data'
[2025-06-01 03:50:27,526] 	ERROR 	63 	pair_data.py 	<module>() 	Error occurred during Pair Data Fusion process. Pair: USDC.e/fxDOLA (0.3%), Address: 0x896ffE2cd28Ba13ddDa98103a3B66E82bb36BeE3, Error: 'data'
[2025-06-01 03:50:27,625] 	ERROR 	63 	pair_data.py 	<module>() 	Error occurred during Pair Data Fusion process. Pair: USDC.e/FRAX (0.3%), Address: 0x091236A16952BC9e4bB817FFA7aB40263183f658, Error: 'data'
[2025-06-01 03:50:27,723] 	ERROR 	63 	pair_data.py 	<module>() 	Error occurred during Pair Data Fusion process. Pair: WBTC/USDC.e (0.3%), Address: 0x459F42C788E6F8faCe4854DDD59C81a6Ad8BB1Aa, Error: 'data'
[2025-06-01 03:50:27,827] 	ERROR 	63 	pair_data.py 	<module>() 	Error occurred during Pair Data Fusion process. Pair: WETH/ERN (0.3%), Address: 0xCF2093da3CeBb8731747EEaCbd486A7fcE2Db901, Error: 'data'
[2025-06-01 03:50:27,922] 	ERROR 	63 	pair_data.py 	<module>() 	Error occurred during Pair Data Fusion process. Pair: WETH/JARVIS (0.3%), Address: 0xf310d505B85E0378790Af9fDB9b79b40736f7b4D, Error: 'data'
[2025-06-01 03:50:28,015] 	ERROR 	63 	pair_data.py 	<module>() 	Error occurred during Pair Data Fusion process. Pair: jEUR/CASH (0.05%), Address: 0x65E6b7C7DfE071E52D6923E4079E3C0FcBeaA401, Error: 'data'
[2025-06-01 03:50:28,107] 	ERROR 	63 	pair_data.py 	<module>() 	Error occurred during Pair Data Fusion process. Pair: USDC.e/USDC (0.01%), Address: 0x1e0aa3f6C3130294845B8e162d838e221d170016, Error: 'data'
[2025-06-01 03:50:28,206] 	ERROR 	63 	pair_data.py 	<module>() 	Error occurred during Pair Data Fusion process. Pair: LUCHA/WETH (1%), Address: 0x098c1e4BB34DEcDF49D5966014B5153Af326E766, Error: 'data'
[2025-06-01 03:50:28,297] 	ERROR 	63 	pair_data.py 	<module>() 	Error occurred during Pair Data Fusion process. Pair: WPOL/LUCHA (1%), Address: 0xde4C8898CD50EBE9C167313b312D147D10d1C898, Error: 'data'
[2025-06-01 03:50:28,388] 	ERROR 	63 	pair_data.py 	<module>() 	Error occurred during Pair Data Fusion process. Pair: LINK/LUCHA (1%), Address: 0xA97B2b9AcA65aab57A6b0840B45777bd66fbcf33, Error: 'data'
[2025-06-01 03:50:28,482] 	ERROR 	63 	pair_data.py 	<module>() 	Error occurred during Pair Data Fusion process. Pair: CASH/LUCHA (1%), Address: 0x5c09352B1aa703d18dbcF48c98655BFA19d07FBB, Error: 'data'
[2025-06-01 03:50:28,630] 	ERROR 	103 	pair_data.py 	<module>() 	Error occurred during Pair Data Fusion process. Error: 'date'
Traceback (most recent call last):
  File "/opt/hostedtoolcache/Python/3.8.18/x64/lib/python3.8/site-packages/pandas/core/indexes/base.py", line 3802, in get_loc
    return self._engine.get_loc(casted_key)
  File "pandas/_libs/index.pyx", line 138, in pandas._libs.index.IndexEngine.get_loc
  File "pandas/_libs/index.pyx", line 165, in pandas._libs.index.IndexEngine.get_loc
  File "pandas/_libs/hashtable_class_helper.pxi", line 5745, in pandas._libs.hashtable.PyObjectHashTable.get_item
  File "pandas/_libs/hashtable_class_helper.pxi", line 5753, in pandas._libs.hashtable.PyObjectHashTable.get_item
KeyError: 'date'

The above exception was the direct cause of the following exception:

Traceback (most recent call last):
  File "pair_data.py", line 68, in <module>
    pairdata_fusion_df["date"] = pairdata_fusion_df["date"].apply(lambda timestamp: datetime.utcfromtimestamp(timestamp).date())
  File "/opt/hostedtoolcache/Python/3.8.18/x64/lib/python3.8/site-packages/pandas/core/frame.py", line 3807, in __getitem__
    indexer = self.columns.get_loc(key)
  File "/opt/hostedtoolcache/Python/3.8.18/x64/lib/python3.8/site-packages/pandas/core/indexes/base.py", line 3804, in get_loc
    raise KeyError(key) from err
KeyError: 'date'
[2025-06-01 03:50:29,499] 	INFO 	36 	bribe_data.py 	<module>() 	Bribe Data Started
[2025-06-01 03:50:30,019] 	ERROR 	159 	bribe_data.py 	<module>() 	Error occurred during Bribe Data process. Error: 403 Client Error: Forbidden for url: https://rpc.ankr.com/polygon
Traceback (most recent call last):
  File "bribe_data.py", line 71, in <module>
    rewardsListLength = contract_instance.functions.rewardsListLength().call()
  File "/opt/hostedtoolcache/Python/3.8.18/x64/lib/python3.8/site-packages/web3/contract.py", line 970, in call
    return call_contract_function(
  File "/opt/hostedtoolcache/Python/3.8.18/x64/lib/python3.8/site-packages/web3/contract.py", line 1525, in call_contract_function
    return_data = web3.eth.call(
  File "/opt/hostedtoolcache/Python/3.8.18/x64/lib/python3.8/site-packages/web3/module.py", line 57, in caller
    result = w3.manager.request_blocking(method_str,
  File "/opt/hostedtoolcache/Python/3.8.18/x64/lib/python3.8/site-packages/web3/manager.py", line 197, in request_blocking
    response = self._make_request(method, params)
  File "/opt/hostedtoolcache/Python/3.8.18/x64/lib/python3.8/site-packages/web3/manager.py", line 150, in _make_request
    return request_func(method, params)
  File "/opt/hostedtoolcache/Python/3.8.18/x64/lib/python3.8/site-packages/web3/middleware/formatting.py", line 94, in middleware
    response = make_request(method, params)
  File "/opt/hostedtoolcache/Python/3.8.18/x64/lib/python3.8/site-packages/web3/middleware/gas_price_strategy.py", line 90, in middleware
    return make_request(method, params)
  File "/opt/hostedtoolcache/Python/3.8.18/x64/lib/python3.8/site-packages/web3/middleware/formatting.py", line 94, in middleware
    response = make_request(method, params)
  File "/opt/hostedtoolcache/Python/3.8.18/x64/lib/python3.8/site-packages/web3/middleware/attrdict.py", line 33, in middleware
    response = make_request(method, params)
  File "/opt/hostedtoolcache/Python/3.8.18/x64/lib/python3.8/site-packages/web3/middleware/formatting.py", line 94, in middleware
    response = make_request(method, params)
  File "/opt/hostedtoolcache/Python/3.8.18/x64/lib/python3.8/site-packages/web3/middleware/formatting.py", line 94, in middleware
    response = make_request(method, params)
  File "/opt/hostedtoolcache/Python/3.8.18/x64/lib/python3.8/site-packages/web3/middleware/formatting.py", line 94, in middleware
    response = make_request(method, params)
  File "/opt/hostedtoolcache/Python/3.8.18/x64/lib/python3.8/site-packages/web3/middleware/buffered_gas_estimate.py", line 40, in middleware
    return make_request(method, params)
  File "/opt/hostedtoolcache/Python/3.8.18/x64/lib/python3.8/site-packages/web3/middleware/exception_retry_request.py", line 105, in middleware
    return make_request(method, params)
  File "/opt/hostedtoolcache/Python/3.8.18/x64/lib/python3.8/site-packages/web3/providers/rpc.py", line 88, in make_request
    raw_response = make_post_request(
  File "/opt/hostedtoolcache/Python/3.8.18/x64/lib/python3.8/site-packages/web3/_utils/request.py", line 113, in make_post_request
    response.raise_for_status()
  File "/opt/hostedtoolcache/Python/3.8.18/x64/lib/python3.8/site-packages/requests/models.py", line 1021, in raise_for_status
    raise HTTPError(http_error_msg, response=self)
requests.exceptions.HTTPError: 403 Client Error: Forbidden for url: https://rpc.ankr.com/polygon
[2025-06-01 03:50:30,876] 	INFO 	36 	fee_data.py 	<module>() 	Fee Data Started
[2025-06-01 03:50:31,166] 	ERROR 	159 	fee_data.py 	<module>() 	Error occurred during Fee Data process. Error: 403 Client Error: Forbidden for url: https://rpc.ankr.com/polygon
Traceback (most recent call last):
  File "fee_data.py", line 71, in <module>
    rewardsListLength = contract_instance.functions.rewardsListLength().call()
  File "/opt/hostedtoolcache/Python/3.8.18/x64/lib/python3.8/site-packages/web3/contract.py", line 970, in call
    return call_contract_function(
  File "/opt/hostedtoolcache/Python/3.8.18/x64/lib/python3.8/site-packages/web3/contract.py", line 1525, in call_contract_function
    return_data = web3.eth.call(
  File "/opt/hostedtoolcache/Python/3.8.18/x64/lib/python3.8/site-packages/web3/module.py", line 57, in caller
    result = w3.manager.request_blocking(method_str,
  File "/opt/hostedtoolcache/Python/3.8.18/x64/lib/python3.8/site-packages/web3/manager.py", line 197, in request_blocking
    response = self._make_request(method, params)
  File "/opt/hostedtoolcache/Python/3.8.18/x64/lib/python3.8/site-packages/web3/manager.py", line 150, in _make_request
    return request_func(method, params)
  File "/opt/hostedtoolcache/Python/3.8.18/x64/lib/python3.8/site-packages/web3/middleware/formatting.py", line 94, in middleware
    response = make_request(method, params)
  File "/opt/hostedtoolcache/Python/3.8.18/x64/lib/python3.8/site-packages/web3/middleware/gas_price_strategy.py", line 90, in middleware
    return make_request(method, params)
  File "/opt/hostedtoolcache/Python/3.8.18/x64/lib/python3.8/site-packages/web3/middleware/formatting.py", line 94, in middleware
    response = make_request(method, params)
  File "/opt/hostedtoolcache/Python/3.8.18/x64/lib/python3.8/site-packages/web3/middleware/attrdict.py", line 33, in middleware
    response = make_request(method, params)
  File "/opt/hostedtoolcache/Python/3.8.18/x64/lib/python3.8/site-packages/web3/middleware/formatting.py", line 94, in middleware
    response = make_request(method, params)
  File "/opt/hostedtoolcache/Python/3.8.18/x64/lib/python3.8/site-packages/web3/middleware/formatting.py", line 94, in middleware
    response = make_request(method, params)
  File "/opt/hostedtoolcache/Python/3.8.18/x64/lib/python3.8/site-packages/web3/middleware/formatting.py", line 94, in middleware
    response = make_request(method, params)
  File "/opt/hostedtoolcache/Python/3.8.18/x64/lib/python3.8/site-packages/web3/middleware/buffered_gas_estimate.py", line 40, in middleware
    return make_request(method, params)
  File "/opt/hostedtoolcache/Python/3.8.18/x64/lib/python3.8/site-packages/web3/middleware/exception_retry_request.py", line 105, in middleware
    return make_request(method, params)
  File "/opt/hostedtoolcache/Python/3.8.18/x64/lib/python3.8/site-packages/web3/providers/rpc.py", line 88, in make_request
    raw_response = make_post_request(
  File "/opt/hostedtoolcache/Python/3.8.18/x64/lib/python3.8/site-packages/web3/_utils/request.py", line 113, in make_post_request
    response.raise_for_status()
  File "/opt/hostedtoolcache/Python/3.8.18/x64/lib/python3.8/site-packages/requests/models.py", line 1021, in raise_for_status
    raise HTTPError(http_error_msg, response=self)
requests.exceptions.HTTPError: 403 Client Error: Forbidden for url: https://rpc.ankr.com/polygon
[2025-06-01 03:50:32,032] 	INFO 	37 	vote_data.py 	<module>() 	Vote Data Started
[2025-06-01 03:50:51,857] 	ERROR 	118 	vote_data.py 	<module>() 	Error occurred during Vote Data process. Error: Expecting value: line 1 column 1 (char 0)
Traceback (most recent call last):
  File "/opt/hostedtoolcache/Python/3.8.18/x64/lib/python3.8/site-packages/requests/models.py", line 971, in json
    return complexjson.loads(self.text, **kwargs)
  File "/opt/hostedtoolcache/Python/3.8.18/x64/lib/python3.8/json/__init__.py", line 357, in loads
    return _default_decoder.decode(s)
  File "/opt/hostedtoolcache/Python/3.8.18/x64/lib/python3.8/json/decoder.py", line 337, in decode
    obj, end = self.raw_decode(s, idx=_w(s, 0).end())
  File "/opt/hostedtoolcache/Python/3.8.18/x64/lib/python3.8/json/decoder.py", line 355, in raw_decode
    raise JSONDecodeError("Expecting value", s, err.value) from None
json.decoder.JSONDecodeError: Expecting value: line 1 column 1 (char 0)

During handling of the above exception, another exception occurred:

Traceback (most recent call last):
  File "vote_data.py", line 64, in <module>
    RETRO_price = jmespath.search("data[?name == 'RETRO'].price", response.json())[0]
  File "/opt/hostedtoolcache/Python/3.8.18/x64/lib/python3.8/site-packages/requests/models.py", line 975, in json
    raise RequestsJSONDecodeError(e.msg, e.doc, e.pos)
requests.exceptions.JSONDecodeError: Expecting value: line 1 column 1 (char 0)
[2025-06-01 03:50:52,722] 	INFO 	30 	revenue_data.py 	<module>() 	Revenue Data Started
[2025-06-01 03:51:16,833] 	ERROR 	152 	revenue_data.py 	<module>() 	Error occurred during Revenue Data process. Error: Expecting value: line 1 column 1 (char 0)
Traceback (most recent call last):
  File "/opt/hostedtoolcache/Python/3.8.18/x64/lib/python3.8/site-packages/requests/models.py", line 971, in json
    return complexjson.loads(self.text, **kwargs)
  File "/opt/hostedtoolcache/Python/3.8.18/x64/lib/python3.8/json/__init__.py", line 357, in loads
    return _default_decoder.decode(s)
  File "/opt/hostedtoolcache/Python/3.8.18/x64/lib/python3.8/json/decoder.py", line 337, in decode
    obj, end = self.raw_decode(s, idx=_w(s, 0).end())
  File "/opt/hostedtoolcache/Python/3.8.18/x64/lib/python3.8/json/decoder.py", line 355, in raw_decode
    raise JSONDecodeError("Expecting value", s, err.value) from None
json.decoder.JSONDecodeError: Expecting value: line 1 column 1 (char 0)

During handling of the above exception, another exception occurred:

Traceback (most recent call last):
  File "revenue_data.py", line 66, in <module>
    RETRO_price = jmespath.search("data[?name == 'RETRO'].price", response.json())[0]
  File "/opt/hostedtoolcache/Python/3.8.18/x64/lib/python3.8/site-packages/requests/models.py", line 975, in json
    raise RequestsJSONDecodeError(e.msg, e.doc, e.pos)
requests.exceptions.JSONDecodeError: Expecting value: line 1 column 1 (char 0)
[2025-06-01 04:40:10,258] 	INFO 	20 	id_data.py 	<module>() 	ID Data Started
[2025-06-01 04:40:29,832] 	ERROR 	33 	id_data.py 	<module>() 	Error occurred during ID Data process. Error: Expecting value: line 1 column 1 (char 0)
Traceback (most recent call last):
  File "/opt/hostedtoolcache/Python/3.8.18/x64/lib/python3.8/site-packages/requests/models.py", line 971, in json
    return complexjson.loads(self.text, **kwargs)
  File "/opt/hostedtoolcache/Python/3.8.18/x64/lib/python3.8/json/__init__.py", line 357, in loads
    return _default_decoder.decode(s)
  File "/opt/hostedtoolcache/Python/3.8.18/x64/lib/python3.8/json/decoder.py", line 337, in decode
    obj, end = self.raw_decode(s, idx=_w(s, 0).end())
  File "/opt/hostedtoolcache/Python/3.8.18/x64/lib/python3.8/json/decoder.py", line 355, in raw_decode
    raise JSONDecodeError("Expecting value", s, err.value) from None
json.decoder.JSONDecodeError: Expecting value: line 1 column 1 (char 0)

During handling of the above exception, another exception occurred:

Traceback (most recent call last):
  File "id_data.py", line 27, in <module>
    data = response.json()["data"]
  File "/opt/hostedtoolcache/Python/3.8.18/x64/lib/python3.8/site-packages/requests/models.py", line 975, in json
    raise RequestsJSONDecodeError(e.msg, e.doc, e.pos)
requests.exceptions.JSONDecodeError: Expecting value: line 1 column 1 (char 0)
[2025-06-01 04:40:30,363] 	INFO 	24 	day_data.py 	<module>() 	Day Data Fusion Started
[2025-06-01 04:40:30,582] 	ERROR 	73 	day_data.py 	<module>() 	Error occurred during Day Data Fusion process. Error: 'data'
Traceback (most recent call last):
  File "day_data.py", line 41, in <module>
    data = response.json()["data"]["uniswapDayDatas"]
KeyError: 'data'
[2025-06-01 04:40:31,476] 	INFO 	35 	pair_data.py 	<module>() 	Pair Data Fusion Started
[2025-06-01 04:40:31,688] 	ERROR 	63 	pair_data.py 	<module>() 	Error occurred during Pair Data Fusion process. Pair: sAMM-USDC.e/USDT, Address: 0xB38245b7fE8D594d883A27DB1055bf67926F6B27, Error: 'data'
[2025-06-01 04:40:31,783] 	ERROR 	63 	pair_data.py 	<module>() 	Error occurred during Pair Data Fusion process. Pair: vAMM-WPOL/elRETRO, Address: 0x90a09fE272540Ecd34661B91252f2aB4b7f7A4CE, Error: 'data'
[2025-06-01 04:40:31,877] 	ERROR 	63 	pair_data.py 	<module>() 	Error occurred during Pair Data Fusion process. Pair: sAMM-oRETRO/elRETRO, Address: 0xc58Eb718892Da5D519587A3ec87063A8a46c9feb, Error: 'data'
[2025-06-01 04:40:31,972] 	ERROR 	63 	pair_data.py 	<module>() 	Error occurred during Pair Data Fusion process. Pair: WPOL/WETH (0.05%), Address: 0x1a34EaBbe928Bf431B679959379b2225d60D9cdA, Error: 'data'
[2025-06-01 04:40:32,071] 	ERROR 	63 	pair_data.py 	<module>() 	Error occurred during Pair Data Fusion process. Pair: WPOL/USDC.e (0.05%), Address: 0xEC15624FBB314eb05BaaD4cA49b7904C0Cb6b645, Error: 'data'
[2025-06-01 04:40:32,172] 	ERROR 	63 	pair_data.py 	<module>() 	Error occurred during Pair Data Fusion process. Pair: USDC.e/WETH (0.05%), Address: 0xCE67850420c82dB45eb7fEeCcD2d181300D2BDB3, Error: 'data'
[2025-06-01 04:40:32,270] 	ERROR 	63 	pair_data.py 	<module>() 	Error occurred during Pair Data Fusion process. Pair: WBTC/WETH (0.05%), Address: 0xb694E3bdd4BCdF843510983D257679D1E627C474, Error: 'data'
[2025-06-01 04:40:32,372] 	ERROR 	63 	pair_data.py 	<module>() 	Error occurred during Pair Data Fusion process. Pair: WPOL/USDT (0.05%), Address: 0xB580229645b240A368768ec3E88cb67A41eBBC5B, Error: 'data'
[2025-06-01 04:40:32,461] 	ERROR 	63 	pair_data.py 	<module>() 	Error occurred during Pair Data Fusion process. Pair: WPOL/CASH (0.05%), Address: 0x63ca6ED3D390C725b7FEb617BAdcab78a61038E8, Error: 'data'
[2025-06-01 04:40:32,557] 	ERROR 	63 	pair_data.py 	<module>() 	Error occurred during Pair Data Fusion process. Pair: CASH/WETH (0.05%), Address: 0x0A46B0712974F201BeD15c2458a023EbED25eF4F, Error: 'data'
[2025-06-01 04:40:32,647] 	ERROR 	63 	pair_data.py 	<module>() 	Error occurred during Pair Data Fusion process. Pair: USDC.e/CASH (0.01%), Address: 0x619259F699839dD1498FFC22297044462483bD27, Error: 'data'
[2025-06-01 04:40:32,760] 	ERROR 	63 	pair_data.py 	<module>() 	Error occurred during Pair Data Fusion process. Pair: CASH/USDT (0.01%), Address: 0x160FBF00AB5fbF0200c0Cd4929aEaa2AdD25FB5b, Error: 'data'
[2025-06-01 04:40:32,848] 	ERROR 	63 	pair_data.py 	<module>() 	Error occurred during Pair Data Fusion process. Pair: CASH/DAI (0.01%), Address: 0x1e683586fCB45a769ef2C7d9d7b1803E9C1AEE79, Error: 'data'
[2025-06-01 04:40:32,935] 	ERROR 	63 	pair_data.py 	<module>() 	Error occurred during Pair Data Fusion process. Pair: CASH/miMATIC (0.01%), Address: 0xeB80047F7d5D4C4A3BC6319250d6b1b8aEe2d0D2, Error: 'data'
[2025-06-01 04:40:33,030] 	ERROR 	63 	pair_data.py 	<module>() 	Error occurred during Pair Data Fusion process. Pair: CASH/MaticX (0.05%), Address: 0xb98F8DF0DC6750A3e54540A1e094186C8bED780a, Error: 'data'
[2025-06-01 04:40:33,116] 	ERROR 	63 	pair_data.py 	<module>() 	Error occurred during Pair Data Fusion process. Pair: USDC.e/EURA (0.05%), Address: 0xC2CB03a819F785bD8eb8D628BAD41Cd7c1C71F4B, Error: 'data'
[2025-06-01 04:40:33,211] 	ERROR 	63 	pair_data.py 	<module>() 	Error occurred during Pair Data Fusion process. Pair: FRAX/CASH (0.01%), Address: 0x72289129Dc4937a5d406d1ECeD8b2A17d007A650, Error: 'data'
[2025-06-01 04:40:33,302] 	ERROR 	63 	pair_data.py 	<module>() 	Error occurred during Pair Data Fusion process. Pair: CASH/RETRO (1%), Address: 0xb47A07966cE6812702C0567d03725F1b37E27877, Error: 'data'
[2025-06-01 04:40:33,403] 	ERROR 	63 	pair_data.py 	<module>() 	Error occurred during Pair Data Fusion process. Pair: WETH/RETRO (1%), Address: 0x35394eED0Be676ec6470fE6531daD809265310ff, Error: 'data'
[2025-06-01 04:40:33,499] 	ERROR 	63 	pair_data.py 	<module>() 	Error occurred during Pair Data Fusion process. Pair: WPOL/RETRO (1%), Address: 0x547FD24AA2ED09d86dAC02E36b8Ce84A59fD644F, Error: 'data'
[2025-06-01 04:40:33,600] 	ERROR 	63 	pair_data.py 	<module>() 	Error occurred during Pair Data Fusion process. Pair: WBTC/RETRO (1%), Address: 0x0F73E719a76947752E4b26A2c3FC80a580e68fB4, Error: 'data'
[2025-06-01 04:40:33,686] 	ERROR 	63 	pair_data.py 	<module>() 	Error occurred during Pair Data Fusion process. Pair: stMATIC/RETRO (1%), Address: 0x0973698BB6399c39d628698f9300430C4e7c9bf9, Error: 'data'
[2025-06-01 04:40:33,780] 	ERROR 	63 	pair_data.py 	<module>() 	Error occurred during Pair Data Fusion process. Pair: USDC.e/RETRO (1%), Address: 0xc7d8B9c270D0E31A6a0Cf4496fe019766Be42E15, Error: 'data'
[2025-06-01 04:40:33,882] 	ERROR 	63 	pair_data.py 	<module>() 	Error occurred during Pair Data Fusion process. Pair: RETRO/USDT (1%), Address: 0x69dCAE97A1286B112a8BD75bD9147bD0a3207756, Error: 'data'
[2025-06-01 04:40:33,977] 	ERROR 	63 	pair_data.py 	<module>() 	Error occurred during Pair Data Fusion process. Pair: miMATIC/RETRO (1%), Address: 0xd98eEf295f78ddDd104a8645854C7F8714B39B88, Error: 'data'
[2025-06-01 04:40:34,072] 	ERROR 	63 	pair_data.py 	<module>() 	Error occurred during Pair Data Fusion process. Pair: LINK/RETRO (1%), Address: 0x7761c7233924C3D72F27Fae6a81B074C0152e03a, Error: 'data'
[2025-06-01 04:40:34,176] 	ERROR 	63 	pair_data.py 	<module>() 	Error occurred during Pair Data Fusion process. Pair: RETRO/EURA (1%), Address: 0x15949526fF03fE6ab5f49dA6a86749c20141b3f1, Error: 'data'
[2025-06-01 04:40:34,277] 	ERROR 	63 	pair_data.py 	<module>() 	Error occurred during Pair Data Fusion process. Pair: USDC.e/USDT (0.01%), Address: 0x772510189425ac63f9a5A5eF2fd0C7FDA58CBFC7, Error: 'data'
[2025-06-01 04:40:34,380] 	ERROR 	63 	pair_data.py 	<module>() 	Error occurred during Pair Data Fusion process. Pair: USDC.e/DAI (0.01%), Address: 0x219116F23BDC11EB25e4D0FbE92eD0972d86BE20, Error: 'data'
[2025-06-01 04:40:34,484] 	ERROR 	63 	pair_data.py 	<module>() 	Error occurred during Pair Data Fusion process. Pair: WPOL/MaticX (0.01%), Address: 0x9aa18301055091e9da7C57b81633632Fa33B9a80, Error: 'data'
[2025-06-01 04:40:34,577] 	ERROR 	63 	pair_data.py 	<module>() 	Error occurred during Pair Data Fusion process. Pair: wstETH/WETH (0.01%), Address: 0xa9439Db1D7025Ce4aAc513Baf5eee5220172126C, Error: 'data'
[2025-06-01 04:40:34,682] 	ERROR 	63 	pair_data.py 	<module>() 	Error occurred during Pair Data Fusion process. Pair: WPOL/stMATIC (0.01%), Address: 0x2d623c33673248E95C7a1C26aE7065eb7A7Ac0Ea, Error: 'data'
[2025-06-01 04:40:34,774] 	ERROR 	63 	pair_data.py 	<module>() 	Error occurred during Pair Data Fusion process. Pair: WETH/frxETH (0.01%), Address: 0xe5069a75Bdfe8F676B778B0aaDCcC597841F819B, Error: 'data'
[2025-06-01 04:40:34,873] 	ERROR 	63 	pair_data.py 	<module>() 	Error occurred during Pair Data Fusion process. Pair: FRAX/frxETH (0.05%), Address: 0x38df0c93bf69a9EfB3d3647fF459eF27235A8968, Error: 'data'
[2025-06-01 04:40:34,967] 	ERROR 	63 	pair_data.py 	<module>() 	Error occurred during Pair Data Fusion process. Pair: WPOL/frxETH (0.05%), Address: 0x44AAE81BE8435b6998A66d9642f66DE57DD03FC2, Error: 'data'
[2025-06-01 04:40:35,059] 	ERROR 	63 	pair_data.py 	<module>() 	Error occurred during Pair Data Fusion process. Pair: xbb-t-USD/CASH (0.01%), Address: 0x07dBf448cCC68cA64247da04F2E24643eCf57385, Error: 'data'
[2025-06-01 04:40:35,157] 	ERROR 	63 	pair_data.py 	<module>() 	Error occurred during Pair Data Fusion process. Pair: LINK/LUCHA (0.3%), Address: 0x91248C85DD408BD216254C3cFb51fc326290cF7e, Error: 'data'
[2025-06-01 04:40:35,261] 	ERROR 	63 	pair_data.py 	<module>() 	Error occurred during Pair Data Fusion process. Pair: CASH/LUCHA (0.3%), Address: 0xc666c4b402Bd797185EA419261D22a8f22DDFce6, Error: 'data'
[2025-06-01 04:40:35,352] 	ERROR 	63 	pair_data.py 	<module>() 	Error occurred during Pair Data Fusion process. Pair: USDC.e/miMATIC (0.3%), Address: 0xb090BE2D2F02646057d4DF997A7A983dFb265de0, Error: 'data'
[2025-06-01 04:40:35,450] 	ERROR 	63 	pair_data.py 	<module>() 	Error occurred during Pair Data Fusion process. Pair: FRAX/miMATIC (0.3%), Address: 0xdeB25Dd2d5D168Fd6f80F154d96a2Dab81d61845, Error: 'data'
[2025-06-01 04:40:35,583] 	ERROR 	63 	pair_data.py 	<module>() 	Error occurred during Pair Data Fusion process. Pair: WPOL/miMATIC (0.3%), Address: 0xC571445Fc93666e1E4FaE2E84A7b74FE6ed3978D, Error: 'data'
[2025-06-01 04:40:35,681] 	ERROR 	63 	pair_data.py 	<module>() 	Error occurred during Pair Data Fusion process. Pair: CASH/ERN (0.3%), Address: 0x777a87889f42C33f9A1E5c117774694bbd857075, Error: 'data'
[2025-06-01 04:40:35,808] 	ERROR 	63 	pair_data.py 	<module>() 	Error occurred during Pair Data Fusion process. Pair: ICHI/RETRO (1%), Address: 0xC26E1a0cDab4Bf5141530C49F3360f162C5Db5Db, Error: 'data'
[2025-06-01 04:40:35,900] 	ERROR 	63 	pair_data.py 	<module>() 	Error occurred during Pair Data Fusion process. Pair: WPOL/ICHI (0.3%), Address: 0x13d5e61838D93F7962C52dc921FD7C0Ccc092E35, Error: 'data'
[2025-06-01 04:40:36,020] 	ERROR 	63 	pair_data.py 	<module>() 	Error occurred during Pair Data Fusion process. Pair: SD/MaticX (0.3%), Address: 0xB97c62834e096858BD0B996b758942dd43d7B5eE, Error: 'data'
[2025-06-01 04:40:36,107] 	ERROR 	63 	pair_data.py 	<module>() 	Error occurred during Pair Data Fusion process. Pair: stERN/ERN (1%), Address: 0x99583057951987beD85CE6934473160bFD4921b9, Error: 'data'
[2025-06-01 04:40:36,202] 	ERROR 	63 	pair_data.py 	<module>() 	Error occurred during Pair Data Fusion process. Pair: tUSDC/STAR (0.05%), Address: 0x53C49b9308c3DB176d351d7914Cec0Fb5D7f1129, Error: 'data'
[2025-06-01 04:40:36,318] 	ERROR 	63 	pair_data.py 	<module>() 	Error occurred during Pair Data Fusion process. Pair: WPOL/LUCHA (0.3%), Address: 0x52BeedA850A7048e9D543668BF54E0d9E1B667E0, Error: 'data'
[2025-06-01 04:40:36,411] 	ERROR 	63 	pair_data.py 	<module>() 	Error occurred during Pair Data Fusion process. Pair: LUCHA/WETH (0.3%), Address: 0x13136EA148331a07497087bfc31fBCcD9b99123c, Error: 'data'
[2025-06-01 04:40:36,517] 	ERROR 	63 	pair_data.py 	<module>() 	Error occurred during Pair Data Fusion process. Pair: JRT/WETH (0.3%), Address: 0xAE107e52ebdF151E61d9Fb4Bd800C86c31741465, Error: 'data'
[2025-06-01 04:40:36,624] 	ERROR 	63 	pair_data.py 	<module>() 	Error occurred during Pair Data Fusion process. Pair: axlLqdr/CASH (0.3%), Address: 0x22c10e61A05a03bcd8BF61a7E648f2330ecdA270, Error: 'data'
[2025-06-01 04:40:36,720] 	ERROR 	63 	pair_data.py 	<module>() 	Error occurred during Pair Data Fusion process. Pair: XOC/jMXN (0.01%), Address: 0xccE01e3615785771b84Eb5F88EC612AC6704FdE2, Error: 'data'
[2025-06-01 04:40:36,808] 	ERROR 	63 	pair_data.py 	<module>() 	Error occurred during Pair Data Fusion process. Pair: ICHI/CASH (1%), Address: 0x8ceD58A2dE3C2ea5D3cED3eb4331158c8cf985Fb, Error: 'data'
[2025-06-01 04:40:36,904] 	ERROR 	63 	pair_data.py 	<module>() 	Error occurred during Pair Data Fusion process. Pair: wUSDR/CASH (0.3%), Address: 0x3baEa49B71461DEaB46E6F42548D0005359ff629, Error: 'data'
[2025-06-01 04:40:36,998] 	ERROR 	63 	pair_data.py 	<module>() 	Error occurred during Pair Data Fusion process. Pair: CASH/STAR (0.05%), Address: 0x88C522E526E5Eea8d636fd6805cA7fEB488780D0, Error: 'data'
[2025-06-01 04:40:37,089] 	ERROR 	63 	pair_data.py 	<module>() 	Error occurred during Pair Data Fusion process. Pair: USDC.e/STAR (0.01%), Address: 0x6De0CA91Ef19A6ce9f02A423ae2dF89Fe09Bff0F, Error: 'data'
[2025-06-01 04:40:37,181] 	ERROR 	63 	pair_data.py 	<module>() 	Error occurred during Pair Data Fusion process. Pair: tUSDC/STAR (1%), Address: 0xaC44f57eEF260eB6E0f896b61984Da8d86FeE9ed, Error: 'data'
[2025-06-01 04:40:37,272] 	ERROR 	63 	pair_data.py 	<module>() 	Error occurred during Pair Data Fusion process. Pair: tUSDC/CASH (1%), Address: 0x4FcdB2DCc4Ce156c723aD541dba8B39d47284FC5, Error: 'data'
[2025-06-01 04:40:37,361] 	ERROR 	63 	pair_data.py 	<module>() 	Error occurred during Pair Data Fusion process. Pair: WPOL/USDC.e (0.3%), Address: 0x8c862d100B94d95a49D91958c9e8C2c348d00F04, Error: 'data'
[2025-06-01 04:40:37,450] 	ERROR 	63 	pair_data.py 	<module>() 	Error occurred during Pair Data Fusion process. Pair: WPOL/WETH (0.3%), Address: 0xB8dD18F9b7C3Ad4bDd4B94cB819eda3bd4465119, Error: 'data'
[2025-06-01 04:40:37,540] 	ERROR 	63 	pair_data.py 	<module>() 	Error occurred during Pair Data Fusion process. Pair: USDC.e/WETH (0.3%), Address: 0x058F5330Fef74445878110e201B04F36f8a51c9b, Error: 'data'
[2025-06-01 04:40:37,636] 	ERROR 	63 	pair_data.py 	<module>() 	Error occurred during Pair Data Fusion process. Pair: WBTC/WETH (0.3%), Address: 0x11275C625A7DEE3532E062Eef6915f00af85C3B5, Error: 'data'
[2025-06-01 04:40:37,738] 	ERROR 	63 	pair_data.py 	<module>() 	Error occurred during Pair Data Fusion process. Pair: LINK/WETH (0.3%), Address: 0x555eABEEfe6a047747071525A2c0fFd96d945f69, Error: 'data'
[2025-06-01 04:40:37,827] 	ERROR 	63 	pair_data.py 	<module>() 	Error occurred during Pair Data Fusion process. Pair: WBTC/CASH (0.3%), Address: 0x2C8F7d92Dc7A414D343CbFB687E31a11F525d29e, Error: 'data'
[2025-06-01 04:40:37,916] 	ERROR 	63 	pair_data.py 	<module>() 	Error occurred during Pair Data Fusion process. Pair: WPOL/DEUS (1%), Address: 0xB5cB765e44Eca4bc5a434fFaf6Bf7De235Bc60a5, Error: 'data'
[2025-06-01 04:40:37,995] 	ERROR 	63 	pair_data.py 	<module>() 	Error occurred during Pair Data Fusion process. Pair: WPOL/WBTC (0.3%), Address: 0x2981A1f699eA7149aa08121A07F000cf82846A9e, Error: 'data'
[2025-06-01 04:40:38,085] 	ERROR 	63 	pair_data.py 	<module>() 	Error occurred during Pair Data Fusion process. Pair: FRAX/STAR (0.05%), Address: 0x7D480cBf5Aee75E72eF26F223937f3981d67a860, Error: 'data'
[2025-06-01 04:40:38,186] 	ERROR 	63 	pair_data.py 	<module>() 	Error occurred during Pair Data Fusion process. Pair: CASH/TAROT (0.3%), Address: 0x217aEb0667b79584FBf6265B74a8cD22E1245fdC, Error: 'data'
[2025-06-01 04:40:38,335] 	ERROR 	63 	pair_data.py 	<module>() 	Error occurred during Pair Data Fusion process. Pair: CASH/fxDOLA (0.05%), Address: 0x4b4B895a0dD744B4893aA4370A8F7eDbde5Fd90e, Error: 'data'
[2025-06-01 04:40:38,421] 	ERROR 	63 	pair_data.py 	<module>() 	Error occurred during Pair Data Fusion process. Pair: RETRO/liveRetro (1%), Address: 0x6333BB8b6f1DDa6f929d70eDEB9e31c8148dC9ef, Error: 'data'
[2025-06-01 04:40:38,512] 	ERROR 	63 	pair_data.py 	<module>() 	Error occurred during Pair Data Fusion process. Pair: MVX/WETH (1%), Address: 0xCC72276de3BCc1b159F1B60A86B0211116022B42, Error: 'data'
[2025-06-01 04:40:38,632] 	ERROR 	63 	pair_data.py 	<module>() 	Error occurred during Pair Data Fusion process. Pair: WPOL/elRETRO (1%), Address: 0x6794Db07e2efE1307b8594FBbBFad78E50eC76fa, Error: 'data'
[2025-06-01 04:40:38,718] 	ERROR 	63 	pair_data.py 	<module>() 	Error occurred during Pair Data Fusion process. Pair: OATH/WETH (1%), Address: 0x0c74834d67c4bf5e6a44D18b2BAc767cddB4CdBf, Error: 'data'
[2025-06-01 04:40:38,813] 	ERROR 	63 	pair_data.py 	<module>() 	Error occurred during Pair Data Fusion process. Pair: USDC.e/IBEX (1%), Address: 0x53D8c25B3d130D2810591cDc7A41Bd848bF79B63, Error: 'data'
[2025-06-01 04:40:38,896] 	ERROR 	63 	pair_data.py 	<module>() 	Error occurred during Pair Data Fusion process. Pair: USDC.e/fxDOLA (0.3%), Address: 0x896ffE2cd28Ba13ddDa98103a3B66E82bb36BeE3, Error: 'data'
[2025-06-01 04:40:38,977] 	ERROR 	63 	pair_data.py 	<module>() 	Error occurred during Pair Data Fusion process. Pair: USDC.e/FRAX (0.3%), Address: 0x091236A16952BC9e4bB817FFA7aB40263183f658, Error: 'data'
[2025-06-01 04:40:39,060] 	ERROR 	63 	pair_data.py 	<module>() 	Error occurred during Pair Data Fusion process. Pair: WBTC/USDC.e (0.3%), Address: 0x459F42C788E6F8faCe4854DDD59C81a6Ad8BB1Aa, Error: 'data'
[2025-06-01 04:40:39,152] 	ERROR 	63 	pair_data.py 	<module>() 	Error occurred during Pair Data Fusion process. Pair: WETH/ERN (0.3%), Address: 0xCF2093da3CeBb8731747EEaCbd486A7fcE2Db901, Error: 'data'
[2025-06-01 04:40:39,255] 	ERROR 	63 	pair_data.py 	<module>() 	Error occurred during Pair Data Fusion process. Pair: WETH/JARVIS (0.3%), Address: 0xf310d505B85E0378790Af9fDB9b79b40736f7b4D, Error: 'data'
[2025-06-01 04:40:39,342] 	ERROR 	63 	pair_data.py 	<module>() 	Error occurred during Pair Data Fusion process. Pair: jEUR/CASH (0.05%), Address: 0x65E6b7C7DfE071E52D6923E4079E3C0FcBeaA401, Error: 'data'
[2025-06-01 04:40:39,427] 	ERROR 	63 	pair_data.py 	<module>() 	Error occurred during Pair Data Fusion process. Pair: USDC.e/USDC (0.01%), Address: 0x1e0aa3f6C3130294845B8e162d838e221d170016, Error: 'data'
[2025-06-01 04:40:39,512] 	ERROR 	63 	pair_data.py 	<module>() 	Error occurred during Pair Data Fusion process. Pair: LUCHA/WETH (1%), Address: 0x098c1e4BB34DEcDF49D5966014B5153Af326E766, Error: 'data'
[2025-06-01 04:40:39,607] 	ERROR 	63 	pair_data.py 	<module>() 	Error occurred during Pair Data Fusion process. Pair: WPOL/LUCHA (1%), Address: 0xde4C8898CD50EBE9C167313b312D147D10d1C898, Error: 'data'
[2025-06-01 04:40:39,697] 	ERROR 	63 	pair_data.py 	<module>() 	Error occurred during Pair Data Fusion process. Pair: LINK/LUCHA (1%), Address: 0xA97B2b9AcA65aab57A6b0840B45777bd66fbcf33, Error: 'data'
[2025-06-01 04:40:39,782] 	ERROR 	63 	pair_data.py 	<module>() 	Error occurred during Pair Data Fusion process. Pair: CASH/LUCHA (1%), Address: 0x5c09352B1aa703d18dbcF48c98655BFA19d07FBB, Error: 'data'
[2025-06-01 04:40:39,896] 	ERROR 	103 	pair_data.py 	<module>() 	Error occurred during Pair Data Fusion process. Error: 'date'
Traceback (most recent call last):
  File "/opt/hostedtoolcache/Python/3.8.18/x64/lib/python3.8/site-packages/pandas/core/indexes/base.py", line 3802, in get_loc
    return self._engine.get_loc(casted_key)
  File "pandas/_libs/index.pyx", line 138, in pandas._libs.index.IndexEngine.get_loc
  File "pandas/_libs/index.pyx", line 165, in pandas._libs.index.IndexEngine.get_loc
  File "pandas/_libs/hashtable_class_helper.pxi", line 5745, in pandas._libs.hashtable.PyObjectHashTable.get_item
  File "pandas/_libs/hashtable_class_helper.pxi", line 5753, in pandas._libs.hashtable.PyObjectHashTable.get_item
KeyError: 'date'

The above exception was the direct cause of the following exception:

Traceback (most recent call last):
  File "pair_data.py", line 68, in <module>
    pairdata_fusion_df["date"] = pairdata_fusion_df["date"].apply(lambda timestamp: datetime.utcfromtimestamp(timestamp).date())
  File "/opt/hostedtoolcache/Python/3.8.18/x64/lib/python3.8/site-packages/pandas/core/frame.py", line 3807, in __getitem__
    indexer = self.columns.get_loc(key)
  File "/opt/hostedtoolcache/Python/3.8.18/x64/lib/python3.8/site-packages/pandas/core/indexes/base.py", line 3804, in get_loc
    raise KeyError(key) from err
KeyError: 'date'
[2025-06-01 04:40:40,730] 	INFO 	36 	bribe_data.py 	<module>() 	Bribe Data Started
[2025-06-01 04:40:42,008] 	ERROR 	159 	bribe_data.py 	<module>() 	Error occurred during Bribe Data process. Error: 403 Client Error: Forbidden for url: https://rpc.ankr.com/polygon
Traceback (most recent call last):
  File "bribe_data.py", line 71, in <module>
    rewardsListLength = contract_instance.functions.rewardsListLength().call()
  File "/opt/hostedtoolcache/Python/3.8.18/x64/lib/python3.8/site-packages/web3/contract.py", line 970, in call
    return call_contract_function(
  File "/opt/hostedtoolcache/Python/3.8.18/x64/lib/python3.8/site-packages/web3/contract.py", line 1525, in call_contract_function
    return_data = web3.eth.call(
  File "/opt/hostedtoolcache/Python/3.8.18/x64/lib/python3.8/site-packages/web3/module.py", line 57, in caller
    result = w3.manager.request_blocking(method_str,
  File "/opt/hostedtoolcache/Python/3.8.18/x64/lib/python3.8/site-packages/web3/manager.py", line 197, in request_blocking
    response = self._make_request(method, params)
  File "/opt/hostedtoolcache/Python/3.8.18/x64/lib/python3.8/site-packages/web3/manager.py", line 150, in _make_request
    return request_func(method, params)
  File "/opt/hostedtoolcache/Python/3.8.18/x64/lib/python3.8/site-packages/web3/middleware/formatting.py", line 94, in middleware
    response = make_request(method, params)
  File "/opt/hostedtoolcache/Python/3.8.18/x64/lib/python3.8/site-packages/web3/middleware/gas_price_strategy.py", line 90, in middleware
    return make_request(method, params)
  File "/opt/hostedtoolcache/Python/3.8.18/x64/lib/python3.8/site-packages/web3/middleware/formatting.py", line 94, in middleware
    response = make_request(method, params)
  File "/opt/hostedtoolcache/Python/3.8.18/x64/lib/python3.8/site-packages/web3/middleware/attrdict.py", line 33, in middleware
    response = make_request(method, params)
  File "/opt/hostedtoolcache/Python/3.8.18/x64/lib/python3.8/site-packages/web3/middleware/formatting.py", line 94, in middleware
    response = make_request(method, params)
  File "/opt/hostedtoolcache/Python/3.8.18/x64/lib/python3.8/site-packages/web3/middleware/formatting.py", line 94, in middleware
    response = make_request(method, params)
  File "/opt/hostedtoolcache/Python/3.8.18/x64/lib/python3.8/site-packages/web3/middleware/formatting.py", line 94, in middleware
    response = make_request(method, params)
  File "/opt/hostedtoolcache/Python/3.8.18/x64/lib/python3.8/site-packages/web3/middleware/buffered_gas_estimate.py", line 40, in middleware
    return make_request(method, params)
  File "/opt/hostedtoolcache/Python/3.8.18/x64/lib/python3.8/site-packages/web3/middleware/exception_retry_request.py", line 105, in middleware
    return make_request(method, params)
  File "/opt/hostedtoolcache/Python/3.8.18/x64/lib/python3.8/site-packages/web3/providers/rpc.py", line 88, in make_request
    raw_response = make_post_request(
  File "/opt/hostedtoolcache/Python/3.8.18/x64/lib/python3.8/site-packages/web3/_utils/request.py", line 113, in make_post_request
    response.raise_for_status()
  File "/opt/hostedtoolcache/Python/3.8.18/x64/lib/python3.8/site-packages/requests/models.py", line 1021, in raise_for_status
    raise HTTPError(http_error_msg, response=self)
requests.exceptions.HTTPError: 403 Client Error: Forbidden for url: https://rpc.ankr.com/polygon
[2025-06-01 04:40:42,842] 	INFO 	36 	fee_data.py 	<module>() 	Fee Data Started
[2025-06-01 04:40:43,019] 	ERROR 	159 	fee_data.py 	<module>() 	Error occurred during Fee Data process. Error: 403 Client Error: Forbidden for url: https://rpc.ankr.com/polygon
Traceback (most recent call last):
  File "fee_data.py", line 71, in <module>
    rewardsListLength = contract_instance.functions.rewardsListLength().call()
  File "/opt/hostedtoolcache/Python/3.8.18/x64/lib/python3.8/site-packages/web3/contract.py", line 970, in call
    return call_contract_function(
  File "/opt/hostedtoolcache/Python/3.8.18/x64/lib/python3.8/site-packages/web3/contract.py", line 1525, in call_contract_function
    return_data = web3.eth.call(
  File "/opt/hostedtoolcache/Python/3.8.18/x64/lib/python3.8/site-packages/web3/module.py", line 57, in caller
    result = w3.manager.request_blocking(method_str,
  File "/opt/hostedtoolcache/Python/3.8.18/x64/lib/python3.8/site-packages/web3/manager.py", line 197, in request_blocking
    response = self._make_request(method, params)
  File "/opt/hostedtoolcache/Python/3.8.18/x64/lib/python3.8/site-packages/web3/manager.py", line 150, in _make_request
    return request_func(method, params)
  File "/opt/hostedtoolcache/Python/3.8.18/x64/lib/python3.8/site-packages/web3/middleware/formatting.py", line 94, in middleware
    response = make_request(method, params)
  File "/opt/hostedtoolcache/Python/3.8.18/x64/lib/python3.8/site-packages/web3/middleware/gas_price_strategy.py", line 90, in middleware
    return make_request(method, params)
  File "/opt/hostedtoolcache/Python/3.8.18/x64/lib/python3.8/site-packages/web3/middleware/formatting.py", line 94, in middleware
    response = make_request(method, params)
  File "/opt/hostedtoolcache/Python/3.8.18/x64/lib/python3.8/site-packages/web3/middleware/attrdict.py", line 33, in middleware
    response = make_request(method, params)
  File "/opt/hostedtoolcache/Python/3.8.18/x64/lib/python3.8/site-packages/web3/middleware/formatting.py", line 94, in middleware
    response = make_request(method, params)
  File "/opt/hostedtoolcache/Python/3.8.18/x64/lib/python3.8/site-packages/web3/middleware/formatting.py", line 94, in middleware
    response = make_request(method, params)
  File "/opt/hostedtoolcache/Python/3.8.18/x64/lib/python3.8/site-packages/web3/middleware/formatting.py", line 94, in middleware
    response = make_request(method, params)
  File "/opt/hostedtoolcache/Python/3.8.18/x64/lib/python3.8/site-packages/web3/middleware/buffered_gas_estimate.py", line 40, in middleware
    return make_request(method, params)
  File "/opt/hostedtoolcache/Python/3.8.18/x64/lib/python3.8/site-packages/web3/middleware/exception_retry_request.py", line 105, in middleware
    return make_request(method, params)
  File "/opt/hostedtoolcache/Python/3.8.18/x64/lib/python3.8/site-packages/web3/providers/rpc.py", line 88, in make_request
    raw_response = make_post_request(
  File "/opt/hostedtoolcache/Python/3.8.18/x64/lib/python3.8/site-packages/web3/_utils/request.py", line 113, in make_post_request
    response.raise_for_status()
  File "/opt/hostedtoolcache/Python/3.8.18/x64/lib/python3.8/site-packages/requests/models.py", line 1021, in raise_for_status
    raise HTTPError(http_error_msg, response=self)
requests.exceptions.HTTPError: 403 Client Error: Forbidden for url: https://rpc.ankr.com/polygon
[2025-06-01 04:40:43,859] 	INFO 	37 	vote_data.py 	<module>() 	Vote Data Started
[2025-06-01 04:41:03,753] 	ERROR 	118 	vote_data.py 	<module>() 	Error occurred during Vote Data process. Error: Expecting value: line 1 column 1 (char 0)
Traceback (most recent call last):
  File "/opt/hostedtoolcache/Python/3.8.18/x64/lib/python3.8/site-packages/requests/models.py", line 971, in json
    return complexjson.loads(self.text, **kwargs)
  File "/opt/hostedtoolcache/Python/3.8.18/x64/lib/python3.8/json/__init__.py", line 357, in loads
    return _default_decoder.decode(s)
  File "/opt/hostedtoolcache/Python/3.8.18/x64/lib/python3.8/json/decoder.py", line 337, in decode
    obj, end = self.raw_decode(s, idx=_w(s, 0).end())
  File "/opt/hostedtoolcache/Python/3.8.18/x64/lib/python3.8/json/decoder.py", line 355, in raw_decode
    raise JSONDecodeError("Expecting value", s, err.value) from None
json.decoder.JSONDecodeError: Expecting value: line 1 column 1 (char 0)

During handling of the above exception, another exception occurred:

Traceback (most recent call last):
  File "vote_data.py", line 64, in <module>
    RETRO_price = jmespath.search("data[?name == 'RETRO'].price", response.json())[0]
  File "/opt/hostedtoolcache/Python/3.8.18/x64/lib/python3.8/site-packages/requests/models.py", line 975, in json
    raise RequestsJSONDecodeError(e.msg, e.doc, e.pos)
requests.exceptions.JSONDecodeError: Expecting value: line 1 column 1 (char 0)
[2025-06-01 04:41:04,596] 	INFO 	30 	revenue_data.py 	<module>() 	Revenue Data Started
[2025-06-01 04:41:28,334] 	ERROR 	152 	revenue_data.py 	<module>() 	Error occurred during Revenue Data process. Error: Expecting value: line 1 column 1 (char 0)
Traceback (most recent call last):
  File "/opt/hostedtoolcache/Python/3.8.18/x64/lib/python3.8/site-packages/requests/models.py", line 971, in json
    return complexjson.loads(self.text, **kwargs)
  File "/opt/hostedtoolcache/Python/3.8.18/x64/lib/python3.8/json/__init__.py", line 357, in loads
    return _default_decoder.decode(s)
  File "/opt/hostedtoolcache/Python/3.8.18/x64/lib/python3.8/json/decoder.py", line 337, in decode
    obj, end = self.raw_decode(s, idx=_w(s, 0).end())
  File "/opt/hostedtoolcache/Python/3.8.18/x64/lib/python3.8/json/decoder.py", line 355, in raw_decode
    raise JSONDecodeError("Expecting value", s, err.value) from None
json.decoder.JSONDecodeError: Expecting value: line 1 column 1 (char 0)

During handling of the above exception, another exception occurred:

Traceback (most recent call last):
  File "revenue_data.py", line 66, in <module>
    RETRO_price = jmespath.search("data[?name == 'RETRO'].price", response.json())[0]
  File "/opt/hostedtoolcache/Python/3.8.18/x64/lib/python3.8/site-packages/requests/models.py", line 975, in json
    raise RequestsJSONDecodeError(e.msg, e.doc, e.pos)
requests.exceptions.JSONDecodeError: Expecting value: line 1 column 1 (char 0)
[2025-06-01 05:26:06,749] 	INFO 	20 	id_data.py 	<module>() 	ID Data Started
[2025-06-01 05:26:26,471] 	ERROR 	33 	id_data.py 	<module>() 	Error occurred during ID Data process. Error: Expecting value: line 1 column 1 (char 0)
Traceback (most recent call last):
  File "/opt/hostedtoolcache/Python/3.8.18/x64/lib/python3.8/site-packages/requests/models.py", line 971, in json
    return complexjson.loads(self.text, **kwargs)
  File "/opt/hostedtoolcache/Python/3.8.18/x64/lib/python3.8/json/__init__.py", line 357, in loads
    return _default_decoder.decode(s)
  File "/opt/hostedtoolcache/Python/3.8.18/x64/lib/python3.8/json/decoder.py", line 337, in decode
    obj, end = self.raw_decode(s, idx=_w(s, 0).end())
  File "/opt/hostedtoolcache/Python/3.8.18/x64/lib/python3.8/json/decoder.py", line 355, in raw_decode
    raise JSONDecodeError("Expecting value", s, err.value) from None
json.decoder.JSONDecodeError: Expecting value: line 1 column 1 (char 0)

During handling of the above exception, another exception occurred:

Traceback (most recent call last):
  File "id_data.py", line 27, in <module>
    data = response.json()["data"]
  File "/opt/hostedtoolcache/Python/3.8.18/x64/lib/python3.8/site-packages/requests/models.py", line 975, in json
    raise RequestsJSONDecodeError(e.msg, e.doc, e.pos)
requests.exceptions.JSONDecodeError: Expecting value: line 1 column 1 (char 0)
[2025-06-01 05:26:26,992] 	INFO 	24 	day_data.py 	<module>() 	Day Data Fusion Started
[2025-06-01 05:26:27,225] 	ERROR 	73 	day_data.py 	<module>() 	Error occurred during Day Data Fusion process. Error: 'data'
Traceback (most recent call last):
  File "day_data.py", line 41, in <module>
    data = response.json()["data"]["uniswapDayDatas"]
KeyError: 'data'
[2025-06-01 05:26:28,113] 	INFO 	35 	pair_data.py 	<module>() 	Pair Data Fusion Started
[2025-06-01 05:26:28,344] 	ERROR 	63 	pair_data.py 	<module>() 	Error occurred during Pair Data Fusion process. Pair: sAMM-USDC.e/USDT, Address: 0xB38245b7fE8D594d883A27DB1055bf67926F6B27, Error: 'data'
[2025-06-01 05:26:28,436] 	ERROR 	63 	pair_data.py 	<module>() 	Error occurred during Pair Data Fusion process. Pair: vAMM-WPOL/elRETRO, Address: 0x90a09fE272540Ecd34661B91252f2aB4b7f7A4CE, Error: 'data'
[2025-06-01 05:26:28,531] 	ERROR 	63 	pair_data.py 	<module>() 	Error occurred during Pair Data Fusion process. Pair: sAMM-oRETRO/elRETRO, Address: 0xc58Eb718892Da5D519587A3ec87063A8a46c9feb, Error: 'data'
[2025-06-01 05:26:28,637] 	ERROR 	63 	pair_data.py 	<module>() 	Error occurred during Pair Data Fusion process. Pair: WPOL/WETH (0.05%), Address: 0x1a34EaBbe928Bf431B679959379b2225d60D9cdA, Error: 'data'
[2025-06-01 05:26:28,728] 	ERROR 	63 	pair_data.py 	<module>() 	Error occurred during Pair Data Fusion process. Pair: WPOL/USDC.e (0.05%), Address: 0xEC15624FBB314eb05BaaD4cA49b7904C0Cb6b645, Error: 'data'
[2025-06-01 05:26:28,817] 	ERROR 	63 	pair_data.py 	<module>() 	Error occurred during Pair Data Fusion process. Pair: USDC.e/WETH (0.05%), Address: 0xCE67850420c82dB45eb7fEeCcD2d181300D2BDB3, Error: 'data'
[2025-06-01 05:26:28,909] 	ERROR 	63 	pair_data.py 	<module>() 	Error occurred during Pair Data Fusion process. Pair: WBTC/WETH (0.05%), Address: 0xb694E3bdd4BCdF843510983D257679D1E627C474, Error: 'data'
[2025-06-01 05:26:28,998] 	ERROR 	63 	pair_data.py 	<module>() 	Error occurred during Pair Data Fusion process. Pair: WPOL/USDT (0.05%), Address: 0xB580229645b240A368768ec3E88cb67A41eBBC5B, Error: 'data'
[2025-06-01 05:26:29,108] 	ERROR 	63 	pair_data.py 	<module>() 	Error occurred during Pair Data Fusion process. Pair: WPOL/CASH (0.05%), Address: 0x63ca6ED3D390C725b7FEb617BAdcab78a61038E8, Error: 'data'
[2025-06-01 05:26:29,211] 	ERROR 	63 	pair_data.py 	<module>() 	Error occurred during Pair Data Fusion process. Pair: CASH/WETH (0.05%), Address: 0x0A46B0712974F201BeD15c2458a023EbED25eF4F, Error: 'data'
[2025-06-01 05:26:29,306] 	ERROR 	63 	pair_data.py 	<module>() 	Error occurred during Pair Data Fusion process. Pair: USDC.e/CASH (0.01%), Address: 0x619259F699839dD1498FFC22297044462483bD27, Error: 'data'
[2025-06-01 05:26:29,403] 	ERROR 	63 	pair_data.py 	<module>() 	Error occurred during Pair Data Fusion process. Pair: CASH/USDT (0.01%), Address: 0x160FBF00AB5fbF0200c0Cd4929aEaa2AdD25FB5b, Error: 'data'
[2025-06-01 05:26:29,494] 	ERROR 	63 	pair_data.py 	<module>() 	Error occurred during Pair Data Fusion process. Pair: CASH/DAI (0.01%), Address: 0x1e683586fCB45a769ef2C7d9d7b1803E9C1AEE79, Error: 'data'
[2025-06-01 05:26:29,591] 	ERROR 	63 	pair_data.py 	<module>() 	Error occurred during Pair Data Fusion process. Pair: CASH/miMATIC (0.01%), Address: 0xeB80047F7d5D4C4A3BC6319250d6b1b8aEe2d0D2, Error: 'data'
[2025-06-01 05:26:29,686] 	ERROR 	63 	pair_data.py 	<module>() 	Error occurred during Pair Data Fusion process. Pair: CASH/MaticX (0.05%), Address: 0xb98F8DF0DC6750A3e54540A1e094186C8bED780a, Error: 'data'
[2025-06-01 05:26:29,776] 	ERROR 	63 	pair_data.py 	<module>() 	Error occurred during Pair Data Fusion process. Pair: USDC.e/EURA (0.05%), Address: 0xC2CB03a819F785bD8eb8D628BAD41Cd7c1C71F4B, Error: 'data'
[2025-06-01 05:26:29,873] 	ERROR 	63 	pair_data.py 	<module>() 	Error occurred during Pair Data Fusion process. Pair: FRAX/CASH (0.01%), Address: 0x72289129Dc4937a5d406d1ECeD8b2A17d007A650, Error: 'data'
[2025-06-01 05:26:29,961] 	ERROR 	63 	pair_data.py 	<module>() 	Error occurred during Pair Data Fusion process. Pair: CASH/RETRO (1%), Address: 0xb47A07966cE6812702C0567d03725F1b37E27877, Error: 'data'
[2025-06-01 05:26:30,046] 	ERROR 	63 	pair_data.py 	<module>() 	Error occurred during Pair Data Fusion process. Pair: WETH/RETRO (1%), Address: 0x35394eED0Be676ec6470fE6531daD809265310ff, Error: 'data'
[2025-06-01 05:26:30,143] 	ERROR 	63 	pair_data.py 	<module>() 	Error occurred during Pair Data Fusion process. Pair: WPOL/RETRO (1%), Address: 0x547FD24AA2ED09d86dAC02E36b8Ce84A59fD644F, Error: 'data'
[2025-06-01 05:26:30,235] 	ERROR 	63 	pair_data.py 	<module>() 	Error occurred during Pair Data Fusion process. Pair: WBTC/RETRO (1%), Address: 0x0F73E719a76947752E4b26A2c3FC80a580e68fB4, Error: 'data'
[2025-06-01 05:26:30,325] 	ERROR 	63 	pair_data.py 	<module>() 	Error occurred during Pair Data Fusion process. Pair: stMATIC/RETRO (1%), Address: 0x0973698BB6399c39d628698f9300430C4e7c9bf9, Error: 'data'
[2025-06-01 05:26:30,422] 	ERROR 	63 	pair_data.py 	<module>() 	Error occurred during Pair Data Fusion process. Pair: USDC.e/RETRO (1%), Address: 0xc7d8B9c270D0E31A6a0Cf4496fe019766Be42E15, Error: 'data'
[2025-06-01 05:26:30,518] 	ERROR 	63 	pair_data.py 	<module>() 	Error occurred during Pair Data Fusion process. Pair: RETRO/USDT (1%), Address: 0x69dCAE97A1286B112a8BD75bD9147bD0a3207756, Error: 'data'
[2025-06-01 05:26:30,612] 	ERROR 	63 	pair_data.py 	<module>() 	Error occurred during Pair Data Fusion process. Pair: miMATIC/RETRO (1%), Address: 0xd98eEf295f78ddDd104a8645854C7F8714B39B88, Error: 'data'
[2025-06-01 05:26:30,710] 	ERROR 	63 	pair_data.py 	<module>() 	Error occurred during Pair Data Fusion process. Pair: LINK/RETRO (1%), Address: 0x7761c7233924C3D72F27Fae6a81B074C0152e03a, Error: 'data'
[2025-06-01 05:26:30,804] 	ERROR 	63 	pair_data.py 	<module>() 	Error occurred during Pair Data Fusion process. Pair: RETRO/EURA (1%), Address: 0x15949526fF03fE6ab5f49dA6a86749c20141b3f1, Error: 'data'
[2025-06-01 05:26:30,898] 	ERROR 	63 	pair_data.py 	<module>() 	Error occurred during Pair Data Fusion process. Pair: USDC.e/USDT (0.01%), Address: 0x772510189425ac63f9a5A5eF2fd0C7FDA58CBFC7, Error: 'data'
[2025-06-01 05:26:30,988] 	ERROR 	63 	pair_data.py 	<module>() 	Error occurred during Pair Data Fusion process. Pair: USDC.e/DAI (0.01%), Address: 0x219116F23BDC11EB25e4D0FbE92eD0972d86BE20, Error: 'data'
[2025-06-01 05:26:31,080] 	ERROR 	63 	pair_data.py 	<module>() 	Error occurred during Pair Data Fusion process. Pair: WPOL/MaticX (0.01%), Address: 0x9aa18301055091e9da7C57b81633632Fa33B9a80, Error: 'data'
[2025-06-01 05:26:31,177] 	ERROR 	63 	pair_data.py 	<module>() 	Error occurred during Pair Data Fusion process. Pair: wstETH/WETH (0.01%), Address: 0xa9439Db1D7025Ce4aAc513Baf5eee5220172126C, Error: 'data'
[2025-06-01 05:26:31,269] 	ERROR 	63 	pair_data.py 	<module>() 	Error occurred during Pair Data Fusion process. Pair: WPOL/stMATIC (0.01%), Address: 0x2d623c33673248E95C7a1C26aE7065eb7A7Ac0Ea, Error: 'data'
[2025-06-01 05:26:31,358] 	ERROR 	63 	pair_data.py 	<module>() 	Error occurred during Pair Data Fusion process. Pair: WETH/frxETH (0.01%), Address: 0xe5069a75Bdfe8F676B778B0aaDCcC597841F819B, Error: 'data'
[2025-06-01 05:26:31,449] 	ERROR 	63 	pair_data.py 	<module>() 	Error occurred during Pair Data Fusion process. Pair: FRAX/frxETH (0.05%), Address: 0x38df0c93bf69a9EfB3d3647fF459eF27235A8968, Error: 'data'
[2025-06-01 05:26:31,536] 	ERROR 	63 	pair_data.py 	<module>() 	Error occurred during Pair Data Fusion process. Pair: WPOL/frxETH (0.05%), Address: 0x44AAE81BE8435b6998A66d9642f66DE57DD03FC2, Error: 'data'
[2025-06-01 05:26:31,627] 	ERROR 	63 	pair_data.py 	<module>() 	Error occurred during Pair Data Fusion process. Pair: xbb-t-USD/CASH (0.01%), Address: 0x07dBf448cCC68cA64247da04F2E24643eCf57385, Error: 'data'
[2025-06-01 05:26:31,727] 	ERROR 	63 	pair_data.py 	<module>() 	Error occurred during Pair Data Fusion process. Pair: LINK/LUCHA (0.3%), Address: 0x91248C85DD408BD216254C3cFb51fc326290cF7e, Error: 'data'
[2025-06-01 05:26:31,835] 	ERROR 	63 	pair_data.py 	<module>() 	Error occurred during Pair Data Fusion process. Pair: CASH/LUCHA (0.3%), Address: 0xc666c4b402Bd797185EA419261D22a8f22DDFce6, Error: 'data'
[2025-06-01 05:26:31,928] 	ERROR 	63 	pair_data.py 	<module>() 	Error occurred during Pair Data Fusion process. Pair: USDC.e/miMATIC (0.3%), Address: 0xb090BE2D2F02646057d4DF997A7A983dFb265de0, Error: 'data'
[2025-06-01 05:26:32,029] 	ERROR 	63 	pair_data.py 	<module>() 	Error occurred during Pair Data Fusion process. Pair: FRAX/miMATIC (0.3%), Address: 0xdeB25Dd2d5D168Fd6f80F154d96a2Dab81d61845, Error: 'data'
[2025-06-01 05:26:32,126] 	ERROR 	63 	pair_data.py 	<module>() 	Error occurred during Pair Data Fusion process. Pair: WPOL/miMATIC (0.3%), Address: 0xC571445Fc93666e1E4FaE2E84A7b74FE6ed3978D, Error: 'data'
[2025-06-01 05:26:32,228] 	ERROR 	63 	pair_data.py 	<module>() 	Error occurred during Pair Data Fusion process. Pair: CASH/ERN (0.3%), Address: 0x777a87889f42C33f9A1E5c117774694bbd857075, Error: 'data'
[2025-06-01 05:26:32,325] 	ERROR 	63 	pair_data.py 	<module>() 	Error occurred during Pair Data Fusion process. Pair: ICHI/RETRO (1%), Address: 0xC26E1a0cDab4Bf5141530C49F3360f162C5Db5Db, Error: 'data'
[2025-06-01 05:26:32,420] 	ERROR 	63 	pair_data.py 	<module>() 	Error occurred during Pair Data Fusion process. Pair: WPOL/ICHI (0.3%), Address: 0x13d5e61838D93F7962C52dc921FD7C0Ccc092E35, Error: 'data'
[2025-06-01 05:26:32,509] 	ERROR 	63 	pair_data.py 	<module>() 	Error occurred during Pair Data Fusion process. Pair: SD/MaticX (0.3%), Address: 0xB97c62834e096858BD0B996b758942dd43d7B5eE, Error: 'data'
[2025-06-01 05:26:32,603] 	ERROR 	63 	pair_data.py 	<module>() 	Error occurred during Pair Data Fusion process. Pair: stERN/ERN (1%), Address: 0x99583057951987beD85CE6934473160bFD4921b9, Error: 'data'
[2025-06-01 05:26:32,693] 	ERROR 	63 	pair_data.py 	<module>() 	Error occurred during Pair Data Fusion process. Pair: tUSDC/STAR (0.05%), Address: 0x53C49b9308c3DB176d351d7914Cec0Fb5D7f1129, Error: 'data'
[2025-06-01 05:26:32,796] 	ERROR 	63 	pair_data.py 	<module>() 	Error occurred during Pair Data Fusion process. Pair: WPOL/LUCHA (0.3%), Address: 0x52BeedA850A7048e9D543668BF54E0d9E1B667E0, Error: 'data'
[2025-06-01 05:26:32,886] 	ERROR 	63 	pair_data.py 	<module>() 	Error occurred during Pair Data Fusion process. Pair: LUCHA/WETH (0.3%), Address: 0x13136EA148331a07497087bfc31fBCcD9b99123c, Error: 'data'
[2025-06-01 05:26:32,974] 	ERROR 	63 	pair_data.py 	<module>() 	Error occurred during Pair Data Fusion process. Pair: JRT/WETH (0.3%), Address: 0xAE107e52ebdF151E61d9Fb4Bd800C86c31741465, Error: 'data'
[2025-06-01 05:26:33,067] 	ERROR 	63 	pair_data.py 	<module>() 	Error occurred during Pair Data Fusion process. Pair: axlLqdr/CASH (0.3%), Address: 0x22c10e61A05a03bcd8BF61a7E648f2330ecdA270, Error: 'data'
[2025-06-01 05:26:33,164] 	ERROR 	63 	pair_data.py 	<module>() 	Error occurred during Pair Data Fusion process. Pair: XOC/jMXN (0.01%), Address: 0xccE01e3615785771b84Eb5F88EC612AC6704FdE2, Error: 'data'
[2025-06-01 05:26:33,263] 	ERROR 	63 	pair_data.py 	<module>() 	Error occurred during Pair Data Fusion process. Pair: ICHI/CASH (1%), Address: 0x8ceD58A2dE3C2ea5D3cED3eb4331158c8cf985Fb, Error: 'data'
[2025-06-01 05:26:33,353] 	ERROR 	63 	pair_data.py 	<module>() 	Error occurred during Pair Data Fusion process. Pair: wUSDR/CASH (0.3%), Address: 0x3baEa49B71461DEaB46E6F42548D0005359ff629, Error: 'data'
[2025-06-01 05:26:33,453] 	ERROR 	63 	pair_data.py 	<module>() 	Error occurred during Pair Data Fusion process. Pair: CASH/STAR (0.05%), Address: 0x88C522E526E5Eea8d636fd6805cA7fEB488780D0, Error: 'data'
[2025-06-01 05:26:33,541] 	ERROR 	63 	pair_data.py 	<module>() 	Error occurred during Pair Data Fusion process. Pair: USDC.e/STAR (0.01%), Address: 0x6De0CA91Ef19A6ce9f02A423ae2dF89Fe09Bff0F, Error: 'data'
[2025-06-01 05:26:33,638] 	ERROR 	63 	pair_data.py 	<module>() 	Error occurred during Pair Data Fusion process. Pair: tUSDC/STAR (1%), Address: 0xaC44f57eEF260eB6E0f896b61984Da8d86FeE9ed, Error: 'data'
[2025-06-01 05:26:33,735] 	ERROR 	63 	pair_data.py 	<module>() 	Error occurred during Pair Data Fusion process. Pair: tUSDC/CASH (1%), Address: 0x4FcdB2DCc4Ce156c723aD541dba8B39d47284FC5, Error: 'data'
[2025-06-01 05:26:33,824] 	ERROR 	63 	pair_data.py 	<module>() 	Error occurred during Pair Data Fusion process. Pair: WPOL/USDC.e (0.3%), Address: 0x8c862d100B94d95a49D91958c9e8C2c348d00F04, Error: 'data'
[2025-06-01 05:26:33,922] 	ERROR 	63 	pair_data.py 	<module>() 	Error occurred during Pair Data Fusion process. Pair: WPOL/WETH (0.3%), Address: 0xB8dD18F9b7C3Ad4bDd4B94cB819eda3bd4465119, Error: 'data'
[2025-06-01 05:26:34,020] 	ERROR 	63 	pair_data.py 	<module>() 	Error occurred during Pair Data Fusion process. Pair: USDC.e/WETH (0.3%), Address: 0x058F5330Fef74445878110e201B04F36f8a51c9b, Error: 'data'
[2025-06-01 05:26:34,112] 	ERROR 	63 	pair_data.py 	<module>() 	Error occurred during Pair Data Fusion process. Pair: WBTC/WETH (0.3%), Address: 0x11275C625A7DEE3532E062Eef6915f00af85C3B5, Error: 'data'
[2025-06-01 05:26:34,205] 	ERROR 	63 	pair_data.py 	<module>() 	Error occurred during Pair Data Fusion process. Pair: LINK/WETH (0.3%), Address: 0x555eABEEfe6a047747071525A2c0fFd96d945f69, Error: 'data'
[2025-06-01 05:26:34,297] 	ERROR 	63 	pair_data.py 	<module>() 	Error occurred during Pair Data Fusion process. Pair: WBTC/CASH (0.3%), Address: 0x2C8F7d92Dc7A414D343CbFB687E31a11F525d29e, Error: 'data'
[2025-06-01 05:26:34,395] 	ERROR 	63 	pair_data.py 	<module>() 	Error occurred during Pair Data Fusion process. Pair: WPOL/DEUS (1%), Address: 0xB5cB765e44Eca4bc5a434fFaf6Bf7De235Bc60a5, Error: 'data'
[2025-06-01 05:26:34,484] 	ERROR 	63 	pair_data.py 	<module>() 	Error occurred during Pair Data Fusion process. Pair: WPOL/WBTC (0.3%), Address: 0x2981A1f699eA7149aa08121A07F000cf82846A9e, Error: 'data'
[2025-06-01 05:26:34,574] 	ERROR 	63 	pair_data.py 	<module>() 	Error occurred during Pair Data Fusion process. Pair: FRAX/STAR (0.05%), Address: 0x7D480cBf5Aee75E72eF26F223937f3981d67a860, Error: 'data'
[2025-06-01 05:26:34,665] 	ERROR 	63 	pair_data.py 	<module>() 	Error occurred during Pair Data Fusion process. Pair: CASH/TAROT (0.3%), Address: 0x217aEb0667b79584FBf6265B74a8cD22E1245fdC, Error: 'data'
[2025-06-01 05:26:34,755] 	ERROR 	63 	pair_data.py 	<module>() 	Error occurred during Pair Data Fusion process. Pair: CASH/fxDOLA (0.05%), Address: 0x4b4B895a0dD744B4893aA4370A8F7eDbde5Fd90e, Error: 'data'
[2025-06-01 05:26:34,843] 	ERROR 	63 	pair_data.py 	<module>() 	Error occurred during Pair Data Fusion process. Pair: RETRO/liveRetro (1%), Address: 0x6333BB8b6f1DDa6f929d70eDEB9e31c8148dC9ef, Error: 'data'
[2025-06-01 05:26:34,934] 	ERROR 	63 	pair_data.py 	<module>() 	Error occurred during Pair Data Fusion process. Pair: MVX/WETH (1%), Address: 0xCC72276de3BCc1b159F1B60A86B0211116022B42, Error: 'data'
[2025-06-01 05:26:35,023] 	ERROR 	63 	pair_data.py 	<module>() 	Error occurred during Pair Data Fusion process. Pair: WPOL/elRETRO (1%), Address: 0x6794Db07e2efE1307b8594FBbBFad78E50eC76fa, Error: 'data'
[2025-06-01 05:26:35,115] 	ERROR 	63 	pair_data.py 	<module>() 	Error occurred during Pair Data Fusion process. Pair: OATH/WETH (1%), Address: 0x0c74834d67c4bf5e6a44D18b2BAc767cddB4CdBf, Error: 'data'
[2025-06-01 05:26:35,210] 	ERROR 	63 	pair_data.py 	<module>() 	Error occurred during Pair Data Fusion process. Pair: USDC.e/IBEX (1%), Address: 0x53D8c25B3d130D2810591cDc7A41Bd848bF79B63, Error: 'data'
[2025-06-01 05:26:35,315] 	ERROR 	63 	pair_data.py 	<module>() 	Error occurred during Pair Data Fusion process. Pair: USDC.e/fxDOLA (0.3%), Address: 0x896ffE2cd28Ba13ddDa98103a3B66E82bb36BeE3, Error: 'data'
[2025-06-01 05:26:35,406] 	ERROR 	63 	pair_data.py 	<module>() 	Error occurred during Pair Data Fusion process. Pair: USDC.e/FRAX (0.3%), Address: 0x091236A16952BC9e4bB817FFA7aB40263183f658, Error: 'data'
[2025-06-01 05:26:35,500] 	ERROR 	63 	pair_data.py 	<module>() 	Error occurred during Pair Data Fusion process. Pair: WBTC/USDC.e (0.3%), Address: 0x459F42C788E6F8faCe4854DDD59C81a6Ad8BB1Aa, Error: 'data'
[2025-06-01 05:26:35,591] 	ERROR 	63 	pair_data.py 	<module>() 	Error occurred during Pair Data Fusion process. Pair: WETH/ERN (0.3%), Address: 0xCF2093da3CeBb8731747EEaCbd486A7fcE2Db901, Error: 'data'
[2025-06-01 05:26:35,685] 	ERROR 	63 	pair_data.py 	<module>() 	Error occurred during Pair Data Fusion process. Pair: WETH/JARVIS (0.3%), Address: 0xf310d505B85E0378790Af9fDB9b79b40736f7b4D, Error: 'data'
[2025-06-01 05:26:35,775] 	ERROR 	63 	pair_data.py 	<module>() 	Error occurred during Pair Data Fusion process. Pair: jEUR/CASH (0.05%), Address: 0x65E6b7C7DfE071E52D6923E4079E3C0FcBeaA401, Error: 'data'
[2025-06-01 05:26:35,870] 	ERROR 	63 	pair_data.py 	<module>() 	Error occurred during Pair Data Fusion process. Pair: USDC.e/USDC (0.01%), Address: 0x1e0aa3f6C3130294845B8e162d838e221d170016, Error: 'data'
[2025-06-01 05:26:35,961] 	ERROR 	63 	pair_data.py 	<module>() 	Error occurred during Pair Data Fusion process. Pair: LUCHA/WETH (1%), Address: 0x098c1e4BB34DEcDF49D5966014B5153Af326E766, Error: 'data'
[2025-06-01 05:26:36,053] 	ERROR 	63 	pair_data.py 	<module>() 	Error occurred during Pair Data Fusion process. Pair: WPOL/LUCHA (1%), Address: 0xde4C8898CD50EBE9C167313b312D147D10d1C898, Error: 'data'
[2025-06-01 05:26:36,141] 	ERROR 	63 	pair_data.py 	<module>() 	Error occurred during Pair Data Fusion process. Pair: LINK/LUCHA (1%), Address: 0xA97B2b9AcA65aab57A6b0840B45777bd66fbcf33, Error: 'data'
[2025-06-01 05:26:36,241] 	ERROR 	63 	pair_data.py 	<module>() 	Error occurred during Pair Data Fusion process. Pair: CASH/LUCHA (1%), Address: 0x5c09352B1aa703d18dbcF48c98655BFA19d07FBB, Error: 'data'
[2025-06-01 05:26:36,398] 	ERROR 	103 	pair_data.py 	<module>() 	Error occurred during Pair Data Fusion process. Error: 'date'
Traceback (most recent call last):
  File "/opt/hostedtoolcache/Python/3.8.18/x64/lib/python3.8/site-packages/pandas/core/indexes/base.py", line 3802, in get_loc
    return self._engine.get_loc(casted_key)
  File "pandas/_libs/index.pyx", line 138, in pandas._libs.index.IndexEngine.get_loc
  File "pandas/_libs/index.pyx", line 165, in pandas._libs.index.IndexEngine.get_loc
  File "pandas/_libs/hashtable_class_helper.pxi", line 5745, in pandas._libs.hashtable.PyObjectHashTable.get_item
  File "pandas/_libs/hashtable_class_helper.pxi", line 5753, in pandas._libs.hashtable.PyObjectHashTable.get_item
KeyError: 'date'

The above exception was the direct cause of the following exception:

Traceback (most recent call last):
  File "pair_data.py", line 68, in <module>
    pairdata_fusion_df["date"] = pairdata_fusion_df["date"].apply(lambda timestamp: datetime.utcfromtimestamp(timestamp).date())
  File "/opt/hostedtoolcache/Python/3.8.18/x64/lib/python3.8/site-packages/pandas/core/frame.py", line 3807, in __getitem__
    indexer = self.columns.get_loc(key)
  File "/opt/hostedtoolcache/Python/3.8.18/x64/lib/python3.8/site-packages/pandas/core/indexes/base.py", line 3804, in get_loc
    raise KeyError(key) from err
KeyError: 'date'
[2025-06-01 05:26:37,223] 	INFO 	36 	bribe_data.py 	<module>() 	Bribe Data Started
[2025-06-01 05:26:37,728] 	ERROR 	159 	bribe_data.py 	<module>() 	Error occurred during Bribe Data process. Error: 403 Client Error: Forbidden for url: https://rpc.ankr.com/polygon
Traceback (most recent call last):
  File "bribe_data.py", line 71, in <module>
    rewardsListLength = contract_instance.functions.rewardsListLength().call()
  File "/opt/hostedtoolcache/Python/3.8.18/x64/lib/python3.8/site-packages/web3/contract.py", line 970, in call
    return call_contract_function(
  File "/opt/hostedtoolcache/Python/3.8.18/x64/lib/python3.8/site-packages/web3/contract.py", line 1525, in call_contract_function
    return_data = web3.eth.call(
  File "/opt/hostedtoolcache/Python/3.8.18/x64/lib/python3.8/site-packages/web3/module.py", line 57, in caller
    result = w3.manager.request_blocking(method_str,
  File "/opt/hostedtoolcache/Python/3.8.18/x64/lib/python3.8/site-packages/web3/manager.py", line 197, in request_blocking
    response = self._make_request(method, params)
  File "/opt/hostedtoolcache/Python/3.8.18/x64/lib/python3.8/site-packages/web3/manager.py", line 150, in _make_request
    return request_func(method, params)
  File "/opt/hostedtoolcache/Python/3.8.18/x64/lib/python3.8/site-packages/web3/middleware/formatting.py", line 94, in middleware
    response = make_request(method, params)
  File "/opt/hostedtoolcache/Python/3.8.18/x64/lib/python3.8/site-packages/web3/middleware/gas_price_strategy.py", line 90, in middleware
    return make_request(method, params)
  File "/opt/hostedtoolcache/Python/3.8.18/x64/lib/python3.8/site-packages/web3/middleware/formatting.py", line 94, in middleware
    response = make_request(method, params)
  File "/opt/hostedtoolcache/Python/3.8.18/x64/lib/python3.8/site-packages/web3/middleware/attrdict.py", line 33, in middleware
    response = make_request(method, params)
  File "/opt/hostedtoolcache/Python/3.8.18/x64/lib/python3.8/site-packages/web3/middleware/formatting.py", line 94, in middleware
    response = make_request(method, params)
  File "/opt/hostedtoolcache/Python/3.8.18/x64/lib/python3.8/site-packages/web3/middleware/formatting.py", line 94, in middleware
    response = make_request(method, params)
  File "/opt/hostedtoolcache/Python/3.8.18/x64/lib/python3.8/site-packages/web3/middleware/formatting.py", line 94, in middleware
    response = make_request(method, params)
  File "/opt/hostedtoolcache/Python/3.8.18/x64/lib/python3.8/site-packages/web3/middleware/buffered_gas_estimate.py", line 40, in middleware
    return make_request(method, params)
  File "/opt/hostedtoolcache/Python/3.8.18/x64/lib/python3.8/site-packages/web3/middleware/exception_retry_request.py", line 105, in middleware
    return make_request(method, params)
  File "/opt/hostedtoolcache/Python/3.8.18/x64/lib/python3.8/site-packages/web3/providers/rpc.py", line 88, in make_request
    raw_response = make_post_request(
  File "/opt/hostedtoolcache/Python/3.8.18/x64/lib/python3.8/site-packages/web3/_utils/request.py", line 113, in make_post_request
    response.raise_for_status()
  File "/opt/hostedtoolcache/Python/3.8.18/x64/lib/python3.8/site-packages/requests/models.py", line 1021, in raise_for_status
    raise HTTPError(http_error_msg, response=self)
requests.exceptions.HTTPError: 403 Client Error: Forbidden for url: https://rpc.ankr.com/polygon
[2025-06-01 05:26:38,568] 	INFO 	36 	fee_data.py 	<module>() 	Fee Data Started
[2025-06-01 05:26:38,852] 	ERROR 	159 	fee_data.py 	<module>() 	Error occurred during Fee Data process. Error: 403 Client Error: Forbidden for url: https://rpc.ankr.com/polygon
Traceback (most recent call last):
  File "fee_data.py", line 71, in <module>
    rewardsListLength = contract_instance.functions.rewardsListLength().call()
  File "/opt/hostedtoolcache/Python/3.8.18/x64/lib/python3.8/site-packages/web3/contract.py", line 970, in call
    return call_contract_function(
  File "/opt/hostedtoolcache/Python/3.8.18/x64/lib/python3.8/site-packages/web3/contract.py", line 1525, in call_contract_function
    return_data = web3.eth.call(
  File "/opt/hostedtoolcache/Python/3.8.18/x64/lib/python3.8/site-packages/web3/module.py", line 57, in caller
    result = w3.manager.request_blocking(method_str,
  File "/opt/hostedtoolcache/Python/3.8.18/x64/lib/python3.8/site-packages/web3/manager.py", line 197, in request_blocking
    response = self._make_request(method, params)
  File "/opt/hostedtoolcache/Python/3.8.18/x64/lib/python3.8/site-packages/web3/manager.py", line 150, in _make_request
    return request_func(method, params)
  File "/opt/hostedtoolcache/Python/3.8.18/x64/lib/python3.8/site-packages/web3/middleware/formatting.py", line 94, in middleware
    response = make_request(method, params)
  File "/opt/hostedtoolcache/Python/3.8.18/x64/lib/python3.8/site-packages/web3/middleware/gas_price_strategy.py", line 90, in middleware
    return make_request(method, params)
  File "/opt/hostedtoolcache/Python/3.8.18/x64/lib/python3.8/site-packages/web3/middleware/formatting.py", line 94, in middleware
    response = make_request(method, params)
  File "/opt/hostedtoolcache/Python/3.8.18/x64/lib/python3.8/site-packages/web3/middleware/attrdict.py", line 33, in middleware
    response = make_request(method, params)
  File "/opt/hostedtoolcache/Python/3.8.18/x64/lib/python3.8/site-packages/web3/middleware/formatting.py", line 94, in middleware
    response = make_request(method, params)
  File "/opt/hostedtoolcache/Python/3.8.18/x64/lib/python3.8/site-packages/web3/middleware/formatting.py", line 94, in middleware
    response = make_request(method, params)
  File "/opt/hostedtoolcache/Python/3.8.18/x64/lib/python3.8/site-packages/web3/middleware/formatting.py", line 94, in middleware
    response = make_request(method, params)
  File "/opt/hostedtoolcache/Python/3.8.18/x64/lib/python3.8/site-packages/web3/middleware/buffered_gas_estimate.py", line 40, in middleware
    return make_request(method, params)
  File "/opt/hostedtoolcache/Python/3.8.18/x64/lib/python3.8/site-packages/web3/middleware/exception_retry_request.py", line 105, in middleware
    return make_request(method, params)
  File "/opt/hostedtoolcache/Python/3.8.18/x64/lib/python3.8/site-packages/web3/providers/rpc.py", line 88, in make_request
    raw_response = make_post_request(
  File "/opt/hostedtoolcache/Python/3.8.18/x64/lib/python3.8/site-packages/web3/_utils/request.py", line 113, in make_post_request
    response.raise_for_status()
  File "/opt/hostedtoolcache/Python/3.8.18/x64/lib/python3.8/site-packages/requests/models.py", line 1021, in raise_for_status
    raise HTTPError(http_error_msg, response=self)
requests.exceptions.HTTPError: 403 Client Error: Forbidden for url: https://rpc.ankr.com/polygon
[2025-06-01 05:26:39,689] 	INFO 	37 	vote_data.py 	<module>() 	Vote Data Started
[2025-06-01 05:26:59,410] 	ERROR 	118 	vote_data.py 	<module>() 	Error occurred during Vote Data process. Error: Expecting value: line 1 column 1 (char 0)
Traceback (most recent call last):
  File "/opt/hostedtoolcache/Python/3.8.18/x64/lib/python3.8/site-packages/requests/models.py", line 971, in json
    return complexjson.loads(self.text, **kwargs)
  File "/opt/hostedtoolcache/Python/3.8.18/x64/lib/python3.8/json/__init__.py", line 357, in loads
    return _default_decoder.decode(s)
  File "/opt/hostedtoolcache/Python/3.8.18/x64/lib/python3.8/json/decoder.py", line 337, in decode
    obj, end = self.raw_decode(s, idx=_w(s, 0).end())
  File "/opt/hostedtoolcache/Python/3.8.18/x64/lib/python3.8/json/decoder.py", line 355, in raw_decode
    raise JSONDecodeError("Expecting value", s, err.value) from None
json.decoder.JSONDecodeError: Expecting value: line 1 column 1 (char 0)

During handling of the above exception, another exception occurred:

Traceback (most recent call last):
  File "vote_data.py", line 64, in <module>
    RETRO_price = jmespath.search("data[?name == 'RETRO'].price", response.json())[0]
  File "/opt/hostedtoolcache/Python/3.8.18/x64/lib/python3.8/site-packages/requests/models.py", line 975, in json
    raise RequestsJSONDecodeError(e.msg, e.doc, e.pos)
requests.exceptions.JSONDecodeError: Expecting value: line 1 column 1 (char 0)
[2025-06-01 05:27:00,233] 	INFO 	30 	revenue_data.py 	<module>() 	Revenue Data Started
[2025-06-01 05:27:24,991] 	ERROR 	152 	revenue_data.py 	<module>() 	Error occurred during Revenue Data process. Error: Expecting value: line 1 column 1 (char 0)
Traceback (most recent call last):
  File "/opt/hostedtoolcache/Python/3.8.18/x64/lib/python3.8/site-packages/requests/models.py", line 971, in json
    return complexjson.loads(self.text, **kwargs)
  File "/opt/hostedtoolcache/Python/3.8.18/x64/lib/python3.8/json/__init__.py", line 357, in loads
    return _default_decoder.decode(s)
  File "/opt/hostedtoolcache/Python/3.8.18/x64/lib/python3.8/json/decoder.py", line 337, in decode
    obj, end = self.raw_decode(s, idx=_w(s, 0).end())
  File "/opt/hostedtoolcache/Python/3.8.18/x64/lib/python3.8/json/decoder.py", line 355, in raw_decode
    raise JSONDecodeError("Expecting value", s, err.value) from None
json.decoder.JSONDecodeError: Expecting value: line 1 column 1 (char 0)

During handling of the above exception, another exception occurred:

Traceback (most recent call last):
  File "revenue_data.py", line 66, in <module>
    RETRO_price = jmespath.search("data[?name == 'RETRO'].price", response.json())[0]
  File "/opt/hostedtoolcache/Python/3.8.18/x64/lib/python3.8/site-packages/requests/models.py", line 975, in json
    raise RequestsJSONDecodeError(e.msg, e.doc, e.pos)
requests.exceptions.JSONDecodeError: Expecting value: line 1 column 1 (char 0)
[2025-06-01 05:44:41,228] 	INFO 	20 	id_data.py 	<module>() 	ID Data Started
[2025-06-01 05:45:00,874] 	ERROR 	33 	id_data.py 	<module>() 	Error occurred during ID Data process. Error: Expecting value: line 1 column 1 (char 0)
Traceback (most recent call last):
  File "/opt/hostedtoolcache/Python/3.8.18/x64/lib/python3.8/site-packages/requests/models.py", line 971, in json
    return complexjson.loads(self.text, **kwargs)
  File "/opt/hostedtoolcache/Python/3.8.18/x64/lib/python3.8/json/__init__.py", line 357, in loads
    return _default_decoder.decode(s)
  File "/opt/hostedtoolcache/Python/3.8.18/x64/lib/python3.8/json/decoder.py", line 337, in decode
    obj, end = self.raw_decode(s, idx=_w(s, 0).end())
  File "/opt/hostedtoolcache/Python/3.8.18/x64/lib/python3.8/json/decoder.py", line 355, in raw_decode
    raise JSONDecodeError("Expecting value", s, err.value) from None
json.decoder.JSONDecodeError: Expecting value: line 1 column 1 (char 0)

During handling of the above exception, another exception occurred:

Traceback (most recent call last):
  File "id_data.py", line 27, in <module>
    data = response.json()["data"]
  File "/opt/hostedtoolcache/Python/3.8.18/x64/lib/python3.8/site-packages/requests/models.py", line 975, in json
    raise RequestsJSONDecodeError(e.msg, e.doc, e.pos)
requests.exceptions.JSONDecodeError: Expecting value: line 1 column 1 (char 0)
[2025-06-01 05:45:01,410] 	INFO 	24 	day_data.py 	<module>() 	Day Data Fusion Started
[2025-06-01 05:45:01,737] 	ERROR 	73 	day_data.py 	<module>() 	Error occurred during Day Data Fusion process. Error: 'data'
Traceback (most recent call last):
  File "day_data.py", line 41, in <module>
    data = response.json()["data"]["uniswapDayDatas"]
KeyError: 'data'
[2025-06-01 05:45:02,692] 	INFO 	35 	pair_data.py 	<module>() 	Pair Data Fusion Started
[2025-06-01 05:45:03,100] 	ERROR 	63 	pair_data.py 	<module>() 	Error occurred during Pair Data Fusion process. Pair: sAMM-USDC.e/USDT, Address: 0xB38245b7fE8D594d883A27DB1055bf67926F6B27, Error: 'data'
[2025-06-01 05:45:03,303] 	ERROR 	63 	pair_data.py 	<module>() 	Error occurred during Pair Data Fusion process. Pair: vAMM-WPOL/elRETRO, Address: 0x90a09fE272540Ecd34661B91252f2aB4b7f7A4CE, Error: 'data'
[2025-06-01 05:45:03,498] 	ERROR 	63 	pair_data.py 	<module>() 	Error occurred during Pair Data Fusion process. Pair: sAMM-oRETRO/elRETRO, Address: 0xc58Eb718892Da5D519587A3ec87063A8a46c9feb, Error: 'data'
[2025-06-01 05:45:03,674] 	ERROR 	63 	pair_data.py 	<module>() 	Error occurred during Pair Data Fusion process. Pair: WPOL/WETH (0.05%), Address: 0x1a34EaBbe928Bf431B679959379b2225d60D9cdA, Error: 'data'
[2025-06-01 05:45:03,849] 	ERROR 	63 	pair_data.py 	<module>() 	Error occurred during Pair Data Fusion process. Pair: WPOL/USDC.e (0.05%), Address: 0xEC15624FBB314eb05BaaD4cA49b7904C0Cb6b645, Error: 'data'
[2025-06-01 05:45:04,036] 	ERROR 	63 	pair_data.py 	<module>() 	Error occurred during Pair Data Fusion process. Pair: USDC.e/WETH (0.05%), Address: 0xCE67850420c82dB45eb7fEeCcD2d181300D2BDB3, Error: 'data'
[2025-06-01 05:45:04,212] 	ERROR 	63 	pair_data.py 	<module>() 	Error occurred during Pair Data Fusion process. Pair: WBTC/WETH (0.05%), Address: 0xb694E3bdd4BCdF843510983D257679D1E627C474, Error: 'data'
[2025-06-01 05:45:04,398] 	ERROR 	63 	pair_data.py 	<module>() 	Error occurred during Pair Data Fusion process. Pair: WPOL/USDT (0.05%), Address: 0xB580229645b240A368768ec3E88cb67A41eBBC5B, Error: 'data'
[2025-06-01 05:45:04,586] 	ERROR 	63 	pair_data.py 	<module>() 	Error occurred during Pair Data Fusion process. Pair: WPOL/CASH (0.05%), Address: 0x63ca6ED3D390C725b7FEb617BAdcab78a61038E8, Error: 'data'
[2025-06-01 05:45:04,761] 	ERROR 	63 	pair_data.py 	<module>() 	Error occurred during Pair Data Fusion process. Pair: CASH/WETH (0.05%), Address: 0x0A46B0712974F201BeD15c2458a023EbED25eF4F, Error: 'data'
[2025-06-01 05:45:04,951] 	ERROR 	63 	pair_data.py 	<module>() 	Error occurred during Pair Data Fusion process. Pair: USDC.e/CASH (0.01%), Address: 0x619259F699839dD1498FFC22297044462483bD27, Error: 'data'
[2025-06-01 05:45:05,127] 	ERROR 	63 	pair_data.py 	<module>() 	Error occurred during Pair Data Fusion process. Pair: CASH/USDT (0.01%), Address: 0x160FBF00AB5fbF0200c0Cd4929aEaa2AdD25FB5b, Error: 'data'
[2025-06-01 05:45:05,310] 	ERROR 	63 	pair_data.py 	<module>() 	Error occurred during Pair Data Fusion process. Pair: CASH/DAI (0.01%), Address: 0x1e683586fCB45a769ef2C7d9d7b1803E9C1AEE79, Error: 'data'
[2025-06-01 05:45:05,483] 	ERROR 	63 	pair_data.py 	<module>() 	Error occurred during Pair Data Fusion process. Pair: CASH/miMATIC (0.01%), Address: 0xeB80047F7d5D4C4A3BC6319250d6b1b8aEe2d0D2, Error: 'data'
[2025-06-01 05:45:05,661] 	ERROR 	63 	pair_data.py 	<module>() 	Error occurred during Pair Data Fusion process. Pair: CASH/MaticX (0.05%), Address: 0xb98F8DF0DC6750A3e54540A1e094186C8bED780a, Error: 'data'
[2025-06-01 05:45:05,845] 	ERROR 	63 	pair_data.py 	<module>() 	Error occurred during Pair Data Fusion process. Pair: USDC.e/EURA (0.05%), Address: 0xC2CB03a819F785bD8eb8D628BAD41Cd7c1C71F4B, Error: 'data'
[2025-06-01 05:45:06,038] 	ERROR 	63 	pair_data.py 	<module>() 	Error occurred during Pair Data Fusion process. Pair: FRAX/CASH (0.01%), Address: 0x72289129Dc4937a5d406d1ECeD8b2A17d007A650, Error: 'data'
[2025-06-01 05:45:06,236] 	ERROR 	63 	pair_data.py 	<module>() 	Error occurred during Pair Data Fusion process. Pair: CASH/RETRO (1%), Address: 0xb47A07966cE6812702C0567d03725F1b37E27877, Error: 'data'
[2025-06-01 05:45:06,424] 	ERROR 	63 	pair_data.py 	<module>() 	Error occurred during Pair Data Fusion process. Pair: WETH/RETRO (1%), Address: 0x35394eED0Be676ec6470fE6531daD809265310ff, Error: 'data'
[2025-06-01 05:45:06,609] 	ERROR 	63 	pair_data.py 	<module>() 	Error occurred during Pair Data Fusion process. Pair: WPOL/RETRO (1%), Address: 0x547FD24AA2ED09d86dAC02E36b8Ce84A59fD644F, Error: 'data'
[2025-06-01 05:45:06,801] 	ERROR 	63 	pair_data.py 	<module>() 	Error occurred during Pair Data Fusion process. Pair: WBTC/RETRO (1%), Address: 0x0F73E719a76947752E4b26A2c3FC80a580e68fB4, Error: 'data'
[2025-06-01 05:45:06,995] 	ERROR 	63 	pair_data.py 	<module>() 	Error occurred during Pair Data Fusion process. Pair: stMATIC/RETRO (1%), Address: 0x0973698BB6399c39d628698f9300430C4e7c9bf9, Error: 'data'
[2025-06-01 05:45:07,179] 	ERROR 	63 	pair_data.py 	<module>() 	Error occurred during Pair Data Fusion process. Pair: USDC.e/RETRO (1%), Address: 0xc7d8B9c270D0E31A6a0Cf4496fe019766Be42E15, Error: 'data'
[2025-06-01 05:45:07,356] 	ERROR 	63 	pair_data.py 	<module>() 	Error occurred during Pair Data Fusion process. Pair: RETRO/USDT (1%), Address: 0x69dCAE97A1286B112a8BD75bD9147bD0a3207756, Error: 'data'
[2025-06-01 05:45:07,547] 	ERROR 	63 	pair_data.py 	<module>() 	Error occurred during Pair Data Fusion process. Pair: miMATIC/RETRO (1%), Address: 0xd98eEf295f78ddDd104a8645854C7F8714B39B88, Error: 'data'
[2025-06-01 05:45:07,732] 	ERROR 	63 	pair_data.py 	<module>() 	Error occurred during Pair Data Fusion process. Pair: LINK/RETRO (1%), Address: 0x7761c7233924C3D72F27Fae6a81B074C0152e03a, Error: 'data'
[2025-06-01 05:45:07,951] 	ERROR 	63 	pair_data.py 	<module>() 	Error occurred during Pair Data Fusion process. Pair: RETRO/EURA (1%), Address: 0x15949526fF03fE6ab5f49dA6a86749c20141b3f1, Error: 'data'
[2025-06-01 05:45:08,144] 	ERROR 	63 	pair_data.py 	<module>() 	Error occurred during Pair Data Fusion process. Pair: USDC.e/USDT (0.01%), Address: 0x772510189425ac63f9a5A5eF2fd0C7FDA58CBFC7, Error: 'data'
[2025-06-01 05:45:08,322] 	ERROR 	63 	pair_data.py 	<module>() 	Error occurred during Pair Data Fusion process. Pair: USDC.e/DAI (0.01%), Address: 0x219116F23BDC11EB25e4D0FbE92eD0972d86BE20, Error: 'data'
[2025-06-01 05:45:08,511] 	ERROR 	63 	pair_data.py 	<module>() 	Error occurred during Pair Data Fusion process. Pair: WPOL/MaticX (0.01%), Address: 0x9aa18301055091e9da7C57b81633632Fa33B9a80, Error: 'data'
[2025-06-01 05:45:08,693] 	ERROR 	63 	pair_data.py 	<module>() 	Error occurred during Pair Data Fusion process. Pair: wstETH/WETH (0.01%), Address: 0xa9439Db1D7025Ce4aAc513Baf5eee5220172126C, Error: 'data'
[2025-06-01 05:45:08,874] 	ERROR 	63 	pair_data.py 	<module>() 	Error occurred during Pair Data Fusion process. Pair: WPOL/stMATIC (0.01%), Address: 0x2d623c33673248E95C7a1C26aE7065eb7A7Ac0Ea, Error: 'data'
[2025-06-01 05:45:09,049] 	ERROR 	63 	pair_data.py 	<module>() 	Error occurred during Pair Data Fusion process. Pair: WETH/frxETH (0.01%), Address: 0xe5069a75Bdfe8F676B778B0aaDCcC597841F819B, Error: 'data'
[2025-06-01 05:45:09,227] 	ERROR 	63 	pair_data.py 	<module>() 	Error occurred during Pair Data Fusion process. Pair: FRAX/frxETH (0.05%), Address: 0x38df0c93bf69a9EfB3d3647fF459eF27235A8968, Error: 'data'
[2025-06-01 05:45:09,408] 	ERROR 	63 	pair_data.py 	<module>() 	Error occurred during Pair Data Fusion process. Pair: WPOL/frxETH (0.05%), Address: 0x44AAE81BE8435b6998A66d9642f66DE57DD03FC2, Error: 'data'
[2025-06-01 05:45:09,585] 	ERROR 	63 	pair_data.py 	<module>() 	Error occurred during Pair Data Fusion process. Pair: xbb-t-USD/CASH (0.01%), Address: 0x07dBf448cCC68cA64247da04F2E24643eCf57385, Error: 'data'
[2025-06-01 05:45:09,762] 	ERROR 	63 	pair_data.py 	<module>() 	Error occurred during Pair Data Fusion process. Pair: LINK/LUCHA (0.3%), Address: 0x91248C85DD408BD216254C3cFb51fc326290cF7e, Error: 'data'
[2025-06-01 05:45:09,927] 	ERROR 	63 	pair_data.py 	<module>() 	Error occurred during Pair Data Fusion process. Pair: CASH/LUCHA (0.3%), Address: 0xc666c4b402Bd797185EA419261D22a8f22DDFce6, Error: 'data'
[2025-06-01 05:45:10,106] 	ERROR 	63 	pair_data.py 	<module>() 	Error occurred during Pair Data Fusion process. Pair: USDC.e/miMATIC (0.3%), Address: 0xb090BE2D2F02646057d4DF997A7A983dFb265de0, Error: 'data'
[2025-06-01 05:45:10,279] 	ERROR 	63 	pair_data.py 	<module>() 	Error occurred during Pair Data Fusion process. Pair: FRAX/miMATIC (0.3%), Address: 0xdeB25Dd2d5D168Fd6f80F154d96a2Dab81d61845, Error: 'data'
[2025-06-01 05:45:10,453] 	ERROR 	63 	pair_data.py 	<module>() 	Error occurred during Pair Data Fusion process. Pair: WPOL/miMATIC (0.3%), Address: 0xC571445Fc93666e1E4FaE2E84A7b74FE6ed3978D, Error: 'data'
[2025-06-01 05:45:10,646] 	ERROR 	63 	pair_data.py 	<module>() 	Error occurred during Pair Data Fusion process. Pair: CASH/ERN (0.3%), Address: 0x777a87889f42C33f9A1E5c117774694bbd857075, Error: 'data'
[2025-06-01 05:45:10,823] 	ERROR 	63 	pair_data.py 	<module>() 	Error occurred during Pair Data Fusion process. Pair: ICHI/RETRO (1%), Address: 0xC26E1a0cDab4Bf5141530C49F3360f162C5Db5Db, Error: 'data'
[2025-06-01 05:45:11,020] 	ERROR 	63 	pair_data.py 	<module>() 	Error occurred during Pair Data Fusion process. Pair: WPOL/ICHI (0.3%), Address: 0x13d5e61838D93F7962C52dc921FD7C0Ccc092E35, Error: 'data'
[2025-06-01 05:45:11,208] 	ERROR 	63 	pair_data.py 	<module>() 	Error occurred during Pair Data Fusion process. Pair: SD/MaticX (0.3%), Address: 0xB97c62834e096858BD0B996b758942dd43d7B5eE, Error: 'data'
[2025-06-01 05:45:11,391] 	ERROR 	63 	pair_data.py 	<module>() 	Error occurred during Pair Data Fusion process. Pair: stERN/ERN (1%), Address: 0x99583057951987beD85CE6934473160bFD4921b9, Error: 'data'
[2025-06-01 05:45:11,572] 	ERROR 	63 	pair_data.py 	<module>() 	Error occurred during Pair Data Fusion process. Pair: tUSDC/STAR (0.05%), Address: 0x53C49b9308c3DB176d351d7914Cec0Fb5D7f1129, Error: 'data'
[2025-06-01 05:45:11,759] 	ERROR 	63 	pair_data.py 	<module>() 	Error occurred during Pair Data Fusion process. Pair: WPOL/LUCHA (0.3%), Address: 0x52BeedA850A7048e9D543668BF54E0d9E1B667E0, Error: 'data'
[2025-06-01 05:45:11,940] 	ERROR 	63 	pair_data.py 	<module>() 	Error occurred during Pair Data Fusion process. Pair: LUCHA/WETH (0.3%), Address: 0x13136EA148331a07497087bfc31fBCcD9b99123c, Error: 'data'
[2025-06-01 05:45:12,127] 	ERROR 	63 	pair_data.py 	<module>() 	Error occurred during Pair Data Fusion process. Pair: JRT/WETH (0.3%), Address: 0xAE107e52ebdF151E61d9Fb4Bd800C86c31741465, Error: 'data'
[2025-06-01 05:45:12,307] 	ERROR 	63 	pair_data.py 	<module>() 	Error occurred during Pair Data Fusion process. Pair: axlLqdr/CASH (0.3%), Address: 0x22c10e61A05a03bcd8BF61a7E648f2330ecdA270, Error: 'data'
[2025-06-01 05:45:12,493] 	ERROR 	63 	pair_data.py 	<module>() 	Error occurred during Pair Data Fusion process. Pair: XOC/jMXN (0.01%), Address: 0xccE01e3615785771b84Eb5F88EC612AC6704FdE2, Error: 'data'
[2025-06-01 05:45:12,665] 	ERROR 	63 	pair_data.py 	<module>() 	Error occurred during Pair Data Fusion process. Pair: ICHI/CASH (1%), Address: 0x8ceD58A2dE3C2ea5D3cED3eb4331158c8cf985Fb, Error: 'data'
[2025-06-01 05:45:12,841] 	ERROR 	63 	pair_data.py 	<module>() 	Error occurred during Pair Data Fusion process. Pair: wUSDR/CASH (0.3%), Address: 0x3baEa49B71461DEaB46E6F42548D0005359ff629, Error: 'data'
[2025-06-01 05:45:13,016] 	ERROR 	63 	pair_data.py 	<module>() 	Error occurred during Pair Data Fusion process. Pair: CASH/STAR (0.05%), Address: 0x88C522E526E5Eea8d636fd6805cA7fEB488780D0, Error: 'data'
[2025-06-01 05:45:13,189] 	ERROR 	63 	pair_data.py 	<module>() 	Error occurred during Pair Data Fusion process. Pair: USDC.e/STAR (0.01%), Address: 0x6De0CA91Ef19A6ce9f02A423ae2dF89Fe09Bff0F, Error: 'data'
[2025-06-01 05:45:13,363] 	ERROR 	63 	pair_data.py 	<module>() 	Error occurred during Pair Data Fusion process. Pair: tUSDC/STAR (1%), Address: 0xaC44f57eEF260eB6E0f896b61984Da8d86FeE9ed, Error: 'data'
[2025-06-01 05:45:13,543] 	ERROR 	63 	pair_data.py 	<module>() 	Error occurred during Pair Data Fusion process. Pair: tUSDC/CASH (1%), Address: 0x4FcdB2DCc4Ce156c723aD541dba8B39d47284FC5, Error: 'data'
[2025-06-01 05:45:13,723] 	ERROR 	63 	pair_data.py 	<module>() 	Error occurred during Pair Data Fusion process. Pair: WPOL/USDC.e (0.3%), Address: 0x8c862d100B94d95a49D91958c9e8C2c348d00F04, Error: 'data'
[2025-06-01 05:45:13,914] 	ERROR 	63 	pair_data.py 	<module>() 	Error occurred during Pair Data Fusion process. Pair: WPOL/WETH (0.3%), Address: 0xB8dD18F9b7C3Ad4bDd4B94cB819eda3bd4465119, Error: 'data'
[2025-06-01 05:45:14,102] 	ERROR 	63 	pair_data.py 	<module>() 	Error occurred during Pair Data Fusion process. Pair: USDC.e/WETH (0.3%), Address: 0x058F5330Fef74445878110e201B04F36f8a51c9b, Error: 'data'
[2025-06-01 05:45:14,272] 	ERROR 	63 	pair_data.py 	<module>() 	Error occurred during Pair Data Fusion process. Pair: WBTC/WETH (0.3%), Address: 0x11275C625A7DEE3532E062Eef6915f00af85C3B5, Error: 'data'
[2025-06-01 05:45:14,451] 	ERROR 	63 	pair_data.py 	<module>() 	Error occurred during Pair Data Fusion process. Pair: LINK/WETH (0.3%), Address: 0x555eABEEfe6a047747071525A2c0fFd96d945f69, Error: 'data'
[2025-06-01 05:45:14,637] 	ERROR 	63 	pair_data.py 	<module>() 	Error occurred during Pair Data Fusion process. Pair: WBTC/CASH (0.3%), Address: 0x2C8F7d92Dc7A414D343CbFB687E31a11F525d29e, Error: 'data'
[2025-06-01 05:45:14,814] 	ERROR 	63 	pair_data.py 	<module>() 	Error occurred during Pair Data Fusion process. Pair: WPOL/DEUS (1%), Address: 0xB5cB765e44Eca4bc5a434fFaf6Bf7De235Bc60a5, Error: 'data'
[2025-06-01 05:45:14,988] 	ERROR 	63 	pair_data.py 	<module>() 	Error occurred during Pair Data Fusion process. Pair: WPOL/WBTC (0.3%), Address: 0x2981A1f699eA7149aa08121A07F000cf82846A9e, Error: 'data'
[2025-06-01 05:45:15,175] 	ERROR 	63 	pair_data.py 	<module>() 	Error occurred during Pair Data Fusion process. Pair: FRAX/STAR (0.05%), Address: 0x7D480cBf5Aee75E72eF26F223937f3981d67a860, Error: 'data'
[2025-06-01 05:45:15,348] 	ERROR 	63 	pair_data.py 	<module>() 	Error occurred during Pair Data Fusion process. Pair: CASH/TAROT (0.3%), Address: 0x217aEb0667b79584FBf6265B74a8cD22E1245fdC, Error: 'data'
[2025-06-01 05:45:15,523] 	ERROR 	63 	pair_data.py 	<module>() 	Error occurred during Pair Data Fusion process. Pair: CASH/fxDOLA (0.05%), Address: 0x4b4B895a0dD744B4893aA4370A8F7eDbde5Fd90e, Error: 'data'
[2025-06-01 05:45:15,727] 	ERROR 	63 	pair_data.py 	<module>() 	Error occurred during Pair Data Fusion process. Pair: RETRO/liveRetro (1%), Address: 0x6333BB8b6f1DDa6f929d70eDEB9e31c8148dC9ef, Error: 'data'
[2025-06-01 05:45:15,895] 	ERROR 	63 	pair_data.py 	<module>() 	Error occurred during Pair Data Fusion process. Pair: MVX/WETH (1%), Address: 0xCC72276de3BCc1b159F1B60A86B0211116022B42, Error: 'data'
[2025-06-01 05:45:16,077] 	ERROR 	63 	pair_data.py 	<module>() 	Error occurred during Pair Data Fusion process. Pair: WPOL/elRETRO (1%), Address: 0x6794Db07e2efE1307b8594FBbBFad78E50eC76fa, Error: 'data'
[2025-06-01 05:45:16,259] 	ERROR 	63 	pair_data.py 	<module>() 	Error occurred during Pair Data Fusion process. Pair: OATH/WETH (1%), Address: 0x0c74834d67c4bf5e6a44D18b2BAc767cddB4CdBf, Error: 'data'
[2025-06-01 05:45:16,435] 	ERROR 	63 	pair_data.py 	<module>() 	Error occurred during Pair Data Fusion process. Pair: USDC.e/IBEX (1%), Address: 0x53D8c25B3d130D2810591cDc7A41Bd848bF79B63, Error: 'data'
[2025-06-01 05:45:16,612] 	ERROR 	63 	pair_data.py 	<module>() 	Error occurred during Pair Data Fusion process. Pair: USDC.e/fxDOLA (0.3%), Address: 0x896ffE2cd28Ba13ddDa98103a3B66E82bb36BeE3, Error: 'data'
[2025-06-01 05:45:16,790] 	ERROR 	63 	pair_data.py 	<module>() 	Error occurred during Pair Data Fusion process. Pair: USDC.e/FRAX (0.3%), Address: 0x091236A16952BC9e4bB817FFA7aB40263183f658, Error: 'data'
[2025-06-01 05:45:16,967] 	ERROR 	63 	pair_data.py 	<module>() 	Error occurred during Pair Data Fusion process. Pair: WBTC/USDC.e (0.3%), Address: 0x459F42C788E6F8faCe4854DDD59C81a6Ad8BB1Aa, Error: 'data'
[2025-06-01 05:45:17,137] 	ERROR 	63 	pair_data.py 	<module>() 	Error occurred during Pair Data Fusion process. Pair: WETH/ERN (0.3%), Address: 0xCF2093da3CeBb8731747EEaCbd486A7fcE2Db901, Error: 'data'
[2025-06-01 05:45:17,326] 	ERROR 	63 	pair_data.py 	<module>() 	Error occurred during Pair Data Fusion process. Pair: WETH/JARVIS (0.3%), Address: 0xf310d505B85E0378790Af9fDB9b79b40736f7b4D, Error: 'data'
[2025-06-01 05:45:17,504] 	ERROR 	63 	pair_data.py 	<module>() 	Error occurred during Pair Data Fusion process. Pair: jEUR/CASH (0.05%), Address: 0x65E6b7C7DfE071E52D6923E4079E3C0FcBeaA401, Error: 'data'
[2025-06-01 05:45:17,692] 	ERROR 	63 	pair_data.py 	<module>() 	Error occurred during Pair Data Fusion process. Pair: USDC.e/USDC (0.01%), Address: 0x1e0aa3f6C3130294845B8e162d838e221d170016, Error: 'data'
[2025-06-01 05:45:17,867] 	ERROR 	63 	pair_data.py 	<module>() 	Error occurred during Pair Data Fusion process. Pair: LUCHA/WETH (1%), Address: 0x098c1e4BB34DEcDF49D5966014B5153Af326E766, Error: 'data'
[2025-06-01 05:45:18,051] 	ERROR 	63 	pair_data.py 	<module>() 	Error occurred during Pair Data Fusion process. Pair: WPOL/LUCHA (1%), Address: 0xde4C8898CD50EBE9C167313b312D147D10d1C898, Error: 'data'
[2025-06-01 05:45:18,231] 	ERROR 	63 	pair_data.py 	<module>() 	Error occurred during Pair Data Fusion process. Pair: LINK/LUCHA (1%), Address: 0xA97B2b9AcA65aab57A6b0840B45777bd66fbcf33, Error: 'data'
[2025-06-01 05:45:18,406] 	ERROR 	63 	pair_data.py 	<module>() 	Error occurred during Pair Data Fusion process. Pair: CASH/LUCHA (1%), Address: 0x5c09352B1aa703d18dbcF48c98655BFA19d07FBB, Error: 'data'
[2025-06-01 05:45:18,609] 	ERROR 	103 	pair_data.py 	<module>() 	Error occurred during Pair Data Fusion process. Error: 'date'
Traceback (most recent call last):
  File "/opt/hostedtoolcache/Python/3.8.18/x64/lib/python3.8/site-packages/pandas/core/indexes/base.py", line 3802, in get_loc
    return self._engine.get_loc(casted_key)
  File "pandas/_libs/index.pyx", line 138, in pandas._libs.index.IndexEngine.get_loc
  File "pandas/_libs/index.pyx", line 165, in pandas._libs.index.IndexEngine.get_loc
  File "pandas/_libs/hashtable_class_helper.pxi", line 5745, in pandas._libs.hashtable.PyObjectHashTable.get_item
  File "pandas/_libs/hashtable_class_helper.pxi", line 5753, in pandas._libs.hashtable.PyObjectHashTable.get_item
KeyError: 'date'

The above exception was the direct cause of the following exception:

Traceback (most recent call last):
  File "pair_data.py", line 68, in <module>
    pairdata_fusion_df["date"] = pairdata_fusion_df["date"].apply(lambda timestamp: datetime.utcfromtimestamp(timestamp).date())
  File "/opt/hostedtoolcache/Python/3.8.18/x64/lib/python3.8/site-packages/pandas/core/frame.py", line 3807, in __getitem__
    indexer = self.columns.get_loc(key)
  File "/opt/hostedtoolcache/Python/3.8.18/x64/lib/python3.8/site-packages/pandas/core/indexes/base.py", line 3804, in get_loc
    raise KeyError(key) from err
KeyError: 'date'
[2025-06-01 05:45:19,472] 	INFO 	36 	bribe_data.py 	<module>() 	Bribe Data Started
[2025-06-01 05:45:20,217] 	ERROR 	159 	bribe_data.py 	<module>() 	Error occurred during Bribe Data process. Error: 403 Client Error: Forbidden for url: https://rpc.ankr.com/polygon
Traceback (most recent call last):
  File "bribe_data.py", line 71, in <module>
    rewardsListLength = contract_instance.functions.rewardsListLength().call()
  File "/opt/hostedtoolcache/Python/3.8.18/x64/lib/python3.8/site-packages/web3/contract.py", line 970, in call
    return call_contract_function(
  File "/opt/hostedtoolcache/Python/3.8.18/x64/lib/python3.8/site-packages/web3/contract.py", line 1525, in call_contract_function
    return_data = web3.eth.call(
  File "/opt/hostedtoolcache/Python/3.8.18/x64/lib/python3.8/site-packages/web3/module.py", line 57, in caller
    result = w3.manager.request_blocking(method_str,
  File "/opt/hostedtoolcache/Python/3.8.18/x64/lib/python3.8/site-packages/web3/manager.py", line 197, in request_blocking
    response = self._make_request(method, params)
  File "/opt/hostedtoolcache/Python/3.8.18/x64/lib/python3.8/site-packages/web3/manager.py", line 150, in _make_request
    return request_func(method, params)
  File "/opt/hostedtoolcache/Python/3.8.18/x64/lib/python3.8/site-packages/web3/middleware/formatting.py", line 94, in middleware
    response = make_request(method, params)
  File "/opt/hostedtoolcache/Python/3.8.18/x64/lib/python3.8/site-packages/web3/middleware/gas_price_strategy.py", line 90, in middleware
    return make_request(method, params)
  File "/opt/hostedtoolcache/Python/3.8.18/x64/lib/python3.8/site-packages/web3/middleware/formatting.py", line 94, in middleware
    response = make_request(method, params)
  File "/opt/hostedtoolcache/Python/3.8.18/x64/lib/python3.8/site-packages/web3/middleware/attrdict.py", line 33, in middleware
    response = make_request(method, params)
  File "/opt/hostedtoolcache/Python/3.8.18/x64/lib/python3.8/site-packages/web3/middleware/formatting.py", line 94, in middleware
    response = make_request(method, params)
  File "/opt/hostedtoolcache/Python/3.8.18/x64/lib/python3.8/site-packages/web3/middleware/formatting.py", line 94, in middleware
    response = make_request(method, params)
  File "/opt/hostedtoolcache/Python/3.8.18/x64/lib/python3.8/site-packages/web3/middleware/formatting.py", line 94, in middleware
    response = make_request(method, params)
  File "/opt/hostedtoolcache/Python/3.8.18/x64/lib/python3.8/site-packages/web3/middleware/buffered_gas_estimate.py", line 40, in middleware
    return make_request(method, params)
  File "/opt/hostedtoolcache/Python/3.8.18/x64/lib/python3.8/site-packages/web3/middleware/exception_retry_request.py", line 105, in middleware
    return make_request(method, params)
  File "/opt/hostedtoolcache/Python/3.8.18/x64/lib/python3.8/site-packages/web3/providers/rpc.py", line 88, in make_request
    raw_response = make_post_request(
  File "/opt/hostedtoolcache/Python/3.8.18/x64/lib/python3.8/site-packages/web3/_utils/request.py", line 113, in make_post_request
    response.raise_for_status()
  File "/opt/hostedtoolcache/Python/3.8.18/x64/lib/python3.8/site-packages/requests/models.py", line 1021, in raise_for_status
    raise HTTPError(http_error_msg, response=self)
requests.exceptions.HTTPError: 403 Client Error: Forbidden for url: https://rpc.ankr.com/polygon
[2025-06-01 05:45:21,087] 	INFO 	36 	fee_data.py 	<module>() 	Fee Data Started
[2025-06-01 05:45:21,605] 	ERROR 	159 	fee_data.py 	<module>() 	Error occurred during Fee Data process. Error: 403 Client Error: Forbidden for url: https://rpc.ankr.com/polygon
Traceback (most recent call last):
  File "fee_data.py", line 71, in <module>
    rewardsListLength = contract_instance.functions.rewardsListLength().call()
  File "/opt/hostedtoolcache/Python/3.8.18/x64/lib/python3.8/site-packages/web3/contract.py", line 970, in call
    return call_contract_function(
  File "/opt/hostedtoolcache/Python/3.8.18/x64/lib/python3.8/site-packages/web3/contract.py", line 1525, in call_contract_function
    return_data = web3.eth.call(
  File "/opt/hostedtoolcache/Python/3.8.18/x64/lib/python3.8/site-packages/web3/module.py", line 57, in caller
    result = w3.manager.request_blocking(method_str,
  File "/opt/hostedtoolcache/Python/3.8.18/x64/lib/python3.8/site-packages/web3/manager.py", line 197, in request_blocking
    response = self._make_request(method, params)
  File "/opt/hostedtoolcache/Python/3.8.18/x64/lib/python3.8/site-packages/web3/manager.py", line 150, in _make_request
    return request_func(method, params)
  File "/opt/hostedtoolcache/Python/3.8.18/x64/lib/python3.8/site-packages/web3/middleware/formatting.py", line 94, in middleware
    response = make_request(method, params)
  File "/opt/hostedtoolcache/Python/3.8.18/x64/lib/python3.8/site-packages/web3/middleware/gas_price_strategy.py", line 90, in middleware
    return make_request(method, params)
  File "/opt/hostedtoolcache/Python/3.8.18/x64/lib/python3.8/site-packages/web3/middleware/formatting.py", line 94, in middleware
    response = make_request(method, params)
  File "/opt/hostedtoolcache/Python/3.8.18/x64/lib/python3.8/site-packages/web3/middleware/attrdict.py", line 33, in middleware
    response = make_request(method, params)
  File "/opt/hostedtoolcache/Python/3.8.18/x64/lib/python3.8/site-packages/web3/middleware/formatting.py", line 94, in middleware
    response = make_request(method, params)
  File "/opt/hostedtoolcache/Python/3.8.18/x64/lib/python3.8/site-packages/web3/middleware/formatting.py", line 94, in middleware
    response = make_request(method, params)
  File "/opt/hostedtoolcache/Python/3.8.18/x64/lib/python3.8/site-packages/web3/middleware/formatting.py", line 94, in middleware
    response = make_request(method, params)
  File "/opt/hostedtoolcache/Python/3.8.18/x64/lib/python3.8/site-packages/web3/middleware/buffered_gas_estimate.py", line 40, in middleware
    return make_request(method, params)
  File "/opt/hostedtoolcache/Python/3.8.18/x64/lib/python3.8/site-packages/web3/middleware/exception_retry_request.py", line 105, in middleware
    return make_request(method, params)
  File "/opt/hostedtoolcache/Python/3.8.18/x64/lib/python3.8/site-packages/web3/providers/rpc.py", line 88, in make_request
    raw_response = make_post_request(
  File "/opt/hostedtoolcache/Python/3.8.18/x64/lib/python3.8/site-packages/web3/_utils/request.py", line 113, in make_post_request
    response.raise_for_status()
  File "/opt/hostedtoolcache/Python/3.8.18/x64/lib/python3.8/site-packages/requests/models.py", line 1021, in raise_for_status
    raise HTTPError(http_error_msg, response=self)
requests.exceptions.HTTPError: 403 Client Error: Forbidden for url: https://rpc.ankr.com/polygon
[2025-06-01 05:45:22,484] 	INFO 	37 	vote_data.py 	<module>() 	Vote Data Started
[2025-06-01 05:45:42,238] 	ERROR 	118 	vote_data.py 	<module>() 	Error occurred during Vote Data process. Error: Expecting value: line 1 column 1 (char 0)
Traceback (most recent call last):
  File "/opt/hostedtoolcache/Python/3.8.18/x64/lib/python3.8/site-packages/requests/models.py", line 971, in json
    return complexjson.loads(self.text, **kwargs)
  File "/opt/hostedtoolcache/Python/3.8.18/x64/lib/python3.8/json/__init__.py", line 357, in loads
    return _default_decoder.decode(s)
  File "/opt/hostedtoolcache/Python/3.8.18/x64/lib/python3.8/json/decoder.py", line 337, in decode
    obj, end = self.raw_decode(s, idx=_w(s, 0).end())
  File "/opt/hostedtoolcache/Python/3.8.18/x64/lib/python3.8/json/decoder.py", line 355, in raw_decode
    raise JSONDecodeError("Expecting value", s, err.value) from None
json.decoder.JSONDecodeError: Expecting value: line 1 column 1 (char 0)

During handling of the above exception, another exception occurred:

Traceback (most recent call last):
  File "vote_data.py", line 64, in <module>
    RETRO_price = jmespath.search("data[?name == 'RETRO'].price", response.json())[0]
  File "/opt/hostedtoolcache/Python/3.8.18/x64/lib/python3.8/site-packages/requests/models.py", line 975, in json
    raise RequestsJSONDecodeError(e.msg, e.doc, e.pos)
requests.exceptions.JSONDecodeError: Expecting value: line 1 column 1 (char 0)
[2025-06-01 05:45:43,094] 	INFO 	30 	revenue_data.py 	<module>() 	Revenue Data Started
[2025-06-01 05:46:08,862] 	ERROR 	152 	revenue_data.py 	<module>() 	Error occurred during Revenue Data process. Error: Expecting value: line 1 column 1 (char 0)
Traceback (most recent call last):
  File "/opt/hostedtoolcache/Python/3.8.18/x64/lib/python3.8/site-packages/requests/models.py", line 971, in json
    return complexjson.loads(self.text, **kwargs)
  File "/opt/hostedtoolcache/Python/3.8.18/x64/lib/python3.8/json/__init__.py", line 357, in loads
    return _default_decoder.decode(s)
  File "/opt/hostedtoolcache/Python/3.8.18/x64/lib/python3.8/json/decoder.py", line 337, in decode
    obj, end = self.raw_decode(s, idx=_w(s, 0).end())
  File "/opt/hostedtoolcache/Python/3.8.18/x64/lib/python3.8/json/decoder.py", line 355, in raw_decode
    raise JSONDecodeError("Expecting value", s, err.value) from None
json.decoder.JSONDecodeError: Expecting value: line 1 column 1 (char 0)

During handling of the above exception, another exception occurred:

Traceback (most recent call last):
  File "revenue_data.py", line 66, in <module>
    RETRO_price = jmespath.search("data[?name == 'RETRO'].price", response.json())[0]
  File "/opt/hostedtoolcache/Python/3.8.18/x64/lib/python3.8/site-packages/requests/models.py", line 975, in json
    raise RequestsJSONDecodeError(e.msg, e.doc, e.pos)
requests.exceptions.JSONDecodeError: Expecting value: line 1 column 1 (char 0)
