[2025-08-01 02:36:09,673] 	INFO 	20 	id_data.py 	<module>() 	ID Data Started
[2025-08-01 02:36:10,566] 	ERROR 	33 	id_data.py 	<module>() 	Error occurred during ID Data process. Error: Expecting value: line 1 column 1 (char 0)
Traceback (most recent call last):
  File "/opt/hostedtoolcache/Python/3.8.18/x64/lib/python3.8/site-packages/requests/models.py", line 971, in json
    return complexjson.loads(self.text, **kwargs)
  File "/opt/hostedtoolcache/Python/3.8.18/x64/lib/python3.8/json/__init__.py", line 357, in loads
    return _default_decoder.decode(s)
  File "/opt/hostedtoolcache/Python/3.8.18/x64/lib/python3.8/json/decoder.py", line 337, in decode
    obj, end = self.raw_decode(s, idx=_w(s, 0).end())
  File "/opt/hostedtoolcache/Python/3.8.18/x64/lib/python3.8/json/decoder.py", line 355, in raw_decode
    raise JSONDecodeError("Expecting value", s, err.value) from None
json.decoder.JSONDecodeError: Expecting value: line 1 column 1 (char 0)

During handling of the above exception, another exception occurred:

Traceback (most recent call last):
  File "id_data.py", line 27, in <module>
    data = response.json()["data"]
  File "/opt/hostedtoolcache/Python/3.8.18/x64/lib/python3.8/site-packages/requests/models.py", line 975, in json
    raise RequestsJSONDecodeError(e.msg, e.doc, e.pos)
requests.exceptions.JSONDecodeError: Expecting value: line 1 column 1 (char 0)
[2025-08-01 02:36:11,089] 	INFO 	24 	day_data.py 	<module>() 	Day Data Fusion Started
[2025-08-01 02:36:11,252] 	ERROR 	73 	day_data.py 	<module>() 	Error occurred during Day Data Fusion process. Error: 'data'
Traceback (most recent call last):
  File "day_data.py", line 41, in <module>
    data = response.json()["data"]["uniswapDayDatas"]
KeyError: 'data'
[2025-08-01 02:36:12,159] 	INFO 	35 	pair_data.py 	<module>() 	Pair Data Fusion Started
[2025-08-01 02:36:12,360] 	ERROR 	63 	pair_data.py 	<module>() 	Error occurred during Pair Data Fusion process. Pair: sAMM-USDC.e/USDT, Address: 0xB38245b7fE8D594d883A27DB1055bf67926F6B27, Error: 'data'
[2025-08-01 02:36:12,473] 	ERROR 	63 	pair_data.py 	<module>() 	Error occurred during Pair Data Fusion process. Pair: vAMM-WPOL/elRETRO, Address: 0x90a09fE272540Ecd34661B91252f2aB4b7f7A4CE, Error: 'data'
[2025-08-01 02:36:12,597] 	ERROR 	63 	pair_data.py 	<module>() 	Error occurred during Pair Data Fusion process. Pair: sAMM-oRETRO/elRETRO, Address: 0xc58Eb718892Da5D519587A3ec87063A8a46c9feb, Error: 'data'
[2025-08-01 02:36:12,723] 	ERROR 	63 	pair_data.py 	<module>() 	Error occurred during Pair Data Fusion process. Pair: WPOL/WETH (0.05%), Address: 0x1a34EaBbe928Bf431B679959379b2225d60D9cdA, Error: 'data'
[2025-08-01 02:36:12,824] 	ERROR 	63 	pair_data.py 	<module>() 	Error occurred during Pair Data Fusion process. Pair: WPOL/USDC.e (0.05%), Address: 0xEC15624FBB314eb05BaaD4cA49b7904C0Cb6b645, Error: 'data'
[2025-08-01 02:36:12,952] 	ERROR 	63 	pair_data.py 	<module>() 	Error occurred during Pair Data Fusion process. Pair: USDC.e/WETH (0.05%), Address: 0xCE67850420c82dB45eb7fEeCcD2d181300D2BDB3, Error: 'data'
[2025-08-01 02:36:13,063] 	ERROR 	63 	pair_data.py 	<module>() 	Error occurred during Pair Data Fusion process. Pair: WBTC/WETH (0.05%), Address: 0xb694E3bdd4BCdF843510983D257679D1E627C474, Error: 'data'
[2025-08-01 02:36:13,181] 	ERROR 	63 	pair_data.py 	<module>() 	Error occurred during Pair Data Fusion process. Pair: WPOL/USDT (0.05%), Address: 0xB580229645b240A368768ec3E88cb67A41eBBC5B, Error: 'data'
[2025-08-01 02:36:13,306] 	ERROR 	63 	pair_data.py 	<module>() 	Error occurred during Pair Data Fusion process. Pair: WPOL/CASH (0.05%), Address: 0x63ca6ED3D390C725b7FEb617BAdcab78a61038E8, Error: 'data'
[2025-08-01 02:36:13,422] 	ERROR 	63 	pair_data.py 	<module>() 	Error occurred during Pair Data Fusion process. Pair: CASH/WETH (0.05%), Address: 0x0A46B0712974F201BeD15c2458a023EbED25eF4F, Error: 'data'
[2025-08-01 02:36:13,555] 	ERROR 	63 	pair_data.py 	<module>() 	Error occurred during Pair Data Fusion process. Pair: USDC.e/CASH (0.01%), Address: 0x619259F699839dD1498FFC22297044462483bD27, Error: 'data'
[2025-08-01 02:36:13,670] 	ERROR 	63 	pair_data.py 	<module>() 	Error occurred during Pair Data Fusion process. Pair: CASH/USDT (0.01%), Address: 0x160FBF00AB5fbF0200c0Cd4929aEaa2AdD25FB5b, Error: 'data'
[2025-08-01 02:36:13,772] 	ERROR 	63 	pair_data.py 	<module>() 	Error occurred during Pair Data Fusion process. Pair: CASH/DAI (0.01%), Address: 0x1e683586fCB45a769ef2C7d9d7b1803E9C1AEE79, Error: 'data'
[2025-08-01 02:36:13,886] 	ERROR 	63 	pair_data.py 	<module>() 	Error occurred during Pair Data Fusion process. Pair: CASH/miMATIC (0.01%), Address: 0xeB80047F7d5D4C4A3BC6319250d6b1b8aEe2d0D2, Error: 'data'
[2025-08-01 02:36:14,006] 	ERROR 	63 	pair_data.py 	<module>() 	Error occurred during Pair Data Fusion process. Pair: CASH/MaticX (0.05%), Address: 0xb98F8DF0DC6750A3e54540A1e094186C8bED780a, Error: 'data'
[2025-08-01 02:36:14,110] 	ERROR 	63 	pair_data.py 	<module>() 	Error occurred during Pair Data Fusion process. Pair: USDC.e/EURA (0.05%), Address: 0xC2CB03a819F785bD8eb8D628BAD41Cd7c1C71F4B, Error: 'data'
[2025-08-01 02:36:14,224] 	ERROR 	63 	pair_data.py 	<module>() 	Error occurred during Pair Data Fusion process. Pair: FRAX/CASH (0.01%), Address: 0x72289129Dc4937a5d406d1ECeD8b2A17d007A650, Error: 'data'
[2025-08-01 02:36:14,326] 	ERROR 	63 	pair_data.py 	<module>() 	Error occurred during Pair Data Fusion process. Pair: CASH/RETRO (1%), Address: 0xb47A07966cE6812702C0567d03725F1b37E27877, Error: 'data'
[2025-08-01 02:36:14,448] 	ERROR 	63 	pair_data.py 	<module>() 	Error occurred during Pair Data Fusion process. Pair: WETH/RETRO (1%), Address: 0x35394eED0Be676ec6470fE6531daD809265310ff, Error: 'data'
[2025-08-01 02:36:14,574] 	ERROR 	63 	pair_data.py 	<module>() 	Error occurred during Pair Data Fusion process. Pair: WPOL/RETRO (1%), Address: 0x547FD24AA2ED09d86dAC02E36b8Ce84A59fD644F, Error: 'data'
[2025-08-01 02:36:14,711] 	ERROR 	63 	pair_data.py 	<module>() 	Error occurred during Pair Data Fusion process. Pair: WBTC/RETRO (1%), Address: 0x0F73E719a76947752E4b26A2c3FC80a580e68fB4, Error: 'data'
[2025-08-01 02:36:14,844] 	ERROR 	63 	pair_data.py 	<module>() 	Error occurred during Pair Data Fusion process. Pair: stMATIC/RETRO (1%), Address: 0x0973698BB6399c39d628698f9300430C4e7c9bf9, Error: 'data'
[2025-08-01 02:36:14,951] 	ERROR 	63 	pair_data.py 	<module>() 	Error occurred during Pair Data Fusion process. Pair: USDC.e/RETRO (1%), Address: 0xc7d8B9c270D0E31A6a0Cf4496fe019766Be42E15, Error: 'data'
[2025-08-01 02:36:15,113] 	ERROR 	63 	pair_data.py 	<module>() 	Error occurred during Pair Data Fusion process. Pair: RETRO/USDT (1%), Address: 0x69dCAE97A1286B112a8BD75bD9147bD0a3207756, Error: 'data'
[2025-08-01 02:36:15,217] 	ERROR 	63 	pair_data.py 	<module>() 	Error occurred during Pair Data Fusion process. Pair: miMATIC/RETRO (1%), Address: 0xd98eEf295f78ddDd104a8645854C7F8714B39B88, Error: 'data'
[2025-08-01 02:36:15,369] 	ERROR 	63 	pair_data.py 	<module>() 	Error occurred during Pair Data Fusion process. Pair: LINK/RETRO (1%), Address: 0x7761c7233924C3D72F27Fae6a81B074C0152e03a, Error: 'data'
[2025-08-01 02:36:15,488] 	ERROR 	63 	pair_data.py 	<module>() 	Error occurred during Pair Data Fusion process. Pair: RETRO/EURA (1%), Address: 0x15949526fF03fE6ab5f49dA6a86749c20141b3f1, Error: 'data'
[2025-08-01 02:36:15,615] 	ERROR 	63 	pair_data.py 	<module>() 	Error occurred during Pair Data Fusion process. Pair: USDC.e/USDT (0.01%), Address: 0x772510189425ac63f9a5A5eF2fd0C7FDA58CBFC7, Error: 'data'
[2025-08-01 02:36:15,745] 	ERROR 	63 	pair_data.py 	<module>() 	Error occurred during Pair Data Fusion process. Pair: USDC.e/DAI (0.01%), Address: 0x219116F23BDC11EB25e4D0FbE92eD0972d86BE20, Error: 'data'
[2025-08-01 02:36:15,860] 	ERROR 	63 	pair_data.py 	<module>() 	Error occurred during Pair Data Fusion process. Pair: WPOL/MaticX (0.01%), Address: 0x9aa18301055091e9da7C57b81633632Fa33B9a80, Error: 'data'
[2025-08-01 02:36:15,979] 	ERROR 	63 	pair_data.py 	<module>() 	Error occurred during Pair Data Fusion process. Pair: wstETH/WETH (0.01%), Address: 0xa9439Db1D7025Ce4aAc513Baf5eee5220172126C, Error: 'data'
[2025-08-01 02:36:16,076] 	ERROR 	63 	pair_data.py 	<module>() 	Error occurred during Pair Data Fusion process. Pair: WPOL/stMATIC (0.01%), Address: 0x2d623c33673248E95C7a1C26aE7065eb7A7Ac0Ea, Error: 'data'
[2025-08-01 02:36:16,196] 	ERROR 	63 	pair_data.py 	<module>() 	Error occurred during Pair Data Fusion process. Pair: WETH/frxETH (0.01%), Address: 0xe5069a75Bdfe8F676B778B0aaDCcC597841F819B, Error: 'data'
[2025-08-01 02:36:16,315] 	ERROR 	63 	pair_data.py 	<module>() 	Error occurred during Pair Data Fusion process. Pair: FRAX/frxETH (0.05%), Address: 0x38df0c93bf69a9EfB3d3647fF459eF27235A8968, Error: 'data'
[2025-08-01 02:36:16,439] 	ERROR 	63 	pair_data.py 	<module>() 	Error occurred during Pair Data Fusion process. Pair: WPOL/frxETH (0.05%), Address: 0x44AAE81BE8435b6998A66d9642f66DE57DD03FC2, Error: 'data'
[2025-08-01 02:36:16,538] 	ERROR 	63 	pair_data.py 	<module>() 	Error occurred during Pair Data Fusion process. Pair: xbb-t-USD/CASH (0.01%), Address: 0x07dBf448cCC68cA64247da04F2E24643eCf57385, Error: 'data'
[2025-08-01 02:36:16,640] 	ERROR 	63 	pair_data.py 	<module>() 	Error occurred during Pair Data Fusion process. Pair: LINK/LUCHA (0.3%), Address: 0x91248C85DD408BD216254C3cFb51fc326290cF7e, Error: 'data'
[2025-08-01 02:36:16,752] 	ERROR 	63 	pair_data.py 	<module>() 	Error occurred during Pair Data Fusion process. Pair: CASH/LUCHA (0.3%), Address: 0xc666c4b402Bd797185EA419261D22a8f22DDFce6, Error: 'data'
[2025-08-01 02:36:16,869] 	ERROR 	63 	pair_data.py 	<module>() 	Error occurred during Pair Data Fusion process. Pair: USDC.e/miMATIC (0.3%), Address: 0xb090BE2D2F02646057d4DF997A7A983dFb265de0, Error: 'data'
[2025-08-01 02:36:16,978] 	ERROR 	63 	pair_data.py 	<module>() 	Error occurred during Pair Data Fusion process. Pair: FRAX/miMATIC (0.3%), Address: 0xdeB25Dd2d5D168Fd6f80F154d96a2Dab81d61845, Error: 'data'
[2025-08-01 02:36:17,170] 	ERROR 	63 	pair_data.py 	<module>() 	Error occurred during Pair Data Fusion process. Pair: WPOL/miMATIC (0.3%), Address: 0xC571445Fc93666e1E4FaE2E84A7b74FE6ed3978D, Error: 'data'
[2025-08-01 02:36:17,272] 	ERROR 	63 	pair_data.py 	<module>() 	Error occurred during Pair Data Fusion process. Pair: CASH/ERN (0.3%), Address: 0x777a87889f42C33f9A1E5c117774694bbd857075, Error: 'data'
[2025-08-01 02:36:17,411] 	ERROR 	63 	pair_data.py 	<module>() 	Error occurred during Pair Data Fusion process. Pair: ICHI/RETRO (1%), Address: 0xC26E1a0cDab4Bf5141530C49F3360f162C5Db5Db, Error: 'data'
[2025-08-01 02:36:17,555] 	ERROR 	63 	pair_data.py 	<module>() 	Error occurred during Pair Data Fusion process. Pair: WPOL/ICHI (0.3%), Address: 0x13d5e61838D93F7962C52dc921FD7C0Ccc092E35, Error: 'data'
[2025-08-01 02:36:17,693] 	ERROR 	63 	pair_data.py 	<module>() 	Error occurred during Pair Data Fusion process. Pair: SD/MaticX (0.3%), Address: 0xB97c62834e096858BD0B996b758942dd43d7B5eE, Error: 'data'
[2025-08-01 02:36:17,823] 	ERROR 	63 	pair_data.py 	<module>() 	Error occurred during Pair Data Fusion process. Pair: stERN/ERN (1%), Address: 0x99583057951987beD85CE6934473160bFD4921b9, Error: 'data'
[2025-08-01 02:36:17,950] 	ERROR 	63 	pair_data.py 	<module>() 	Error occurred during Pair Data Fusion process. Pair: tUSDC/STAR (0.05%), Address: 0x53C49b9308c3DB176d351d7914Cec0Fb5D7f1129, Error: 'data'
[2025-08-01 02:36:18,081] 	ERROR 	63 	pair_data.py 	<module>() 	Error occurred during Pair Data Fusion process. Pair: WPOL/LUCHA (0.3%), Address: 0x52BeedA850A7048e9D543668BF54E0d9E1B667E0, Error: 'data'
[2025-08-01 02:36:18,180] 	ERROR 	63 	pair_data.py 	<module>() 	Error occurred during Pair Data Fusion process. Pair: LUCHA/WETH (0.3%), Address: 0x13136EA148331a07497087bfc31fBCcD9b99123c, Error: 'data'
[2025-08-01 02:36:18,284] 	ERROR 	63 	pair_data.py 	<module>() 	Error occurred during Pair Data Fusion process. Pair: JRT/WETH (0.3%), Address: 0xAE107e52ebdF151E61d9Fb4Bd800C86c31741465, Error: 'data'
[2025-08-01 02:36:18,380] 	ERROR 	63 	pair_data.py 	<module>() 	Error occurred during Pair Data Fusion process. Pair: axlLqdr/CASH (0.3%), Address: 0x22c10e61A05a03bcd8BF61a7E648f2330ecdA270, Error: 'data'
[2025-08-01 02:36:18,484] 	ERROR 	63 	pair_data.py 	<module>() 	Error occurred during Pair Data Fusion process. Pair: XOC/jMXN (0.01%), Address: 0xccE01e3615785771b84Eb5F88EC612AC6704FdE2, Error: 'data'
[2025-08-01 02:36:18,592] 	ERROR 	63 	pair_data.py 	<module>() 	Error occurred during Pair Data Fusion process. Pair: ICHI/CASH (1%), Address: 0x8ceD58A2dE3C2ea5D3cED3eb4331158c8cf985Fb, Error: 'data'
[2025-08-01 02:36:18,686] 	ERROR 	63 	pair_data.py 	<module>() 	Error occurred during Pair Data Fusion process. Pair: wUSDR/CASH (0.3%), Address: 0x3baEa49B71461DEaB46E6F42548D0005359ff629, Error: 'data'
[2025-08-01 02:36:18,825] 	ERROR 	63 	pair_data.py 	<module>() 	Error occurred during Pair Data Fusion process. Pair: CASH/STAR (0.05%), Address: 0x88C522E526E5Eea8d636fd6805cA7fEB488780D0, Error: 'data'
[2025-08-01 02:36:18,942] 	ERROR 	63 	pair_data.py 	<module>() 	Error occurred during Pair Data Fusion process. Pair: USDC.e/STAR (0.01%), Address: 0x6De0CA91Ef19A6ce9f02A423ae2dF89Fe09Bff0F, Error: 'data'
[2025-08-01 02:36:19,039] 	ERROR 	63 	pair_data.py 	<module>() 	Error occurred during Pair Data Fusion process. Pair: tUSDC/STAR (1%), Address: 0xaC44f57eEF260eB6E0f896b61984Da8d86FeE9ed, Error: 'data'
[2025-08-01 02:36:19,153] 	ERROR 	63 	pair_data.py 	<module>() 	Error occurred during Pair Data Fusion process. Pair: tUSDC/CASH (1%), Address: 0x4FcdB2DCc4Ce156c723aD541dba8B39d47284FC5, Error: 'data'
[2025-08-01 02:36:19,265] 	ERROR 	63 	pair_data.py 	<module>() 	Error occurred during Pair Data Fusion process. Pair: WPOL/USDC.e (0.3%), Address: 0x8c862d100B94d95a49D91958c9e8C2c348d00F04, Error: 'data'
[2025-08-01 02:36:19,373] 	ERROR 	63 	pair_data.py 	<module>() 	Error occurred during Pair Data Fusion process. Pair: WPOL/WETH (0.3%), Address: 0xB8dD18F9b7C3Ad4bDd4B94cB819eda3bd4465119, Error: 'data'
[2025-08-01 02:36:19,478] 	ERROR 	63 	pair_data.py 	<module>() 	Error occurred during Pair Data Fusion process. Pair: USDC.e/WETH (0.3%), Address: 0x058F5330Fef74445878110e201B04F36f8a51c9b, Error: 'data'
[2025-08-01 02:36:19,585] 	ERROR 	63 	pair_data.py 	<module>() 	Error occurred during Pair Data Fusion process. Pair: WBTC/WETH (0.3%), Address: 0x11275C625A7DEE3532E062Eef6915f00af85C3B5, Error: 'data'
[2025-08-01 02:36:19,683] 	ERROR 	63 	pair_data.py 	<module>() 	Error occurred during Pair Data Fusion process. Pair: LINK/WETH (0.3%), Address: 0x555eABEEfe6a047747071525A2c0fFd96d945f69, Error: 'data'
[2025-08-01 02:36:19,792] 	ERROR 	63 	pair_data.py 	<module>() 	Error occurred during Pair Data Fusion process. Pair: WBTC/CASH (0.3%), Address: 0x2C8F7d92Dc7A414D343CbFB687E31a11F525d29e, Error: 'data'
[2025-08-01 02:36:19,925] 	ERROR 	63 	pair_data.py 	<module>() 	Error occurred during Pair Data Fusion process. Pair: WPOL/DEUS (1%), Address: 0xB5cB765e44Eca4bc5a434fFaf6Bf7De235Bc60a5, Error: 'data'
[2025-08-01 02:36:20,014] 	ERROR 	63 	pair_data.py 	<module>() 	Error occurred during Pair Data Fusion process. Pair: WPOL/WBTC (0.3%), Address: 0x2981A1f699eA7149aa08121A07F000cf82846A9e, Error: 'data'
[2025-08-01 02:36:20,114] 	ERROR 	63 	pair_data.py 	<module>() 	Error occurred during Pair Data Fusion process. Pair: FRAX/STAR (0.05%), Address: 0x7D480cBf5Aee75E72eF26F223937f3981d67a860, Error: 'data'
[2025-08-01 02:36:20,216] 	ERROR 	63 	pair_data.py 	<module>() 	Error occurred during Pair Data Fusion process. Pair: CASH/TAROT (0.3%), Address: 0x217aEb0667b79584FBf6265B74a8cD22E1245fdC, Error: 'data'
[2025-08-01 02:36:20,310] 	ERROR 	63 	pair_data.py 	<module>() 	Error occurred during Pair Data Fusion process. Pair: CASH/fxDOLA (0.05%), Address: 0x4b4B895a0dD744B4893aA4370A8F7eDbde5Fd90e, Error: 'data'
[2025-08-01 02:36:20,406] 	ERROR 	63 	pair_data.py 	<module>() 	Error occurred during Pair Data Fusion process. Pair: RETRO/liveRetro (1%), Address: 0x6333BB8b6f1DDa6f929d70eDEB9e31c8148dC9ef, Error: 'data'
[2025-08-01 02:36:20,551] 	ERROR 	63 	pair_data.py 	<module>() 	Error occurred during Pair Data Fusion process. Pair: MVX/WETH (1%), Address: 0xCC72276de3BCc1b159F1B60A86B0211116022B42, Error: 'data'
[2025-08-01 02:36:20,674] 	ERROR 	63 	pair_data.py 	<module>() 	Error occurred during Pair Data Fusion process. Pair: WPOL/elRETRO (1%), Address: 0x6794Db07e2efE1307b8594FBbBFad78E50eC76fa, Error: 'data'
[2025-08-01 02:36:20,764] 	ERROR 	63 	pair_data.py 	<module>() 	Error occurred during Pair Data Fusion process. Pair: OATH/WETH (1%), Address: 0x0c74834d67c4bf5e6a44D18b2BAc767cddB4CdBf, Error: 'data'
[2025-08-01 02:36:20,881] 	ERROR 	63 	pair_data.py 	<module>() 	Error occurred during Pair Data Fusion process. Pair: USDC.e/IBEX (1%), Address: 0x53D8c25B3d130D2810591cDc7A41Bd848bF79B63, Error: 'data'
[2025-08-01 02:36:20,975] 	ERROR 	63 	pair_data.py 	<module>() 	Error occurred during Pair Data Fusion process. Pair: USDC.e/fxDOLA (0.3%), Address: 0x896ffE2cd28Ba13ddDa98103a3B66E82bb36BeE3, Error: 'data'
[2025-08-01 02:36:21,090] 	ERROR 	63 	pair_data.py 	<module>() 	Error occurred during Pair Data Fusion process. Pair: USDC.e/FRAX (0.3%), Address: 0x091236A16952BC9e4bB817FFA7aB40263183f658, Error: 'data'
[2025-08-01 02:36:21,200] 	ERROR 	63 	pair_data.py 	<module>() 	Error occurred during Pair Data Fusion process. Pair: WBTC/USDC.e (0.3%), Address: 0x459F42C788E6F8faCe4854DDD59C81a6Ad8BB1Aa, Error: 'data'
[2025-08-01 02:36:21,313] 	ERROR 	63 	pair_data.py 	<module>() 	Error occurred during Pair Data Fusion process. Pair: WETH/ERN (0.3%), Address: 0xCF2093da3CeBb8731747EEaCbd486A7fcE2Db901, Error: 'data'
[2025-08-01 02:36:21,424] 	ERROR 	63 	pair_data.py 	<module>() 	Error occurred during Pair Data Fusion process. Pair: WETH/JARVIS (0.3%), Address: 0xf310d505B85E0378790Af9fDB9b79b40736f7b4D, Error: 'data'
[2025-08-01 02:36:21,529] 	ERROR 	63 	pair_data.py 	<module>() 	Error occurred during Pair Data Fusion process. Pair: jEUR/CASH (0.05%), Address: 0x65E6b7C7DfE071E52D6923E4079E3C0FcBeaA401, Error: 'data'
[2025-08-01 02:36:21,694] 	ERROR 	63 	pair_data.py 	<module>() 	Error occurred during Pair Data Fusion process. Pair: USDC.e/USDC (0.01%), Address: 0x1e0aa3f6C3130294845B8e162d838e221d170016, Error: 'data'
[2025-08-01 02:36:21,794] 	ERROR 	63 	pair_data.py 	<module>() 	Error occurred during Pair Data Fusion process. Pair: LUCHA/WETH (1%), Address: 0x098c1e4BB34DEcDF49D5966014B5153Af326E766, Error: 'data'
[2025-08-01 02:36:21,906] 	ERROR 	63 	pair_data.py 	<module>() 	Error occurred during Pair Data Fusion process. Pair: WPOL/LUCHA (1%), Address: 0xde4C8898CD50EBE9C167313b312D147D10d1C898, Error: 'data'
[2025-08-01 02:36:22,008] 	ERROR 	63 	pair_data.py 	<module>() 	Error occurred during Pair Data Fusion process. Pair: LINK/LUCHA (1%), Address: 0xA97B2b9AcA65aab57A6b0840B45777bd66fbcf33, Error: 'data'
[2025-08-01 02:36:22,139] 	ERROR 	63 	pair_data.py 	<module>() 	Error occurred during Pair Data Fusion process. Pair: CASH/LUCHA (1%), Address: 0x5c09352B1aa703d18dbcF48c98655BFA19d07FBB, Error: 'data'
[2025-08-01 02:36:22,236] 	ERROR 	103 	pair_data.py 	<module>() 	Error occurred during Pair Data Fusion process. Error: 'date'
Traceback (most recent call last):
  File "/opt/hostedtoolcache/Python/3.8.18/x64/lib/python3.8/site-packages/pandas/core/indexes/base.py", line 3802, in get_loc
    return self._engine.get_loc(casted_key)
  File "pandas/_libs/index.pyx", line 138, in pandas._libs.index.IndexEngine.get_loc
  File "pandas/_libs/index.pyx", line 165, in pandas._libs.index.IndexEngine.get_loc
  File "pandas/_libs/hashtable_class_helper.pxi", line 5745, in pandas._libs.hashtable.PyObjectHashTable.get_item
  File "pandas/_libs/hashtable_class_helper.pxi", line 5753, in pandas._libs.hashtable.PyObjectHashTable.get_item
KeyError: 'date'

The above exception was the direct cause of the following exception:

Traceback (most recent call last):
  File "pair_data.py", line 68, in <module>
    pairdata_fusion_df["date"] = pairdata_fusion_df["date"].apply(lambda timestamp: datetime.utcfromtimestamp(timestamp).date())
  File "/opt/hostedtoolcache/Python/3.8.18/x64/lib/python3.8/site-packages/pandas/core/frame.py", line 3807, in __getitem__
    indexer = self.columns.get_loc(key)
  File "/opt/hostedtoolcache/Python/3.8.18/x64/lib/python3.8/site-packages/pandas/core/indexes/base.py", line 3804, in get_loc
    raise KeyError(key) from err
KeyError: 'date'
[2025-08-01 02:36:23,081] 	INFO 	36 	bribe_data.py 	<module>() 	Bribe Data Started
[2025-08-01 02:36:23,447] 	ERROR 	159 	bribe_data.py 	<module>() 	Error occurred during Bribe Data process. Error: {'code': -32000, 'message': 'Unauthorized: You must authenticate your request with an API key. Create an account on https://www.ankr.com/rpc/ and generate your personal API key for free.'}
Traceback (most recent call last):
  File "bribe_data.py", line 71, in <module>
    rewardsListLength = contract_instance.functions.rewardsListLength().call()
  File "/opt/hostedtoolcache/Python/3.8.18/x64/lib/python3.8/site-packages/web3/contract.py", line 970, in call
    return call_contract_function(
  File "/opt/hostedtoolcache/Python/3.8.18/x64/lib/python3.8/site-packages/web3/contract.py", line 1525, in call_contract_function
    return_data = web3.eth.call(
  File "/opt/hostedtoolcache/Python/3.8.18/x64/lib/python3.8/site-packages/web3/module.py", line 57, in caller
    result = w3.manager.request_blocking(method_str,
  File "/opt/hostedtoolcache/Python/3.8.18/x64/lib/python3.8/site-packages/web3/manager.py", line 198, in request_blocking
    return self.formatted_response(response,
  File "/opt/hostedtoolcache/Python/3.8.18/x64/lib/python3.8/site-packages/web3/manager.py", line 171, in formatted_response
    raise ValueError(response["error"])
ValueError: {'code': -32000, 'message': 'Unauthorized: You must authenticate your request with an API key. Create an account on https://www.ankr.com/rpc/ and generate your personal API key for free.'}
[2025-08-01 02:36:24,302] 	INFO 	36 	fee_data.py 	<module>() 	Fee Data Started
[2025-08-01 02:36:24,451] 	ERROR 	159 	fee_data.py 	<module>() 	Error occurred during Fee Data process. Error: {'code': -32000, 'message': 'Unauthorized: You must authenticate your request with an API key. Create an account on https://www.ankr.com/rpc/ and generate your personal API key for free.'}
Traceback (most recent call last):
  File "fee_data.py", line 71, in <module>
    rewardsListLength = contract_instance.functions.rewardsListLength().call()
  File "/opt/hostedtoolcache/Python/3.8.18/x64/lib/python3.8/site-packages/web3/contract.py", line 970, in call
    return call_contract_function(
  File "/opt/hostedtoolcache/Python/3.8.18/x64/lib/python3.8/site-packages/web3/contract.py", line 1525, in call_contract_function
    return_data = web3.eth.call(
  File "/opt/hostedtoolcache/Python/3.8.18/x64/lib/python3.8/site-packages/web3/module.py", line 57, in caller
    result = w3.manager.request_blocking(method_str,
  File "/opt/hostedtoolcache/Python/3.8.18/x64/lib/python3.8/site-packages/web3/manager.py", line 198, in request_blocking
    return self.formatted_response(response,
  File "/opt/hostedtoolcache/Python/3.8.18/x64/lib/python3.8/site-packages/web3/manager.py", line 171, in formatted_response
    raise ValueError(response["error"])
ValueError: {'code': -32000, 'message': 'Unauthorized: You must authenticate your request with an API key. Create an account on https://www.ankr.com/rpc/ and generate your personal API key for free.'}
[2025-08-01 02:36:25,301] 	INFO 	37 	vote_data.py 	<module>() 	Vote Data Started
[2025-08-01 02:37:01,339] 	ERROR 	118 	vote_data.py 	<module>() 	Error occurred during Vote Data process. Error: Expecting value: line 1 column 1 (char 0)
Traceback (most recent call last):
  File "/opt/hostedtoolcache/Python/3.8.18/x64/lib/python3.8/site-packages/requests/models.py", line 971, in json
    return complexjson.loads(self.text, **kwargs)
  File "/opt/hostedtoolcache/Python/3.8.18/x64/lib/python3.8/json/__init__.py", line 357, in loads
    return _default_decoder.decode(s)
  File "/opt/hostedtoolcache/Python/3.8.18/x64/lib/python3.8/json/decoder.py", line 337, in decode
    obj, end = self.raw_decode(s, idx=_w(s, 0).end())
  File "/opt/hostedtoolcache/Python/3.8.18/x64/lib/python3.8/json/decoder.py", line 355, in raw_decode
    raise JSONDecodeError("Expecting value", s, err.value) from None
json.decoder.JSONDecodeError: Expecting value: line 1 column 1 (char 0)

During handling of the above exception, another exception occurred:

Traceback (most recent call last):
  File "vote_data.py", line 64, in <module>
    RETRO_price = jmespath.search("data[?name == 'RETRO'].price", response.json())[0]
  File "/opt/hostedtoolcache/Python/3.8.18/x64/lib/python3.8/site-packages/requests/models.py", line 975, in json
    raise RequestsJSONDecodeError(e.msg, e.doc, e.pos)
requests.exceptions.JSONDecodeError: Expecting value: line 1 column 1 (char 0)
[2025-08-01 02:37:02,175] 	INFO 	30 	revenue_data.py 	<module>() 	Revenue Data Started
[2025-08-01 02:37:07,514] 	ERROR 	152 	revenue_data.py 	<module>() 	Error occurred during Revenue Data process. Error: Expecting value: line 1 column 1 (char 0)
Traceback (most recent call last):
  File "/opt/hostedtoolcache/Python/3.8.18/x64/lib/python3.8/site-packages/requests/models.py", line 971, in json
    return complexjson.loads(self.text, **kwargs)
  File "/opt/hostedtoolcache/Python/3.8.18/x64/lib/python3.8/json/__init__.py", line 357, in loads
    return _default_decoder.decode(s)
  File "/opt/hostedtoolcache/Python/3.8.18/x64/lib/python3.8/json/decoder.py", line 337, in decode
    obj, end = self.raw_decode(s, idx=_w(s, 0).end())
  File "/opt/hostedtoolcache/Python/3.8.18/x64/lib/python3.8/json/decoder.py", line 355, in raw_decode
    raise JSONDecodeError("Expecting value", s, err.value) from None
json.decoder.JSONDecodeError: Expecting value: line 1 column 1 (char 0)

During handling of the above exception, another exception occurred:

Traceback (most recent call last):
  File "revenue_data.py", line 66, in <module>
    RETRO_price = jmespath.search("data[?name == 'RETRO'].price", response.json())[0]
  File "/opt/hostedtoolcache/Python/3.8.18/x64/lib/python3.8/site-packages/requests/models.py", line 975, in json
    raise RequestsJSONDecodeError(e.msg, e.doc, e.pos)
requests.exceptions.JSONDecodeError: Expecting value: line 1 column 1 (char 0)
[2025-08-01 04:18:50,884] 	INFO 	20 	id_data.py 	<module>() 	ID Data Started
[2025-08-01 04:18:51,166] 	ERROR 	33 	id_data.py 	<module>() 	Error occurred during ID Data process. Error: Expecting value: line 1 column 1 (char 0)
Traceback (most recent call last):
  File "/opt/hostedtoolcache/Python/3.8.18/x64/lib/python3.8/site-packages/requests/models.py", line 971, in json
    return complexjson.loads(self.text, **kwargs)
  File "/opt/hostedtoolcache/Python/3.8.18/x64/lib/python3.8/json/__init__.py", line 357, in loads
    return _default_decoder.decode(s)
  File "/opt/hostedtoolcache/Python/3.8.18/x64/lib/python3.8/json/decoder.py", line 337, in decode
    obj, end = self.raw_decode(s, idx=_w(s, 0).end())
  File "/opt/hostedtoolcache/Python/3.8.18/x64/lib/python3.8/json/decoder.py", line 355, in raw_decode
    raise JSONDecodeError("Expecting value", s, err.value) from None
json.decoder.JSONDecodeError: Expecting value: line 1 column 1 (char 0)

During handling of the above exception, another exception occurred:

Traceback (most recent call last):
  File "id_data.py", line 27, in <module>
    data = response.json()["data"]
  File "/opt/hostedtoolcache/Python/3.8.18/x64/lib/python3.8/site-packages/requests/models.py", line 975, in json
    raise RequestsJSONDecodeError(e.msg, e.doc, e.pos)
requests.exceptions.JSONDecodeError: Expecting value: line 1 column 1 (char 0)
[2025-08-01 04:18:51,680] 	INFO 	24 	day_data.py 	<module>() 	Day Data Fusion Started
[2025-08-01 04:18:51,893] 	ERROR 	73 	day_data.py 	<module>() 	Error occurred during Day Data Fusion process. Error: 'data'
Traceback (most recent call last):
  File "day_data.py", line 41, in <module>
    data = response.json()["data"]["uniswapDayDatas"]
KeyError: 'data'
[2025-08-01 04:18:52,779] 	INFO 	35 	pair_data.py 	<module>() 	Pair Data Fusion Started
[2025-08-01 04:18:52,983] 	ERROR 	63 	pair_data.py 	<module>() 	Error occurred during Pair Data Fusion process. Pair: sAMM-USDC.e/USDT, Address: 0xB38245b7fE8D594d883A27DB1055bf67926F6B27, Error: 'data'
[2025-08-01 04:18:53,082] 	ERROR 	63 	pair_data.py 	<module>() 	Error occurred during Pair Data Fusion process. Pair: vAMM-WPOL/elRETRO, Address: 0x90a09fE272540Ecd34661B91252f2aB4b7f7A4CE, Error: 'data'
[2025-08-01 04:18:53,182] 	ERROR 	63 	pair_data.py 	<module>() 	Error occurred during Pair Data Fusion process. Pair: sAMM-oRETRO/elRETRO, Address: 0xc58Eb718892Da5D519587A3ec87063A8a46c9feb, Error: 'data'
[2025-08-01 04:18:53,287] 	ERROR 	63 	pair_data.py 	<module>() 	Error occurred during Pair Data Fusion process. Pair: WPOL/WETH (0.05%), Address: 0x1a34EaBbe928Bf431B679959379b2225d60D9cdA, Error: 'data'
[2025-08-01 04:18:53,402] 	ERROR 	63 	pair_data.py 	<module>() 	Error occurred during Pair Data Fusion process. Pair: WPOL/USDC.e (0.05%), Address: 0xEC15624FBB314eb05BaaD4cA49b7904C0Cb6b645, Error: 'data'
[2025-08-01 04:18:53,501] 	ERROR 	63 	pair_data.py 	<module>() 	Error occurred during Pair Data Fusion process. Pair: USDC.e/WETH (0.05%), Address: 0xCE67850420c82dB45eb7fEeCcD2d181300D2BDB3, Error: 'data'
[2025-08-01 04:18:53,597] 	ERROR 	63 	pair_data.py 	<module>() 	Error occurred during Pair Data Fusion process. Pair: WBTC/WETH (0.05%), Address: 0xb694E3bdd4BCdF843510983D257679D1E627C474, Error: 'data'
[2025-08-01 04:18:53,704] 	ERROR 	63 	pair_data.py 	<module>() 	Error occurred during Pair Data Fusion process. Pair: WPOL/USDT (0.05%), Address: 0xB580229645b240A368768ec3E88cb67A41eBBC5B, Error: 'data'
[2025-08-01 04:18:53,801] 	ERROR 	63 	pair_data.py 	<module>() 	Error occurred during Pair Data Fusion process. Pair: WPOL/CASH (0.05%), Address: 0x63ca6ED3D390C725b7FEb617BAdcab78a61038E8, Error: 'data'
[2025-08-01 04:18:53,906] 	ERROR 	63 	pair_data.py 	<module>() 	Error occurred during Pair Data Fusion process. Pair: CASH/WETH (0.05%), Address: 0x0A46B0712974F201BeD15c2458a023EbED25eF4F, Error: 'data'
[2025-08-01 04:18:54,002] 	ERROR 	63 	pair_data.py 	<module>() 	Error occurred during Pair Data Fusion process. Pair: USDC.e/CASH (0.01%), Address: 0x619259F699839dD1498FFC22297044462483bD27, Error: 'data'
[2025-08-01 04:18:54,096] 	ERROR 	63 	pair_data.py 	<module>() 	Error occurred during Pair Data Fusion process. Pair: CASH/USDT (0.01%), Address: 0x160FBF00AB5fbF0200c0Cd4929aEaa2AdD25FB5b, Error: 'data'
[2025-08-01 04:18:54,199] 	ERROR 	63 	pair_data.py 	<module>() 	Error occurred during Pair Data Fusion process. Pair: CASH/DAI (0.01%), Address: 0x1e683586fCB45a769ef2C7d9d7b1803E9C1AEE79, Error: 'data'
[2025-08-01 04:18:54,307] 	ERROR 	63 	pair_data.py 	<module>() 	Error occurred during Pair Data Fusion process. Pair: CASH/miMATIC (0.01%), Address: 0xeB80047F7d5D4C4A3BC6319250d6b1b8aEe2d0D2, Error: 'data'
[2025-08-01 04:18:54,414] 	ERROR 	63 	pair_data.py 	<module>() 	Error occurred during Pair Data Fusion process. Pair: CASH/MaticX (0.05%), Address: 0xb98F8DF0DC6750A3e54540A1e094186C8bED780a, Error: 'data'
[2025-08-01 04:18:54,511] 	ERROR 	63 	pair_data.py 	<module>() 	Error occurred during Pair Data Fusion process. Pair: USDC.e/EURA (0.05%), Address: 0xC2CB03a819F785bD8eb8D628BAD41Cd7c1C71F4B, Error: 'data'
[2025-08-01 04:18:54,629] 	ERROR 	63 	pair_data.py 	<module>() 	Error occurred during Pair Data Fusion process. Pair: FRAX/CASH (0.01%), Address: 0x72289129Dc4937a5d406d1ECeD8b2A17d007A650, Error: 'data'
[2025-08-01 04:18:54,725] 	ERROR 	63 	pair_data.py 	<module>() 	Error occurred during Pair Data Fusion process. Pair: CASH/RETRO (1%), Address: 0xb47A07966cE6812702C0567d03725F1b37E27877, Error: 'data'
[2025-08-01 04:18:54,837] 	ERROR 	63 	pair_data.py 	<module>() 	Error occurred during Pair Data Fusion process. Pair: WETH/RETRO (1%), Address: 0x35394eED0Be676ec6470fE6531daD809265310ff, Error: 'data'
[2025-08-01 04:18:54,927] 	ERROR 	63 	pair_data.py 	<module>() 	Error occurred during Pair Data Fusion process. Pair: WPOL/RETRO (1%), Address: 0x547FD24AA2ED09d86dAC02E36b8Ce84A59fD644F, Error: 'data'
[2025-08-01 04:18:55,029] 	ERROR 	63 	pair_data.py 	<module>() 	Error occurred during Pair Data Fusion process. Pair: WBTC/RETRO (1%), Address: 0x0F73E719a76947752E4b26A2c3FC80a580e68fB4, Error: 'data'
[2025-08-01 04:18:55,138] 	ERROR 	63 	pair_data.py 	<module>() 	Error occurred during Pair Data Fusion process. Pair: stMATIC/RETRO (1%), Address: 0x0973698BB6399c39d628698f9300430C4e7c9bf9, Error: 'data'
[2025-08-01 04:18:55,231] 	ERROR 	63 	pair_data.py 	<module>() 	Error occurred during Pair Data Fusion process. Pair: USDC.e/RETRO (1%), Address: 0xc7d8B9c270D0E31A6a0Cf4496fe019766Be42E15, Error: 'data'
[2025-08-01 04:18:55,339] 	ERROR 	63 	pair_data.py 	<module>() 	Error occurred during Pair Data Fusion process. Pair: RETRO/USDT (1%), Address: 0x69dCAE97A1286B112a8BD75bD9147bD0a3207756, Error: 'data'
[2025-08-01 04:18:55,454] 	ERROR 	63 	pair_data.py 	<module>() 	Error occurred during Pair Data Fusion process. Pair: miMATIC/RETRO (1%), Address: 0xd98eEf295f78ddDd104a8645854C7F8714B39B88, Error: 'data'
[2025-08-01 04:18:55,554] 	ERROR 	63 	pair_data.py 	<module>() 	Error occurred during Pair Data Fusion process. Pair: LINK/RETRO (1%), Address: 0x7761c7233924C3D72F27Fae6a81B074C0152e03a, Error: 'data'
[2025-08-01 04:18:55,656] 	ERROR 	63 	pair_data.py 	<module>() 	Error occurred during Pair Data Fusion process. Pair: RETRO/EURA (1%), Address: 0x15949526fF03fE6ab5f49dA6a86749c20141b3f1, Error: 'data'
[2025-08-01 04:18:55,759] 	ERROR 	63 	pair_data.py 	<module>() 	Error occurred during Pair Data Fusion process. Pair: USDC.e/USDT (0.01%), Address: 0x772510189425ac63f9a5A5eF2fd0C7FDA58CBFC7, Error: 'data'
[2025-08-01 04:18:55,866] 	ERROR 	63 	pair_data.py 	<module>() 	Error occurred during Pair Data Fusion process. Pair: USDC.e/DAI (0.01%), Address: 0x219116F23BDC11EB25e4D0FbE92eD0972d86BE20, Error: 'data'
[2025-08-01 04:18:56,009] 	ERROR 	63 	pair_data.py 	<module>() 	Error occurred during Pair Data Fusion process. Pair: WPOL/MaticX (0.01%), Address: 0x9aa18301055091e9da7C57b81633632Fa33B9a80, Error: 'data'
[2025-08-01 04:18:56,140] 	ERROR 	63 	pair_data.py 	<module>() 	Error occurred during Pair Data Fusion process. Pair: wstETH/WETH (0.01%), Address: 0xa9439Db1D7025Ce4aAc513Baf5eee5220172126C, Error: 'data'
[2025-08-01 04:18:56,251] 	ERROR 	63 	pair_data.py 	<module>() 	Error occurred during Pair Data Fusion process. Pair: WPOL/stMATIC (0.01%), Address: 0x2d623c33673248E95C7a1C26aE7065eb7A7Ac0Ea, Error: 'data'
[2025-08-01 04:18:56,346] 	ERROR 	63 	pair_data.py 	<module>() 	Error occurred during Pair Data Fusion process. Pair: WETH/frxETH (0.01%), Address: 0xe5069a75Bdfe8F676B778B0aaDCcC597841F819B, Error: 'data'
[2025-08-01 04:18:56,446] 	ERROR 	63 	pair_data.py 	<module>() 	Error occurred during Pair Data Fusion process. Pair: FRAX/frxETH (0.05%), Address: 0x38df0c93bf69a9EfB3d3647fF459eF27235A8968, Error: 'data'
[2025-08-01 04:18:56,561] 	ERROR 	63 	pair_data.py 	<module>() 	Error occurred during Pair Data Fusion process. Pair: WPOL/frxETH (0.05%), Address: 0x44AAE81BE8435b6998A66d9642f66DE57DD03FC2, Error: 'data'
[2025-08-01 04:18:56,684] 	ERROR 	63 	pair_data.py 	<module>() 	Error occurred during Pair Data Fusion process. Pair: xbb-t-USD/CASH (0.01%), Address: 0x07dBf448cCC68cA64247da04F2E24643eCf57385, Error: 'data'
[2025-08-01 04:18:56,787] 	ERROR 	63 	pair_data.py 	<module>() 	Error occurred during Pair Data Fusion process. Pair: LINK/LUCHA (0.3%), Address: 0x91248C85DD408BD216254C3cFb51fc326290cF7e, Error: 'data'
[2025-08-01 04:18:56,883] 	ERROR 	63 	pair_data.py 	<module>() 	Error occurred during Pair Data Fusion process. Pair: CASH/LUCHA (0.3%), Address: 0xc666c4b402Bd797185EA419261D22a8f22DDFce6, Error: 'data'
[2025-08-01 04:18:56,980] 	ERROR 	63 	pair_data.py 	<module>() 	Error occurred during Pair Data Fusion process. Pair: USDC.e/miMATIC (0.3%), Address: 0xb090BE2D2F02646057d4DF997A7A983dFb265de0, Error: 'data'
[2025-08-01 04:18:57,076] 	ERROR 	63 	pair_data.py 	<module>() 	Error occurred during Pair Data Fusion process. Pair: FRAX/miMATIC (0.3%), Address: 0xdeB25Dd2d5D168Fd6f80F154d96a2Dab81d61845, Error: 'data'
[2025-08-01 04:18:57,185] 	ERROR 	63 	pair_data.py 	<module>() 	Error occurred during Pair Data Fusion process. Pair: WPOL/miMATIC (0.3%), Address: 0xC571445Fc93666e1E4FaE2E84A7b74FE6ed3978D, Error: 'data'
[2025-08-01 04:18:57,278] 	ERROR 	63 	pair_data.py 	<module>() 	Error occurred during Pair Data Fusion process. Pair: CASH/ERN (0.3%), Address: 0x777a87889f42C33f9A1E5c117774694bbd857075, Error: 'data'
[2025-08-01 04:18:57,381] 	ERROR 	63 	pair_data.py 	<module>() 	Error occurred during Pair Data Fusion process. Pair: ICHI/RETRO (1%), Address: 0xC26E1a0cDab4Bf5141530C49F3360f162C5Db5Db, Error: 'data'
[2025-08-01 04:18:57,497] 	ERROR 	63 	pair_data.py 	<module>() 	Error occurred during Pair Data Fusion process. Pair: WPOL/ICHI (0.3%), Address: 0x13d5e61838D93F7962C52dc921FD7C0Ccc092E35, Error: 'data'
[2025-08-01 04:18:57,594] 	ERROR 	63 	pair_data.py 	<module>() 	Error occurred during Pair Data Fusion process. Pair: SD/MaticX (0.3%), Address: 0xB97c62834e096858BD0B996b758942dd43d7B5eE, Error: 'data'
[2025-08-01 04:18:57,695] 	ERROR 	63 	pair_data.py 	<module>() 	Error occurred during Pair Data Fusion process. Pair: stERN/ERN (1%), Address: 0x99583057951987beD85CE6934473160bFD4921b9, Error: 'data'
[2025-08-01 04:18:57,800] 	ERROR 	63 	pair_data.py 	<module>() 	Error occurred during Pair Data Fusion process. Pair: tUSDC/STAR (0.05%), Address: 0x53C49b9308c3DB176d351d7914Cec0Fb5D7f1129, Error: 'data'
[2025-08-01 04:18:57,904] 	ERROR 	63 	pair_data.py 	<module>() 	Error occurred during Pair Data Fusion process. Pair: WPOL/LUCHA (0.3%), Address: 0x52BeedA850A7048e9D543668BF54E0d9E1B667E0, Error: 'data'
[2025-08-01 04:18:58,016] 	ERROR 	63 	pair_data.py 	<module>() 	Error occurred during Pair Data Fusion process. Pair: LUCHA/WETH (0.3%), Address: 0x13136EA148331a07497087bfc31fBCcD9b99123c, Error: 'data'
[2025-08-01 04:18:58,127] 	ERROR 	63 	pair_data.py 	<module>() 	Error occurred during Pair Data Fusion process. Pair: JRT/WETH (0.3%), Address: 0xAE107e52ebdF151E61d9Fb4Bd800C86c31741465, Error: 'data'
[2025-08-01 04:18:58,233] 	ERROR 	63 	pair_data.py 	<module>() 	Error occurred during Pair Data Fusion process. Pair: axlLqdr/CASH (0.3%), Address: 0x22c10e61A05a03bcd8BF61a7E648f2330ecdA270, Error: 'data'
[2025-08-01 04:18:58,339] 	ERROR 	63 	pair_data.py 	<module>() 	Error occurred during Pair Data Fusion process. Pair: XOC/jMXN (0.01%), Address: 0xccE01e3615785771b84Eb5F88EC612AC6704FdE2, Error: 'data'
[2025-08-01 04:18:58,438] 	ERROR 	63 	pair_data.py 	<module>() 	Error occurred during Pair Data Fusion process. Pair: ICHI/CASH (1%), Address: 0x8ceD58A2dE3C2ea5D3cED3eb4331158c8cf985Fb, Error: 'data'
[2025-08-01 04:18:58,537] 	ERROR 	63 	pair_data.py 	<module>() 	Error occurred during Pair Data Fusion process. Pair: wUSDR/CASH (0.3%), Address: 0x3baEa49B71461DEaB46E6F42548D0005359ff629, Error: 'data'
[2025-08-01 04:18:58,648] 	ERROR 	63 	pair_data.py 	<module>() 	Error occurred during Pair Data Fusion process. Pair: CASH/STAR (0.05%), Address: 0x88C522E526E5Eea8d636fd6805cA7fEB488780D0, Error: 'data'
[2025-08-01 04:18:58,745] 	ERROR 	63 	pair_data.py 	<module>() 	Error occurred during Pair Data Fusion process. Pair: USDC.e/STAR (0.01%), Address: 0x6De0CA91Ef19A6ce9f02A423ae2dF89Fe09Bff0F, Error: 'data'
[2025-08-01 04:18:58,840] 	ERROR 	63 	pair_data.py 	<module>() 	Error occurred during Pair Data Fusion process. Pair: tUSDC/STAR (1%), Address: 0xaC44f57eEF260eB6E0f896b61984Da8d86FeE9ed, Error: 'data'
[2025-08-01 04:18:58,941] 	ERROR 	63 	pair_data.py 	<module>() 	Error occurred during Pair Data Fusion process. Pair: tUSDC/CASH (1%), Address: 0x4FcdB2DCc4Ce156c723aD541dba8B39d47284FC5, Error: 'data'
[2025-08-01 04:18:59,033] 	ERROR 	63 	pair_data.py 	<module>() 	Error occurred during Pair Data Fusion process. Pair: WPOL/USDC.e (0.3%), Address: 0x8c862d100B94d95a49D91958c9e8C2c348d00F04, Error: 'data'
[2025-08-01 04:18:59,122] 	ERROR 	63 	pair_data.py 	<module>() 	Error occurred during Pair Data Fusion process. Pair: WPOL/WETH (0.3%), Address: 0xB8dD18F9b7C3Ad4bDd4B94cB819eda3bd4465119, Error: 'data'
[2025-08-01 04:18:59,221] 	ERROR 	63 	pair_data.py 	<module>() 	Error occurred during Pair Data Fusion process. Pair: USDC.e/WETH (0.3%), Address: 0x058F5330Fef74445878110e201B04F36f8a51c9b, Error: 'data'
[2025-08-01 04:18:59,318] 	ERROR 	63 	pair_data.py 	<module>() 	Error occurred during Pair Data Fusion process. Pair: WBTC/WETH (0.3%), Address: 0x11275C625A7DEE3532E062Eef6915f00af85C3B5, Error: 'data'
[2025-08-01 04:18:59,415] 	ERROR 	63 	pair_data.py 	<module>() 	Error occurred during Pair Data Fusion process. Pair: LINK/WETH (0.3%), Address: 0x555eABEEfe6a047747071525A2c0fFd96d945f69, Error: 'data'
[2025-08-01 04:18:59,512] 	ERROR 	63 	pair_data.py 	<module>() 	Error occurred during Pair Data Fusion process. Pair: WBTC/CASH (0.3%), Address: 0x2C8F7d92Dc7A414D343CbFB687E31a11F525d29e, Error: 'data'
[2025-08-01 04:18:59,606] 	ERROR 	63 	pair_data.py 	<module>() 	Error occurred during Pair Data Fusion process. Pair: WPOL/DEUS (1%), Address: 0xB5cB765e44Eca4bc5a434fFaf6Bf7De235Bc60a5, Error: 'data'
[2025-08-01 04:18:59,711] 	ERROR 	63 	pair_data.py 	<module>() 	Error occurred during Pair Data Fusion process. Pair: WPOL/WBTC (0.3%), Address: 0x2981A1f699eA7149aa08121A07F000cf82846A9e, Error: 'data'
[2025-08-01 04:18:59,803] 	ERROR 	63 	pair_data.py 	<module>() 	Error occurred during Pair Data Fusion process. Pair: FRAX/STAR (0.05%), Address: 0x7D480cBf5Aee75E72eF26F223937f3981d67a860, Error: 'data'
[2025-08-01 04:18:59,895] 	ERROR 	63 	pair_data.py 	<module>() 	Error occurred during Pair Data Fusion process. Pair: CASH/TAROT (0.3%), Address: 0x217aEb0667b79584FBf6265B74a8cD22E1245fdC, Error: 'data'
[2025-08-01 04:18:59,995] 	ERROR 	63 	pair_data.py 	<module>() 	Error occurred during Pair Data Fusion process. Pair: CASH/fxDOLA (0.05%), Address: 0x4b4B895a0dD744B4893aA4370A8F7eDbde5Fd90e, Error: 'data'
[2025-08-01 04:19:00,097] 	ERROR 	63 	pair_data.py 	<module>() 	Error occurred during Pair Data Fusion process. Pair: RETRO/liveRetro (1%), Address: 0x6333BB8b6f1DDa6f929d70eDEB9e31c8148dC9ef, Error: 'data'
[2025-08-01 04:19:00,202] 	ERROR 	63 	pair_data.py 	<module>() 	Error occurred during Pair Data Fusion process. Pair: MVX/WETH (1%), Address: 0xCC72276de3BCc1b159F1B60A86B0211116022B42, Error: 'data'
[2025-08-01 04:19:00,293] 	ERROR 	63 	pair_data.py 	<module>() 	Error occurred during Pair Data Fusion process. Pair: WPOL/elRETRO (1%), Address: 0x6794Db07e2efE1307b8594FBbBFad78E50eC76fa, Error: 'data'
[2025-08-01 04:19:00,384] 	ERROR 	63 	pair_data.py 	<module>() 	Error occurred during Pair Data Fusion process. Pair: OATH/WETH (1%), Address: 0x0c74834d67c4bf5e6a44D18b2BAc767cddB4CdBf, Error: 'data'
[2025-08-01 04:19:00,483] 	ERROR 	63 	pair_data.py 	<module>() 	Error occurred during Pair Data Fusion process. Pair: USDC.e/IBEX (1%), Address: 0x53D8c25B3d130D2810591cDc7A41Bd848bF79B63, Error: 'data'
[2025-08-01 04:19:00,579] 	ERROR 	63 	pair_data.py 	<module>() 	Error occurred during Pair Data Fusion process. Pair: USDC.e/fxDOLA (0.3%), Address: 0x896ffE2cd28Ba13ddDa98103a3B66E82bb36BeE3, Error: 'data'
[2025-08-01 04:19:00,671] 	ERROR 	63 	pair_data.py 	<module>() 	Error occurred during Pair Data Fusion process. Pair: USDC.e/FRAX (0.3%), Address: 0x091236A16952BC9e4bB817FFA7aB40263183f658, Error: 'data'
[2025-08-01 04:19:00,774] 	ERROR 	63 	pair_data.py 	<module>() 	Error occurred during Pair Data Fusion process. Pair: WBTC/USDC.e (0.3%), Address: 0x459F42C788E6F8faCe4854DDD59C81a6Ad8BB1Aa, Error: 'data'
[2025-08-01 04:19:00,868] 	ERROR 	63 	pair_data.py 	<module>() 	Error occurred during Pair Data Fusion process. Pair: WETH/ERN (0.3%), Address: 0xCF2093da3CeBb8731747EEaCbd486A7fcE2Db901, Error: 'data'
[2025-08-01 04:19:00,966] 	ERROR 	63 	pair_data.py 	<module>() 	Error occurred during Pair Data Fusion process. Pair: WETH/JARVIS (0.3%), Address: 0xf310d505B85E0378790Af9fDB9b79b40736f7b4D, Error: 'data'
[2025-08-01 04:19:01,066] 	ERROR 	63 	pair_data.py 	<module>() 	Error occurred during Pair Data Fusion process. Pair: jEUR/CASH (0.05%), Address: 0x65E6b7C7DfE071E52D6923E4079E3C0FcBeaA401, Error: 'data'
[2025-08-01 04:19:01,156] 	ERROR 	63 	pair_data.py 	<module>() 	Error occurred during Pair Data Fusion process. Pair: USDC.e/USDC (0.01%), Address: 0x1e0aa3f6C3130294845B8e162d838e221d170016, Error: 'data'
[2025-08-01 04:19:01,255] 	ERROR 	63 	pair_data.py 	<module>() 	Error occurred during Pair Data Fusion process. Pair: LUCHA/WETH (1%), Address: 0x098c1e4BB34DEcDF49D5966014B5153Af326E766, Error: 'data'
[2025-08-01 04:19:01,360] 	ERROR 	63 	pair_data.py 	<module>() 	Error occurred during Pair Data Fusion process. Pair: WPOL/LUCHA (1%), Address: 0xde4C8898CD50EBE9C167313b312D147D10d1C898, Error: 'data'
[2025-08-01 04:19:01,475] 	ERROR 	63 	pair_data.py 	<module>() 	Error occurred during Pair Data Fusion process. Pair: LINK/LUCHA (1%), Address: 0xA97B2b9AcA65aab57A6b0840B45777bd66fbcf33, Error: 'data'
[2025-08-01 04:19:01,570] 	ERROR 	63 	pair_data.py 	<module>() 	Error occurred during Pair Data Fusion process. Pair: CASH/LUCHA (1%), Address: 0x5c09352B1aa703d18dbcF48c98655BFA19d07FBB, Error: 'data'
[2025-08-01 04:19:01,682] 	ERROR 	103 	pair_data.py 	<module>() 	Error occurred during Pair Data Fusion process. Error: 'date'
Traceback (most recent call last):
  File "/opt/hostedtoolcache/Python/3.8.18/x64/lib/python3.8/site-packages/pandas/core/indexes/base.py", line 3802, in get_loc
    return self._engine.get_loc(casted_key)
  File "pandas/_libs/index.pyx", line 138, in pandas._libs.index.IndexEngine.get_loc
  File "pandas/_libs/index.pyx", line 165, in pandas._libs.index.IndexEngine.get_loc
  File "pandas/_libs/hashtable_class_helper.pxi", line 5745, in pandas._libs.hashtable.PyObjectHashTable.get_item
  File "pandas/_libs/hashtable_class_helper.pxi", line 5753, in pandas._libs.hashtable.PyObjectHashTable.get_item
KeyError: 'date'

The above exception was the direct cause of the following exception:

Traceback (most recent call last):
  File "pair_data.py", line 68, in <module>
    pairdata_fusion_df["date"] = pairdata_fusion_df["date"].apply(lambda timestamp: datetime.utcfromtimestamp(timestamp).date())
  File "/opt/hostedtoolcache/Python/3.8.18/x64/lib/python3.8/site-packages/pandas/core/frame.py", line 3807, in __getitem__
    indexer = self.columns.get_loc(key)
  File "/opt/hostedtoolcache/Python/3.8.18/x64/lib/python3.8/site-packages/pandas/core/indexes/base.py", line 3804, in get_loc
    raise KeyError(key) from err
KeyError: 'date'
[2025-08-01 04:19:02,517] 	INFO 	36 	bribe_data.py 	<module>() 	Bribe Data Started
[2025-08-01 04:19:02,989] 	ERROR 	159 	bribe_data.py 	<module>() 	Error occurred during Bribe Data process. Error: {'code': -32000, 'message': 'Unauthorized: You must authenticate your request with an API key. Create an account on https://www.ankr.com/rpc/ and generate your personal API key for free.'}
Traceback (most recent call last):
  File "bribe_data.py", line 71, in <module>
    rewardsListLength = contract_instance.functions.rewardsListLength().call()
  File "/opt/hostedtoolcache/Python/3.8.18/x64/lib/python3.8/site-packages/web3/contract.py", line 970, in call
    return call_contract_function(
  File "/opt/hostedtoolcache/Python/3.8.18/x64/lib/python3.8/site-packages/web3/contract.py", line 1525, in call_contract_function
    return_data = web3.eth.call(
  File "/opt/hostedtoolcache/Python/3.8.18/x64/lib/python3.8/site-packages/web3/module.py", line 57, in caller
    result = w3.manager.request_blocking(method_str,
  File "/opt/hostedtoolcache/Python/3.8.18/x64/lib/python3.8/site-packages/web3/manager.py", line 198, in request_blocking
    return self.formatted_response(response,
  File "/opt/hostedtoolcache/Python/3.8.18/x64/lib/python3.8/site-packages/web3/manager.py", line 171, in formatted_response
    raise ValueError(response["error"])
ValueError: {'code': -32000, 'message': 'Unauthorized: You must authenticate your request with an API key. Create an account on https://www.ankr.com/rpc/ and generate your personal API key for free.'}
[2025-08-01 04:19:03,823] 	INFO 	36 	fee_data.py 	<module>() 	Fee Data Started
[2025-08-01 04:19:04,024] 	ERROR 	159 	fee_data.py 	<module>() 	Error occurred during Fee Data process. Error: {'code': -32000, 'message': 'Unauthorized: You must authenticate your request with an API key. Create an account on https://www.ankr.com/rpc/ and generate your personal API key for free.'}
Traceback (most recent call last):
  File "fee_data.py", line 71, in <module>
    rewardsListLength = contract_instance.functions.rewardsListLength().call()
  File "/opt/hostedtoolcache/Python/3.8.18/x64/lib/python3.8/site-packages/web3/contract.py", line 970, in call
    return call_contract_function(
  File "/opt/hostedtoolcache/Python/3.8.18/x64/lib/python3.8/site-packages/web3/contract.py", line 1525, in call_contract_function
    return_data = web3.eth.call(
  File "/opt/hostedtoolcache/Python/3.8.18/x64/lib/python3.8/site-packages/web3/module.py", line 57, in caller
    result = w3.manager.request_blocking(method_str,
  File "/opt/hostedtoolcache/Python/3.8.18/x64/lib/python3.8/site-packages/web3/manager.py", line 198, in request_blocking
    return self.formatted_response(response,
  File "/opt/hostedtoolcache/Python/3.8.18/x64/lib/python3.8/site-packages/web3/manager.py", line 171, in formatted_response
    raise ValueError(response["error"])
ValueError: {'code': -32000, 'message': 'Unauthorized: You must authenticate your request with an API key. Create an account on https://www.ankr.com/rpc/ and generate your personal API key for free.'}
[2025-08-01 04:19:04,853] 	INFO 	37 	vote_data.py 	<module>() 	Vote Data Started
[2025-08-01 04:19:05,041] 	ERROR 	118 	vote_data.py 	<module>() 	Error occurred during Vote Data process. Error: Expecting value: line 1 column 1 (char 0)
Traceback (most recent call last):
  File "/opt/hostedtoolcache/Python/3.8.18/x64/lib/python3.8/site-packages/requests/models.py", line 971, in json
    return complexjson.loads(self.text, **kwargs)
  File "/opt/hostedtoolcache/Python/3.8.18/x64/lib/python3.8/json/__init__.py", line 357, in loads
    return _default_decoder.decode(s)
  File "/opt/hostedtoolcache/Python/3.8.18/x64/lib/python3.8/json/decoder.py", line 337, in decode
    obj, end = self.raw_decode(s, idx=_w(s, 0).end())
  File "/opt/hostedtoolcache/Python/3.8.18/x64/lib/python3.8/json/decoder.py", line 355, in raw_decode
    raise JSONDecodeError("Expecting value", s, err.value) from None
json.decoder.JSONDecodeError: Expecting value: line 1 column 1 (char 0)

During handling of the above exception, another exception occurred:

Traceback (most recent call last):
  File "vote_data.py", line 64, in <module>
    RETRO_price = jmespath.search("data[?name == 'RETRO'].price", response.json())[0]
  File "/opt/hostedtoolcache/Python/3.8.18/x64/lib/python3.8/site-packages/requests/models.py", line 975, in json
    raise RequestsJSONDecodeError(e.msg, e.doc, e.pos)
requests.exceptions.JSONDecodeError: Expecting value: line 1 column 1 (char 0)
[2025-08-01 04:19:05,862] 	INFO 	30 	revenue_data.py 	<module>() 	Revenue Data Started
[2025-08-01 04:19:14,194] 	ERROR 	152 	revenue_data.py 	<module>() 	Error occurred during Revenue Data process. Error: Expecting value: line 1 column 1 (char 0)
Traceback (most recent call last):
  File "/opt/hostedtoolcache/Python/3.8.18/x64/lib/python3.8/site-packages/requests/models.py", line 971, in json
    return complexjson.loads(self.text, **kwargs)
  File "/opt/hostedtoolcache/Python/3.8.18/x64/lib/python3.8/json/__init__.py", line 357, in loads
    return _default_decoder.decode(s)
  File "/opt/hostedtoolcache/Python/3.8.18/x64/lib/python3.8/json/decoder.py", line 337, in decode
    obj, end = self.raw_decode(s, idx=_w(s, 0).end())
  File "/opt/hostedtoolcache/Python/3.8.18/x64/lib/python3.8/json/decoder.py", line 355, in raw_decode
    raise JSONDecodeError("Expecting value", s, err.value) from None
json.decoder.JSONDecodeError: Expecting value: line 1 column 1 (char 0)

During handling of the above exception, another exception occurred:

Traceback (most recent call last):
  File "revenue_data.py", line 66, in <module>
    RETRO_price = jmespath.search("data[?name == 'RETRO'].price", response.json())[0]
  File "/opt/hostedtoolcache/Python/3.8.18/x64/lib/python3.8/site-packages/requests/models.py", line 975, in json
    raise RequestsJSONDecodeError(e.msg, e.doc, e.pos)
requests.exceptions.JSONDecodeError: Expecting value: line 1 column 1 (char 0)
[2025-08-01 05:08:17,897] 	INFO 	20 	id_data.py 	<module>() 	ID Data Started
[2025-08-01 05:08:18,479] 	ERROR 	33 	id_data.py 	<module>() 	Error occurred during ID Data process. Error: Expecting value: line 1 column 1 (char 0)
Traceback (most recent call last):
  File "/opt/hostedtoolcache/Python/3.8.18/x64/lib/python3.8/site-packages/requests/models.py", line 971, in json
    return complexjson.loads(self.text, **kwargs)
  File "/opt/hostedtoolcache/Python/3.8.18/x64/lib/python3.8/json/__init__.py", line 357, in loads
    return _default_decoder.decode(s)
  File "/opt/hostedtoolcache/Python/3.8.18/x64/lib/python3.8/json/decoder.py", line 337, in decode
    obj, end = self.raw_decode(s, idx=_w(s, 0).end())
  File "/opt/hostedtoolcache/Python/3.8.18/x64/lib/python3.8/json/decoder.py", line 355, in raw_decode
    raise JSONDecodeError("Expecting value", s, err.value) from None
json.decoder.JSONDecodeError: Expecting value: line 1 column 1 (char 0)

During handling of the above exception, another exception occurred:

Traceback (most recent call last):
  File "id_data.py", line 27, in <module>
    data = response.json()["data"]
  File "/opt/hostedtoolcache/Python/3.8.18/x64/lib/python3.8/site-packages/requests/models.py", line 975, in json
    raise RequestsJSONDecodeError(e.msg, e.doc, e.pos)
requests.exceptions.JSONDecodeError: Expecting value: line 1 column 1 (char 0)
[2025-08-01 05:08:19,009] 	INFO 	24 	day_data.py 	<module>() 	Day Data Fusion Started
[2025-08-01 05:08:19,319] 	ERROR 	73 	day_data.py 	<module>() 	Error occurred during Day Data Fusion process. Error: 'data'
Traceback (most recent call last):
  File "day_data.py", line 41, in <module>
    data = response.json()["data"]["uniswapDayDatas"]
KeyError: 'data'
[2025-08-01 05:08:20,203] 	INFO 	35 	pair_data.py 	<module>() 	Pair Data Fusion Started
[2025-08-01 05:08:20,664] 	ERROR 	63 	pair_data.py 	<module>() 	Error occurred during Pair Data Fusion process. Pair: sAMM-USDC.e/USDT, Address: 0xB38245b7fE8D594d883A27DB1055bf67926F6B27, Error: 'data'
[2025-08-01 05:08:20,822] 	ERROR 	63 	pair_data.py 	<module>() 	Error occurred during Pair Data Fusion process. Pair: vAMM-WPOL/elRETRO, Address: 0x90a09fE272540Ecd34661B91252f2aB4b7f7A4CE, Error: 'data'
[2025-08-01 05:08:21,078] 	ERROR 	63 	pair_data.py 	<module>() 	Error occurred during Pair Data Fusion process. Pair: sAMM-oRETRO/elRETRO, Address: 0xc58Eb718892Da5D519587A3ec87063A8a46c9feb, Error: 'data'
[2025-08-01 05:08:21,245] 	ERROR 	63 	pair_data.py 	<module>() 	Error occurred during Pair Data Fusion process. Pair: WPOL/WETH (0.05%), Address: 0x1a34EaBbe928Bf431B679959379b2225d60D9cdA, Error: 'data'
[2025-08-01 05:08:21,410] 	ERROR 	63 	pair_data.py 	<module>() 	Error occurred during Pair Data Fusion process. Pair: WPOL/USDC.e (0.05%), Address: 0xEC15624FBB314eb05BaaD4cA49b7904C0Cb6b645, Error: 'data'
[2025-08-01 05:08:21,618] 	ERROR 	63 	pair_data.py 	<module>() 	Error occurred during Pair Data Fusion process. Pair: USDC.e/WETH (0.05%), Address: 0xCE67850420c82dB45eb7fEeCcD2d181300D2BDB3, Error: 'data'
[2025-08-01 05:08:21,786] 	ERROR 	63 	pair_data.py 	<module>() 	Error occurred during Pair Data Fusion process. Pair: WBTC/WETH (0.05%), Address: 0xb694E3bdd4BCdF843510983D257679D1E627C474, Error: 'data'
[2025-08-01 05:08:21,930] 	ERROR 	63 	pair_data.py 	<module>() 	Error occurred during Pair Data Fusion process. Pair: WPOL/USDT (0.05%), Address: 0xB580229645b240A368768ec3E88cb67A41eBBC5B, Error: 'data'
[2025-08-01 05:08:22,090] 	ERROR 	63 	pair_data.py 	<module>() 	Error occurred during Pair Data Fusion process. Pair: WPOL/CASH (0.05%), Address: 0x63ca6ED3D390C725b7FEb617BAdcab78a61038E8, Error: 'data'
[2025-08-01 05:08:22,243] 	ERROR 	63 	pair_data.py 	<module>() 	Error occurred during Pair Data Fusion process. Pair: CASH/WETH (0.05%), Address: 0x0A46B0712974F201BeD15c2458a023EbED25eF4F, Error: 'data'
[2025-08-01 05:08:22,412] 	ERROR 	63 	pair_data.py 	<module>() 	Error occurred during Pair Data Fusion process. Pair: USDC.e/CASH (0.01%), Address: 0x619259F699839dD1498FFC22297044462483bD27, Error: 'data'
[2025-08-01 05:08:22,577] 	ERROR 	63 	pair_data.py 	<module>() 	Error occurred during Pair Data Fusion process. Pair: CASH/USDT (0.01%), Address: 0x160FBF00AB5fbF0200c0Cd4929aEaa2AdD25FB5b, Error: 'data'
[2025-08-01 05:08:22,735] 	ERROR 	63 	pair_data.py 	<module>() 	Error occurred during Pair Data Fusion process. Pair: CASH/DAI (0.01%), Address: 0x1e683586fCB45a769ef2C7d9d7b1803E9C1AEE79, Error: 'data'
[2025-08-01 05:08:22,899] 	ERROR 	63 	pair_data.py 	<module>() 	Error occurred during Pair Data Fusion process. Pair: CASH/miMATIC (0.01%), Address: 0xeB80047F7d5D4C4A3BC6319250d6b1b8aEe2d0D2, Error: 'data'
[2025-08-01 05:08:23,066] 	ERROR 	63 	pair_data.py 	<module>() 	Error occurred during Pair Data Fusion process. Pair: CASH/MaticX (0.05%), Address: 0xb98F8DF0DC6750A3e54540A1e094186C8bED780a, Error: 'data'
[2025-08-01 05:08:23,211] 	ERROR 	63 	pair_data.py 	<module>() 	Error occurred during Pair Data Fusion process. Pair: USDC.e/EURA (0.05%), Address: 0xC2CB03a819F785bD8eb8D628BAD41Cd7c1C71F4B, Error: 'data'
[2025-08-01 05:08:23,379] 	ERROR 	63 	pair_data.py 	<module>() 	Error occurred during Pair Data Fusion process. Pair: FRAX/CASH (0.01%), Address: 0x72289129Dc4937a5d406d1ECeD8b2A17d007A650, Error: 'data'
[2025-08-01 05:08:23,547] 	ERROR 	63 	pair_data.py 	<module>() 	Error occurred during Pair Data Fusion process. Pair: CASH/RETRO (1%), Address: 0xb47A07966cE6812702C0567d03725F1b37E27877, Error: 'data'
[2025-08-01 05:08:23,791] 	ERROR 	63 	pair_data.py 	<module>() 	Error occurred during Pair Data Fusion process. Pair: WETH/RETRO (1%), Address: 0x35394eED0Be676ec6470fE6531daD809265310ff, Error: 'data'
[2025-08-01 05:08:23,971] 	ERROR 	63 	pair_data.py 	<module>() 	Error occurred during Pair Data Fusion process. Pair: WPOL/RETRO (1%), Address: 0x547FD24AA2ED09d86dAC02E36b8Ce84A59fD644F, Error: 'data'
[2025-08-01 05:08:24,150] 	ERROR 	63 	pair_data.py 	<module>() 	Error occurred during Pair Data Fusion process. Pair: WBTC/RETRO (1%), Address: 0x0F73E719a76947752E4b26A2c3FC80a580e68fB4, Error: 'data'
[2025-08-01 05:08:24,353] 	ERROR 	63 	pair_data.py 	<module>() 	Error occurred during Pair Data Fusion process. Pair: stMATIC/RETRO (1%), Address: 0x0973698BB6399c39d628698f9300430C4e7c9bf9, Error: 'data'
[2025-08-01 05:08:24,538] 	ERROR 	63 	pair_data.py 	<module>() 	Error occurred during Pair Data Fusion process. Pair: USDC.e/RETRO (1%), Address: 0xc7d8B9c270D0E31A6a0Cf4496fe019766Be42E15, Error: 'data'
[2025-08-01 05:08:24,725] 	ERROR 	63 	pair_data.py 	<module>() 	Error occurred during Pair Data Fusion process. Pair: RETRO/USDT (1%), Address: 0x69dCAE97A1286B112a8BD75bD9147bD0a3207756, Error: 'data'
[2025-08-01 05:08:24,876] 	ERROR 	63 	pair_data.py 	<module>() 	Error occurred during Pair Data Fusion process. Pair: miMATIC/RETRO (1%), Address: 0xd98eEf295f78ddDd104a8645854C7F8714B39B88, Error: 'data'
[2025-08-01 05:08:25,058] 	ERROR 	63 	pair_data.py 	<module>() 	Error occurred during Pair Data Fusion process. Pair: LINK/RETRO (1%), Address: 0x7761c7233924C3D72F27Fae6a81B074C0152e03a, Error: 'data'
[2025-08-01 05:08:25,215] 	ERROR 	63 	pair_data.py 	<module>() 	Error occurred during Pair Data Fusion process. Pair: RETRO/EURA (1%), Address: 0x15949526fF03fE6ab5f49dA6a86749c20141b3f1, Error: 'data'
[2025-08-01 05:08:25,369] 	ERROR 	63 	pair_data.py 	<module>() 	Error occurred during Pair Data Fusion process. Pair: USDC.e/USDT (0.01%), Address: 0x772510189425ac63f9a5A5eF2fd0C7FDA58CBFC7, Error: 'data'
[2025-08-01 05:08:25,548] 	ERROR 	63 	pair_data.py 	<module>() 	Error occurred during Pair Data Fusion process. Pair: USDC.e/DAI (0.01%), Address: 0x219116F23BDC11EB25e4D0FbE92eD0972d86BE20, Error: 'data'
[2025-08-01 05:08:25,692] 	ERROR 	63 	pair_data.py 	<module>() 	Error occurred during Pair Data Fusion process. Pair: WPOL/MaticX (0.01%), Address: 0x9aa18301055091e9da7C57b81633632Fa33B9a80, Error: 'data'
[2025-08-01 05:08:25,856] 	ERROR 	63 	pair_data.py 	<module>() 	Error occurred during Pair Data Fusion process. Pair: wstETH/WETH (0.01%), Address: 0xa9439Db1D7025Ce4aAc513Baf5eee5220172126C, Error: 'data'
[2025-08-01 05:08:26,154] 	ERROR 	63 	pair_data.py 	<module>() 	Error occurred during Pair Data Fusion process. Pair: WPOL/stMATIC (0.01%), Address: 0x2d623c33673248E95C7a1C26aE7065eb7A7Ac0Ea, Error: 'data'
[2025-08-01 05:08:26,326] 	ERROR 	63 	pair_data.py 	<module>() 	Error occurred during Pair Data Fusion process. Pair: WETH/frxETH (0.01%), Address: 0xe5069a75Bdfe8F676B778B0aaDCcC597841F819B, Error: 'data'
[2025-08-01 05:08:26,514] 	ERROR 	63 	pair_data.py 	<module>() 	Error occurred during Pair Data Fusion process. Pair: FRAX/frxETH (0.05%), Address: 0x38df0c93bf69a9EfB3d3647fF459eF27235A8968, Error: 'data'
[2025-08-01 05:08:26,671] 	ERROR 	63 	pair_data.py 	<module>() 	Error occurred during Pair Data Fusion process. Pair: WPOL/frxETH (0.05%), Address: 0x44AAE81BE8435b6998A66d9642f66DE57DD03FC2, Error: 'data'
[2025-08-01 05:08:26,819] 	ERROR 	63 	pair_data.py 	<module>() 	Error occurred during Pair Data Fusion process. Pair: xbb-t-USD/CASH (0.01%), Address: 0x07dBf448cCC68cA64247da04F2E24643eCf57385, Error: 'data'
[2025-08-01 05:08:27,062] 	ERROR 	63 	pair_data.py 	<module>() 	Error occurred during Pair Data Fusion process. Pair: LINK/LUCHA (0.3%), Address: 0x91248C85DD408BD216254C3cFb51fc326290cF7e, Error: 'data'
[2025-08-01 05:08:27,216] 	ERROR 	63 	pair_data.py 	<module>() 	Error occurred during Pair Data Fusion process. Pair: CASH/LUCHA (0.3%), Address: 0xc666c4b402Bd797185EA419261D22a8f22DDFce6, Error: 'data'
[2025-08-01 05:08:27,458] 	ERROR 	63 	pair_data.py 	<module>() 	Error occurred during Pair Data Fusion process. Pair: USDC.e/miMATIC (0.3%), Address: 0xb090BE2D2F02646057d4DF997A7A983dFb265de0, Error: 'data'
[2025-08-01 05:08:27,620] 	ERROR 	63 	pair_data.py 	<module>() 	Error occurred during Pair Data Fusion process. Pair: FRAX/miMATIC (0.3%), Address: 0xdeB25Dd2d5D168Fd6f80F154d96a2Dab81d61845, Error: 'data'
[2025-08-01 05:08:27,769] 	ERROR 	63 	pair_data.py 	<module>() 	Error occurred during Pair Data Fusion process. Pair: WPOL/miMATIC (0.3%), Address: 0xC571445Fc93666e1E4FaE2E84A7b74FE6ed3978D, Error: 'data'
[2025-08-01 05:08:27,938] 	ERROR 	63 	pair_data.py 	<module>() 	Error occurred during Pair Data Fusion process. Pair: CASH/ERN (0.3%), Address: 0x777a87889f42C33f9A1E5c117774694bbd857075, Error: 'data'
[2025-08-01 05:08:28,114] 	ERROR 	63 	pair_data.py 	<module>() 	Error occurred during Pair Data Fusion process. Pair: ICHI/RETRO (1%), Address: 0xC26E1a0cDab4Bf5141530C49F3360f162C5Db5Db, Error: 'data'
[2025-08-01 05:08:28,257] 	ERROR 	63 	pair_data.py 	<module>() 	Error occurred during Pair Data Fusion process. Pair: WPOL/ICHI (0.3%), Address: 0x13d5e61838D93F7962C52dc921FD7C0Ccc092E35, Error: 'data'
[2025-08-01 05:08:28,458] 	ERROR 	63 	pair_data.py 	<module>() 	Error occurred during Pair Data Fusion process. Pair: SD/MaticX (0.3%), Address: 0xB97c62834e096858BD0B996b758942dd43d7B5eE, Error: 'data'
[2025-08-01 05:08:28,607] 	ERROR 	63 	pair_data.py 	<module>() 	Error occurred during Pair Data Fusion process. Pair: stERN/ERN (1%), Address: 0x99583057951987beD85CE6934473160bFD4921b9, Error: 'data'
[2025-08-01 05:08:28,761] 	ERROR 	63 	pair_data.py 	<module>() 	Error occurred during Pair Data Fusion process. Pair: tUSDC/STAR (0.05%), Address: 0x53C49b9308c3DB176d351d7914Cec0Fb5D7f1129, Error: 'data'
[2025-08-01 05:08:28,921] 	ERROR 	63 	pair_data.py 	<module>() 	Error occurred during Pair Data Fusion process. Pair: WPOL/LUCHA (0.3%), Address: 0x52BeedA850A7048e9D543668BF54E0d9E1B667E0, Error: 'data'
[2025-08-01 05:08:29,116] 	ERROR 	63 	pair_data.py 	<module>() 	Error occurred during Pair Data Fusion process. Pair: LUCHA/WETH (0.3%), Address: 0x13136EA148331a07497087bfc31fBCcD9b99123c, Error: 'data'
[2025-08-01 05:08:29,278] 	ERROR 	63 	pair_data.py 	<module>() 	Error occurred during Pair Data Fusion process. Pair: JRT/WETH (0.3%), Address: 0xAE107e52ebdF151E61d9Fb4Bd800C86c31741465, Error: 'data'
[2025-08-01 05:08:29,426] 	ERROR 	63 	pair_data.py 	<module>() 	Error occurred during Pair Data Fusion process. Pair: axlLqdr/CASH (0.3%), Address: 0x22c10e61A05a03bcd8BF61a7E648f2330ecdA270, Error: 'data'
[2025-08-01 05:08:29,582] 	ERROR 	63 	pair_data.py 	<module>() 	Error occurred during Pair Data Fusion process. Pair: XOC/jMXN (0.01%), Address: 0xccE01e3615785771b84Eb5F88EC612AC6704FdE2, Error: 'data'
[2025-08-01 05:08:29,733] 	ERROR 	63 	pair_data.py 	<module>() 	Error occurred during Pair Data Fusion process. Pair: ICHI/CASH (1%), Address: 0x8ceD58A2dE3C2ea5D3cED3eb4331158c8cf985Fb, Error: 'data'
[2025-08-01 05:08:29,892] 	ERROR 	63 	pair_data.py 	<module>() 	Error occurred during Pair Data Fusion process. Pair: wUSDR/CASH (0.3%), Address: 0x3baEa49B71461DEaB46E6F42548D0005359ff629, Error: 'data'
[2025-08-01 05:08:30,089] 	ERROR 	63 	pair_data.py 	<module>() 	Error occurred during Pair Data Fusion process. Pair: CASH/STAR (0.05%), Address: 0x88C522E526E5Eea8d636fd6805cA7fEB488780D0, Error: 'data'
[2025-08-01 05:08:30,240] 	ERROR 	63 	pair_data.py 	<module>() 	Error occurred during Pair Data Fusion process. Pair: USDC.e/STAR (0.01%), Address: 0x6De0CA91Ef19A6ce9f02A423ae2dF89Fe09Bff0F, Error: 'data'
[2025-08-01 05:08:30,476] 	ERROR 	63 	pair_data.py 	<module>() 	Error occurred during Pair Data Fusion process. Pair: tUSDC/STAR (1%), Address: 0xaC44f57eEF260eB6E0f896b61984Da8d86FeE9ed, Error: 'data'
[2025-08-01 05:08:30,637] 	ERROR 	63 	pair_data.py 	<module>() 	Error occurred during Pair Data Fusion process. Pair: tUSDC/CASH (1%), Address: 0x4FcdB2DCc4Ce156c723aD541dba8B39d47284FC5, Error: 'data'
[2025-08-01 05:08:30,785] 	ERROR 	63 	pair_data.py 	<module>() 	Error occurred during Pair Data Fusion process. Pair: WPOL/USDC.e (0.3%), Address: 0x8c862d100B94d95a49D91958c9e8C2c348d00F04, Error: 'data'
[2025-08-01 05:08:30,940] 	ERROR 	63 	pair_data.py 	<module>() 	Error occurred during Pair Data Fusion process. Pair: WPOL/WETH (0.3%), Address: 0xB8dD18F9b7C3Ad4bDd4B94cB819eda3bd4465119, Error: 'data'
[2025-08-01 05:08:31,103] 	ERROR 	63 	pair_data.py 	<module>() 	Error occurred during Pair Data Fusion process. Pair: USDC.e/WETH (0.3%), Address: 0x058F5330Fef74445878110e201B04F36f8a51c9b, Error: 'data'
[2025-08-01 05:08:31,260] 	ERROR 	63 	pair_data.py 	<module>() 	Error occurred during Pair Data Fusion process. Pair: WBTC/WETH (0.3%), Address: 0x11275C625A7DEE3532E062Eef6915f00af85C3B5, Error: 'data'
[2025-08-01 05:08:31,439] 	ERROR 	63 	pair_data.py 	<module>() 	Error occurred during Pair Data Fusion process. Pair: LINK/WETH (0.3%), Address: 0x555eABEEfe6a047747071525A2c0fFd96d945f69, Error: 'data'
[2025-08-01 05:08:31,600] 	ERROR 	63 	pair_data.py 	<module>() 	Error occurred during Pair Data Fusion process. Pair: WBTC/CASH (0.3%), Address: 0x2C8F7d92Dc7A414D343CbFB687E31a11F525d29e, Error: 'data'
[2025-08-01 05:08:31,790] 	ERROR 	63 	pair_data.py 	<module>() 	Error occurred during Pair Data Fusion process. Pair: WPOL/DEUS (1%), Address: 0xB5cB765e44Eca4bc5a434fFaf6Bf7De235Bc60a5, Error: 'data'
[2025-08-01 05:08:31,960] 	ERROR 	63 	pair_data.py 	<module>() 	Error occurred during Pair Data Fusion process. Pair: WPOL/WBTC (0.3%), Address: 0x2981A1f699eA7149aa08121A07F000cf82846A9e, Error: 'data'
[2025-08-01 05:08:32,200] 	ERROR 	63 	pair_data.py 	<module>() 	Error occurred during Pair Data Fusion process. Pair: FRAX/STAR (0.05%), Address: 0x7D480cBf5Aee75E72eF26F223937f3981d67a860, Error: 'data'
[2025-08-01 05:08:32,402] 	ERROR 	63 	pair_data.py 	<module>() 	Error occurred during Pair Data Fusion process. Pair: CASH/TAROT (0.3%), Address: 0x217aEb0667b79584FBf6265B74a8cD22E1245fdC, Error: 'data'
[2025-08-01 05:08:32,563] 	ERROR 	63 	pair_data.py 	<module>() 	Error occurred during Pair Data Fusion process. Pair: CASH/fxDOLA (0.05%), Address: 0x4b4B895a0dD744B4893aA4370A8F7eDbde5Fd90e, Error: 'data'
[2025-08-01 05:08:32,731] 	ERROR 	63 	pair_data.py 	<module>() 	Error occurred during Pair Data Fusion process. Pair: RETRO/liveRetro (1%), Address: 0x6333BB8b6f1DDa6f929d70eDEB9e31c8148dC9ef, Error: 'data'
[2025-08-01 05:08:32,937] 	ERROR 	63 	pair_data.py 	<module>() 	Error occurred during Pair Data Fusion process. Pair: MVX/WETH (1%), Address: 0xCC72276de3BCc1b159F1B60A86B0211116022B42, Error: 'data'
[2025-08-01 05:08:33,095] 	ERROR 	63 	pair_data.py 	<module>() 	Error occurred during Pair Data Fusion process. Pair: WPOL/elRETRO (1%), Address: 0x6794Db07e2efE1307b8594FBbBFad78E50eC76fa, Error: 'data'
[2025-08-01 05:08:33,239] 	ERROR 	63 	pair_data.py 	<module>() 	Error occurred during Pair Data Fusion process. Pair: OATH/WETH (1%), Address: 0x0c74834d67c4bf5e6a44D18b2BAc767cddB4CdBf, Error: 'data'
[2025-08-01 05:08:33,388] 	ERROR 	63 	pair_data.py 	<module>() 	Error occurred during Pair Data Fusion process. Pair: USDC.e/IBEX (1%), Address: 0x53D8c25B3d130D2810591cDc7A41Bd848bF79B63, Error: 'data'
[2025-08-01 05:08:33,582] 	ERROR 	63 	pair_data.py 	<module>() 	Error occurred during Pair Data Fusion process. Pair: USDC.e/fxDOLA (0.3%), Address: 0x896ffE2cd28Ba13ddDa98103a3B66E82bb36BeE3, Error: 'data'
[2025-08-01 05:08:33,838] 	ERROR 	63 	pair_data.py 	<module>() 	Error occurred during Pair Data Fusion process. Pair: USDC.e/FRAX (0.3%), Address: 0x091236A16952BC9e4bB817FFA7aB40263183f658, Error: 'data'
[2025-08-01 05:08:34,008] 	ERROR 	63 	pair_data.py 	<module>() 	Error occurred during Pair Data Fusion process. Pair: WBTC/USDC.e (0.3%), Address: 0x459F42C788E6F8faCe4854DDD59C81a6Ad8BB1Aa, Error: 'data'
[2025-08-01 05:08:34,158] 	ERROR 	63 	pair_data.py 	<module>() 	Error occurred during Pair Data Fusion process. Pair: WETH/ERN (0.3%), Address: 0xCF2093da3CeBb8731747EEaCbd486A7fcE2Db901, Error: 'data'
[2025-08-01 05:08:34,325] 	ERROR 	63 	pair_data.py 	<module>() 	Error occurred during Pair Data Fusion process. Pair: WETH/JARVIS (0.3%), Address: 0xf310d505B85E0378790Af9fDB9b79b40736f7b4D, Error: 'data'
[2025-08-01 05:08:34,472] 	ERROR 	63 	pair_data.py 	<module>() 	Error occurred during Pair Data Fusion process. Pair: jEUR/CASH (0.05%), Address: 0x65E6b7C7DfE071E52D6923E4079E3C0FcBeaA401, Error: 'data'
[2025-08-01 05:08:34,618] 	ERROR 	63 	pair_data.py 	<module>() 	Error occurred during Pair Data Fusion process. Pair: USDC.e/USDC (0.01%), Address: 0x1e0aa3f6C3130294845B8e162d838e221d170016, Error: 'data'
[2025-08-01 05:08:34,769] 	ERROR 	63 	pair_data.py 	<module>() 	Error occurred during Pair Data Fusion process. Pair: LUCHA/WETH (1%), Address: 0x098c1e4BB34DEcDF49D5966014B5153Af326E766, Error: 'data'
[2025-08-01 05:08:34,964] 	ERROR 	63 	pair_data.py 	<module>() 	Error occurred during Pair Data Fusion process. Pair: WPOL/LUCHA (1%), Address: 0xde4C8898CD50EBE9C167313b312D147D10d1C898, Error: 'data'
[2025-08-01 05:08:35,117] 	ERROR 	63 	pair_data.py 	<module>() 	Error occurred during Pair Data Fusion process. Pair: LINK/LUCHA (1%), Address: 0xA97B2b9AcA65aab57A6b0840B45777bd66fbcf33, Error: 'data'
[2025-08-01 05:08:35,293] 	ERROR 	63 	pair_data.py 	<module>() 	Error occurred during Pair Data Fusion process. Pair: CASH/LUCHA (1%), Address: 0x5c09352B1aa703d18dbcF48c98655BFA19d07FBB, Error: 'data'
[2025-08-01 05:08:35,521] 	ERROR 	103 	pair_data.py 	<module>() 	Error occurred during Pair Data Fusion process. Error: 'date'
Traceback (most recent call last):
  File "/opt/hostedtoolcache/Python/3.8.18/x64/lib/python3.8/site-packages/pandas/core/indexes/base.py", line 3802, in get_loc
    return self._engine.get_loc(casted_key)
  File "pandas/_libs/index.pyx", line 138, in pandas._libs.index.IndexEngine.get_loc
  File "pandas/_libs/index.pyx", line 165, in pandas._libs.index.IndexEngine.get_loc
  File "pandas/_libs/hashtable_class_helper.pxi", line 5745, in pandas._libs.hashtable.PyObjectHashTable.get_item
  File "pandas/_libs/hashtable_class_helper.pxi", line 5753, in pandas._libs.hashtable.PyObjectHashTable.get_item
KeyError: 'date'

The above exception was the direct cause of the following exception:

Traceback (most recent call last):
  File "pair_data.py", line 68, in <module>
    pairdata_fusion_df["date"] = pairdata_fusion_df["date"].apply(lambda timestamp: datetime.utcfromtimestamp(timestamp).date())
  File "/opt/hostedtoolcache/Python/3.8.18/x64/lib/python3.8/site-packages/pandas/core/frame.py", line 3807, in __getitem__
    indexer = self.columns.get_loc(key)
  File "/opt/hostedtoolcache/Python/3.8.18/x64/lib/python3.8/site-packages/pandas/core/indexes/base.py", line 3804, in get_loc
    raise KeyError(key) from err
KeyError: 'date'
[2025-08-01 05:08:36,355] 	INFO 	36 	bribe_data.py 	<module>() 	Bribe Data Started
[2025-08-01 05:08:36,830] 	ERROR 	159 	bribe_data.py 	<module>() 	Error occurred during Bribe Data process. Error: {'code': -32000, 'message': 'Unauthorized: You must authenticate your request with an API key. Create an account on https://www.ankr.com/rpc/ and generate your personal API key for free.'}
Traceback (most recent call last):
  File "bribe_data.py", line 71, in <module>
    rewardsListLength = contract_instance.functions.rewardsListLength().call()
  File "/opt/hostedtoolcache/Python/3.8.18/x64/lib/python3.8/site-packages/web3/contract.py", line 970, in call
    return call_contract_function(
  File "/opt/hostedtoolcache/Python/3.8.18/x64/lib/python3.8/site-packages/web3/contract.py", line 1525, in call_contract_function
    return_data = web3.eth.call(
  File "/opt/hostedtoolcache/Python/3.8.18/x64/lib/python3.8/site-packages/web3/module.py", line 57, in caller
    result = w3.manager.request_blocking(method_str,
  File "/opt/hostedtoolcache/Python/3.8.18/x64/lib/python3.8/site-packages/web3/manager.py", line 198, in request_blocking
    return self.formatted_response(response,
  File "/opt/hostedtoolcache/Python/3.8.18/x64/lib/python3.8/site-packages/web3/manager.py", line 171, in formatted_response
    raise ValueError(response["error"])
ValueError: {'code': -32000, 'message': 'Unauthorized: You must authenticate your request with an API key. Create an account on https://www.ankr.com/rpc/ and generate your personal API key for free.'}
[2025-08-01 05:08:37,694] 	INFO 	36 	fee_data.py 	<module>() 	Fee Data Started
[2025-08-01 05:08:37,876] 	ERROR 	159 	fee_data.py 	<module>() 	Error occurred during Fee Data process. Error: {'code': -32000, 'message': 'Unauthorized: You must authenticate your request with an API key. Create an account on https://www.ankr.com/rpc/ and generate your personal API key for free.'}
Traceback (most recent call last):
  File "fee_data.py", line 71, in <module>
    rewardsListLength = contract_instance.functions.rewardsListLength().call()
  File "/opt/hostedtoolcache/Python/3.8.18/x64/lib/python3.8/site-packages/web3/contract.py", line 970, in call
    return call_contract_function(
  File "/opt/hostedtoolcache/Python/3.8.18/x64/lib/python3.8/site-packages/web3/contract.py", line 1525, in call_contract_function
    return_data = web3.eth.call(
  File "/opt/hostedtoolcache/Python/3.8.18/x64/lib/python3.8/site-packages/web3/module.py", line 57, in caller
    result = w3.manager.request_blocking(method_str,
  File "/opt/hostedtoolcache/Python/3.8.18/x64/lib/python3.8/site-packages/web3/manager.py", line 198, in request_blocking
    return self.formatted_response(response,
  File "/opt/hostedtoolcache/Python/3.8.18/x64/lib/python3.8/site-packages/web3/manager.py", line 171, in formatted_response
    raise ValueError(response["error"])
ValueError: {'code': -32000, 'message': 'Unauthorized: You must authenticate your request with an API key. Create an account on https://www.ankr.com/rpc/ and generate your personal API key for free.'}
[2025-08-01 05:08:38,729] 	INFO 	37 	vote_data.py 	<module>() 	Vote Data Started
[2025-08-01 05:08:39,087] 	ERROR 	118 	vote_data.py 	<module>() 	Error occurred during Vote Data process. Error: Expecting value: line 1 column 1 (char 0)
Traceback (most recent call last):
  File "/opt/hostedtoolcache/Python/3.8.18/x64/lib/python3.8/site-packages/requests/models.py", line 971, in json
    return complexjson.loads(self.text, **kwargs)
  File "/opt/hostedtoolcache/Python/3.8.18/x64/lib/python3.8/json/__init__.py", line 357, in loads
    return _default_decoder.decode(s)
  File "/opt/hostedtoolcache/Python/3.8.18/x64/lib/python3.8/json/decoder.py", line 337, in decode
    obj, end = self.raw_decode(s, idx=_w(s, 0).end())
  File "/opt/hostedtoolcache/Python/3.8.18/x64/lib/python3.8/json/decoder.py", line 355, in raw_decode
    raise JSONDecodeError("Expecting value", s, err.value) from None
json.decoder.JSONDecodeError: Expecting value: line 1 column 1 (char 0)

During handling of the above exception, another exception occurred:

Traceback (most recent call last):
  File "vote_data.py", line 64, in <module>
    RETRO_price = jmespath.search("data[?name == 'RETRO'].price", response.json())[0]
  File "/opt/hostedtoolcache/Python/3.8.18/x64/lib/python3.8/site-packages/requests/models.py", line 975, in json
    raise RequestsJSONDecodeError(e.msg, e.doc, e.pos)
requests.exceptions.JSONDecodeError: Expecting value: line 1 column 1 (char 0)
[2025-08-01 05:08:39,937] 	INFO 	30 	revenue_data.py 	<module>() 	Revenue Data Started
[2025-08-01 05:08:46,691] 	ERROR 	152 	revenue_data.py 	<module>() 	Error occurred during Revenue Data process. Error: Expecting value: line 1 column 1 (char 0)
Traceback (most recent call last):
  File "/opt/hostedtoolcache/Python/3.8.18/x64/lib/python3.8/site-packages/requests/models.py", line 971, in json
    return complexjson.loads(self.text, **kwargs)
  File "/opt/hostedtoolcache/Python/3.8.18/x64/lib/python3.8/json/__init__.py", line 357, in loads
    return _default_decoder.decode(s)
  File "/opt/hostedtoolcache/Python/3.8.18/x64/lib/python3.8/json/decoder.py", line 337, in decode
    obj, end = self.raw_decode(s, idx=_w(s, 0).end())
  File "/opt/hostedtoolcache/Python/3.8.18/x64/lib/python3.8/json/decoder.py", line 355, in raw_decode
    raise JSONDecodeError("Expecting value", s, err.value) from None
json.decoder.JSONDecodeError: Expecting value: line 1 column 1 (char 0)

During handling of the above exception, another exception occurred:

Traceback (most recent call last):
  File "revenue_data.py", line 66, in <module>
    RETRO_price = jmespath.search("data[?name == 'RETRO'].price", response.json())[0]
  File "/opt/hostedtoolcache/Python/3.8.18/x64/lib/python3.8/site-packages/requests/models.py", line 975, in json
    raise RequestsJSONDecodeError(e.msg, e.doc, e.pos)
requests.exceptions.JSONDecodeError: Expecting value: line 1 column 1 (char 0)
[2025-08-01 05:56:23,526] 	INFO 	20 	id_data.py 	<module>() 	ID Data Started
[2025-08-01 05:56:23,729] 	ERROR 	33 	id_data.py 	<module>() 	Error occurred during ID Data process. Error: Expecting value: line 1 column 1 (char 0)
Traceback (most recent call last):
  File "/opt/hostedtoolcache/Python/3.8.18/x64/lib/python3.8/site-packages/requests/models.py", line 971, in json
    return complexjson.loads(self.text, **kwargs)
  File "/opt/hostedtoolcache/Python/3.8.18/x64/lib/python3.8/json/__init__.py", line 357, in loads
    return _default_decoder.decode(s)
  File "/opt/hostedtoolcache/Python/3.8.18/x64/lib/python3.8/json/decoder.py", line 337, in decode
    obj, end = self.raw_decode(s, idx=_w(s, 0).end())
  File "/opt/hostedtoolcache/Python/3.8.18/x64/lib/python3.8/json/decoder.py", line 355, in raw_decode
    raise JSONDecodeError("Expecting value", s, err.value) from None
json.decoder.JSONDecodeError: Expecting value: line 1 column 1 (char 0)

During handling of the above exception, another exception occurred:

Traceback (most recent call last):
  File "id_data.py", line 27, in <module>
    data = response.json()["data"]
  File "/opt/hostedtoolcache/Python/3.8.18/x64/lib/python3.8/site-packages/requests/models.py", line 975, in json
    raise RequestsJSONDecodeError(e.msg, e.doc, e.pos)
requests.exceptions.JSONDecodeError: Expecting value: line 1 column 1 (char 0)
[2025-08-01 05:56:24,268] 	INFO 	24 	day_data.py 	<module>() 	Day Data Fusion Started
[2025-08-01 05:56:24,426] 	ERROR 	73 	day_data.py 	<module>() 	Error occurred during Day Data Fusion process. Error: 'data'
Traceback (most recent call last):
  File "day_data.py", line 41, in <module>
    data = response.json()["data"]["uniswapDayDatas"]
KeyError: 'data'
[2025-08-01 05:56:25,295] 	INFO 	35 	pair_data.py 	<module>() 	Pair Data Fusion Started
[2025-08-01 05:56:25,477] 	ERROR 	63 	pair_data.py 	<module>() 	Error occurred during Pair Data Fusion process. Pair: sAMM-USDC.e/USDT, Address: 0xB38245b7fE8D594d883A27DB1055bf67926F6B27, Error: 'data'
[2025-08-01 05:56:25,573] 	ERROR 	63 	pair_data.py 	<module>() 	Error occurred during Pair Data Fusion process. Pair: vAMM-WPOL/elRETRO, Address: 0x90a09fE272540Ecd34661B91252f2aB4b7f7A4CE, Error: 'data'
[2025-08-01 05:56:25,672] 	ERROR 	63 	pair_data.py 	<module>() 	Error occurred during Pair Data Fusion process. Pair: sAMM-oRETRO/elRETRO, Address: 0xc58Eb718892Da5D519587A3ec87063A8a46c9feb, Error: 'data'
[2025-08-01 05:56:25,766] 	ERROR 	63 	pair_data.py 	<module>() 	Error occurred during Pair Data Fusion process. Pair: WPOL/WETH (0.05%), Address: 0x1a34EaBbe928Bf431B679959379b2225d60D9cdA, Error: 'data'
[2025-08-01 05:56:25,863] 	ERROR 	63 	pair_data.py 	<module>() 	Error occurred during Pair Data Fusion process. Pair: WPOL/USDC.e (0.05%), Address: 0xEC15624FBB314eb05BaaD4cA49b7904C0Cb6b645, Error: 'data'
[2025-08-01 05:56:25,959] 	ERROR 	63 	pair_data.py 	<module>() 	Error occurred during Pair Data Fusion process. Pair: USDC.e/WETH (0.05%), Address: 0xCE67850420c82dB45eb7fEeCcD2d181300D2BDB3, Error: 'data'
[2025-08-01 05:56:26,059] 	ERROR 	63 	pair_data.py 	<module>() 	Error occurred during Pair Data Fusion process. Pair: WBTC/WETH (0.05%), Address: 0xb694E3bdd4BCdF843510983D257679D1E627C474, Error: 'data'
[2025-08-01 05:56:26,161] 	ERROR 	63 	pair_data.py 	<module>() 	Error occurred during Pair Data Fusion process. Pair: WPOL/USDT (0.05%), Address: 0xB580229645b240A368768ec3E88cb67A41eBBC5B, Error: 'data'
[2025-08-01 05:56:26,293] 	ERROR 	63 	pair_data.py 	<module>() 	Error occurred during Pair Data Fusion process. Pair: WPOL/CASH (0.05%), Address: 0x63ca6ED3D390C725b7FEb617BAdcab78a61038E8, Error: 'data'
[2025-08-01 05:56:26,399] 	ERROR 	63 	pair_data.py 	<module>() 	Error occurred during Pair Data Fusion process. Pair: CASH/WETH (0.05%), Address: 0x0A46B0712974F201BeD15c2458a023EbED25eF4F, Error: 'data'
[2025-08-01 05:56:26,513] 	ERROR 	63 	pair_data.py 	<module>() 	Error occurred during Pair Data Fusion process. Pair: USDC.e/CASH (0.01%), Address: 0x619259F699839dD1498FFC22297044462483bD27, Error: 'data'
[2025-08-01 05:56:26,615] 	ERROR 	63 	pair_data.py 	<module>() 	Error occurred during Pair Data Fusion process. Pair: CASH/USDT (0.01%), Address: 0x160FBF00AB5fbF0200c0Cd4929aEaa2AdD25FB5b, Error: 'data'
[2025-08-01 05:56:26,742] 	ERROR 	63 	pair_data.py 	<module>() 	Error occurred during Pair Data Fusion process. Pair: CASH/DAI (0.01%), Address: 0x1e683586fCB45a769ef2C7d9d7b1803E9C1AEE79, Error: 'data'
[2025-08-01 05:56:26,842] 	ERROR 	63 	pair_data.py 	<module>() 	Error occurred during Pair Data Fusion process. Pair: CASH/miMATIC (0.01%), Address: 0xeB80047F7d5D4C4A3BC6319250d6b1b8aEe2d0D2, Error: 'data'
[2025-08-01 05:56:26,933] 	ERROR 	63 	pair_data.py 	<module>() 	Error occurred during Pair Data Fusion process. Pair: CASH/MaticX (0.05%), Address: 0xb98F8DF0DC6750A3e54540A1e094186C8bED780a, Error: 'data'
[2025-08-01 05:56:27,026] 	ERROR 	63 	pair_data.py 	<module>() 	Error occurred during Pair Data Fusion process. Pair: USDC.e/EURA (0.05%), Address: 0xC2CB03a819F785bD8eb8D628BAD41Cd7c1C71F4B, Error: 'data'
[2025-08-01 05:56:27,145] 	ERROR 	63 	pair_data.py 	<module>() 	Error occurred during Pair Data Fusion process. Pair: FRAX/CASH (0.01%), Address: 0x72289129Dc4937a5d406d1ECeD8b2A17d007A650, Error: 'data'
[2025-08-01 05:56:27,238] 	ERROR 	63 	pair_data.py 	<module>() 	Error occurred during Pair Data Fusion process. Pair: CASH/RETRO (1%), Address: 0xb47A07966cE6812702C0567d03725F1b37E27877, Error: 'data'
[2025-08-01 05:56:27,348] 	ERROR 	63 	pair_data.py 	<module>() 	Error occurred during Pair Data Fusion process. Pair: WETH/RETRO (1%), Address: 0x35394eED0Be676ec6470fE6531daD809265310ff, Error: 'data'
[2025-08-01 05:56:27,445] 	ERROR 	63 	pair_data.py 	<module>() 	Error occurred during Pair Data Fusion process. Pair: WPOL/RETRO (1%), Address: 0x547FD24AA2ED09d86dAC02E36b8Ce84A59fD644F, Error: 'data'
[2025-08-01 05:56:27,550] 	ERROR 	63 	pair_data.py 	<module>() 	Error occurred during Pair Data Fusion process. Pair: WBTC/RETRO (1%), Address: 0x0F73E719a76947752E4b26A2c3FC80a580e68fB4, Error: 'data'
[2025-08-01 05:56:27,649] 	ERROR 	63 	pair_data.py 	<module>() 	Error occurred during Pair Data Fusion process. Pair: stMATIC/RETRO (1%), Address: 0x0973698BB6399c39d628698f9300430C4e7c9bf9, Error: 'data'
[2025-08-01 05:56:27,772] 	ERROR 	63 	pair_data.py 	<module>() 	Error occurred during Pair Data Fusion process. Pair: USDC.e/RETRO (1%), Address: 0xc7d8B9c270D0E31A6a0Cf4496fe019766Be42E15, Error: 'data'
[2025-08-01 05:56:27,882] 	ERROR 	63 	pair_data.py 	<module>() 	Error occurred during Pair Data Fusion process. Pair: RETRO/USDT (1%), Address: 0x69dCAE97A1286B112a8BD75bD9147bD0a3207756, Error: 'data'
[2025-08-01 05:56:28,007] 	ERROR 	63 	pair_data.py 	<module>() 	Error occurred during Pair Data Fusion process. Pair: miMATIC/RETRO (1%), Address: 0xd98eEf295f78ddDd104a8645854C7F8714B39B88, Error: 'data'
[2025-08-01 05:56:28,100] 	ERROR 	63 	pair_data.py 	<module>() 	Error occurred during Pair Data Fusion process. Pair: LINK/RETRO (1%), Address: 0x7761c7233924C3D72F27Fae6a81B074C0152e03a, Error: 'data'
[2025-08-01 05:56:28,202] 	ERROR 	63 	pair_data.py 	<module>() 	Error occurred during Pair Data Fusion process. Pair: RETRO/EURA (1%), Address: 0x15949526fF03fE6ab5f49dA6a86749c20141b3f1, Error: 'data'
[2025-08-01 05:56:28,319] 	ERROR 	63 	pair_data.py 	<module>() 	Error occurred during Pair Data Fusion process. Pair: USDC.e/USDT (0.01%), Address: 0x772510189425ac63f9a5A5eF2fd0C7FDA58CBFC7, Error: 'data'
[2025-08-01 05:56:28,419] 	ERROR 	63 	pair_data.py 	<module>() 	Error occurred during Pair Data Fusion process. Pair: USDC.e/DAI (0.01%), Address: 0x219116F23BDC11EB25e4D0FbE92eD0972d86BE20, Error: 'data'
[2025-08-01 05:56:28,511] 	ERROR 	63 	pair_data.py 	<module>() 	Error occurred during Pair Data Fusion process. Pair: WPOL/MaticX (0.01%), Address: 0x9aa18301055091e9da7C57b81633632Fa33B9a80, Error: 'data'
[2025-08-01 05:56:28,634] 	ERROR 	63 	pair_data.py 	<module>() 	Error occurred during Pair Data Fusion process. Pair: wstETH/WETH (0.01%), Address: 0xa9439Db1D7025Ce4aAc513Baf5eee5220172126C, Error: 'data'
[2025-08-01 05:56:28,725] 	ERROR 	63 	pair_data.py 	<module>() 	Error occurred during Pair Data Fusion process. Pair: WPOL/stMATIC (0.01%), Address: 0x2d623c33673248E95C7a1C26aE7065eb7A7Ac0Ea, Error: 'data'
[2025-08-01 05:56:28,836] 	ERROR 	63 	pair_data.py 	<module>() 	Error occurred during Pair Data Fusion process. Pair: WETH/frxETH (0.01%), Address: 0xe5069a75Bdfe8F676B778B0aaDCcC597841F819B, Error: 'data'
[2025-08-01 05:56:28,949] 	ERROR 	63 	pair_data.py 	<module>() 	Error occurred during Pair Data Fusion process. Pair: FRAX/frxETH (0.05%), Address: 0x38df0c93bf69a9EfB3d3647fF459eF27235A8968, Error: 'data'
[2025-08-01 05:56:29,056] 	ERROR 	63 	pair_data.py 	<module>() 	Error occurred during Pair Data Fusion process. Pair: WPOL/frxETH (0.05%), Address: 0x44AAE81BE8435b6998A66d9642f66DE57DD03FC2, Error: 'data'
[2025-08-01 05:56:29,161] 	ERROR 	63 	pair_data.py 	<module>() 	Error occurred during Pair Data Fusion process. Pair: xbb-t-USD/CASH (0.01%), Address: 0x07dBf448cCC68cA64247da04F2E24643eCf57385, Error: 'data'
[2025-08-01 05:56:29,273] 	ERROR 	63 	pair_data.py 	<module>() 	Error occurred during Pair Data Fusion process. Pair: LINK/LUCHA (0.3%), Address: 0x91248C85DD408BD216254C3cFb51fc326290cF7e, Error: 'data'
[2025-08-01 05:56:29,387] 	ERROR 	63 	pair_data.py 	<module>() 	Error occurred during Pair Data Fusion process. Pair: CASH/LUCHA (0.3%), Address: 0xc666c4b402Bd797185EA419261D22a8f22DDFce6, Error: 'data'
[2025-08-01 05:56:29,487] 	ERROR 	63 	pair_data.py 	<module>() 	Error occurred during Pair Data Fusion process. Pair: USDC.e/miMATIC (0.3%), Address: 0xb090BE2D2F02646057d4DF997A7A983dFb265de0, Error: 'data'
[2025-08-01 05:56:29,588] 	ERROR 	63 	pair_data.py 	<module>() 	Error occurred during Pair Data Fusion process. Pair: FRAX/miMATIC (0.3%), Address: 0xdeB25Dd2d5D168Fd6f80F154d96a2Dab81d61845, Error: 'data'
[2025-08-01 05:56:29,697] 	ERROR 	63 	pair_data.py 	<module>() 	Error occurred during Pair Data Fusion process. Pair: WPOL/miMATIC (0.3%), Address: 0xC571445Fc93666e1E4FaE2E84A7b74FE6ed3978D, Error: 'data'
[2025-08-01 05:56:29,795] 	ERROR 	63 	pair_data.py 	<module>() 	Error occurred during Pair Data Fusion process. Pair: CASH/ERN (0.3%), Address: 0x777a87889f42C33f9A1E5c117774694bbd857075, Error: 'data'
[2025-08-01 05:56:29,891] 	ERROR 	63 	pair_data.py 	<module>() 	Error occurred during Pair Data Fusion process. Pair: ICHI/RETRO (1%), Address: 0xC26E1a0cDab4Bf5141530C49F3360f162C5Db5Db, Error: 'data'
[2025-08-01 05:56:29,996] 	ERROR 	63 	pair_data.py 	<module>() 	Error occurred during Pair Data Fusion process. Pair: WPOL/ICHI (0.3%), Address: 0x13d5e61838D93F7962C52dc921FD7C0Ccc092E35, Error: 'data'
[2025-08-01 05:56:30,093] 	ERROR 	63 	pair_data.py 	<module>() 	Error occurred during Pair Data Fusion process. Pair: SD/MaticX (0.3%), Address: 0xB97c62834e096858BD0B996b758942dd43d7B5eE, Error: 'data'
[2025-08-01 05:56:30,206] 	ERROR 	63 	pair_data.py 	<module>() 	Error occurred during Pair Data Fusion process. Pair: stERN/ERN (1%), Address: 0x99583057951987beD85CE6934473160bFD4921b9, Error: 'data'
[2025-08-01 05:56:30,320] 	ERROR 	63 	pair_data.py 	<module>() 	Error occurred during Pair Data Fusion process. Pair: tUSDC/STAR (0.05%), Address: 0x53C49b9308c3DB176d351d7914Cec0Fb5D7f1129, Error: 'data'
[2025-08-01 05:56:30,432] 	ERROR 	63 	pair_data.py 	<module>() 	Error occurred during Pair Data Fusion process. Pair: WPOL/LUCHA (0.3%), Address: 0x52BeedA850A7048e9D543668BF54E0d9E1B667E0, Error: 'data'
[2025-08-01 05:56:30,531] 	ERROR 	63 	pair_data.py 	<module>() 	Error occurred during Pair Data Fusion process. Pair: LUCHA/WETH (0.3%), Address: 0x13136EA148331a07497087bfc31fBCcD9b99123c, Error: 'data'
[2025-08-01 05:56:30,635] 	ERROR 	63 	pair_data.py 	<module>() 	Error occurred during Pair Data Fusion process. Pair: JRT/WETH (0.3%), Address: 0xAE107e52ebdF151E61d9Fb4Bd800C86c31741465, Error: 'data'
[2025-08-01 05:56:30,740] 	ERROR 	63 	pair_data.py 	<module>() 	Error occurred during Pair Data Fusion process. Pair: axlLqdr/CASH (0.3%), Address: 0x22c10e61A05a03bcd8BF61a7E648f2330ecdA270, Error: 'data'
[2025-08-01 05:56:30,850] 	ERROR 	63 	pair_data.py 	<module>() 	Error occurred during Pair Data Fusion process. Pair: XOC/jMXN (0.01%), Address: 0xccE01e3615785771b84Eb5F88EC612AC6704FdE2, Error: 'data'
[2025-08-01 05:56:30,960] 	ERROR 	63 	pair_data.py 	<module>() 	Error occurred during Pair Data Fusion process. Pair: ICHI/CASH (1%), Address: 0x8ceD58A2dE3C2ea5D3cED3eb4331158c8cf985Fb, Error: 'data'
[2025-08-01 05:56:31,077] 	ERROR 	63 	pair_data.py 	<module>() 	Error occurred during Pair Data Fusion process. Pair: wUSDR/CASH (0.3%), Address: 0x3baEa49B71461DEaB46E6F42548D0005359ff629, Error: 'data'
[2025-08-01 05:56:31,197] 	ERROR 	63 	pair_data.py 	<module>() 	Error occurred during Pair Data Fusion process. Pair: CASH/STAR (0.05%), Address: 0x88C522E526E5Eea8d636fd6805cA7fEB488780D0, Error: 'data'
[2025-08-01 05:56:31,294] 	ERROR 	63 	pair_data.py 	<module>() 	Error occurred during Pair Data Fusion process. Pair: USDC.e/STAR (0.01%), Address: 0x6De0CA91Ef19A6ce9f02A423ae2dF89Fe09Bff0F, Error: 'data'
[2025-08-01 05:56:31,387] 	ERROR 	63 	pair_data.py 	<module>() 	Error occurred during Pair Data Fusion process. Pair: tUSDC/STAR (1%), Address: 0xaC44f57eEF260eB6E0f896b61984Da8d86FeE9ed, Error: 'data'
[2025-08-01 05:56:31,499] 	ERROR 	63 	pair_data.py 	<module>() 	Error occurred during Pair Data Fusion process. Pair: tUSDC/CASH (1%), Address: 0x4FcdB2DCc4Ce156c723aD541dba8B39d47284FC5, Error: 'data'
[2025-08-01 05:56:31,602] 	ERROR 	63 	pair_data.py 	<module>() 	Error occurred during Pair Data Fusion process. Pair: WPOL/USDC.e (0.3%), Address: 0x8c862d100B94d95a49D91958c9e8C2c348d00F04, Error: 'data'
[2025-08-01 05:56:31,707] 	ERROR 	63 	pair_data.py 	<module>() 	Error occurred during Pair Data Fusion process. Pair: WPOL/WETH (0.3%), Address: 0xB8dD18F9b7C3Ad4bDd4B94cB819eda3bd4465119, Error: 'data'
[2025-08-01 05:56:31,802] 	ERROR 	63 	pair_data.py 	<module>() 	Error occurred during Pair Data Fusion process. Pair: USDC.e/WETH (0.3%), Address: 0x058F5330Fef74445878110e201B04F36f8a51c9b, Error: 'data'
[2025-08-01 05:56:31,898] 	ERROR 	63 	pair_data.py 	<module>() 	Error occurred during Pair Data Fusion process. Pair: WBTC/WETH (0.3%), Address: 0x11275C625A7DEE3532E062Eef6915f00af85C3B5, Error: 'data'
[2025-08-01 05:56:32,035] 	ERROR 	63 	pair_data.py 	<module>() 	Error occurred during Pair Data Fusion process. Pair: LINK/WETH (0.3%), Address: 0x555eABEEfe6a047747071525A2c0fFd96d945f69, Error: 'data'
[2025-08-01 05:56:32,132] 	ERROR 	63 	pair_data.py 	<module>() 	Error occurred during Pair Data Fusion process. Pair: WBTC/CASH (0.3%), Address: 0x2C8F7d92Dc7A414D343CbFB687E31a11F525d29e, Error: 'data'
[2025-08-01 05:56:32,229] 	ERROR 	63 	pair_data.py 	<module>() 	Error occurred during Pair Data Fusion process. Pair: WPOL/DEUS (1%), Address: 0xB5cB765e44Eca4bc5a434fFaf6Bf7De235Bc60a5, Error: 'data'
[2025-08-01 05:56:32,343] 	ERROR 	63 	pair_data.py 	<module>() 	Error occurred during Pair Data Fusion process. Pair: WPOL/WBTC (0.3%), Address: 0x2981A1f699eA7149aa08121A07F000cf82846A9e, Error: 'data'
[2025-08-01 05:56:32,452] 	ERROR 	63 	pair_data.py 	<module>() 	Error occurred during Pair Data Fusion process. Pair: FRAX/STAR (0.05%), Address: 0x7D480cBf5Aee75E72eF26F223937f3981d67a860, Error: 'data'
[2025-08-01 05:56:32,562] 	ERROR 	63 	pair_data.py 	<module>() 	Error occurred during Pair Data Fusion process. Pair: CASH/TAROT (0.3%), Address: 0x217aEb0667b79584FBf6265B74a8cD22E1245fdC, Error: 'data'
[2025-08-01 05:56:32,663] 	ERROR 	63 	pair_data.py 	<module>() 	Error occurred during Pair Data Fusion process. Pair: CASH/fxDOLA (0.05%), Address: 0x4b4B895a0dD744B4893aA4370A8F7eDbde5Fd90e, Error: 'data'
[2025-08-01 05:56:32,760] 	ERROR 	63 	pair_data.py 	<module>() 	Error occurred during Pair Data Fusion process. Pair: RETRO/liveRetro (1%), Address: 0x6333BB8b6f1DDa6f929d70eDEB9e31c8148dC9ef, Error: 'data'
[2025-08-01 05:56:32,864] 	ERROR 	63 	pair_data.py 	<module>() 	Error occurred during Pair Data Fusion process. Pair: MVX/WETH (1%), Address: 0xCC72276de3BCc1b159F1B60A86B0211116022B42, Error: 'data'
[2025-08-01 05:56:32,961] 	ERROR 	63 	pair_data.py 	<module>() 	Error occurred during Pair Data Fusion process. Pair: WPOL/elRETRO (1%), Address: 0x6794Db07e2efE1307b8594FBbBFad78E50eC76fa, Error: 'data'
[2025-08-01 05:56:33,062] 	ERROR 	63 	pair_data.py 	<module>() 	Error occurred during Pair Data Fusion process. Pair: OATH/WETH (1%), Address: 0x0c74834d67c4bf5e6a44D18b2BAc767cddB4CdBf, Error: 'data'
[2025-08-01 05:56:33,160] 	ERROR 	63 	pair_data.py 	<module>() 	Error occurred during Pair Data Fusion process. Pair: USDC.e/IBEX (1%), Address: 0x53D8c25B3d130D2810591cDc7A41Bd848bF79B63, Error: 'data'
[2025-08-01 05:56:33,260] 	ERROR 	63 	pair_data.py 	<module>() 	Error occurred during Pair Data Fusion process. Pair: USDC.e/fxDOLA (0.3%), Address: 0x896ffE2cd28Ba13ddDa98103a3B66E82bb36BeE3, Error: 'data'
[2025-08-01 05:56:33,355] 	ERROR 	63 	pair_data.py 	<module>() 	Error occurred during Pair Data Fusion process. Pair: USDC.e/FRAX (0.3%), Address: 0x091236A16952BC9e4bB817FFA7aB40263183f658, Error: 'data'
[2025-08-01 05:56:33,458] 	ERROR 	63 	pair_data.py 	<module>() 	Error occurred during Pair Data Fusion process. Pair: WBTC/USDC.e (0.3%), Address: 0x459F42C788E6F8faCe4854DDD59C81a6Ad8BB1Aa, Error: 'data'
[2025-08-01 05:56:33,552] 	ERROR 	63 	pair_data.py 	<module>() 	Error occurred during Pair Data Fusion process. Pair: WETH/ERN (0.3%), Address: 0xCF2093da3CeBb8731747EEaCbd486A7fcE2Db901, Error: 'data'
[2025-08-01 05:56:33,644] 	ERROR 	63 	pair_data.py 	<module>() 	Error occurred during Pair Data Fusion process. Pair: WETH/JARVIS (0.3%), Address: 0xf310d505B85E0378790Af9fDB9b79b40736f7b4D, Error: 'data'
[2025-08-01 05:56:33,732] 	ERROR 	63 	pair_data.py 	<module>() 	Error occurred during Pair Data Fusion process. Pair: jEUR/CASH (0.05%), Address: 0x65E6b7C7DfE071E52D6923E4079E3C0FcBeaA401, Error: 'data'
[2025-08-01 05:56:33,829] 	ERROR 	63 	pair_data.py 	<module>() 	Error occurred during Pair Data Fusion process. Pair: USDC.e/USDC (0.01%), Address: 0x1e0aa3f6C3130294845B8e162d838e221d170016, Error: 'data'
[2025-08-01 05:56:33,931] 	ERROR 	63 	pair_data.py 	<module>() 	Error occurred during Pair Data Fusion process. Pair: LUCHA/WETH (1%), Address: 0x098c1e4BB34DEcDF49D5966014B5153Af326E766, Error: 'data'
[2025-08-01 05:56:34,028] 	ERROR 	63 	pair_data.py 	<module>() 	Error occurred during Pair Data Fusion process. Pair: WPOL/LUCHA (1%), Address: 0xde4C8898CD50EBE9C167313b312D147D10d1C898, Error: 'data'
[2025-08-01 05:56:34,144] 	ERROR 	63 	pair_data.py 	<module>() 	Error occurred during Pair Data Fusion process. Pair: LINK/LUCHA (1%), Address: 0xA97B2b9AcA65aab57A6b0840B45777bd66fbcf33, Error: 'data'
[2025-08-01 05:56:34,248] 	ERROR 	63 	pair_data.py 	<module>() 	Error occurred during Pair Data Fusion process. Pair: CASH/LUCHA (1%), Address: 0x5c09352B1aa703d18dbcF48c98655BFA19d07FBB, Error: 'data'
[2025-08-01 05:56:34,341] 	ERROR 	103 	pair_data.py 	<module>() 	Error occurred during Pair Data Fusion process. Error: 'date'
Traceback (most recent call last):
  File "/opt/hostedtoolcache/Python/3.8.18/x64/lib/python3.8/site-packages/pandas/core/indexes/base.py", line 3802, in get_loc
    return self._engine.get_loc(casted_key)
  File "pandas/_libs/index.pyx", line 138, in pandas._libs.index.IndexEngine.get_loc
  File "pandas/_libs/index.pyx", line 165, in pandas._libs.index.IndexEngine.get_loc
  File "pandas/_libs/hashtable_class_helper.pxi", line 5745, in pandas._libs.hashtable.PyObjectHashTable.get_item
  File "pandas/_libs/hashtable_class_helper.pxi", line 5753, in pandas._libs.hashtable.PyObjectHashTable.get_item
KeyError: 'date'

The above exception was the direct cause of the following exception:

Traceback (most recent call last):
  File "pair_data.py", line 68, in <module>
    pairdata_fusion_df["date"] = pairdata_fusion_df["date"].apply(lambda timestamp: datetime.utcfromtimestamp(timestamp).date())
  File "/opt/hostedtoolcache/Python/3.8.18/x64/lib/python3.8/site-packages/pandas/core/frame.py", line 3807, in __getitem__
    indexer = self.columns.get_loc(key)
  File "/opt/hostedtoolcache/Python/3.8.18/x64/lib/python3.8/site-packages/pandas/core/indexes/base.py", line 3804, in get_loc
    raise KeyError(key) from err
KeyError: 'date'
[2025-08-01 05:56:35,200] 	INFO 	36 	bribe_data.py 	<module>() 	Bribe Data Started
[2025-08-01 05:56:35,495] 	ERROR 	159 	bribe_data.py 	<module>() 	Error occurred during Bribe Data process. Error: {'code': -32000, 'message': 'Unauthorized: You must authenticate your request with an API key. Create an account on https://www.ankr.com/rpc/ and generate your personal API key for free.'}
Traceback (most recent call last):
  File "bribe_data.py", line 71, in <module>
    rewardsListLength = contract_instance.functions.rewardsListLength().call()
  File "/opt/hostedtoolcache/Python/3.8.18/x64/lib/python3.8/site-packages/web3/contract.py", line 970, in call
    return call_contract_function(
  File "/opt/hostedtoolcache/Python/3.8.18/x64/lib/python3.8/site-packages/web3/contract.py", line 1525, in call_contract_function
    return_data = web3.eth.call(
  File "/opt/hostedtoolcache/Python/3.8.18/x64/lib/python3.8/site-packages/web3/module.py", line 57, in caller
    result = w3.manager.request_blocking(method_str,
  File "/opt/hostedtoolcache/Python/3.8.18/x64/lib/python3.8/site-packages/web3/manager.py", line 198, in request_blocking
    return self.formatted_response(response,
  File "/opt/hostedtoolcache/Python/3.8.18/x64/lib/python3.8/site-packages/web3/manager.py", line 171, in formatted_response
    raise ValueError(response["error"])
ValueError: {'code': -32000, 'message': 'Unauthorized: You must authenticate your request with an API key. Create an account on https://www.ankr.com/rpc/ and generate your personal API key for free.'}
[2025-08-01 05:56:36,343] 	INFO 	36 	fee_data.py 	<module>() 	Fee Data Started
[2025-08-01 05:56:36,483] 	ERROR 	159 	fee_data.py 	<module>() 	Error occurred during Fee Data process. Error: {'code': -32000, 'message': 'Unauthorized: You must authenticate your request with an API key. Create an account on https://www.ankr.com/rpc/ and generate your personal API key for free.'}
Traceback (most recent call last):
  File "fee_data.py", line 71, in <module>
    rewardsListLength = contract_instance.functions.rewardsListLength().call()
  File "/opt/hostedtoolcache/Python/3.8.18/x64/lib/python3.8/site-packages/web3/contract.py", line 970, in call
    return call_contract_function(
  File "/opt/hostedtoolcache/Python/3.8.18/x64/lib/python3.8/site-packages/web3/contract.py", line 1525, in call_contract_function
    return_data = web3.eth.call(
  File "/opt/hostedtoolcache/Python/3.8.18/x64/lib/python3.8/site-packages/web3/module.py", line 57, in caller
    result = w3.manager.request_blocking(method_str,
  File "/opt/hostedtoolcache/Python/3.8.18/x64/lib/python3.8/site-packages/web3/manager.py", line 198, in request_blocking
    return self.formatted_response(response,
  File "/opt/hostedtoolcache/Python/3.8.18/x64/lib/python3.8/site-packages/web3/manager.py", line 171, in formatted_response
    raise ValueError(response["error"])
ValueError: {'code': -32000, 'message': 'Unauthorized: You must authenticate your request with an API key. Create an account on https://www.ankr.com/rpc/ and generate your personal API key for free.'}
[2025-08-01 05:56:37,348] 	INFO 	37 	vote_data.py 	<module>() 	Vote Data Started
[2025-08-01 05:56:37,571] 	ERROR 	118 	vote_data.py 	<module>() 	Error occurred during Vote Data process. Error: Expecting value: line 1 column 1 (char 0)
Traceback (most recent call last):
  File "/opt/hostedtoolcache/Python/3.8.18/x64/lib/python3.8/site-packages/requests/models.py", line 971, in json
    return complexjson.loads(self.text, **kwargs)
  File "/opt/hostedtoolcache/Python/3.8.18/x64/lib/python3.8/json/__init__.py", line 357, in loads
    return _default_decoder.decode(s)
  File "/opt/hostedtoolcache/Python/3.8.18/x64/lib/python3.8/json/decoder.py", line 337, in decode
    obj, end = self.raw_decode(s, idx=_w(s, 0).end())
  File "/opt/hostedtoolcache/Python/3.8.18/x64/lib/python3.8/json/decoder.py", line 355, in raw_decode
    raise JSONDecodeError("Expecting value", s, err.value) from None
json.decoder.JSONDecodeError: Expecting value: line 1 column 1 (char 0)

During handling of the above exception, another exception occurred:

Traceback (most recent call last):
  File "vote_data.py", line 64, in <module>
    RETRO_price = jmespath.search("data[?name == 'RETRO'].price", response.json())[0]
  File "/opt/hostedtoolcache/Python/3.8.18/x64/lib/python3.8/site-packages/requests/models.py", line 975, in json
    raise RequestsJSONDecodeError(e.msg, e.doc, e.pos)
requests.exceptions.JSONDecodeError: Expecting value: line 1 column 1 (char 0)
[2025-08-01 05:56:38,419] 	INFO 	30 	revenue_data.py 	<module>() 	Revenue Data Started
[2025-08-01 05:56:43,621] 	ERROR 	152 	revenue_data.py 	<module>() 	Error occurred during Revenue Data process. Error: Expecting value: line 1 column 1 (char 0)
Traceback (most recent call last):
  File "/opt/hostedtoolcache/Python/3.8.18/x64/lib/python3.8/site-packages/requests/models.py", line 971, in json
    return complexjson.loads(self.text, **kwargs)
  File "/opt/hostedtoolcache/Python/3.8.18/x64/lib/python3.8/json/__init__.py", line 357, in loads
    return _default_decoder.decode(s)
  File "/opt/hostedtoolcache/Python/3.8.18/x64/lib/python3.8/json/decoder.py", line 337, in decode
    obj, end = self.raw_decode(s, idx=_w(s, 0).end())
  File "/opt/hostedtoolcache/Python/3.8.18/x64/lib/python3.8/json/decoder.py", line 355, in raw_decode
    raise JSONDecodeError("Expecting value", s, err.value) from None
json.decoder.JSONDecodeError: Expecting value: line 1 column 1 (char 0)

During handling of the above exception, another exception occurred:

Traceback (most recent call last):
  File "revenue_data.py", line 66, in <module>
    RETRO_price = jmespath.search("data[?name == 'RETRO'].price", response.json())[0]
  File "/opt/hostedtoolcache/Python/3.8.18/x64/lib/python3.8/site-packages/requests/models.py", line 975, in json
    raise RequestsJSONDecodeError(e.msg, e.doc, e.pos)
requests.exceptions.JSONDecodeError: Expecting value: line 1 column 1 (char 0)
