[2023-08-01 01:38:41,007] 	INFO 	20 	id_data.py 	<module>() 	ID Data Started
[2023-08-01 01:38:41,935] 	INFO 	31 	id_data.py 	<module>() 	ID Data Ended
[2023-08-01 01:38:42,762] 	INFO 	79 	day_data.py 	<module>() 	Day Data Fusion Started
[2023-08-01 01:38:46,455] 	INFO 	126 	day_data.py 	<module>() 	Day Data Fusion Ended
[2023-08-01 01:38:47,890] 	INFO 	123 	pair_data.py 	<module>() 	Pair Data Fusion Started
[2023-08-01 01:39:01,309] 	INFO 	187 	pair_data.py 	<module>() 	Pair Data Fusion Ended
[2023-08-01 01:39:02,609] 	INFO 	37 	bribe_data.py 	<module>() 	Bribe Data Started
[2023-08-01 01:40:01,463] 	INFO 	136 	bribe_data.py 	<module>() 	Bribe Data Ended
[2023-08-01 01:40:02,645] 	INFO 	37 	fee_data.py 	<module>() 	Fee Data Started
[2023-08-01 01:41:00,472] 	INFO 	136 	fee_data.py 	<module>() 	Fee Data Ended
[2023-08-01 01:41:01,362] 	INFO 	24 	revenue_data.py 	<module>() 	Revenue Data Started
[2023-08-01 01:41:05,681] 	INFO 	82 	revenue_data.py 	<module>() 	Revenue Data Ended
[2023-08-01 02:37:53,290] 	INFO 	20 	id_data.py 	<module>() 	ID Data Started
[2023-08-01 02:37:53,595] 	INFO 	31 	id_data.py 	<module>() 	ID Data Ended
[2023-08-01 02:37:54,269] 	INFO 	79 	day_data.py 	<module>() 	Day Data Fusion Started
[2023-08-01 02:37:58,120] 	INFO 	126 	day_data.py 	<module>() 	Day Data Fusion Ended
[2023-08-01 02:37:59,320] 	INFO 	123 	pair_data.py 	<module>() 	Pair Data Fusion Started
[2023-08-01 02:38:10,540] 	INFO 	187 	pair_data.py 	<module>() 	Pair Data Fusion Ended
[2023-08-01 02:38:11,622] 	INFO 	37 	bribe_data.py 	<module>() 	Bribe Data Started
[2023-08-01 02:38:53,749] 	INFO 	136 	bribe_data.py 	<module>() 	Bribe Data Ended
[2023-08-01 02:38:54,771] 	INFO 	37 	fee_data.py 	<module>() 	Fee Data Started
[2023-08-01 02:39:36,225] 	INFO 	136 	fee_data.py 	<module>() 	Fee Data Ended
[2023-08-01 02:39:36,925] 	INFO 	24 	revenue_data.py 	<module>() 	Revenue Data Started
[2023-08-01 02:39:40,514] 	INFO 	82 	revenue_data.py 	<module>() 	Revenue Data Ended
[2023-08-01 03:17:51,853] 	INFO 	20 	id_data.py 	<module>() 	ID Data Started
[2023-08-01 03:17:52,290] 	INFO 	31 	id_data.py 	<module>() 	ID Data Ended
[2023-08-01 03:17:53,021] 	INFO 	79 	day_data.py 	<module>() 	Day Data Fusion Started
[2023-08-01 03:17:56,162] 	INFO 	126 	day_data.py 	<module>() 	Day Data Fusion Ended
[2023-08-01 03:17:57,590] 	INFO 	123 	pair_data.py 	<module>() 	Pair Data Fusion Started
[2023-08-01 03:18:09,345] 	INFO 	187 	pair_data.py 	<module>() 	Pair Data Fusion Ended
[2023-08-01 03:18:10,448] 	INFO 	37 	bribe_data.py 	<module>() 	Bribe Data Started
[2023-08-01 03:18:51,813] 	INFO 	136 	bribe_data.py 	<module>() 	Bribe Data Ended
[2023-08-01 03:18:52,939] 	INFO 	37 	fee_data.py 	<module>() 	Fee Data Started
[2023-08-01 03:19:34,549] 	INFO 	136 	fee_data.py 	<module>() 	Fee Data Ended
[2023-08-01 03:19:35,270] 	INFO 	24 	revenue_data.py 	<module>() 	Revenue Data Started
[2023-08-01 03:19:38,084] 	INFO 	82 	revenue_data.py 	<module>() 	Revenue Data Ended
[2023-08-01 04:20:04,525] 	INFO 	20 	id_data.py 	<module>() 	ID Data Started
[2023-08-01 04:20:04,984] 	INFO 	31 	id_data.py 	<module>() 	ID Data Ended
[2023-08-01 04:20:05,723] 	INFO 	79 	day_data.py 	<module>() 	Day Data Fusion Started
[2023-08-01 04:20:08,946] 	INFO 	126 	day_data.py 	<module>() 	Day Data Fusion Ended
[2023-08-01 04:20:10,490] 	INFO 	123 	pair_data.py 	<module>() 	Pair Data Fusion Started
[2023-08-01 04:20:21,703] 	INFO 	187 	pair_data.py 	<module>() 	Pair Data Fusion Ended
[2023-08-01 04:20:22,767] 	INFO 	37 	bribe_data.py 	<module>() 	Bribe Data Started
[2023-08-01 04:21:07,270] 	INFO 	136 	bribe_data.py 	<module>() 	Bribe Data Ended
[2023-08-01 04:21:08,335] 	INFO 	37 	fee_data.py 	<module>() 	Fee Data Started
[2023-08-01 04:21:50,597] 	INFO 	136 	fee_data.py 	<module>() 	Fee Data Ended
[2023-08-01 04:21:51,308] 	INFO 	24 	revenue_data.py 	<module>() 	Revenue Data Started
[2023-08-01 04:21:54,657] 	INFO 	82 	revenue_data.py 	<module>() 	Revenue Data Ended
[2023-08-01 05:16:03,013] 	INFO 	20 	id_data.py 	<module>() 	ID Data Started
[2023-08-01 05:16:03,691] 	INFO 	31 	id_data.py 	<module>() 	ID Data Ended
[2023-08-01 05:16:04,395] 	INFO 	79 	day_data.py 	<module>() 	Day Data Fusion Started
[2023-08-01 05:16:07,123] 	INFO 	126 	day_data.py 	<module>() 	Day Data Fusion Ended
[2023-08-01 05:16:08,281] 	INFO 	123 	pair_data.py 	<module>() 	Pair Data Fusion Started
[2023-08-01 05:16:21,336] 	INFO 	187 	pair_data.py 	<module>() 	Pair Data Fusion Ended
[2023-08-01 05:16:22,396] 	INFO 	37 	bribe_data.py 	<module>() 	Bribe Data Started
[2023-08-01 05:17:12,641] 	INFO 	136 	bribe_data.py 	<module>() 	Bribe Data Ended
[2023-08-01 05:17:13,729] 	INFO 	37 	fee_data.py 	<module>() 	Fee Data Started
[2023-08-01 05:18:04,365] 	INFO 	136 	fee_data.py 	<module>() 	Fee Data Ended
[2023-08-01 05:18:05,067] 	INFO 	24 	revenue_data.py 	<module>() 	Revenue Data Started
[2023-08-01 05:18:24,123] 	INFO 	82 	revenue_data.py 	<module>() 	Revenue Data Ended
[2023-08-01 06:23:11,500] 	INFO 	20 	id_data.py 	<module>() 	ID Data Started
[2023-08-01 06:23:11,822] 	INFO 	31 	id_data.py 	<module>() 	ID Data Ended
[2023-08-01 06:23:12,461] 	INFO 	79 	day_data.py 	<module>() 	Day Data Fusion Started
[2023-08-01 06:23:14,466] 	INFO 	126 	day_data.py 	<module>() 	Day Data Fusion Ended
[2023-08-01 06:23:15,704] 	INFO 	123 	pair_data.py 	<module>() 	Pair Data Fusion Started
[2023-08-01 06:23:25,564] 	INFO 	187 	pair_data.py 	<module>() 	Pair Data Fusion Ended
[2023-08-01 06:23:26,479] 	INFO 	37 	bribe_data.py 	<module>() 	Bribe Data Started
[2023-08-01 06:24:02,782] 	INFO 	136 	bribe_data.py 	<module>() 	Bribe Data Ended
[2023-08-01 06:24:03,685] 	INFO 	37 	fee_data.py 	<module>() 	Fee Data Started
[2023-08-01 06:24:41,354] 	INFO 	136 	fee_data.py 	<module>() 	Fee Data Ended
[2023-08-01 06:24:41,961] 	INFO 	24 	revenue_data.py 	<module>() 	Revenue Data Started
[2023-08-01 06:24:45,027] 	INFO 	82 	revenue_data.py 	<module>() 	Revenue Data Ended
[2023-08-01 07:15:58,568] 	INFO 	20 	id_data.py 	<module>() 	ID Data Started
[2023-08-01 07:15:58,932] 	INFO 	31 	id_data.py 	<module>() 	ID Data Ended
[2023-08-01 07:15:59,513] 	INFO 	79 	day_data.py 	<module>() 	Day Data Fusion Started
[2023-08-01 07:16:02,283] 	INFO 	126 	day_data.py 	<module>() 	Day Data Fusion Ended
[2023-08-01 07:16:03,273] 	INFO 	123 	pair_data.py 	<module>() 	Pair Data Fusion Started
[2023-08-01 07:16:14,244] 	INFO 	187 	pair_data.py 	<module>() 	Pair Data Fusion Ended
[2023-08-01 07:16:15,120] 	INFO 	37 	bribe_data.py 	<module>() 	Bribe Data Started
[2023-08-01 07:16:52,849] 	INFO 	136 	bribe_data.py 	<module>() 	Bribe Data Ended
[2023-08-01 07:16:53,734] 	INFO 	37 	fee_data.py 	<module>() 	Fee Data Started
[2023-08-01 07:17:31,484] 	INFO 	136 	fee_data.py 	<module>() 	Fee Data Ended
[2023-08-01 07:17:32,089] 	INFO 	24 	revenue_data.py 	<module>() 	Revenue Data Started
[2023-08-01 07:17:35,574] 	INFO 	82 	revenue_data.py 	<module>() 	Revenue Data Ended
[2023-08-01 08:20:51,766] 	INFO 	20 	id_data.py 	<module>() 	ID Data Started
[2023-08-01 08:20:52,033] 	INFO 	31 	id_data.py 	<module>() 	ID Data Ended
[2023-08-01 08:20:52,766] 	INFO 	79 	day_data.py 	<module>() 	Day Data Fusion Started
[2023-08-01 08:20:54,648] 	INFO 	126 	day_data.py 	<module>() 	Day Data Fusion Ended
[2023-08-01 08:20:55,615] 	INFO 	123 	pair_data.py 	<module>() 	Pair Data Fusion Started
[2023-08-01 08:21:04,998] 	INFO 	187 	pair_data.py 	<module>() 	Pair Data Fusion Ended
[2023-08-01 08:21:05,926] 	INFO 	37 	bribe_data.py 	<module>() 	Bribe Data Started
[2023-08-01 08:21:40,674] 	INFO 	136 	bribe_data.py 	<module>() 	Bribe Data Ended
[2023-08-01 08:21:41,622] 	INFO 	37 	fee_data.py 	<module>() 	Fee Data Started
[2023-08-01 08:22:17,694] 	INFO 	136 	fee_data.py 	<module>() 	Fee Data Ended
[2023-08-01 08:22:18,344] 	INFO 	24 	revenue_data.py 	<module>() 	Revenue Data Started
[2023-08-01 08:22:21,276] 	INFO 	82 	revenue_data.py 	<module>() 	Revenue Data Ended
[2023-08-01 09:16:35,766] 	INFO 	20 	id_data.py 	<module>() 	ID Data Started
[2023-08-01 09:16:36,180] 	INFO 	31 	id_data.py 	<module>() 	ID Data Ended
[2023-08-01 09:16:36,894] 	INFO 	79 	day_data.py 	<module>() 	Day Data Fusion Started
[2023-08-01 09:16:39,821] 	INFO 	126 	day_data.py 	<module>() 	Day Data Fusion Ended
[2023-08-01 09:16:40,857] 	INFO 	123 	pair_data.py 	<module>() 	Pair Data Fusion Started
[2023-08-01 09:16:50,750] 	INFO 	187 	pair_data.py 	<module>() 	Pair Data Fusion Ended
[2023-08-01 09:16:51,782] 	INFO 	37 	bribe_data.py 	<module>() 	Bribe Data Started
[2023-08-01 09:17:32,206] 	INFO 	136 	bribe_data.py 	<module>() 	Bribe Data Ended
[2023-08-01 09:17:33,272] 	INFO 	37 	fee_data.py 	<module>() 	Fee Data Started
[2023-08-01 09:22:12,473] 	INFO 	136 	fee_data.py 	<module>() 	Fee Data Ended
[2023-08-01 09:22:13,185] 	INFO 	24 	revenue_data.py 	<module>() 	Revenue Data Started
[2023-08-01 09:22:16,917] 	INFO 	82 	revenue_data.py 	<module>() 	Revenue Data Ended
[2023-08-01 10:18:03,359] 	INFO 	20 	id_data.py 	<module>() 	ID Data Started
[2023-08-01 10:18:03,618] 	INFO 	31 	id_data.py 	<module>() 	ID Data Ended
[2023-08-01 10:18:04,352] 	INFO 	79 	day_data.py 	<module>() 	Day Data Fusion Started
[2023-08-01 10:18:06,400] 	INFO 	126 	day_data.py 	<module>() 	Day Data Fusion Ended
[2023-08-01 10:18:07,742] 	INFO 	123 	pair_data.py 	<module>() 	Pair Data Fusion Started
[2023-08-01 10:18:19,081] 	INFO 	187 	pair_data.py 	<module>() 	Pair Data Fusion Ended
[2023-08-01 10:18:20,176] 	INFO 	37 	bribe_data.py 	<module>() 	Bribe Data Started
[2023-08-01 10:19:00,269] 	INFO 	136 	bribe_data.py 	<module>() 	Bribe Data Ended
[2023-08-01 10:19:01,360] 	INFO 	37 	fee_data.py 	<module>() 	Fee Data Started
[2023-08-01 10:19:42,084] 	INFO 	136 	fee_data.py 	<module>() 	Fee Data Ended
[2023-08-01 10:19:42,855] 	INFO 	24 	revenue_data.py 	<module>() 	Revenue Data Started
[2023-08-01 10:19:45,566] 	INFO 	82 	revenue_data.py 	<module>() 	Revenue Data Ended
[2023-08-01 11:13:37,360] 	INFO 	20 	id_data.py 	<module>() 	ID Data Started
[2023-08-01 11:13:37,796] 	INFO 	31 	id_data.py 	<module>() 	ID Data Ended
[2023-08-01 11:13:38,620] 	INFO 	79 	day_data.py 	<module>() 	Day Data Fusion Started
[2023-08-01 11:13:41,602] 	INFO 	126 	day_data.py 	<module>() 	Day Data Fusion Ended
[2023-08-01 11:13:43,089] 	INFO 	123 	pair_data.py 	<module>() 	Pair Data Fusion Started
[2023-08-01 11:13:53,382] 	INFO 	187 	pair_data.py 	<module>() 	Pair Data Fusion Ended
[2023-08-01 11:13:54,347] 	INFO 	37 	bribe_data.py 	<module>() 	Bribe Data Started
[2023-08-01 11:14:42,077] 	INFO 	136 	bribe_data.py 	<module>() 	Bribe Data Ended
[2023-08-01 11:14:43,054] 	INFO 	37 	fee_data.py 	<module>() 	Fee Data Started
[2023-08-01 11:15:33,535] 	INFO 	136 	fee_data.py 	<module>() 	Fee Data Ended
[2023-08-01 11:15:34,186] 	INFO 	24 	revenue_data.py 	<module>() 	Revenue Data Started
[2023-08-01 11:15:37,509] 	INFO 	82 	revenue_data.py 	<module>() 	Revenue Data Ended
[2023-08-01 12:34:36,130] 	INFO 	20 	id_data.py 	<module>() 	ID Data Started
[2023-08-01 12:34:36,510] 	INFO 	31 	id_data.py 	<module>() 	ID Data Ended
[2023-08-01 12:34:37,239] 	INFO 	79 	day_data.py 	<module>() 	Day Data Fusion Started
[2023-08-01 12:34:39,368] 	INFO 	126 	day_data.py 	<module>() 	Day Data Fusion Ended
[2023-08-01 12:34:40,668] 	INFO 	123 	pair_data.py 	<module>() 	Pair Data Fusion Started
[2023-08-01 12:34:52,468] 	INFO 	187 	pair_data.py 	<module>() 	Pair Data Fusion Ended
[2023-08-01 12:34:53,553] 	INFO 	37 	bribe_data.py 	<module>() 	Bribe Data Started
[2023-08-01 12:35:34,503] 	INFO 	136 	bribe_data.py 	<module>() 	Bribe Data Ended
[2023-08-01 12:35:35,632] 	INFO 	37 	fee_data.py 	<module>() 	Fee Data Started
[2023-08-01 12:36:14,979] 	INFO 	136 	fee_data.py 	<module>() 	Fee Data Ended
[2023-08-01 12:36:15,706] 	INFO 	24 	revenue_data.py 	<module>() 	Revenue Data Started
[2023-08-01 12:36:18,414] 	INFO 	82 	revenue_data.py 	<module>() 	Revenue Data Ended
[2023-08-01 13:20:13,071] 	INFO 	20 	id_data.py 	<module>() 	ID Data Started
[2023-08-01 13:20:14,064] 	INFO 	31 	id_data.py 	<module>() 	ID Data Ended
[2023-08-01 13:20:14,918] 	INFO 	79 	day_data.py 	<module>() 	Day Data Fusion Started
[2023-08-01 13:20:18,543] 	INFO 	126 	day_data.py 	<module>() 	Day Data Fusion Ended
[2023-08-01 13:20:20,114] 	INFO 	123 	pair_data.py 	<module>() 	Pair Data Fusion Started
[2023-08-01 13:20:31,878] 	INFO 	187 	pair_data.py 	<module>() 	Pair Data Fusion Ended
[2023-08-01 13:20:33,166] 	INFO 	37 	bribe_data.py 	<module>() 	Bribe Data Started
[2023-08-01 13:21:28,685] 	INFO 	136 	bribe_data.py 	<module>() 	Bribe Data Ended
[2023-08-01 13:21:29,929] 	INFO 	37 	fee_data.py 	<module>() 	Fee Data Started
[2023-08-01 13:22:20,915] 	INFO 	136 	fee_data.py 	<module>() 	Fee Data Ended
[2023-08-01 13:22:21,702] 	INFO 	24 	revenue_data.py 	<module>() 	Revenue Data Started
[2023-08-01 13:22:24,626] 	INFO 	82 	revenue_data.py 	<module>() 	Revenue Data Ended
[2023-08-01 14:15:25,612] 	INFO 	20 	id_data.py 	<module>() 	ID Data Started
[2023-08-01 14:15:26,023] 	INFO 	31 	id_data.py 	<module>() 	ID Data Ended
[2023-08-01 14:15:27,013] 	INFO 	79 	day_data.py 	<module>() 	Day Data Fusion Started
[2023-08-01 14:15:29,058] 	INFO 	126 	day_data.py 	<module>() 	Day Data Fusion Ended
[2023-08-01 14:15:31,089] 	INFO 	123 	pair_data.py 	<module>() 	Pair Data Fusion Started
[2023-08-01 14:15:42,028] 	INFO 	187 	pair_data.py 	<module>() 	Pair Data Fusion Ended
[2023-08-01 14:15:43,165] 	INFO 	37 	bribe_data.py 	<module>() 	Bribe Data Started
[2023-08-01 14:16:22,925] 	INFO 	136 	bribe_data.py 	<module>() 	Bribe Data Ended
[2023-08-01 14:16:24,029] 	INFO 	37 	fee_data.py 	<module>() 	Fee Data Started
[2023-08-01 14:17:02,569] 	INFO 	136 	fee_data.py 	<module>() 	Fee Data Ended
[2023-08-01 14:17:03,330] 	INFO 	24 	revenue_data.py 	<module>() 	Revenue Data Started
[2023-08-01 14:17:06,934] 	INFO 	82 	revenue_data.py 	<module>() 	Revenue Data Ended
[2023-08-01 15:17:31,078] 	INFO 	20 	id_data.py 	<module>() 	ID Data Started
[2023-08-01 15:17:31,499] 	INFO 	31 	id_data.py 	<module>() 	ID Data Ended
[2023-08-01 15:17:32,308] 	INFO 	79 	day_data.py 	<module>() 	Day Data Fusion Started
[2023-08-01 15:17:34,997] 	INFO 	126 	day_data.py 	<module>() 	Day Data Fusion Ended
[2023-08-01 15:17:36,481] 	INFO 	123 	pair_data.py 	<module>() 	Pair Data Fusion Started
[2023-08-01 15:17:47,978] 	INFO 	187 	pair_data.py 	<module>() 	Pair Data Fusion Ended
[2023-08-01 15:17:49,184] 	INFO 	37 	bribe_data.py 	<module>() 	Bribe Data Started
[2023-08-01 15:18:36,137] 	INFO 	136 	bribe_data.py 	<module>() 	Bribe Data Ended
[2023-08-01 15:18:37,371] 	INFO 	37 	fee_data.py 	<module>() 	Fee Data Started
[2023-08-01 15:19:20,321] 	INFO 	136 	fee_data.py 	<module>() 	Fee Data Ended
[2023-08-01 15:19:21,225] 	INFO 	24 	revenue_data.py 	<module>() 	Revenue Data Started
[2023-08-01 15:19:25,023] 	INFO 	82 	revenue_data.py 	<module>() 	Revenue Data Ended
[2023-08-01 16:20:30,861] 	INFO 	20 	id_data.py 	<module>() 	ID Data Started
[2023-08-01 16:20:31,180] 	INFO 	31 	id_data.py 	<module>() 	ID Data Ended
[2023-08-01 16:20:31,924] 	INFO 	79 	day_data.py 	<module>() 	Day Data Fusion Started
[2023-08-01 16:20:33,523] 	INFO 	126 	day_data.py 	<module>() 	Day Data Fusion Ended
[2023-08-01 16:20:34,956] 	INFO 	123 	pair_data.py 	<module>() 	Pair Data Fusion Started
[2023-08-01 16:20:47,572] 	INFO 	187 	pair_data.py 	<module>() 	Pair Data Fusion Ended
[2023-08-01 16:20:48,677] 	INFO 	37 	bribe_data.py 	<module>() 	Bribe Data Started
[2023-08-01 16:21:48,281] 	INFO 	136 	bribe_data.py 	<module>() 	Bribe Data Ended
[2023-08-01 16:21:49,369] 	INFO 	37 	fee_data.py 	<module>() 	Fee Data Started
[2023-08-01 16:22:52,243] 	INFO 	136 	fee_data.py 	<module>() 	Fee Data Ended
[2023-08-01 16:22:53,005] 	INFO 	24 	revenue_data.py 	<module>() 	Revenue Data Started
[2023-08-01 16:22:56,448] 	INFO 	82 	revenue_data.py 	<module>() 	Revenue Data Ended
[2023-08-01 17:14:39,424] 	INFO 	20 	id_data.py 	<module>() 	ID Data Started
[2023-08-01 17:14:39,874] 	INFO 	31 	id_data.py 	<module>() 	ID Data Ended
[2023-08-01 17:14:40,679] 	INFO 	79 	day_data.py 	<module>() 	Day Data Fusion Started
[2023-08-01 17:14:42,736] 	INFO 	126 	day_data.py 	<module>() 	Day Data Fusion Ended
[2023-08-01 17:14:43,998] 	INFO 	123 	pair_data.py 	<module>() 	Pair Data Fusion Started
[2023-08-01 17:14:55,849] 	INFO 	187 	pair_data.py 	<module>() 	Pair Data Fusion Ended
[2023-08-01 17:14:57,144] 	INFO 	37 	bribe_data.py 	<module>() 	Bribe Data Started
[2023-08-01 17:15:43,954] 	INFO 	136 	bribe_data.py 	<module>() 	Bribe Data Ended
[2023-08-01 17:15:45,216] 	INFO 	37 	fee_data.py 	<module>() 	Fee Data Started
[2023-08-01 17:16:29,685] 	INFO 	136 	fee_data.py 	<module>() 	Fee Data Ended
[2023-08-01 17:16:30,573] 	INFO 	24 	revenue_data.py 	<module>() 	Revenue Data Started
[2023-08-01 17:16:33,659] 	INFO 	82 	revenue_data.py 	<module>() 	Revenue Data Ended
[2023-08-01 18:20:20,904] 	INFO 	20 	id_data.py 	<module>() 	ID Data Started
[2023-08-01 18:20:21,279] 	INFO 	31 	id_data.py 	<module>() 	ID Data Ended
[2023-08-01 18:20:21,835] 	INFO 	79 	day_data.py 	<module>() 	Day Data Fusion Started
[2023-08-01 18:20:24,443] 	INFO 	126 	day_data.py 	<module>() 	Day Data Fusion Ended
[2023-08-01 18:20:25,388] 	INFO 	123 	pair_data.py 	<module>() 	Pair Data Fusion Started
[2023-08-01 18:20:37,414] 	INFO 	187 	pair_data.py 	<module>() 	Pair Data Fusion Ended
[2023-08-01 18:20:38,257] 	INFO 	37 	bribe_data.py 	<module>() 	Bribe Data Started
[2023-08-01 18:21:21,544] 	INFO 	136 	bribe_data.py 	<module>() 	Bribe Data Ended
[2023-08-01 18:21:22,387] 	INFO 	37 	fee_data.py 	<module>() 	Fee Data Started
[2023-08-01 18:22:06,370] 	INFO 	136 	fee_data.py 	<module>() 	Fee Data Ended
[2023-08-01 18:22:06,937] 	INFO 	24 	revenue_data.py 	<module>() 	Revenue Data Started
[2023-08-01 18:22:10,133] 	INFO 	82 	revenue_data.py 	<module>() 	Revenue Data Ended
[2023-08-01 19:12:58,015] 	INFO 	20 	id_data.py 	<module>() 	ID Data Started
[2023-08-01 19:12:58,492] 	INFO 	31 	id_data.py 	<module>() 	ID Data Ended
[2023-08-01 19:12:59,084] 	INFO 	79 	day_data.py 	<module>() 	Day Data Fusion Started
[2023-08-01 19:13:00,960] 	INFO 	126 	day_data.py 	<module>() 	Day Data Fusion Ended
[2023-08-01 19:13:01,845] 	INFO 	123 	pair_data.py 	<module>() 	Pair Data Fusion Started
[2023-08-01 19:13:13,372] 	INFO 	187 	pair_data.py 	<module>() 	Pair Data Fusion Ended
[2023-08-01 19:13:14,210] 	INFO 	37 	bribe_data.py 	<module>() 	Bribe Data Started
[2023-08-01 19:14:01,738] 	INFO 	136 	bribe_data.py 	<module>() 	Bribe Data Ended
[2023-08-01 19:14:02,585] 	INFO 	37 	fee_data.py 	<module>() 	Fee Data Started
[2023-08-01 19:14:47,267] 	INFO 	136 	fee_data.py 	<module>() 	Fee Data Ended
[2023-08-01 19:14:47,838] 	INFO 	24 	revenue_data.py 	<module>() 	Revenue Data Started
[2023-08-01 19:14:50,706] 	INFO 	82 	revenue_data.py 	<module>() 	Revenue Data Ended
[2023-08-01 20:17:15,111] 	INFO 	20 	id_data.py 	<module>() 	ID Data Started
[2023-08-01 20:17:15,478] 	INFO 	31 	id_data.py 	<module>() 	ID Data Ended
[2023-08-01 20:17:16,173] 	INFO 	79 	day_data.py 	<module>() 	Day Data Fusion Started
[2023-08-01 20:17:19,389] 	INFO 	126 	day_data.py 	<module>() 	Day Data Fusion Ended
[2023-08-01 20:17:20,605] 	INFO 	123 	pair_data.py 	<module>() 	Pair Data Fusion Started
[2023-08-01 20:17:32,178] 	INFO 	187 	pair_data.py 	<module>() 	Pair Data Fusion Ended
[2023-08-01 20:17:33,289] 	INFO 	37 	bribe_data.py 	<module>() 	Bribe Data Started
[2023-08-01 20:18:16,958] 	INFO 	136 	bribe_data.py 	<module>() 	Bribe Data Ended
[2023-08-01 20:18:18,056] 	INFO 	37 	fee_data.py 	<module>() 	Fee Data Started
[2023-08-01 20:18:59,519] 	INFO 	136 	fee_data.py 	<module>() 	Fee Data Ended
[2023-08-01 20:19:00,277] 	INFO 	24 	revenue_data.py 	<module>() 	Revenue Data Started
[2023-08-01 20:19:04,808] 	INFO 	82 	revenue_data.py 	<module>() 	Revenue Data Ended
[2023-08-01 21:14:02,763] 	INFO 	20 	id_data.py 	<module>() 	ID Data Started
[2023-08-01 21:14:03,168] 	INFO 	31 	id_data.py 	<module>() 	ID Data Ended
[2023-08-01 21:14:03,780] 	INFO 	79 	day_data.py 	<module>() 	Day Data Fusion Started
[2023-08-01 21:14:06,315] 	INFO 	126 	day_data.py 	<module>() 	Day Data Fusion Ended
[2023-08-01 21:14:07,565] 	INFO 	123 	pair_data.py 	<module>() 	Pair Data Fusion Started
[2023-08-01 21:14:18,831] 	INFO 	187 	pair_data.py 	<module>() 	Pair Data Fusion Ended
[2023-08-01 21:14:19,770] 	INFO 	37 	bribe_data.py 	<module>() 	Bribe Data Started
[2023-08-01 21:15:20,917] 	INFO 	136 	bribe_data.py 	<module>() 	Bribe Data Ended
[2023-08-01 21:15:21,877] 	INFO 	37 	fee_data.py 	<module>() 	Fee Data Started
[2023-08-01 21:16:20,449] 	INFO 	136 	fee_data.py 	<module>() 	Fee Data Ended
[2023-08-01 21:16:21,095] 	INFO 	24 	revenue_data.py 	<module>() 	Revenue Data Started
[2023-08-01 21:16:23,542] 	INFO 	82 	revenue_data.py 	<module>() 	Revenue Data Ended
[2023-08-01 22:15:16,969] 	INFO 	20 	id_data.py 	<module>() 	ID Data Started
[2023-08-01 22:15:17,408] 	INFO 	31 	id_data.py 	<module>() 	ID Data Ended
[2023-08-01 22:15:18,213] 	INFO 	79 	day_data.py 	<module>() 	Day Data Fusion Started
[2023-08-01 22:15:20,957] 	INFO 	126 	day_data.py 	<module>() 	Day Data Fusion Ended
[2023-08-01 22:15:22,473] 	INFO 	123 	pair_data.py 	<module>() 	Pair Data Fusion Started
[2023-08-01 22:15:35,050] 	INFO 	187 	pair_data.py 	<module>() 	Pair Data Fusion Ended
[2023-08-01 22:15:36,190] 	INFO 	37 	bribe_data.py 	<module>() 	Bribe Data Started
[2023-08-01 22:16:36,027] 	INFO 	136 	bribe_data.py 	<module>() 	Bribe Data Ended
[2023-08-01 22:16:37,137] 	INFO 	37 	fee_data.py 	<module>() 	Fee Data Started
[2023-08-01 22:17:35,014] 	INFO 	136 	fee_data.py 	<module>() 	Fee Data Ended
[2023-08-01 22:17:35,749] 	INFO 	24 	revenue_data.py 	<module>() 	Revenue Data Started
[2023-08-01 22:17:40,388] 	INFO 	82 	revenue_data.py 	<module>() 	Revenue Data Ended
[2023-08-01 23:16:07,298] 	INFO 	20 	id_data.py 	<module>() 	ID Data Started
[2023-08-01 23:16:07,550] 	INFO 	31 	id_data.py 	<module>() 	ID Data Ended
[2023-08-01 23:16:08,166] 	INFO 	79 	day_data.py 	<module>() 	Day Data Fusion Started
[2023-08-01 23:16:10,786] 	INFO 	126 	day_data.py 	<module>() 	Day Data Fusion Ended
[2023-08-01 23:16:11,910] 	INFO 	123 	pair_data.py 	<module>() 	Pair Data Fusion Started
[2023-08-01 23:16:21,505] 	INFO 	187 	pair_data.py 	<module>() 	Pair Data Fusion Ended
[2023-08-01 23:16:22,449] 	INFO 	37 	bribe_data.py 	<module>() 	Bribe Data Started
[2023-08-01 23:17:03,750] 	INFO 	136 	bribe_data.py 	<module>() 	Bribe Data Ended
[2023-08-01 23:17:04,694] 	INFO 	37 	fee_data.py 	<module>() 	Fee Data Started
[2023-08-01 23:17:43,649] 	INFO 	136 	fee_data.py 	<module>() 	Fee Data Ended
[2023-08-01 23:17:44,312] 	INFO 	24 	revenue_data.py 	<module>() 	Revenue Data Started
[2023-08-01 23:17:47,703] 	INFO 	82 	revenue_data.py 	<module>() 	Revenue Data Ended
[2023-08-02 01:19:36,855] 	INFO 	20 	id_data.py 	<module>() 	ID Data Started
[2023-08-02 01:19:37,297] 	INFO 	31 	id_data.py 	<module>() 	ID Data Ended
[2023-08-02 01:19:37,898] 	INFO 	79 	day_data.py 	<module>() 	Day Data Fusion Started
[2023-08-02 01:19:40,053] 	INFO 	126 	day_data.py 	<module>() 	Day Data Fusion Ended
[2023-08-02 01:19:41,206] 	INFO 	123 	pair_data.py 	<module>() 	Pair Data Fusion Started
[2023-08-02 01:19:51,727] 	INFO 	187 	pair_data.py 	<module>() 	Pair Data Fusion Ended
[2023-08-02 01:19:52,643] 	INFO 	37 	bribe_data.py 	<module>() 	Bribe Data Started
[2023-08-02 01:20:35,666] 	INFO 	136 	bribe_data.py 	<module>() 	Bribe Data Ended
[2023-08-02 01:20:36,601] 	INFO 	37 	fee_data.py 	<module>() 	Fee Data Started
[2023-08-02 01:21:16,631] 	INFO 	136 	fee_data.py 	<module>() 	Fee Data Ended
[2023-08-02 01:21:17,273] 	INFO 	24 	revenue_data.py 	<module>() 	Revenue Data Started
[2023-08-02 01:21:20,140] 	INFO 	82 	revenue_data.py 	<module>() 	Revenue Data Ended
[2023-08-02 02:27:25,879] 	INFO 	20 	id_data.py 	<module>() 	ID Data Started
[2023-08-02 02:27:26,328] 	INFO 	31 	id_data.py 	<module>() 	ID Data Ended
[2023-08-02 02:27:27,243] 	INFO 	79 	day_data.py 	<module>() 	Day Data Fusion Started
[2023-08-02 02:27:32,016] 	INFO 	126 	day_data.py 	<module>() 	Day Data Fusion Ended
[2023-08-02 02:27:33,264] 	INFO 	123 	pair_data.py 	<module>() 	Pair Data Fusion Started
[2023-08-02 02:27:46,098] 	INFO 	187 	pair_data.py 	<module>() 	Pair Data Fusion Ended
[2023-08-02 02:27:47,215] 	INFO 	37 	bribe_data.py 	<module>() 	Bribe Data Started
[2023-08-02 02:28:51,886] 	INFO 	136 	bribe_data.py 	<module>() 	Bribe Data Ended
[2023-08-02 02:28:53,019] 	INFO 	37 	fee_data.py 	<module>() 	Fee Data Started
[2023-08-02 02:29:54,910] 	INFO 	136 	fee_data.py 	<module>() 	Fee Data Ended
[2023-08-02 02:29:55,680] 	INFO 	24 	revenue_data.py 	<module>() 	Revenue Data Started
[2023-08-02 02:30:00,390] 	INFO 	82 	revenue_data.py 	<module>() 	Revenue Data Ended
[2023-08-02 03:16:29,562] 	INFO 	20 	id_data.py 	<module>() 	ID Data Started
[2023-08-02 03:16:29,812] 	INFO 	31 	id_data.py 	<module>() 	ID Data Ended
[2023-08-02 03:16:30,631] 	INFO 	79 	day_data.py 	<module>() 	Day Data Fusion Started
[2023-08-02 03:16:32,600] 	INFO 	126 	day_data.py 	<module>() 	Day Data Fusion Ended
[2023-08-02 03:16:33,883] 	INFO 	123 	pair_data.py 	<module>() 	Pair Data Fusion Started
[2023-08-02 03:16:44,889] 	INFO 	187 	pair_data.py 	<module>() 	Pair Data Fusion Ended
[2023-08-02 03:16:45,737] 	INFO 	37 	bribe_data.py 	<module>() 	Bribe Data Started
[2023-08-02 03:17:24,973] 	INFO 	136 	bribe_data.py 	<module>() 	Bribe Data Ended
[2023-08-02 03:17:25,821] 	INFO 	37 	fee_data.py 	<module>() 	Fee Data Started
[2023-08-02 03:18:06,011] 	INFO 	136 	fee_data.py 	<module>() 	Fee Data Ended
[2023-08-02 03:18:06,586] 	INFO 	24 	revenue_data.py 	<module>() 	Revenue Data Started
[2023-08-02 03:18:08,909] 	INFO 	82 	revenue_data.py 	<module>() 	Revenue Data Ended
[2023-08-02 04:19:07,635] 	INFO 	20 	id_data.py 	<module>() 	ID Data Started
[2023-08-02 04:19:07,958] 	INFO 	31 	id_data.py 	<module>() 	ID Data Ended
[2023-08-02 04:19:08,573] 	INFO 	79 	day_data.py 	<module>() 	Day Data Fusion Started
[2023-08-02 04:19:11,810] 	INFO 	126 	day_data.py 	<module>() 	Day Data Fusion Ended
[2023-08-02 04:19:12,788] 	INFO 	123 	pair_data.py 	<module>() 	Pair Data Fusion Started
[2023-08-02 04:19:25,287] 	INFO 	187 	pair_data.py 	<module>() 	Pair Data Fusion Ended
[2023-08-02 04:19:26,199] 	INFO 	37 	bribe_data.py 	<module>() 	Bribe Data Started
[2023-08-02 04:20:16,949] 	INFO 	136 	bribe_data.py 	<module>() 	Bribe Data Ended
[2023-08-02 04:20:17,922] 	INFO 	37 	fee_data.py 	<module>() 	Fee Data Started
[2023-08-02 04:21:14,833] 	INFO 	136 	fee_data.py 	<module>() 	Fee Data Ended
[2023-08-02 04:21:15,471] 	INFO 	24 	revenue_data.py 	<module>() 	Revenue Data Started
[2023-08-02 04:21:42,944] 	INFO 	82 	revenue_data.py 	<module>() 	Revenue Data Ended
[2023-08-02 05:15:31,151] 	INFO 	20 	id_data.py 	<module>() 	ID Data Started
[2023-08-02 05:15:31,490] 	INFO 	31 	id_data.py 	<module>() 	ID Data Ended
[2023-08-02 05:15:32,269] 	INFO 	79 	day_data.py 	<module>() 	Day Data Fusion Started
[2023-08-02 05:15:35,429] 	INFO 	126 	day_data.py 	<module>() 	Day Data Fusion Ended
[2023-08-02 05:15:36,810] 	INFO 	123 	pair_data.py 	<module>() 	Pair Data Fusion Started
[2023-08-02 05:15:50,500] 	INFO 	187 	pair_data.py 	<module>() 	Pair Data Fusion Ended
[2023-08-02 05:15:51,686] 	INFO 	37 	bribe_data.py 	<module>() 	Bribe Data Started
[2023-08-02 05:16:51,224] 	INFO 	136 	bribe_data.py 	<module>() 	Bribe Data Ended
[2023-08-02 05:16:52,422] 	INFO 	37 	fee_data.py 	<module>() 	Fee Data Started
[2023-08-02 05:17:46,954] 	INFO 	136 	fee_data.py 	<module>() 	Fee Data Ended
[2023-08-02 05:17:47,753] 	INFO 	24 	revenue_data.py 	<module>() 	Revenue Data Started
[2023-08-02 05:17:51,802] 	INFO 	82 	revenue_data.py 	<module>() 	Revenue Data Ended
[2023-08-02 06:21:07,342] 	INFO 	20 	id_data.py 	<module>() 	ID Data Started
[2023-08-02 06:21:07,626] 	INFO 	31 	id_data.py 	<module>() 	ID Data Ended
[2023-08-02 06:21:08,193] 	INFO 	79 	day_data.py 	<module>() 	Day Data Fusion Started
[2023-08-02 06:21:10,033] 	INFO 	126 	day_data.py 	<module>() 	Day Data Fusion Ended
[2023-08-02 06:21:10,991] 	INFO 	123 	pair_data.py 	<module>() 	Pair Data Fusion Started
[2023-08-02 06:21:22,949] 	INFO 	187 	pair_data.py 	<module>() 	Pair Data Fusion Ended
[2023-08-02 06:21:23,882] 	INFO 	37 	bribe_data.py 	<module>() 	Bribe Data Started
[2023-08-02 06:22:03,202] 	INFO 	136 	bribe_data.py 	<module>() 	Bribe Data Ended
[2023-08-02 06:22:04,119] 	INFO 	37 	fee_data.py 	<module>() 	Fee Data Started
[2023-08-02 06:22:42,700] 	INFO 	136 	fee_data.py 	<module>() 	Fee Data Ended
[2023-08-02 06:22:43,335] 	INFO 	24 	revenue_data.py 	<module>() 	Revenue Data Started
[2023-08-02 06:22:46,358] 	INFO 	82 	revenue_data.py 	<module>() 	Revenue Data Ended
[2023-08-02 07:14:42,665] 	INFO 	20 	id_data.py 	<module>() 	ID Data Started
[2023-08-02 07:14:42,884] 	INFO 	31 	id_data.py 	<module>() 	ID Data Ended
[2023-08-02 07:14:43,550] 	INFO 	79 	day_data.py 	<module>() 	Day Data Fusion Started
[2023-08-02 07:14:45,430] 	INFO 	126 	day_data.py 	<module>() 	Day Data Fusion Ended
[2023-08-02 07:14:46,598] 	INFO 	123 	pair_data.py 	<module>() 	Pair Data Fusion Started
[2023-08-02 07:14:57,023] 	INFO 	187 	pair_data.py 	<module>() 	Pair Data Fusion Ended
[2023-08-02 07:14:57,947] 	INFO 	37 	bribe_data.py 	<module>() 	Bribe Data Started
[2023-08-02 07:15:36,570] 	INFO 	136 	bribe_data.py 	<module>() 	Bribe Data Ended
[2023-08-02 07:15:37,517] 	INFO 	37 	fee_data.py 	<module>() 	Fee Data Started
[2023-08-02 07:16:13,420] 	INFO 	136 	fee_data.py 	<module>() 	Fee Data Ended
[2023-08-02 07:16:14,049] 	INFO 	24 	revenue_data.py 	<module>() 	Revenue Data Started
[2023-08-02 07:16:17,142] 	INFO 	82 	revenue_data.py 	<module>() 	Revenue Data Ended
[2023-08-02 08:20:28,328] 	INFO 	20 	id_data.py 	<module>() 	ID Data Started
[2023-08-02 08:20:28,551] 	INFO 	31 	id_data.py 	<module>() 	ID Data Ended
[2023-08-02 08:20:29,202] 	INFO 	79 	day_data.py 	<module>() 	Day Data Fusion Started
[2023-08-02 08:20:31,160] 	INFO 	126 	day_data.py 	<module>() 	Day Data Fusion Ended
[2023-08-02 08:20:32,589] 	INFO 	123 	pair_data.py 	<module>() 	Pair Data Fusion Started
[2023-08-02 08:20:43,246] 	INFO 	187 	pair_data.py 	<module>() 	Pair Data Fusion Ended
[2023-08-02 08:20:44,140] 	INFO 	37 	bribe_data.py 	<module>() 	Bribe Data Started
[2023-08-02 08:21:20,271] 	INFO 	136 	bribe_data.py 	<module>() 	Bribe Data Ended
[2023-08-02 08:21:21,178] 	INFO 	37 	fee_data.py 	<module>() 	Fee Data Started
[2023-08-02 08:21:56,648] 	INFO 	136 	fee_data.py 	<module>() 	Fee Data Ended
[2023-08-02 08:21:57,264] 	INFO 	24 	revenue_data.py 	<module>() 	Revenue Data Started
[2023-08-02 08:22:00,120] 	INFO 	82 	revenue_data.py 	<module>() 	Revenue Data Ended
[2023-08-02 09:16:00,268] 	INFO 	20 	id_data.py 	<module>() 	ID Data Started
[2023-08-02 09:16:00,609] 	INFO 	31 	id_data.py 	<module>() 	ID Data Ended
[2023-08-02 09:16:01,538] 	INFO 	79 	day_data.py 	<module>() 	Day Data Fusion Started
[2023-08-02 09:16:04,680] 	INFO 	126 	day_data.py 	<module>() 	Day Data Fusion Ended
[2023-08-02 09:16:06,081] 	INFO 	123 	pair_data.py 	<module>() 	Pair Data Fusion Started
[2023-08-02 09:16:18,866] 	INFO 	187 	pair_data.py 	<module>() 	Pair Data Fusion Ended
[2023-08-02 09:16:19,954] 	INFO 	37 	bribe_data.py 	<module>() 	Bribe Data Started
[2023-08-02 09:17:04,619] 	INFO 	136 	bribe_data.py 	<module>() 	Bribe Data Ended
[2023-08-02 09:17:05,731] 	INFO 	37 	fee_data.py 	<module>() 	Fee Data Started
[2023-08-02 09:17:45,722] 	INFO 	136 	fee_data.py 	<module>() 	Fee Data Ended
[2023-08-02 09:17:46,452] 	INFO 	24 	revenue_data.py 	<module>() 	Revenue Data Started
[2023-08-02 09:17:50,879] 	INFO 	82 	revenue_data.py 	<module>() 	Revenue Data Ended
[2023-08-02 10:17:53,715] 	INFO 	20 	id_data.py 	<module>() 	ID Data Started
[2023-08-02 10:17:54,408] 	INFO 	31 	id_data.py 	<module>() 	ID Data Ended
[2023-08-02 10:17:55,268] 	INFO 	79 	day_data.py 	<module>() 	Day Data Fusion Started
[2023-08-02 10:17:58,083] 	INFO 	126 	day_data.py 	<module>() 	Day Data Fusion Ended
[2023-08-02 10:17:59,563] 	INFO 	123 	pair_data.py 	<module>() 	Pair Data Fusion Started
[2023-08-02 10:18:12,229] 	INFO 	187 	pair_data.py 	<module>() 	Pair Data Fusion Ended
[2023-08-02 10:18:13,379] 	INFO 	37 	bribe_data.py 	<module>() 	Bribe Data Started
[2023-08-02 10:19:12,800] 	INFO 	136 	bribe_data.py 	<module>() 	Bribe Data Ended
[2023-08-02 10:19:13,936] 	INFO 	37 	fee_data.py 	<module>() 	Fee Data Started
[2023-08-02 10:20:07,022] 	INFO 	136 	fee_data.py 	<module>() 	Fee Data Ended
[2023-08-02 10:20:07,764] 	INFO 	24 	revenue_data.py 	<module>() 	Revenue Data Started
[2023-08-02 10:20:10,645] 	INFO 	82 	revenue_data.py 	<module>() 	Revenue Data Ended
[2023-08-02 11:13:30,404] 	INFO 	20 	id_data.py 	<module>() 	ID Data Started
[2023-08-02 11:13:30,679] 	INFO 	31 	id_data.py 	<module>() 	ID Data Ended
[2023-08-02 11:13:31,464] 	INFO 	79 	day_data.py 	<module>() 	Day Data Fusion Started
[2023-08-02 11:13:38,501] 	INFO 	126 	day_data.py 	<module>() 	Day Data Fusion Ended
[2023-08-02 11:13:39,689] 	INFO 	123 	pair_data.py 	<module>() 	Pair Data Fusion Started
[2023-08-02 11:13:55,793] 	INFO 	187 	pair_data.py 	<module>() 	Pair Data Fusion Ended
[2023-08-02 11:13:56,917] 	INFO 	37 	bribe_data.py 	<module>() 	Bribe Data Started
[2023-08-02 11:14:43,539] 	INFO 	136 	bribe_data.py 	<module>() 	Bribe Data Ended
[2023-08-02 11:14:44,603] 	INFO 	37 	fee_data.py 	<module>() 	Fee Data Started
[2023-08-02 11:15:27,819] 	INFO 	136 	fee_data.py 	<module>() 	Fee Data Ended
[2023-08-02 11:15:28,591] 	INFO 	24 	revenue_data.py 	<module>() 	Revenue Data Started
[2023-08-02 11:15:31,794] 	INFO 	82 	revenue_data.py 	<module>() 	Revenue Data Ended
[2023-08-02 12:31:49,165] 	INFO 	29 	revenue_data.py 	<module>() 	Revenue Data Started
[2023-08-02 12:31:51,259] 	ERROR 	136 	revenue_data.py 	<module>() 	Error occurred during Revenue Data process. Error: name 'epoch' is not defined
Traceback (most recent call last):
  File "revenue_data.py", line 46, in <module>
    ids_df["epoch"] = epoch-1
NameError: name 'epoch' is not defined
[2023-08-02 12:36:45,640] 	INFO 	29 	revenue_data.py 	<module>() 	Revenue Data Started
[2023-08-02 12:36:47,682] 	ERROR 	163 	revenue_data.py 	<module>() 	Error occurred during Revenue Data process. Error: name 'requests' is not defined
Traceback (most recent call last):
  File "revenue_data.py", line 70, in <module>
    response = requests.get(price_api)
NameError: name 'requests' is not defined
[2023-08-02 12:44:26,114] 	INFO 	30 	revenue_data.py 	<module>() 	Revenue Data Started
[2023-08-02 12:44:33,193] 	INFO 	161 	revenue_data.py 	<module>() 	Revenue Data Ended
[2023-08-02 13:19:58,385] 	INFO 	20 	id_data.py 	<module>() 	ID Data Started
[2023-08-02 13:19:58,768] 	INFO 	31 	id_data.py 	<module>() 	ID Data Ended
[2023-08-02 13:19:59,353] 	INFO 	79 	day_data.py 	<module>() 	Day Data Fusion Started
[2023-08-02 13:20:01,234] 	INFO 	126 	day_data.py 	<module>() 	Day Data Fusion Ended
[2023-08-02 13:20:02,388] 	INFO 	123 	pair_data.py 	<module>() 	Pair Data Fusion Started
[2023-08-02 13:20:14,669] 	INFO 	187 	pair_data.py 	<module>() 	Pair Data Fusion Ended
[2023-08-02 13:20:15,530] 	INFO 	37 	bribe_data.py 	<module>() 	Bribe Data Started
[2023-08-02 13:21:00,791] 	INFO 	151 	bribe_data.py 	<module>() 	Bribe Data Ended
[2023-08-02 13:21:01,666] 	INFO 	37 	fee_data.py 	<module>() 	Fee Data Started
[2023-08-02 13:21:43,446] 	INFO 	151 	fee_data.py 	<module>() 	Fee Data Ended
[2023-08-02 13:21:44,315] 	INFO 	30 	revenue_data.py 	<module>() 	Revenue Data Started
[2023-08-02 13:21:51,634] 	INFO 	161 	revenue_data.py 	<module>() 	Revenue Data Ended
[2023-08-02 14:15:24,971] 	INFO 	20 	id_data.py 	<module>() 	ID Data Started
[2023-08-02 14:15:25,436] 	INFO 	31 	id_data.py 	<module>() 	ID Data Ended
[2023-08-02 14:15:26,204] 	INFO 	79 	day_data.py 	<module>() 	Day Data Fusion Started
[2023-08-02 14:15:29,010] 	INFO 	126 	day_data.py 	<module>() 	Day Data Fusion Ended
[2023-08-02 14:15:30,225] 	INFO 	123 	pair_data.py 	<module>() 	Pair Data Fusion Started
[2023-08-02 14:15:49,523] 	INFO 	187 	pair_data.py 	<module>() 	Pair Data Fusion Ended
[2023-08-02 14:15:50,723] 	INFO 	37 	bribe_data.py 	<module>() 	Bribe Data Started
[2023-08-02 14:17:05,193] 	INFO 	151 	bribe_data.py 	<module>() 	Bribe Data Ended
[2023-08-02 14:17:06,419] 	INFO 	37 	fee_data.py 	<module>() 	Fee Data Started
[2023-08-02 14:18:05,431] 	INFO 	151 	fee_data.py 	<module>() 	Fee Data Ended
[2023-08-02 14:18:06,641] 	INFO 	30 	revenue_data.py 	<module>() 	Revenue Data Started
[2023-08-02 14:18:14,135] 	INFO 	161 	revenue_data.py 	<module>() 	Revenue Data Ended
[2023-08-02 14:25:12,834] 	INFO 	30 	revenue_data.py 	<module>() 	Revenue Data Started
[2023-08-02 14:25:21,795] 	INFO 	173 	revenue_data.py 	<module>() 	Revenue Data Ended
[2023-08-02 15:16:37,017] 	INFO 	20 	id_data.py 	<module>() 	ID Data Started
[2023-08-02 15:16:37,703] 	INFO 	31 	id_data.py 	<module>() 	ID Data Ended
[2023-08-02 15:16:38,270] 	INFO 	79 	day_data.py 	<module>() 	Day Data Fusion Started
[2023-08-02 15:16:41,878] 	INFO 	126 	day_data.py 	<module>() 	Day Data Fusion Ended
[2023-08-02 15:16:42,931] 	INFO 	123 	pair_data.py 	<module>() 	Pair Data Fusion Started
[2023-08-02 15:16:55,549] 	INFO 	187 	pair_data.py 	<module>() 	Pair Data Fusion Ended
[2023-08-02 15:16:56,402] 	INFO 	37 	bribe_data.py 	<module>() 	Bribe Data Started
[2023-08-02 15:18:09,752] 	INFO 	151 	bribe_data.py 	<module>() 	Bribe Data Ended
[2023-08-02 15:18:10,599] 	INFO 	37 	fee_data.py 	<module>() 	Fee Data Started
[2023-08-02 15:19:11,988] 	INFO 	151 	fee_data.py 	<module>() 	Fee Data Ended
[2023-08-02 15:19:12,845] 	INFO 	30 	revenue_data.py 	<module>() 	Revenue Data Started
[2023-08-02 15:19:20,508] 	INFO 	173 	revenue_data.py 	<module>() 	Revenue Data Ended
[2023-08-02 16:22:08,782] 	INFO 	20 	id_data.py 	<module>() 	ID Data Started
[2023-08-02 16:22:09,219] 	INFO 	31 	id_data.py 	<module>() 	ID Data Ended
[2023-08-02 16:22:10,143] 	INFO 	79 	day_data.py 	<module>() 	Day Data Fusion Started
[2023-08-02 16:22:12,656] 	INFO 	126 	day_data.py 	<module>() 	Day Data Fusion Ended
[2023-08-02 16:22:13,995] 	INFO 	123 	pair_data.py 	<module>() 	Pair Data Fusion Started
[2023-08-02 16:22:26,256] 	INFO 	187 	pair_data.py 	<module>() 	Pair Data Fusion Ended
[2023-08-02 16:22:27,399] 	INFO 	37 	bribe_data.py 	<module>() 	Bribe Data Started
[2023-08-02 16:23:14,139] 	INFO 	151 	bribe_data.py 	<module>() 	Bribe Data Ended
[2023-08-02 16:23:15,312] 	INFO 	37 	fee_data.py 	<module>() 	Fee Data Started
[2023-08-02 16:23:59,173] 	INFO 	151 	fee_data.py 	<module>() 	Fee Data Ended
[2023-08-02 16:24:00,262] 	INFO 	30 	revenue_data.py 	<module>() 	Revenue Data Started
[2023-08-02 16:24:07,952] 	INFO 	173 	revenue_data.py 	<module>() 	Revenue Data Ended
[2023-08-02 17:14:26,175] 	INFO 	20 	id_data.py 	<module>() 	ID Data Started
[2023-08-02 17:14:26,568] 	INFO 	31 	id_data.py 	<module>() 	ID Data Ended
[2023-08-02 17:14:27,399] 	INFO 	79 	day_data.py 	<module>() 	Day Data Fusion Started
[2023-08-02 17:14:29,597] 	INFO 	126 	day_data.py 	<module>() 	Day Data Fusion Ended
[2023-08-02 17:14:30,896] 	INFO 	123 	pair_data.py 	<module>() 	Pair Data Fusion Started
[2023-08-02 17:14:44,601] 	INFO 	187 	pair_data.py 	<module>() 	Pair Data Fusion Ended
[2023-08-02 17:14:45,863] 	INFO 	37 	bribe_data.py 	<module>() 	Bribe Data Started
[2023-08-02 17:15:50,766] 	INFO 	151 	bribe_data.py 	<module>() 	Bribe Data Ended
[2023-08-02 17:15:51,981] 	INFO 	37 	fee_data.py 	<module>() 	Fee Data Started
[2023-08-02 17:17:00,100] 	INFO 	151 	fee_data.py 	<module>() 	Fee Data Ended
[2023-08-02 17:17:01,304] 	INFO 	30 	revenue_data.py 	<module>() 	Revenue Data Started
[2023-08-02 17:17:09,971] 	INFO 	173 	revenue_data.py 	<module>() 	Revenue Data Ended
[2023-08-02 18:20:27,269] 	INFO 	20 	id_data.py 	<module>() 	ID Data Started
[2023-08-02 18:20:27,720] 	INFO 	31 	id_data.py 	<module>() 	ID Data Ended
[2023-08-02 18:20:28,612] 	INFO 	79 	day_data.py 	<module>() 	Day Data Fusion Started
[2023-08-02 18:20:31,319] 	INFO 	126 	day_data.py 	<module>() 	Day Data Fusion Ended
[2023-08-02 18:20:32,693] 	INFO 	123 	pair_data.py 	<module>() 	Pair Data Fusion Started
[2023-08-02 18:20:48,623] 	INFO 	187 	pair_data.py 	<module>() 	Pair Data Fusion Ended
[2023-08-02 18:20:49,711] 	INFO 	37 	bribe_data.py 	<module>() 	Bribe Data Started
[2023-08-02 18:21:56,598] 	INFO 	151 	bribe_data.py 	<module>() 	Bribe Data Ended
[2023-08-02 18:21:57,704] 	INFO 	37 	fee_data.py 	<module>() 	Fee Data Started
[2023-08-02 18:23:01,511] 	INFO 	151 	fee_data.py 	<module>() 	Fee Data Ended
[2023-08-02 18:23:02,591] 	INFO 	30 	revenue_data.py 	<module>() 	Revenue Data Started
[2023-08-02 18:23:12,243] 	INFO 	173 	revenue_data.py 	<module>() 	Revenue Data Ended
[2023-08-02 19:13:13,238] 	INFO 	20 	id_data.py 	<module>() 	ID Data Started
[2023-08-02 19:13:13,800] 	INFO 	31 	id_data.py 	<module>() 	ID Data Ended
[2023-08-02 19:13:14,512] 	INFO 	79 	day_data.py 	<module>() 	Day Data Fusion Started
[2023-08-02 19:13:17,247] 	INFO 	126 	day_data.py 	<module>() 	Day Data Fusion Ended
[2023-08-02 19:13:18,551] 	INFO 	123 	pair_data.py 	<module>() 	Pair Data Fusion Started
[2023-08-02 19:13:31,600] 	INFO 	187 	pair_data.py 	<module>() 	Pair Data Fusion Ended
[2023-08-02 19:13:32,881] 	INFO 	37 	bribe_data.py 	<module>() 	Bribe Data Started
[2023-08-02 19:14:16,581] 	INFO 	151 	bribe_data.py 	<module>() 	Bribe Data Ended
[2023-08-02 19:14:17,881] 	INFO 	37 	fee_data.py 	<module>() 	Fee Data Started
[2023-08-02 19:15:00,304] 	INFO 	151 	fee_data.py 	<module>() 	Fee Data Ended
[2023-08-02 19:15:01,567] 	INFO 	30 	revenue_data.py 	<module>() 	Revenue Data Started
[2023-08-02 19:15:09,725] 	INFO 	173 	revenue_data.py 	<module>() 	Revenue Data Ended
[2023-08-02 20:17:08,261] 	INFO 	20 	id_data.py 	<module>() 	ID Data Started
[2023-08-02 20:17:08,705] 	INFO 	31 	id_data.py 	<module>() 	ID Data Ended
[2023-08-02 20:17:09,610] 	INFO 	79 	day_data.py 	<module>() 	Day Data Fusion Started
[2023-08-02 20:17:12,108] 	INFO 	126 	day_data.py 	<module>() 	Day Data Fusion Ended
[2023-08-02 20:17:16,149] 	INFO 	123 	pair_data.py 	<module>() 	Pair Data Fusion Started
[2023-08-02 20:17:27,057] 	INFO 	187 	pair_data.py 	<module>() 	Pair Data Fusion Ended
[2023-08-02 20:17:28,182] 	INFO 	37 	bribe_data.py 	<module>() 	Bribe Data Started
[2023-08-02 20:18:13,436] 	INFO 	151 	bribe_data.py 	<module>() 	Bribe Data Ended
[2023-08-02 20:18:14,582] 	INFO 	37 	fee_data.py 	<module>() 	Fee Data Started
[2023-08-02 20:18:58,760] 	INFO 	151 	fee_data.py 	<module>() 	Fee Data Ended
[2023-08-02 20:18:59,902] 	INFO 	30 	revenue_data.py 	<module>() 	Revenue Data Started
[2023-08-02 20:19:07,116] 	INFO 	173 	revenue_data.py 	<module>() 	Revenue Data Ended
[2023-08-02 21:13:50,360] 	INFO 	20 	id_data.py 	<module>() 	ID Data Started
[2023-08-02 21:13:50,828] 	INFO 	31 	id_data.py 	<module>() 	ID Data Ended
[2023-08-02 21:13:51,874] 	INFO 	79 	day_data.py 	<module>() 	Day Data Fusion Started
[2023-08-02 21:13:53,881] 	INFO 	126 	day_data.py 	<module>() 	Day Data Fusion Ended
[2023-08-02 21:13:55,073] 	INFO 	123 	pair_data.py 	<module>() 	Pair Data Fusion Started
[2023-08-02 21:14:05,383] 	INFO 	187 	pair_data.py 	<module>() 	Pair Data Fusion Ended
[2023-08-02 21:14:06,276] 	INFO 	37 	bribe_data.py 	<module>() 	Bribe Data Started
[2023-08-02 21:14:49,998] 	INFO 	151 	bribe_data.py 	<module>() 	Bribe Data Ended
[2023-08-02 21:14:50,899] 	INFO 	37 	fee_data.py 	<module>() 	Fee Data Started
[2023-08-02 21:15:41,816] 	INFO 	151 	fee_data.py 	<module>() 	Fee Data Ended
[2023-08-02 21:15:42,711] 	INFO 	30 	revenue_data.py 	<module>() 	Revenue Data Started
[2023-08-02 21:15:50,616] 	INFO 	173 	revenue_data.py 	<module>() 	Revenue Data Ended
[2023-08-02 22:15:09,769] 	INFO 	20 	id_data.py 	<module>() 	ID Data Started
[2023-08-02 22:15:10,114] 	INFO 	31 	id_data.py 	<module>() 	ID Data Ended
[2023-08-02 22:15:10,901] 	INFO 	79 	day_data.py 	<module>() 	Day Data Fusion Started
[2023-08-02 22:15:13,942] 	INFO 	126 	day_data.py 	<module>() 	Day Data Fusion Ended
[2023-08-02 22:15:15,380] 	INFO 	123 	pair_data.py 	<module>() 	Pair Data Fusion Started
[2023-08-02 22:15:27,586] 	INFO 	187 	pair_data.py 	<module>() 	Pair Data Fusion Ended
[2023-08-02 22:15:28,755] 	INFO 	37 	bribe_data.py 	<module>() 	Bribe Data Started
[2023-08-02 22:16:33,049] 	INFO 	151 	bribe_data.py 	<module>() 	Bribe Data Ended
[2023-08-02 22:16:34,218] 	INFO 	37 	fee_data.py 	<module>() 	Fee Data Started
[2023-08-02 22:17:44,886] 	INFO 	151 	fee_data.py 	<module>() 	Fee Data Ended
[2023-08-02 22:17:46,087] 	INFO 	30 	revenue_data.py 	<module>() 	Revenue Data Started
[2023-08-02 22:17:54,114] 	INFO 	173 	revenue_data.py 	<module>() 	Revenue Data Ended
[2023-08-02 23:15:35,045] 	INFO 	20 	id_data.py 	<module>() 	ID Data Started
[2023-08-02 23:15:35,574] 	INFO 	31 	id_data.py 	<module>() 	ID Data Ended
[2023-08-02 23:15:36,112] 	INFO 	79 	day_data.py 	<module>() 	Day Data Fusion Started
[2023-08-02 23:15:38,100] 	INFO 	126 	day_data.py 	<module>() 	Day Data Fusion Ended
[2023-08-02 23:15:38,992] 	INFO 	123 	pair_data.py 	<module>() 	Pair Data Fusion Started
[2023-08-02 23:15:49,703] 	INFO 	187 	pair_data.py 	<module>() 	Pair Data Fusion Ended
[2023-08-02 23:15:50,549] 	INFO 	37 	bribe_data.py 	<module>() 	Bribe Data Started
[2023-08-02 23:16:35,588] 	INFO 	151 	bribe_data.py 	<module>() 	Bribe Data Ended
[2023-08-02 23:16:36,461] 	INFO 	37 	fee_data.py 	<module>() 	Fee Data Started
[2023-08-02 23:17:20,043] 	INFO 	151 	fee_data.py 	<module>() 	Fee Data Ended
[2023-08-02 23:17:20,911] 	INFO 	30 	revenue_data.py 	<module>() 	Revenue Data Started
[2023-08-02 23:17:27,346] 	INFO 	173 	revenue_data.py 	<module>() 	Revenue Data Ended
[2023-08-03 01:15:36,840] 	INFO 	27 	emissions_data.py 	<module>() 	Emissions Data Started
[2023-08-03 01:15:41,128] 	INFO 	88 	emissions_data.py 	<module>() 	Emissions Data Ended
[2023-08-03 01:21:43,787] 	INFO 	20 	id_data.py 	<module>() 	ID Data Started
[2023-08-03 01:21:44,102] 	INFO 	31 	id_data.py 	<module>() 	ID Data Ended
[2023-08-03 01:21:44,727] 	INFO 	79 	day_data.py 	<module>() 	Day Data Fusion Started
[2023-08-03 01:21:48,942] 	INFO 	126 	day_data.py 	<module>() 	Day Data Fusion Ended
[2023-08-03 01:21:49,956] 	INFO 	123 	pair_data.py 	<module>() 	Pair Data Fusion Started
[2023-08-03 01:22:02,947] 	INFO 	187 	pair_data.py 	<module>() 	Pair Data Fusion Ended
[2023-08-03 01:22:03,934] 	INFO 	37 	bribe_data.py 	<module>() 	Bribe Data Started
[2023-08-03 01:23:09,407] 	INFO 	151 	bribe_data.py 	<module>() 	Bribe Data Ended
[2023-08-03 01:23:10,438] 	INFO 	37 	fee_data.py 	<module>() 	Fee Data Started
[2023-08-03 01:24:13,807] 	INFO 	151 	fee_data.py 	<module>() 	Fee Data Ended
[2023-08-03 01:24:14,826] 	INFO 	30 	revenue_data.py 	<module>() 	Revenue Data Started
[2023-08-03 01:24:23,574] 	INFO 	173 	revenue_data.py 	<module>() 	Revenue Data Ended
[2023-08-03 02:29:33,384] 	INFO 	20 	id_data.py 	<module>() 	ID Data Started
[2023-08-03 02:29:33,696] 	INFO 	31 	id_data.py 	<module>() 	ID Data Ended
[2023-08-03 02:29:34,257] 	INFO 	79 	day_data.py 	<module>() 	Day Data Fusion Started
[2023-08-03 02:29:37,630] 	INFO 	126 	day_data.py 	<module>() 	Day Data Fusion Ended
[2023-08-03 02:29:38,573] 	INFO 	123 	pair_data.py 	<module>() 	Pair Data Fusion Started
[2023-08-03 02:29:51,486] 	INFO 	187 	pair_data.py 	<module>() 	Pair Data Fusion Ended
[2023-08-03 02:29:52,331] 	INFO 	37 	bribe_data.py 	<module>() 	Bribe Data Started
[2023-08-03 02:30:39,547] 	INFO 	151 	bribe_data.py 	<module>() 	Bribe Data Ended
[2023-08-03 02:30:40,396] 	INFO 	37 	fee_data.py 	<module>() 	Fee Data Started
[2023-08-03 02:31:26,554] 	INFO 	151 	fee_data.py 	<module>() 	Fee Data Ended
[2023-08-03 02:31:27,403] 	INFO 	30 	revenue_data.py 	<module>() 	Revenue Data Started
[2023-08-03 02:31:35,384] 	INFO 	173 	revenue_data.py 	<module>() 	Revenue Data Ended
[2023-08-03 03:16:35,577] 	INFO 	20 	id_data.py 	<module>() 	ID Data Started
[2023-08-03 03:16:35,809] 	ERROR 	33 	id_data.py 	<module>() 	Error occurred during ID Data process. Error: HTTPSConnectionPool(host='retro-backend.stabl.finance', port=443): Max retries exceeded with url: /api/v1/fusions (Caused by NewConnectionError('<urllib3.connection.HTTPSConnection object at 0x7efeec7c7610>: Failed to establish a new connection: [Errno -2] Name or service not known'))
Traceback (most recent call last):
  File "/opt/hostedtoolcache/Python/3.8.17/x64/lib/python3.8/site-packages/urllib3/connection.py", line 174, in _new_conn
    conn = connection.create_connection(
  File "/opt/hostedtoolcache/Python/3.8.17/x64/lib/python3.8/site-packages/urllib3/util/connection.py", line 72, in create_connection
    for res in socket.getaddrinfo(host, port, family, socket.SOCK_STREAM):
  File "/opt/hostedtoolcache/Python/3.8.17/x64/lib/python3.8/socket.py", line 918, in getaddrinfo
    for res in _socket.getaddrinfo(host, port, family, type, proto, flags):
socket.gaierror: [Errno -2] Name or service not known

During handling of the above exception, another exception occurred:

Traceback (most recent call last):
  File "/opt/hostedtoolcache/Python/3.8.17/x64/lib/python3.8/site-packages/urllib3/connectionpool.py", line 714, in urlopen
    httplib_response = self._make_request(
  File "/opt/hostedtoolcache/Python/3.8.17/x64/lib/python3.8/site-packages/urllib3/connectionpool.py", line 403, in _make_request
    self._validate_conn(conn)
  File "/opt/hostedtoolcache/Python/3.8.17/x64/lib/python3.8/site-packages/urllib3/connectionpool.py", line 1053, in _validate_conn
    conn.connect()
  File "/opt/hostedtoolcache/Python/3.8.17/x64/lib/python3.8/site-packages/urllib3/connection.py", line 363, in connect
    self.sock = conn = self._new_conn()
  File "/opt/hostedtoolcache/Python/3.8.17/x64/lib/python3.8/site-packages/urllib3/connection.py", line 186, in _new_conn
    raise NewConnectionError(
urllib3.exceptions.NewConnectionError: <urllib3.connection.HTTPSConnection object at 0x7efeec7c7610>: Failed to establish a new connection: [Errno -2] Name or service not known

During handling of the above exception, another exception occurred:

Traceback (most recent call last):
  File "/opt/hostedtoolcache/Python/3.8.17/x64/lib/python3.8/site-packages/requests/adapters.py", line 486, in send
    resp = conn.urlopen(
  File "/opt/hostedtoolcache/Python/3.8.17/x64/lib/python3.8/site-packages/urllib3/connectionpool.py", line 798, in urlopen
    retries = retries.increment(
  File "/opt/hostedtoolcache/Python/3.8.17/x64/lib/python3.8/site-packages/urllib3/util/retry.py", line 592, in increment
    raise MaxRetryError(_pool, url, error or ResponseError(cause))
urllib3.exceptions.MaxRetryError: HTTPSConnectionPool(host='retro-backend.stabl.finance', port=443): Max retries exceeded with url: /api/v1/fusions (Caused by NewConnectionError('<urllib3.connection.HTTPSConnection object at 0x7efeec7c7610>: Failed to establish a new connection: [Errno -2] Name or service not known'))

During handling of the above exception, another exception occurred:

Traceback (most recent call last):
  File "id_data.py", line 26, in <module>
    response = requests.get(url=fusion_api)
  File "/opt/hostedtoolcache/Python/3.8.17/x64/lib/python3.8/site-packages/requests/api.py", line 73, in get
    return request("get", url, params=params, **kwargs)
  File "/opt/hostedtoolcache/Python/3.8.17/x64/lib/python3.8/site-packages/requests/api.py", line 59, in request
    return session.request(method=method, url=url, **kwargs)
  File "/opt/hostedtoolcache/Python/3.8.17/x64/lib/python3.8/site-packages/requests/sessions.py", line 589, in request
    resp = self.send(prep, **send_kwargs)
  File "/opt/hostedtoolcache/Python/3.8.17/x64/lib/python3.8/site-packages/requests/sessions.py", line 703, in send
    r = adapter.send(request, **kwargs)
  File "/opt/hostedtoolcache/Python/3.8.17/x64/lib/python3.8/site-packages/requests/adapters.py", line 519, in send
    raise ConnectionError(e, request=request)
requests.exceptions.ConnectionError: HTTPSConnectionPool(host='retro-backend.stabl.finance', port=443): Max retries exceeded with url: /api/v1/fusions (Caused by NewConnectionError('<urllib3.connection.HTTPSConnection object at 0x7efeec7c7610>: Failed to establish a new connection: [Errno -2] Name or service not known'))
[2023-08-03 03:16:36,609] 	INFO 	79 	day_data.py 	<module>() 	Day Data Fusion Started
[2023-08-03 03:16:40,063] 	INFO 	126 	day_data.py 	<module>() 	Day Data Fusion Ended
[2023-08-03 03:16:41,290] 	INFO 	123 	pair_data.py 	<module>() 	Pair Data Fusion Started
[2023-08-03 03:16:54,165] 	INFO 	187 	pair_data.py 	<module>() 	Pair Data Fusion Ended
[2023-08-03 03:16:55,332] 	INFO 	37 	bribe_data.py 	<module>() 	Bribe Data Started
[2023-08-03 03:17:56,656] 	ERROR 	153 	bribe_data.py 	<module>() 	Error occurred during Bribe Data process. Error: HTTPSConnectionPool(host='retro-backend.stabl.finance', port=443): Max retries exceeded with url: /api/v1/assets (Caused by NewConnectionError('<urllib3.connection.HTTPSConnection object at 0x7f2801744790>: Failed to establish a new connection: [Errno -2] Name or service not known'))
Traceback (most recent call last):
  File "/opt/hostedtoolcache/Python/3.8.17/x64/lib/python3.8/site-packages/urllib3/connection.py", line 174, in _new_conn
    conn = connection.create_connection(
  File "/opt/hostedtoolcache/Python/3.8.17/x64/lib/python3.8/site-packages/urllib3/util/connection.py", line 72, in create_connection
    for res in socket.getaddrinfo(host, port, family, socket.SOCK_STREAM):
  File "/opt/hostedtoolcache/Python/3.8.17/x64/lib/python3.8/socket.py", line 918, in getaddrinfo
    for res in _socket.getaddrinfo(host, port, family, type, proto, flags):
socket.gaierror: [Errno -2] Name or service not known

During handling of the above exception, another exception occurred:

Traceback (most recent call last):
  File "/opt/hostedtoolcache/Python/3.8.17/x64/lib/python3.8/site-packages/urllib3/connectionpool.py", line 714, in urlopen
    httplib_response = self._make_request(
  File "/opt/hostedtoolcache/Python/3.8.17/x64/lib/python3.8/site-packages/urllib3/connectionpool.py", line 403, in _make_request
    self._validate_conn(conn)
  File "/opt/hostedtoolcache/Python/3.8.17/x64/lib/python3.8/site-packages/urllib3/connectionpool.py", line 1053, in _validate_conn
    conn.connect()
  File "/opt/hostedtoolcache/Python/3.8.17/x64/lib/python3.8/site-packages/urllib3/connection.py", line 363, in connect
    self.sock = conn = self._new_conn()
  File "/opt/hostedtoolcache/Python/3.8.17/x64/lib/python3.8/site-packages/urllib3/connection.py", line 186, in _new_conn
    raise NewConnectionError(
urllib3.exceptions.NewConnectionError: <urllib3.connection.HTTPSConnection object at 0x7f2801744790>: Failed to establish a new connection: [Errno -2] Name or service not known

During handling of the above exception, another exception occurred:

Traceback (most recent call last):
  File "/opt/hostedtoolcache/Python/3.8.17/x64/lib/python3.8/site-packages/requests/adapters.py", line 486, in send
    resp = conn.urlopen(
  File "/opt/hostedtoolcache/Python/3.8.17/x64/lib/python3.8/site-packages/urllib3/connectionpool.py", line 798, in urlopen
    retries = retries.increment(
  File "/opt/hostedtoolcache/Python/3.8.17/x64/lib/python3.8/site-packages/urllib3/util/retry.py", line 592, in increment
    raise MaxRetryError(_pool, url, error or ResponseError(cause))
urllib3.exceptions.MaxRetryError: HTTPSConnectionPool(host='retro-backend.stabl.finance', port=443): Max retries exceeded with url: /api/v1/assets (Caused by NewConnectionError('<urllib3.connection.HTTPSConnection object at 0x7f2801744790>: Failed to establish a new connection: [Errno -2] Name or service not known'))

During handling of the above exception, another exception occurred:

Traceback (most recent call last):
  File "bribe_data.py", line 93, in <module>
    response = requests.get(price_api)
  File "/opt/hostedtoolcache/Python/3.8.17/x64/lib/python3.8/site-packages/requests/api.py", line 73, in get
    return request("get", url, params=params, **kwargs)
  File "/opt/hostedtoolcache/Python/3.8.17/x64/lib/python3.8/site-packages/requests/api.py", line 59, in request
    return session.request(method=method, url=url, **kwargs)
  File "/opt/hostedtoolcache/Python/3.8.17/x64/lib/python3.8/site-packages/requests/sessions.py", line 589, in request
    resp = self.send(prep, **send_kwargs)
  File "/opt/hostedtoolcache/Python/3.8.17/x64/lib/python3.8/site-packages/requests/sessions.py", line 703, in send
    r = adapter.send(request, **kwargs)
  File "/opt/hostedtoolcache/Python/3.8.17/x64/lib/python3.8/site-packages/requests/adapters.py", line 519, in send
    raise ConnectionError(e, request=request)
requests.exceptions.ConnectionError: HTTPSConnectionPool(host='retro-backend.stabl.finance', port=443): Max retries exceeded with url: /api/v1/assets (Caused by NewConnectionError('<urllib3.connection.HTTPSConnection object at 0x7f2801744790>: Failed to establish a new connection: [Errno -2] Name or service not known'))
[2023-08-03 03:17:57,818] 	INFO 	37 	fee_data.py 	<module>() 	Fee Data Started
[2023-08-03 03:19:01,109] 	ERROR 	153 	fee_data.py 	<module>() 	Error occurred during Fee Data process. Error: HTTPSConnectionPool(host='retro-backend.stabl.finance', port=443): Max retries exceeded with url: /api/v1/assets (Caused by NewConnectionError('<urllib3.connection.HTTPSConnection object at 0x7f1bf8b1d8e0>: Failed to establish a new connection: [Errno -2] Name or service not known'))
Traceback (most recent call last):
  File "/opt/hostedtoolcache/Python/3.8.17/x64/lib/python3.8/site-packages/urllib3/connection.py", line 174, in _new_conn
    conn = connection.create_connection(
  File "/opt/hostedtoolcache/Python/3.8.17/x64/lib/python3.8/site-packages/urllib3/util/connection.py", line 72, in create_connection
    for res in socket.getaddrinfo(host, port, family, socket.SOCK_STREAM):
  File "/opt/hostedtoolcache/Python/3.8.17/x64/lib/python3.8/socket.py", line 918, in getaddrinfo
    for res in _socket.getaddrinfo(host, port, family, type, proto, flags):
socket.gaierror: [Errno -2] Name or service not known

During handling of the above exception, another exception occurred:

Traceback (most recent call last):
  File "/opt/hostedtoolcache/Python/3.8.17/x64/lib/python3.8/site-packages/urllib3/connectionpool.py", line 714, in urlopen
    httplib_response = self._make_request(
  File "/opt/hostedtoolcache/Python/3.8.17/x64/lib/python3.8/site-packages/urllib3/connectionpool.py", line 403, in _make_request
    self._validate_conn(conn)
  File "/opt/hostedtoolcache/Python/3.8.17/x64/lib/python3.8/site-packages/urllib3/connectionpool.py", line 1053, in _validate_conn
    conn.connect()
  File "/opt/hostedtoolcache/Python/3.8.17/x64/lib/python3.8/site-packages/urllib3/connection.py", line 363, in connect
    self.sock = conn = self._new_conn()
  File "/opt/hostedtoolcache/Python/3.8.17/x64/lib/python3.8/site-packages/urllib3/connection.py", line 186, in _new_conn
    raise NewConnectionError(
urllib3.exceptions.NewConnectionError: <urllib3.connection.HTTPSConnection object at 0x7f1bf8b1d8e0>: Failed to establish a new connection: [Errno -2] Name or service not known

During handling of the above exception, another exception occurred:

Traceback (most recent call last):
  File "/opt/hostedtoolcache/Python/3.8.17/x64/lib/python3.8/site-packages/requests/adapters.py", line 486, in send
    resp = conn.urlopen(
  File "/opt/hostedtoolcache/Python/3.8.17/x64/lib/python3.8/site-packages/urllib3/connectionpool.py", line 798, in urlopen
    retries = retries.increment(
  File "/opt/hostedtoolcache/Python/3.8.17/x64/lib/python3.8/site-packages/urllib3/util/retry.py", line 592, in increment
    raise MaxRetryError(_pool, url, error or ResponseError(cause))
urllib3.exceptions.MaxRetryError: HTTPSConnectionPool(host='retro-backend.stabl.finance', port=443): Max retries exceeded with url: /api/v1/assets (Caused by NewConnectionError('<urllib3.connection.HTTPSConnection object at 0x7f1bf8b1d8e0>: Failed to establish a new connection: [Errno -2] Name or service not known'))

During handling of the above exception, another exception occurred:

Traceback (most recent call last):
  File "fee_data.py", line 93, in <module>
    response = requests.get(price_api)
  File "/opt/hostedtoolcache/Python/3.8.17/x64/lib/python3.8/site-packages/requests/api.py", line 73, in get
    return request("get", url, params=params, **kwargs)
  File "/opt/hostedtoolcache/Python/3.8.17/x64/lib/python3.8/site-packages/requests/api.py", line 59, in request
    return session.request(method=method, url=url, **kwargs)
  File "/opt/hostedtoolcache/Python/3.8.17/x64/lib/python3.8/site-packages/requests/sessions.py", line 589, in request
    resp = self.send(prep, **send_kwargs)
  File "/opt/hostedtoolcache/Python/3.8.17/x64/lib/python3.8/site-packages/requests/sessions.py", line 703, in send
    r = adapter.send(request, **kwargs)
  File "/opt/hostedtoolcache/Python/3.8.17/x64/lib/python3.8/site-packages/requests/adapters.py", line 519, in send
    raise ConnectionError(e, request=request)
requests.exceptions.ConnectionError: HTTPSConnectionPool(host='retro-backend.stabl.finance', port=443): Max retries exceeded with url: /api/v1/assets (Caused by NewConnectionError('<urllib3.connection.HTTPSConnection object at 0x7f1bf8b1d8e0>: Failed to establish a new connection: [Errno -2] Name or service not known'))
[2023-08-03 03:19:02,278] 	INFO 	30 	revenue_data.py 	<module>() 	Revenue Data Started
[2023-08-03 03:19:04,742] 	ERROR 	175 	revenue_data.py 	<module>() 	Error occurred during Revenue Data process. Error: HTTPSConnectionPool(host='retro-backend.stabl.finance', port=443): Max retries exceeded with url: /api/v1/assets (Caused by NewConnectionError('<urllib3.connection.HTTPSConnection object at 0x7f12180c24f0>: Failed to establish a new connection: [Errno -2] Name or service not known'))
Traceback (most recent call last):
  File "/opt/hostedtoolcache/Python/3.8.17/x64/lib/python3.8/site-packages/urllib3/connection.py", line 174, in _new_conn
    conn = connection.create_connection(
  File "/opt/hostedtoolcache/Python/3.8.17/x64/lib/python3.8/site-packages/urllib3/util/connection.py", line 72, in create_connection
    for res in socket.getaddrinfo(host, port, family, socket.SOCK_STREAM):
  File "/opt/hostedtoolcache/Python/3.8.17/x64/lib/python3.8/socket.py", line 918, in getaddrinfo
    for res in _socket.getaddrinfo(host, port, family, type, proto, flags):
socket.gaierror: [Errno -2] Name or service not known

During handling of the above exception, another exception occurred:

Traceback (most recent call last):
  File "/opt/hostedtoolcache/Python/3.8.17/x64/lib/python3.8/site-packages/urllib3/connectionpool.py", line 714, in urlopen
    httplib_response = self._make_request(
  File "/opt/hostedtoolcache/Python/3.8.17/x64/lib/python3.8/site-packages/urllib3/connectionpool.py", line 403, in _make_request
    self._validate_conn(conn)
  File "/opt/hostedtoolcache/Python/3.8.17/x64/lib/python3.8/site-packages/urllib3/connectionpool.py", line 1053, in _validate_conn
    conn.connect()
  File "/opt/hostedtoolcache/Python/3.8.17/x64/lib/python3.8/site-packages/urllib3/connection.py", line 363, in connect
    self.sock = conn = self._new_conn()
  File "/opt/hostedtoolcache/Python/3.8.17/x64/lib/python3.8/site-packages/urllib3/connection.py", line 186, in _new_conn
    raise NewConnectionError(
urllib3.exceptions.NewConnectionError: <urllib3.connection.HTTPSConnection object at 0x7f12180c24f0>: Failed to establish a new connection: [Errno -2] Name or service not known

During handling of the above exception, another exception occurred:

Traceback (most recent call last):
  File "/opt/hostedtoolcache/Python/3.8.17/x64/lib/python3.8/site-packages/requests/adapters.py", line 486, in send
    resp = conn.urlopen(
  File "/opt/hostedtoolcache/Python/3.8.17/x64/lib/python3.8/site-packages/urllib3/connectionpool.py", line 798, in urlopen
    retries = retries.increment(
  File "/opt/hostedtoolcache/Python/3.8.17/x64/lib/python3.8/site-packages/urllib3/util/retry.py", line 592, in increment
    raise MaxRetryError(_pool, url, error or ResponseError(cause))
urllib3.exceptions.MaxRetryError: HTTPSConnectionPool(host='retro-backend.stabl.finance', port=443): Max retries exceeded with url: /api/v1/assets (Caused by NewConnectionError('<urllib3.connection.HTTPSConnection object at 0x7f12180c24f0>: Failed to establish a new connection: [Errno -2] Name or service not known'))

During handling of the above exception, another exception occurred:

Traceback (most recent call last):
  File "revenue_data.py", line 73, in <module>
    response = requests.get(price_api)
  File "/opt/hostedtoolcache/Python/3.8.17/x64/lib/python3.8/site-packages/requests/api.py", line 73, in get
    return request("get", url, params=params, **kwargs)
  File "/opt/hostedtoolcache/Python/3.8.17/x64/lib/python3.8/site-packages/requests/api.py", line 59, in request
    return session.request(method=method, url=url, **kwargs)
  File "/opt/hostedtoolcache/Python/3.8.17/x64/lib/python3.8/site-packages/requests/sessions.py", line 589, in request
    resp = self.send(prep, **send_kwargs)
  File "/opt/hostedtoolcache/Python/3.8.17/x64/lib/python3.8/site-packages/requests/sessions.py", line 703, in send
    r = adapter.send(request, **kwargs)
  File "/opt/hostedtoolcache/Python/3.8.17/x64/lib/python3.8/site-packages/requests/adapters.py", line 519, in send
    raise ConnectionError(e, request=request)
requests.exceptions.ConnectionError: HTTPSConnectionPool(host='retro-backend.stabl.finance', port=443): Max retries exceeded with url: /api/v1/assets (Caused by NewConnectionError('<urllib3.connection.HTTPSConnection object at 0x7f12180c24f0>: Failed to establish a new connection: [Errno -2] Name or service not known'))
[2023-08-03 04:19:44,397] 	INFO 	20 	id_data.py 	<module>() 	ID Data Started
[2023-08-03 04:19:44,434] 	ERROR 	33 	id_data.py 	<module>() 	Error occurred during ID Data process. Error: HTTPSConnectionPool(host='retro-backend.stabl.finance', port=443): Max retries exceeded with url: /api/v1/fusions (Caused by NewConnectionError('<urllib3.connection.HTTPSConnection object at 0x7f9a88617610>: Failed to establish a new connection: [Errno -2] Name or service not known'))
Traceback (most recent call last):
  File "/opt/hostedtoolcache/Python/3.8.17/x64/lib/python3.8/site-packages/urllib3/connection.py", line 174, in _new_conn
    conn = connection.create_connection(
  File "/opt/hostedtoolcache/Python/3.8.17/x64/lib/python3.8/site-packages/urllib3/util/connection.py", line 72, in create_connection
    for res in socket.getaddrinfo(host, port, family, socket.SOCK_STREAM):
  File "/opt/hostedtoolcache/Python/3.8.17/x64/lib/python3.8/socket.py", line 918, in getaddrinfo
    for res in _socket.getaddrinfo(host, port, family, type, proto, flags):
socket.gaierror: [Errno -2] Name or service not known

During handling of the above exception, another exception occurred:

Traceback (most recent call last):
  File "/opt/hostedtoolcache/Python/3.8.17/x64/lib/python3.8/site-packages/urllib3/connectionpool.py", line 714, in urlopen
    httplib_response = self._make_request(
  File "/opt/hostedtoolcache/Python/3.8.17/x64/lib/python3.8/site-packages/urllib3/connectionpool.py", line 403, in _make_request
    self._validate_conn(conn)
  File "/opt/hostedtoolcache/Python/3.8.17/x64/lib/python3.8/site-packages/urllib3/connectionpool.py", line 1053, in _validate_conn
    conn.connect()
  File "/opt/hostedtoolcache/Python/3.8.17/x64/lib/python3.8/site-packages/urllib3/connection.py", line 363, in connect
    self.sock = conn = self._new_conn()
  File "/opt/hostedtoolcache/Python/3.8.17/x64/lib/python3.8/site-packages/urllib3/connection.py", line 186, in _new_conn
    raise NewConnectionError(
urllib3.exceptions.NewConnectionError: <urllib3.connection.HTTPSConnection object at 0x7f9a88617610>: Failed to establish a new connection: [Errno -2] Name or service not known

During handling of the above exception, another exception occurred:

Traceback (most recent call last):
  File "/opt/hostedtoolcache/Python/3.8.17/x64/lib/python3.8/site-packages/requests/adapters.py", line 486, in send
    resp = conn.urlopen(
  File "/opt/hostedtoolcache/Python/3.8.17/x64/lib/python3.8/site-packages/urllib3/connectionpool.py", line 798, in urlopen
    retries = retries.increment(
  File "/opt/hostedtoolcache/Python/3.8.17/x64/lib/python3.8/site-packages/urllib3/util/retry.py", line 592, in increment
    raise MaxRetryError(_pool, url, error or ResponseError(cause))
urllib3.exceptions.MaxRetryError: HTTPSConnectionPool(host='retro-backend.stabl.finance', port=443): Max retries exceeded with url: /api/v1/fusions (Caused by NewConnectionError('<urllib3.connection.HTTPSConnection object at 0x7f9a88617610>: Failed to establish a new connection: [Errno -2] Name or service not known'))

During handling of the above exception, another exception occurred:

Traceback (most recent call last):
  File "id_data.py", line 26, in <module>
    response = requests.get(url=fusion_api)
  File "/opt/hostedtoolcache/Python/3.8.17/x64/lib/python3.8/site-packages/requests/api.py", line 73, in get
    return request("get", url, params=params, **kwargs)
  File "/opt/hostedtoolcache/Python/3.8.17/x64/lib/python3.8/site-packages/requests/api.py", line 59, in request
    return session.request(method=method, url=url, **kwargs)
  File "/opt/hostedtoolcache/Python/3.8.17/x64/lib/python3.8/site-packages/requests/sessions.py", line 589, in request
    resp = self.send(prep, **send_kwargs)
  File "/opt/hostedtoolcache/Python/3.8.17/x64/lib/python3.8/site-packages/requests/sessions.py", line 703, in send
    r = adapter.send(request, **kwargs)
  File "/opt/hostedtoolcache/Python/3.8.17/x64/lib/python3.8/site-packages/requests/adapters.py", line 519, in send
    raise ConnectionError(e, request=request)
requests.exceptions.ConnectionError: HTTPSConnectionPool(host='retro-backend.stabl.finance', port=443): Max retries exceeded with url: /api/v1/fusions (Caused by NewConnectionError('<urllib3.connection.HTTPSConnection object at 0x7f9a88617610>: Failed to establish a new connection: [Errno -2] Name or service not known'))
[2023-08-03 04:19:45,205] 	INFO 	79 	day_data.py 	<module>() 	Day Data Fusion Started
[2023-08-03 04:19:48,865] 	INFO 	126 	day_data.py 	<module>() 	Day Data Fusion Ended
[2023-08-03 04:19:50,308] 	INFO 	123 	pair_data.py 	<module>() 	Pair Data Fusion Started
[2023-08-03 04:20:02,700] 	INFO 	187 	pair_data.py 	<module>() 	Pair Data Fusion Ended
[2023-08-03 04:20:03,772] 	INFO 	37 	bribe_data.py 	<module>() 	Bribe Data Started
[2023-08-03 04:20:47,003] 	ERROR 	153 	bribe_data.py 	<module>() 	Error occurred during Bribe Data process. Error: HTTPSConnectionPool(host='retro-backend.stabl.finance', port=443): Max retries exceeded with url: /api/v1/assets (Caused by NewConnectionError('<urllib3.connection.HTTPSConnection object at 0x7f67339886d0>: Failed to establish a new connection: [Errno -2] Name or service not known'))
Traceback (most recent call last):
  File "/opt/hostedtoolcache/Python/3.8.17/x64/lib/python3.8/site-packages/urllib3/connection.py", line 174, in _new_conn
    conn = connection.create_connection(
  File "/opt/hostedtoolcache/Python/3.8.17/x64/lib/python3.8/site-packages/urllib3/util/connection.py", line 72, in create_connection
    for res in socket.getaddrinfo(host, port, family, socket.SOCK_STREAM):
  File "/opt/hostedtoolcache/Python/3.8.17/x64/lib/python3.8/socket.py", line 918, in getaddrinfo
    for res in _socket.getaddrinfo(host, port, family, type, proto, flags):
socket.gaierror: [Errno -2] Name or service not known

During handling of the above exception, another exception occurred:

Traceback (most recent call last):
  File "/opt/hostedtoolcache/Python/3.8.17/x64/lib/python3.8/site-packages/urllib3/connectionpool.py", line 714, in urlopen
    httplib_response = self._make_request(
  File "/opt/hostedtoolcache/Python/3.8.17/x64/lib/python3.8/site-packages/urllib3/connectionpool.py", line 403, in _make_request
    self._validate_conn(conn)
  File "/opt/hostedtoolcache/Python/3.8.17/x64/lib/python3.8/site-packages/urllib3/connectionpool.py", line 1053, in _validate_conn
    conn.connect()
  File "/opt/hostedtoolcache/Python/3.8.17/x64/lib/python3.8/site-packages/urllib3/connection.py", line 363, in connect
    self.sock = conn = self._new_conn()
  File "/opt/hostedtoolcache/Python/3.8.17/x64/lib/python3.8/site-packages/urllib3/connection.py", line 186, in _new_conn
    raise NewConnectionError(
urllib3.exceptions.NewConnectionError: <urllib3.connection.HTTPSConnection object at 0x7f67339886d0>: Failed to establish a new connection: [Errno -2] Name or service not known

During handling of the above exception, another exception occurred:

Traceback (most recent call last):
  File "/opt/hostedtoolcache/Python/3.8.17/x64/lib/python3.8/site-packages/requests/adapters.py", line 486, in send
    resp = conn.urlopen(
  File "/opt/hostedtoolcache/Python/3.8.17/x64/lib/python3.8/site-packages/urllib3/connectionpool.py", line 798, in urlopen
    retries = retries.increment(
  File "/opt/hostedtoolcache/Python/3.8.17/x64/lib/python3.8/site-packages/urllib3/util/retry.py", line 592, in increment
    raise MaxRetryError(_pool, url, error or ResponseError(cause))
urllib3.exceptions.MaxRetryError: HTTPSConnectionPool(host='retro-backend.stabl.finance', port=443): Max retries exceeded with url: /api/v1/assets (Caused by NewConnectionError('<urllib3.connection.HTTPSConnection object at 0x7f67339886d0>: Failed to establish a new connection: [Errno -2] Name or service not known'))

During handling of the above exception, another exception occurred:

Traceback (most recent call last):
  File "bribe_data.py", line 93, in <module>
    response = requests.get(price_api)
  File "/opt/hostedtoolcache/Python/3.8.17/x64/lib/python3.8/site-packages/requests/api.py", line 73, in get
    return request("get", url, params=params, **kwargs)
  File "/opt/hostedtoolcache/Python/3.8.17/x64/lib/python3.8/site-packages/requests/api.py", line 59, in request
    return session.request(method=method, url=url, **kwargs)
  File "/opt/hostedtoolcache/Python/3.8.17/x64/lib/python3.8/site-packages/requests/sessions.py", line 589, in request
    resp = self.send(prep, **send_kwargs)
  File "/opt/hostedtoolcache/Python/3.8.17/x64/lib/python3.8/site-packages/requests/sessions.py", line 703, in send
    r = adapter.send(request, **kwargs)
  File "/opt/hostedtoolcache/Python/3.8.17/x64/lib/python3.8/site-packages/requests/adapters.py", line 519, in send
    raise ConnectionError(e, request=request)
requests.exceptions.ConnectionError: HTTPSConnectionPool(host='retro-backend.stabl.finance', port=443): Max retries exceeded with url: /api/v1/assets (Caused by NewConnectionError('<urllib3.connection.HTTPSConnection object at 0x7f67339886d0>: Failed to establish a new connection: [Errno -2] Name or service not known'))
[2023-08-03 04:20:48,115] 	INFO 	37 	fee_data.py 	<module>() 	Fee Data Started
[2023-08-03 04:21:27,232] 	ERROR 	153 	fee_data.py 	<module>() 	Error occurred during Fee Data process. Error: HTTPSConnectionPool(host='retro-backend.stabl.finance', port=443): Max retries exceeded with url: /api/v1/assets (Caused by NewConnectionError('<urllib3.connection.HTTPSConnection object at 0x7fb1525a4790>: Failed to establish a new connection: [Errno -2] Name or service not known'))
Traceback (most recent call last):
  File "/opt/hostedtoolcache/Python/3.8.17/x64/lib/python3.8/site-packages/urllib3/connection.py", line 174, in _new_conn
    conn = connection.create_connection(
  File "/opt/hostedtoolcache/Python/3.8.17/x64/lib/python3.8/site-packages/urllib3/util/connection.py", line 72, in create_connection
    for res in socket.getaddrinfo(host, port, family, socket.SOCK_STREAM):
  File "/opt/hostedtoolcache/Python/3.8.17/x64/lib/python3.8/socket.py", line 918, in getaddrinfo
    for res in _socket.getaddrinfo(host, port, family, type, proto, flags):
socket.gaierror: [Errno -2] Name or service not known

During handling of the above exception, another exception occurred:

Traceback (most recent call last):
  File "/opt/hostedtoolcache/Python/3.8.17/x64/lib/python3.8/site-packages/urllib3/connectionpool.py", line 714, in urlopen
    httplib_response = self._make_request(
  File "/opt/hostedtoolcache/Python/3.8.17/x64/lib/python3.8/site-packages/urllib3/connectionpool.py", line 403, in _make_request
    self._validate_conn(conn)
  File "/opt/hostedtoolcache/Python/3.8.17/x64/lib/python3.8/site-packages/urllib3/connectionpool.py", line 1053, in _validate_conn
    conn.connect()
  File "/opt/hostedtoolcache/Python/3.8.17/x64/lib/python3.8/site-packages/urllib3/connection.py", line 363, in connect
    self.sock = conn = self._new_conn()
  File "/opt/hostedtoolcache/Python/3.8.17/x64/lib/python3.8/site-packages/urllib3/connection.py", line 186, in _new_conn
    raise NewConnectionError(
urllib3.exceptions.NewConnectionError: <urllib3.connection.HTTPSConnection object at 0x7fb1525a4790>: Failed to establish a new connection: [Errno -2] Name or service not known

During handling of the above exception, another exception occurred:

Traceback (most recent call last):
  File "/opt/hostedtoolcache/Python/3.8.17/x64/lib/python3.8/site-packages/requests/adapters.py", line 486, in send
    resp = conn.urlopen(
  File "/opt/hostedtoolcache/Python/3.8.17/x64/lib/python3.8/site-packages/urllib3/connectionpool.py", line 798, in urlopen
    retries = retries.increment(
  File "/opt/hostedtoolcache/Python/3.8.17/x64/lib/python3.8/site-packages/urllib3/util/retry.py", line 592, in increment
    raise MaxRetryError(_pool, url, error or ResponseError(cause))
urllib3.exceptions.MaxRetryError: HTTPSConnectionPool(host='retro-backend.stabl.finance', port=443): Max retries exceeded with url: /api/v1/assets (Caused by NewConnectionError('<urllib3.connection.HTTPSConnection object at 0x7fb1525a4790>: Failed to establish a new connection: [Errno -2] Name or service not known'))

During handling of the above exception, another exception occurred:

Traceback (most recent call last):
  File "fee_data.py", line 93, in <module>
    response = requests.get(price_api)
  File "/opt/hostedtoolcache/Python/3.8.17/x64/lib/python3.8/site-packages/requests/api.py", line 73, in get
    return request("get", url, params=params, **kwargs)
  File "/opt/hostedtoolcache/Python/3.8.17/x64/lib/python3.8/site-packages/requests/api.py", line 59, in request
    return session.request(method=method, url=url, **kwargs)
  File "/opt/hostedtoolcache/Python/3.8.17/x64/lib/python3.8/site-packages/requests/sessions.py", line 589, in request
    resp = self.send(prep, **send_kwargs)
  File "/opt/hostedtoolcache/Python/3.8.17/x64/lib/python3.8/site-packages/requests/sessions.py", line 703, in send
    r = adapter.send(request, **kwargs)
  File "/opt/hostedtoolcache/Python/3.8.17/x64/lib/python3.8/site-packages/requests/adapters.py", line 519, in send
    raise ConnectionError(e, request=request)
requests.exceptions.ConnectionError: HTTPSConnectionPool(host='retro-backend.stabl.finance', port=443): Max retries exceeded with url: /api/v1/assets (Caused by NewConnectionError('<urllib3.connection.HTTPSConnection object at 0x7fb1525a4790>: Failed to establish a new connection: [Errno -2] Name or service not known'))
[2023-08-03 04:21:28,370] 	INFO 	30 	revenue_data.py 	<module>() 	Revenue Data Started
[2023-08-03 04:21:31,025] 	ERROR 	175 	revenue_data.py 	<module>() 	Error occurred during Revenue Data process. Error: HTTPSConnectionPool(host='retro-backend.stabl.finance', port=443): Max retries exceeded with url: /api/v1/assets (Caused by NewConnectionError('<urllib3.connection.HTTPSConnection object at 0x7f1cca35d910>: Failed to establish a new connection: [Errno -2] Name or service not known'))
Traceback (most recent call last):
  File "/opt/hostedtoolcache/Python/3.8.17/x64/lib/python3.8/site-packages/urllib3/connection.py", line 174, in _new_conn
    conn = connection.create_connection(
  File "/opt/hostedtoolcache/Python/3.8.17/x64/lib/python3.8/site-packages/urllib3/util/connection.py", line 72, in create_connection
    for res in socket.getaddrinfo(host, port, family, socket.SOCK_STREAM):
  File "/opt/hostedtoolcache/Python/3.8.17/x64/lib/python3.8/socket.py", line 918, in getaddrinfo
    for res in _socket.getaddrinfo(host, port, family, type, proto, flags):
socket.gaierror: [Errno -2] Name or service not known

During handling of the above exception, another exception occurred:

Traceback (most recent call last):
  File "/opt/hostedtoolcache/Python/3.8.17/x64/lib/python3.8/site-packages/urllib3/connectionpool.py", line 714, in urlopen
    httplib_response = self._make_request(
  File "/opt/hostedtoolcache/Python/3.8.17/x64/lib/python3.8/site-packages/urllib3/connectionpool.py", line 403, in _make_request
    self._validate_conn(conn)
  File "/opt/hostedtoolcache/Python/3.8.17/x64/lib/python3.8/site-packages/urllib3/connectionpool.py", line 1053, in _validate_conn
    conn.connect()
  File "/opt/hostedtoolcache/Python/3.8.17/x64/lib/python3.8/site-packages/urllib3/connection.py", line 363, in connect
    self.sock = conn = self._new_conn()
  File "/opt/hostedtoolcache/Python/3.8.17/x64/lib/python3.8/site-packages/urllib3/connection.py", line 186, in _new_conn
    raise NewConnectionError(
urllib3.exceptions.NewConnectionError: <urllib3.connection.HTTPSConnection object at 0x7f1cca35d910>: Failed to establish a new connection: [Errno -2] Name or service not known

During handling of the above exception, another exception occurred:

Traceback (most recent call last):
  File "/opt/hostedtoolcache/Python/3.8.17/x64/lib/python3.8/site-packages/requests/adapters.py", line 486, in send
    resp = conn.urlopen(
  File "/opt/hostedtoolcache/Python/3.8.17/x64/lib/python3.8/site-packages/urllib3/connectionpool.py", line 798, in urlopen
    retries = retries.increment(
  File "/opt/hostedtoolcache/Python/3.8.17/x64/lib/python3.8/site-packages/urllib3/util/retry.py", line 592, in increment
    raise MaxRetryError(_pool, url, error or ResponseError(cause))
urllib3.exceptions.MaxRetryError: HTTPSConnectionPool(host='retro-backend.stabl.finance', port=443): Max retries exceeded with url: /api/v1/assets (Caused by NewConnectionError('<urllib3.connection.HTTPSConnection object at 0x7f1cca35d910>: Failed to establish a new connection: [Errno -2] Name or service not known'))

During handling of the above exception, another exception occurred:

Traceback (most recent call last):
  File "revenue_data.py", line 73, in <module>
    response = requests.get(price_api)
  File "/opt/hostedtoolcache/Python/3.8.17/x64/lib/python3.8/site-packages/requests/api.py", line 73, in get
    return request("get", url, params=params, **kwargs)
  File "/opt/hostedtoolcache/Python/3.8.17/x64/lib/python3.8/site-packages/requests/api.py", line 59, in request
    return session.request(method=method, url=url, **kwargs)
  File "/opt/hostedtoolcache/Python/3.8.17/x64/lib/python3.8/site-packages/requests/sessions.py", line 589, in request
    resp = self.send(prep, **send_kwargs)
  File "/opt/hostedtoolcache/Python/3.8.17/x64/lib/python3.8/site-packages/requests/sessions.py", line 703, in send
    r = adapter.send(request, **kwargs)
  File "/opt/hostedtoolcache/Python/3.8.17/x64/lib/python3.8/site-packages/requests/adapters.py", line 519, in send
    raise ConnectionError(e, request=request)
requests.exceptions.ConnectionError: HTTPSConnectionPool(host='retro-backend.stabl.finance', port=443): Max retries exceeded with url: /api/v1/assets (Caused by NewConnectionError('<urllib3.connection.HTTPSConnection object at 0x7f1cca35d910>: Failed to establish a new connection: [Errno -2] Name or service not known'))
[2023-08-03 05:15:20,600] 	INFO 	20 	id_data.py 	<module>() 	ID Data Started
[2023-08-03 05:15:20,662] 	ERROR 	33 	id_data.py 	<module>() 	Error occurred during ID Data process. Error: HTTPSConnectionPool(host='retro-backend.stabl.finance', port=443): Max retries exceeded with url: /api/v1/fusions (Caused by NewConnectionError('<urllib3.connection.HTTPSConnection object at 0x7f3e86164610>: Failed to establish a new connection: [Errno -2] Name or service not known'))
Traceback (most recent call last):
  File "/opt/hostedtoolcache/Python/3.8.17/x64/lib/python3.8/site-packages/urllib3/connection.py", line 174, in _new_conn
    conn = connection.create_connection(
  File "/opt/hostedtoolcache/Python/3.8.17/x64/lib/python3.8/site-packages/urllib3/util/connection.py", line 72, in create_connection
    for res in socket.getaddrinfo(host, port, family, socket.SOCK_STREAM):
  File "/opt/hostedtoolcache/Python/3.8.17/x64/lib/python3.8/socket.py", line 918, in getaddrinfo
    for res in _socket.getaddrinfo(host, port, family, type, proto, flags):
socket.gaierror: [Errno -2] Name or service not known

During handling of the above exception, another exception occurred:

Traceback (most recent call last):
  File "/opt/hostedtoolcache/Python/3.8.17/x64/lib/python3.8/site-packages/urllib3/connectionpool.py", line 714, in urlopen
    httplib_response = self._make_request(
  File "/opt/hostedtoolcache/Python/3.8.17/x64/lib/python3.8/site-packages/urllib3/connectionpool.py", line 403, in _make_request
    self._validate_conn(conn)
  File "/opt/hostedtoolcache/Python/3.8.17/x64/lib/python3.8/site-packages/urllib3/connectionpool.py", line 1053, in _validate_conn
    conn.connect()
  File "/opt/hostedtoolcache/Python/3.8.17/x64/lib/python3.8/site-packages/urllib3/connection.py", line 363, in connect
    self.sock = conn = self._new_conn()
  File "/opt/hostedtoolcache/Python/3.8.17/x64/lib/python3.8/site-packages/urllib3/connection.py", line 186, in _new_conn
    raise NewConnectionError(
urllib3.exceptions.NewConnectionError: <urllib3.connection.HTTPSConnection object at 0x7f3e86164610>: Failed to establish a new connection: [Errno -2] Name or service not known

During handling of the above exception, another exception occurred:

Traceback (most recent call last):
  File "/opt/hostedtoolcache/Python/3.8.17/x64/lib/python3.8/site-packages/requests/adapters.py", line 486, in send
    resp = conn.urlopen(
  File "/opt/hostedtoolcache/Python/3.8.17/x64/lib/python3.8/site-packages/urllib3/connectionpool.py", line 798, in urlopen
    retries = retries.increment(
  File "/opt/hostedtoolcache/Python/3.8.17/x64/lib/python3.8/site-packages/urllib3/util/retry.py", line 592, in increment
    raise MaxRetryError(_pool, url, error or ResponseError(cause))
urllib3.exceptions.MaxRetryError: HTTPSConnectionPool(host='retro-backend.stabl.finance', port=443): Max retries exceeded with url: /api/v1/fusions (Caused by NewConnectionError('<urllib3.connection.HTTPSConnection object at 0x7f3e86164610>: Failed to establish a new connection: [Errno -2] Name or service not known'))

During handling of the above exception, another exception occurred:

Traceback (most recent call last):
  File "id_data.py", line 26, in <module>
    response = requests.get(url=fusion_api)
  File "/opt/hostedtoolcache/Python/3.8.17/x64/lib/python3.8/site-packages/requests/api.py", line 73, in get
    return request("get", url, params=params, **kwargs)
  File "/opt/hostedtoolcache/Python/3.8.17/x64/lib/python3.8/site-packages/requests/api.py", line 59, in request
    return session.request(method=method, url=url, **kwargs)
  File "/opt/hostedtoolcache/Python/3.8.17/x64/lib/python3.8/site-packages/requests/sessions.py", line 589, in request
    resp = self.send(prep, **send_kwargs)
  File "/opt/hostedtoolcache/Python/3.8.17/x64/lib/python3.8/site-packages/requests/sessions.py", line 703, in send
    r = adapter.send(request, **kwargs)
  File "/opt/hostedtoolcache/Python/3.8.17/x64/lib/python3.8/site-packages/requests/adapters.py", line 519, in send
    raise ConnectionError(e, request=request)
requests.exceptions.ConnectionError: HTTPSConnectionPool(host='retro-backend.stabl.finance', port=443): Max retries exceeded with url: /api/v1/fusions (Caused by NewConnectionError('<urllib3.connection.HTTPSConnection object at 0x7f3e86164610>: Failed to establish a new connection: [Errno -2] Name or service not known'))
[2023-08-03 05:15:21,247] 	INFO 	79 	day_data.py 	<module>() 	Day Data Fusion Started
[2023-08-03 05:15:24,298] 	INFO 	126 	day_data.py 	<module>() 	Day Data Fusion Ended
[2023-08-03 05:15:25,179] 	INFO 	123 	pair_data.py 	<module>() 	Pair Data Fusion Started
[2023-08-03 05:15:37,783] 	INFO 	187 	pair_data.py 	<module>() 	Pair Data Fusion Ended
[2023-08-03 05:15:38,623] 	INFO 	37 	bribe_data.py 	<module>() 	Bribe Data Started
[2023-08-03 05:16:22,898] 	ERROR 	153 	bribe_data.py 	<module>() 	Error occurred during Bribe Data process. Error: HTTPSConnectionPool(host='retro-backend.stabl.finance', port=443): Max retries exceeded with url: /api/v1/assets (Caused by NewConnectionError('<urllib3.connection.HTTPSConnection object at 0x7fd526bc3fa0>: Failed to establish a new connection: [Errno -2] Name or service not known'))
Traceback (most recent call last):
  File "/opt/hostedtoolcache/Python/3.8.17/x64/lib/python3.8/site-packages/urllib3/connection.py", line 174, in _new_conn
    conn = connection.create_connection(
  File "/opt/hostedtoolcache/Python/3.8.17/x64/lib/python3.8/site-packages/urllib3/util/connection.py", line 72, in create_connection
    for res in socket.getaddrinfo(host, port, family, socket.SOCK_STREAM):
  File "/opt/hostedtoolcache/Python/3.8.17/x64/lib/python3.8/socket.py", line 918, in getaddrinfo
    for res in _socket.getaddrinfo(host, port, family, type, proto, flags):
socket.gaierror: [Errno -2] Name or service not known

During handling of the above exception, another exception occurred:

Traceback (most recent call last):
  File "/opt/hostedtoolcache/Python/3.8.17/x64/lib/python3.8/site-packages/urllib3/connectionpool.py", line 714, in urlopen
    httplib_response = self._make_request(
  File "/opt/hostedtoolcache/Python/3.8.17/x64/lib/python3.8/site-packages/urllib3/connectionpool.py", line 403, in _make_request
    self._validate_conn(conn)
  File "/opt/hostedtoolcache/Python/3.8.17/x64/lib/python3.8/site-packages/urllib3/connectionpool.py", line 1053, in _validate_conn
    conn.connect()
  File "/opt/hostedtoolcache/Python/3.8.17/x64/lib/python3.8/site-packages/urllib3/connection.py", line 363, in connect
    self.sock = conn = self._new_conn()
  File "/opt/hostedtoolcache/Python/3.8.17/x64/lib/python3.8/site-packages/urllib3/connection.py", line 186, in _new_conn
    raise NewConnectionError(
urllib3.exceptions.NewConnectionError: <urllib3.connection.HTTPSConnection object at 0x7fd526bc3fa0>: Failed to establish a new connection: [Errno -2] Name or service not known

During handling of the above exception, another exception occurred:

Traceback (most recent call last):
  File "/opt/hostedtoolcache/Python/3.8.17/x64/lib/python3.8/site-packages/requests/adapters.py", line 486, in send
    resp = conn.urlopen(
  File "/opt/hostedtoolcache/Python/3.8.17/x64/lib/python3.8/site-packages/urllib3/connectionpool.py", line 798, in urlopen
    retries = retries.increment(
  File "/opt/hostedtoolcache/Python/3.8.17/x64/lib/python3.8/site-packages/urllib3/util/retry.py", line 592, in increment
    raise MaxRetryError(_pool, url, error or ResponseError(cause))
urllib3.exceptions.MaxRetryError: HTTPSConnectionPool(host='retro-backend.stabl.finance', port=443): Max retries exceeded with url: /api/v1/assets (Caused by NewConnectionError('<urllib3.connection.HTTPSConnection object at 0x7fd526bc3fa0>: Failed to establish a new connection: [Errno -2] Name or service not known'))

During handling of the above exception, another exception occurred:

Traceback (most recent call last):
  File "bribe_data.py", line 93, in <module>
    response = requests.get(price_api)
  File "/opt/hostedtoolcache/Python/3.8.17/x64/lib/python3.8/site-packages/requests/api.py", line 73, in get
    return request("get", url, params=params, **kwargs)
  File "/opt/hostedtoolcache/Python/3.8.17/x64/lib/python3.8/site-packages/requests/api.py", line 59, in request
    return session.request(method=method, url=url, **kwargs)
  File "/opt/hostedtoolcache/Python/3.8.17/x64/lib/python3.8/site-packages/requests/sessions.py", line 589, in request
    resp = self.send(prep, **send_kwargs)
  File "/opt/hostedtoolcache/Python/3.8.17/x64/lib/python3.8/site-packages/requests/sessions.py", line 703, in send
    r = adapter.send(request, **kwargs)
  File "/opt/hostedtoolcache/Python/3.8.17/x64/lib/python3.8/site-packages/requests/adapters.py", line 519, in send
    raise ConnectionError(e, request=request)
requests.exceptions.ConnectionError: HTTPSConnectionPool(host='retro-backend.stabl.finance', port=443): Max retries exceeded with url: /api/v1/assets (Caused by NewConnectionError('<urllib3.connection.HTTPSConnection object at 0x7fd526bc3fa0>: Failed to establish a new connection: [Errno -2] Name or service not known'))
[2023-08-03 05:16:23,754] 	INFO 	37 	fee_data.py 	<module>() 	Fee Data Started
[2023-08-03 05:17:06,239] 	ERROR 	153 	fee_data.py 	<module>() 	Error occurred during Fee Data process. Error: 'address'
Traceback (most recent call last):
  File "/opt/hostedtoolcache/Python/3.8.17/x64/lib/python3.8/site-packages/pandas/core/indexes/base.py", line 3802, in get_loc
    return self._engine.get_loc(casted_key)
  File "pandas/_libs/index.pyx", line 138, in pandas._libs.index.IndexEngine.get_loc
  File "pandas/_libs/index.pyx", line 165, in pandas._libs.index.IndexEngine.get_loc
  File "pandas/_libs/hashtable_class_helper.pxi", line 5745, in pandas._libs.hashtable.PyObjectHashTable.get_item
  File "pandas/_libs/hashtable_class_helper.pxi", line 5753, in pandas._libs.hashtable.PyObjectHashTable.get_item
KeyError: 'address'

The above exception was the direct cause of the following exception:

Traceback (most recent call last):
  File "fee_data.py", line 90, in <module>
    fee_df["address"] = fee_df["address"].apply(str.lower)
  File "/opt/hostedtoolcache/Python/3.8.17/x64/lib/python3.8/site-packages/pandas/core/frame.py", line 3807, in __getitem__
    indexer = self.columns.get_loc(key)
  File "/opt/hostedtoolcache/Python/3.8.17/x64/lib/python3.8/site-packages/pandas/core/indexes/base.py", line 3804, in get_loc
    raise KeyError(key) from err
KeyError: 'address'
[2023-08-03 05:17:07,107] 	INFO 	30 	revenue_data.py 	<module>() 	Revenue Data Started
[2023-08-03 05:17:09,987] 	ERROR 	175 	revenue_data.py 	<module>() 	Error occurred during Revenue Data process. Error: HTTPSConnectionPool(host='retro-backend.stabl.finance', port=443): Max retries exceeded with url: /api/v1/assets (Caused by NewConnectionError('<urllib3.connection.HTTPSConnection object at 0x7f2423957d90>: Failed to establish a new connection: [Errno -2] Name or service not known'))
Traceback (most recent call last):
  File "/opt/hostedtoolcache/Python/3.8.17/x64/lib/python3.8/site-packages/urllib3/connection.py", line 174, in _new_conn
    conn = connection.create_connection(
  File "/opt/hostedtoolcache/Python/3.8.17/x64/lib/python3.8/site-packages/urllib3/util/connection.py", line 72, in create_connection
    for res in socket.getaddrinfo(host, port, family, socket.SOCK_STREAM):
  File "/opt/hostedtoolcache/Python/3.8.17/x64/lib/python3.8/socket.py", line 918, in getaddrinfo
    for res in _socket.getaddrinfo(host, port, family, type, proto, flags):
socket.gaierror: [Errno -2] Name or service not known

During handling of the above exception, another exception occurred:

Traceback (most recent call last):
  File "/opt/hostedtoolcache/Python/3.8.17/x64/lib/python3.8/site-packages/urllib3/connectionpool.py", line 714, in urlopen
    httplib_response = self._make_request(
  File "/opt/hostedtoolcache/Python/3.8.17/x64/lib/python3.8/site-packages/urllib3/connectionpool.py", line 403, in _make_request
    self._validate_conn(conn)
  File "/opt/hostedtoolcache/Python/3.8.17/x64/lib/python3.8/site-packages/urllib3/connectionpool.py", line 1053, in _validate_conn
    conn.connect()
  File "/opt/hostedtoolcache/Python/3.8.17/x64/lib/python3.8/site-packages/urllib3/connection.py", line 363, in connect
    self.sock = conn = self._new_conn()
  File "/opt/hostedtoolcache/Python/3.8.17/x64/lib/python3.8/site-packages/urllib3/connection.py", line 186, in _new_conn
    raise NewConnectionError(
urllib3.exceptions.NewConnectionError: <urllib3.connection.HTTPSConnection object at 0x7f2423957d90>: Failed to establish a new connection: [Errno -2] Name or service not known

During handling of the above exception, another exception occurred:

Traceback (most recent call last):
  File "/opt/hostedtoolcache/Python/3.8.17/x64/lib/python3.8/site-packages/requests/adapters.py", line 486, in send
    resp = conn.urlopen(
  File "/opt/hostedtoolcache/Python/3.8.17/x64/lib/python3.8/site-packages/urllib3/connectionpool.py", line 798, in urlopen
    retries = retries.increment(
  File "/opt/hostedtoolcache/Python/3.8.17/x64/lib/python3.8/site-packages/urllib3/util/retry.py", line 592, in increment
    raise MaxRetryError(_pool, url, error or ResponseError(cause))
urllib3.exceptions.MaxRetryError: HTTPSConnectionPool(host='retro-backend.stabl.finance', port=443): Max retries exceeded with url: /api/v1/assets (Caused by NewConnectionError('<urllib3.connection.HTTPSConnection object at 0x7f2423957d90>: Failed to establish a new connection: [Errno -2] Name or service not known'))

During handling of the above exception, another exception occurred:

Traceback (most recent call last):
  File "revenue_data.py", line 73, in <module>
    response = requests.get(price_api)
  File "/opt/hostedtoolcache/Python/3.8.17/x64/lib/python3.8/site-packages/requests/api.py", line 73, in get
    return request("get", url, params=params, **kwargs)
  File "/opt/hostedtoolcache/Python/3.8.17/x64/lib/python3.8/site-packages/requests/api.py", line 59, in request
    return session.request(method=method, url=url, **kwargs)
  File "/opt/hostedtoolcache/Python/3.8.17/x64/lib/python3.8/site-packages/requests/sessions.py", line 589, in request
    resp = self.send(prep, **send_kwargs)
  File "/opt/hostedtoolcache/Python/3.8.17/x64/lib/python3.8/site-packages/requests/sessions.py", line 703, in send
    r = adapter.send(request, **kwargs)
  File "/opt/hostedtoolcache/Python/3.8.17/x64/lib/python3.8/site-packages/requests/adapters.py", line 519, in send
    raise ConnectionError(e, request=request)
requests.exceptions.ConnectionError: HTTPSConnectionPool(host='retro-backend.stabl.finance', port=443): Max retries exceeded with url: /api/v1/assets (Caused by NewConnectionError('<urllib3.connection.HTTPSConnection object at 0x7f2423957d90>: Failed to establish a new connection: [Errno -2] Name or service not known'))
[2023-08-03 06:21:06,050] 	INFO 	20 	id_data.py 	<module>() 	ID Data Started
[2023-08-03 06:21:06,214] 	ERROR 	33 	id_data.py 	<module>() 	Error occurred during ID Data process. Error: HTTPSConnectionPool(host='retro-backend.stabl.finance', port=443): Max retries exceeded with url: /api/v1/fusions (Caused by NewConnectionError('<urllib3.connection.HTTPSConnection object at 0x7fa9d0be15b0>: Failed to establish a new connection: [Errno -2] Name or service not known'))
Traceback (most recent call last):
  File "/opt/hostedtoolcache/Python/3.8.17/x64/lib/python3.8/site-packages/urllib3/connection.py", line 174, in _new_conn
    conn = connection.create_connection(
  File "/opt/hostedtoolcache/Python/3.8.17/x64/lib/python3.8/site-packages/urllib3/util/connection.py", line 72, in create_connection
    for res in socket.getaddrinfo(host, port, family, socket.SOCK_STREAM):
  File "/opt/hostedtoolcache/Python/3.8.17/x64/lib/python3.8/socket.py", line 918, in getaddrinfo
    for res in _socket.getaddrinfo(host, port, family, type, proto, flags):
socket.gaierror: [Errno -2] Name or service not known

During handling of the above exception, another exception occurred:

Traceback (most recent call last):
  File "/opt/hostedtoolcache/Python/3.8.17/x64/lib/python3.8/site-packages/urllib3/connectionpool.py", line 714, in urlopen
    httplib_response = self._make_request(
  File "/opt/hostedtoolcache/Python/3.8.17/x64/lib/python3.8/site-packages/urllib3/connectionpool.py", line 403, in _make_request
    self._validate_conn(conn)
  File "/opt/hostedtoolcache/Python/3.8.17/x64/lib/python3.8/site-packages/urllib3/connectionpool.py", line 1053, in _validate_conn
    conn.connect()
  File "/opt/hostedtoolcache/Python/3.8.17/x64/lib/python3.8/site-packages/urllib3/connection.py", line 363, in connect
    self.sock = conn = self._new_conn()
  File "/opt/hostedtoolcache/Python/3.8.17/x64/lib/python3.8/site-packages/urllib3/connection.py", line 186, in _new_conn
    raise NewConnectionError(
urllib3.exceptions.NewConnectionError: <urllib3.connection.HTTPSConnection object at 0x7fa9d0be15b0>: Failed to establish a new connection: [Errno -2] Name or service not known

During handling of the above exception, another exception occurred:

Traceback (most recent call last):
  File "/opt/hostedtoolcache/Python/3.8.17/x64/lib/python3.8/site-packages/requests/adapters.py", line 486, in send
    resp = conn.urlopen(
  File "/opt/hostedtoolcache/Python/3.8.17/x64/lib/python3.8/site-packages/urllib3/connectionpool.py", line 798, in urlopen
    retries = retries.increment(
  File "/opt/hostedtoolcache/Python/3.8.17/x64/lib/python3.8/site-packages/urllib3/util/retry.py", line 592, in increment
    raise MaxRetryError(_pool, url, error or ResponseError(cause))
urllib3.exceptions.MaxRetryError: HTTPSConnectionPool(host='retro-backend.stabl.finance', port=443): Max retries exceeded with url: /api/v1/fusions (Caused by NewConnectionError('<urllib3.connection.HTTPSConnection object at 0x7fa9d0be15b0>: Failed to establish a new connection: [Errno -2] Name or service not known'))

During handling of the above exception, another exception occurred:

Traceback (most recent call last):
  File "id_data.py", line 26, in <module>
    response = requests.get(url=fusion_api)
  File "/opt/hostedtoolcache/Python/3.8.17/x64/lib/python3.8/site-packages/requests/api.py", line 73, in get
    return request("get", url, params=params, **kwargs)
  File "/opt/hostedtoolcache/Python/3.8.17/x64/lib/python3.8/site-packages/requests/api.py", line 59, in request
    return session.request(method=method, url=url, **kwargs)
  File "/opt/hostedtoolcache/Python/3.8.17/x64/lib/python3.8/site-packages/requests/sessions.py", line 589, in request
    resp = self.send(prep, **send_kwargs)
  File "/opt/hostedtoolcache/Python/3.8.17/x64/lib/python3.8/site-packages/requests/sessions.py", line 703, in send
    r = adapter.send(request, **kwargs)
  File "/opt/hostedtoolcache/Python/3.8.17/x64/lib/python3.8/site-packages/requests/adapters.py", line 519, in send
    raise ConnectionError(e, request=request)
requests.exceptions.ConnectionError: HTTPSConnectionPool(host='retro-backend.stabl.finance', port=443): Max retries exceeded with url: /api/v1/fusions (Caused by NewConnectionError('<urllib3.connection.HTTPSConnection object at 0x7fa9d0be15b0>: Failed to establish a new connection: [Errno -2] Name or service not known'))
[2023-08-03 06:21:06,948] 	INFO 	79 	day_data.py 	<module>() 	Day Data Fusion Started
[2023-08-03 06:21:09,006] 	INFO 	126 	day_data.py 	<module>() 	Day Data Fusion Ended
[2023-08-03 06:21:10,071] 	INFO 	123 	pair_data.py 	<module>() 	Pair Data Fusion Started
[2023-08-03 06:21:22,594] 	INFO 	187 	pair_data.py 	<module>() 	Pair Data Fusion Ended
[2023-08-03 06:21:23,646] 	INFO 	37 	bribe_data.py 	<module>() 	Bribe Data Started
[2023-08-03 06:22:02,410] 	ERROR 	153 	bribe_data.py 	<module>() 	Error occurred during Bribe Data process. Error: HTTPSConnectionPool(host='retro-backend.stabl.finance', port=443): Max retries exceeded with url: /api/v1/assets (Caused by NewConnectionError('<urllib3.connection.HTTPSConnection object at 0x7f3e949d5430>: Failed to establish a new connection: [Errno -2] Name or service not known'))
Traceback (most recent call last):
  File "/opt/hostedtoolcache/Python/3.8.17/x64/lib/python3.8/site-packages/urllib3/connection.py", line 174, in _new_conn
    conn = connection.create_connection(
  File "/opt/hostedtoolcache/Python/3.8.17/x64/lib/python3.8/site-packages/urllib3/util/connection.py", line 72, in create_connection
    for res in socket.getaddrinfo(host, port, family, socket.SOCK_STREAM):
  File "/opt/hostedtoolcache/Python/3.8.17/x64/lib/python3.8/socket.py", line 918, in getaddrinfo
    for res in _socket.getaddrinfo(host, port, family, type, proto, flags):
socket.gaierror: [Errno -2] Name or service not known

During handling of the above exception, another exception occurred:

Traceback (most recent call last):
  File "/opt/hostedtoolcache/Python/3.8.17/x64/lib/python3.8/site-packages/urllib3/connectionpool.py", line 714, in urlopen
    httplib_response = self._make_request(
  File "/opt/hostedtoolcache/Python/3.8.17/x64/lib/python3.8/site-packages/urllib3/connectionpool.py", line 403, in _make_request
    self._validate_conn(conn)
  File "/opt/hostedtoolcache/Python/3.8.17/x64/lib/python3.8/site-packages/urllib3/connectionpool.py", line 1053, in _validate_conn
    conn.connect()
  File "/opt/hostedtoolcache/Python/3.8.17/x64/lib/python3.8/site-packages/urllib3/connection.py", line 363, in connect
    self.sock = conn = self._new_conn()
  File "/opt/hostedtoolcache/Python/3.8.17/x64/lib/python3.8/site-packages/urllib3/connection.py", line 186, in _new_conn
    raise NewConnectionError(
urllib3.exceptions.NewConnectionError: <urllib3.connection.HTTPSConnection object at 0x7f3e949d5430>: Failed to establish a new connection: [Errno -2] Name or service not known

During handling of the above exception, another exception occurred:

Traceback (most recent call last):
  File "/opt/hostedtoolcache/Python/3.8.17/x64/lib/python3.8/site-packages/requests/adapters.py", line 486, in send
    resp = conn.urlopen(
  File "/opt/hostedtoolcache/Python/3.8.17/x64/lib/python3.8/site-packages/urllib3/connectionpool.py", line 798, in urlopen
    retries = retries.increment(
  File "/opt/hostedtoolcache/Python/3.8.17/x64/lib/python3.8/site-packages/urllib3/util/retry.py", line 592, in increment
    raise MaxRetryError(_pool, url, error or ResponseError(cause))
urllib3.exceptions.MaxRetryError: HTTPSConnectionPool(host='retro-backend.stabl.finance', port=443): Max retries exceeded with url: /api/v1/assets (Caused by NewConnectionError('<urllib3.connection.HTTPSConnection object at 0x7f3e949d5430>: Failed to establish a new connection: [Errno -2] Name or service not known'))

During handling of the above exception, another exception occurred:

Traceback (most recent call last):
  File "bribe_data.py", line 93, in <module>
    response = requests.get(price_api)
  File "/opt/hostedtoolcache/Python/3.8.17/x64/lib/python3.8/site-packages/requests/api.py", line 73, in get
    return request("get", url, params=params, **kwargs)
  File "/opt/hostedtoolcache/Python/3.8.17/x64/lib/python3.8/site-packages/requests/api.py", line 59, in request
    return session.request(method=method, url=url, **kwargs)
  File "/opt/hostedtoolcache/Python/3.8.17/x64/lib/python3.8/site-packages/requests/sessions.py", line 589, in request
    resp = self.send(prep, **send_kwargs)
  File "/opt/hostedtoolcache/Python/3.8.17/x64/lib/python3.8/site-packages/requests/sessions.py", line 703, in send
    r = adapter.send(request, **kwargs)
  File "/opt/hostedtoolcache/Python/3.8.17/x64/lib/python3.8/site-packages/requests/adapters.py", line 519, in send
    raise ConnectionError(e, request=request)
requests.exceptions.ConnectionError: HTTPSConnectionPool(host='retro-backend.stabl.finance', port=443): Max retries exceeded with url: /api/v1/assets (Caused by NewConnectionError('<urllib3.connection.HTTPSConnection object at 0x7f3e949d5430>: Failed to establish a new connection: [Errno -2] Name or service not known'))
[2023-08-03 06:22:03,464] 	INFO 	37 	fee_data.py 	<module>() 	Fee Data Started
[2023-08-03 06:22:41,154] 	ERROR 	153 	fee_data.py 	<module>() 	Error occurred during Fee Data process. Error: 'address'
Traceback (most recent call last):
  File "/opt/hostedtoolcache/Python/3.8.17/x64/lib/python3.8/site-packages/pandas/core/indexes/base.py", line 3802, in get_loc
    return self._engine.get_loc(casted_key)
  File "pandas/_libs/index.pyx", line 138, in pandas._libs.index.IndexEngine.get_loc
  File "pandas/_libs/index.pyx", line 165, in pandas._libs.index.IndexEngine.get_loc
  File "pandas/_libs/hashtable_class_helper.pxi", line 5745, in pandas._libs.hashtable.PyObjectHashTable.get_item
  File "pandas/_libs/hashtable_class_helper.pxi", line 5753, in pandas._libs.hashtable.PyObjectHashTable.get_item
KeyError: 'address'

The above exception was the direct cause of the following exception:

Traceback (most recent call last):
  File "fee_data.py", line 90, in <module>
    fee_df["address"] = fee_df["address"].apply(str.lower)
  File "/opt/hostedtoolcache/Python/3.8.17/x64/lib/python3.8/site-packages/pandas/core/frame.py", line 3807, in __getitem__
    indexer = self.columns.get_loc(key)
  File "/opt/hostedtoolcache/Python/3.8.17/x64/lib/python3.8/site-packages/pandas/core/indexes/base.py", line 3804, in get_loc
    raise KeyError(key) from err
KeyError: 'address'
[2023-08-03 06:22:42,106] 	INFO 	30 	revenue_data.py 	<module>() 	Revenue Data Started
[2023-08-03 06:22:44,114] 	ERROR 	175 	revenue_data.py 	<module>() 	Error occurred during Revenue Data process. Error: HTTPSConnectionPool(host='retro-backend.stabl.finance', port=443): Max retries exceeded with url: /api/v1/assets (Caused by NewConnectionError('<urllib3.connection.HTTPSConnection object at 0x7f89156a9f40>: Failed to establish a new connection: [Errno -2] Name or service not known'))
Traceback (most recent call last):
  File "/opt/hostedtoolcache/Python/3.8.17/x64/lib/python3.8/site-packages/urllib3/connection.py", line 174, in _new_conn
    conn = connection.create_connection(
  File "/opt/hostedtoolcache/Python/3.8.17/x64/lib/python3.8/site-packages/urllib3/util/connection.py", line 72, in create_connection
    for res in socket.getaddrinfo(host, port, family, socket.SOCK_STREAM):
  File "/opt/hostedtoolcache/Python/3.8.17/x64/lib/python3.8/socket.py", line 918, in getaddrinfo
    for res in _socket.getaddrinfo(host, port, family, type, proto, flags):
socket.gaierror: [Errno -2] Name or service not known

During handling of the above exception, another exception occurred:

Traceback (most recent call last):
  File "/opt/hostedtoolcache/Python/3.8.17/x64/lib/python3.8/site-packages/urllib3/connectionpool.py", line 714, in urlopen
    httplib_response = self._make_request(
  File "/opt/hostedtoolcache/Python/3.8.17/x64/lib/python3.8/site-packages/urllib3/connectionpool.py", line 403, in _make_request
    self._validate_conn(conn)
  File "/opt/hostedtoolcache/Python/3.8.17/x64/lib/python3.8/site-packages/urllib3/connectionpool.py", line 1053, in _validate_conn
    conn.connect()
  File "/opt/hostedtoolcache/Python/3.8.17/x64/lib/python3.8/site-packages/urllib3/connection.py", line 363, in connect
    self.sock = conn = self._new_conn()
  File "/opt/hostedtoolcache/Python/3.8.17/x64/lib/python3.8/site-packages/urllib3/connection.py", line 186, in _new_conn
    raise NewConnectionError(
urllib3.exceptions.NewConnectionError: <urllib3.connection.HTTPSConnection object at 0x7f89156a9f40>: Failed to establish a new connection: [Errno -2] Name or service not known

During handling of the above exception, another exception occurred:

Traceback (most recent call last):
  File "/opt/hostedtoolcache/Python/3.8.17/x64/lib/python3.8/site-packages/requests/adapters.py", line 486, in send
    resp = conn.urlopen(
  File "/opt/hostedtoolcache/Python/3.8.17/x64/lib/python3.8/site-packages/urllib3/connectionpool.py", line 798, in urlopen
    retries = retries.increment(
  File "/opt/hostedtoolcache/Python/3.8.17/x64/lib/python3.8/site-packages/urllib3/util/retry.py", line 592, in increment
    raise MaxRetryError(_pool, url, error or ResponseError(cause))
urllib3.exceptions.MaxRetryError: HTTPSConnectionPool(host='retro-backend.stabl.finance', port=443): Max retries exceeded with url: /api/v1/assets (Caused by NewConnectionError('<urllib3.connection.HTTPSConnection object at 0x7f89156a9f40>: Failed to establish a new connection: [Errno -2] Name or service not known'))

During handling of the above exception, another exception occurred:

Traceback (most recent call last):
  File "revenue_data.py", line 73, in <module>
    response = requests.get(price_api)
  File "/opt/hostedtoolcache/Python/3.8.17/x64/lib/python3.8/site-packages/requests/api.py", line 73, in get
    return request("get", url, params=params, **kwargs)
  File "/opt/hostedtoolcache/Python/3.8.17/x64/lib/python3.8/site-packages/requests/api.py", line 59, in request
    return session.request(method=method, url=url, **kwargs)
  File "/opt/hostedtoolcache/Python/3.8.17/x64/lib/python3.8/site-packages/requests/sessions.py", line 589, in request
    resp = self.send(prep, **send_kwargs)
  File "/opt/hostedtoolcache/Python/3.8.17/x64/lib/python3.8/site-packages/requests/sessions.py", line 703, in send
    r = adapter.send(request, **kwargs)
  File "/opt/hostedtoolcache/Python/3.8.17/x64/lib/python3.8/site-packages/requests/adapters.py", line 519, in send
    raise ConnectionError(e, request=request)
requests.exceptions.ConnectionError: HTTPSConnectionPool(host='retro-backend.stabl.finance', port=443): Max retries exceeded with url: /api/v1/assets (Caused by NewConnectionError('<urllib3.connection.HTTPSConnection object at 0x7f89156a9f40>: Failed to establish a new connection: [Errno -2] Name or service not known'))
[2023-08-03 07:15:00,443] 	INFO 	20 	id_data.py 	<module>() 	ID Data Started
[2023-08-03 07:15:00,841] 	ERROR 	33 	id_data.py 	<module>() 	Error occurred during ID Data process. Error: HTTPSConnectionPool(host='retro-backend.stabl.finance', port=443): Max retries exceeded with url: /api/v1/fusions (Caused by NewConnectionError('<urllib3.connection.HTTPSConnection object at 0x7fd91ea215b0>: Failed to establish a new connection: [Errno -2] Name or service not known'))
Traceback (most recent call last):
  File "/opt/hostedtoolcache/Python/3.8.17/x64/lib/python3.8/site-packages/urllib3/connection.py", line 174, in _new_conn
    conn = connection.create_connection(
  File "/opt/hostedtoolcache/Python/3.8.17/x64/lib/python3.8/site-packages/urllib3/util/connection.py", line 72, in create_connection
    for res in socket.getaddrinfo(host, port, family, socket.SOCK_STREAM):
  File "/opt/hostedtoolcache/Python/3.8.17/x64/lib/python3.8/socket.py", line 918, in getaddrinfo
    for res in _socket.getaddrinfo(host, port, family, type, proto, flags):
socket.gaierror: [Errno -2] Name or service not known

During handling of the above exception, another exception occurred:

Traceback (most recent call last):
  File "/opt/hostedtoolcache/Python/3.8.17/x64/lib/python3.8/site-packages/urllib3/connectionpool.py", line 714, in urlopen
    httplib_response = self._make_request(
  File "/opt/hostedtoolcache/Python/3.8.17/x64/lib/python3.8/site-packages/urllib3/connectionpool.py", line 403, in _make_request
    self._validate_conn(conn)
  File "/opt/hostedtoolcache/Python/3.8.17/x64/lib/python3.8/site-packages/urllib3/connectionpool.py", line 1053, in _validate_conn
    conn.connect()
  File "/opt/hostedtoolcache/Python/3.8.17/x64/lib/python3.8/site-packages/urllib3/connection.py", line 363, in connect
    self.sock = conn = self._new_conn()
  File "/opt/hostedtoolcache/Python/3.8.17/x64/lib/python3.8/site-packages/urllib3/connection.py", line 186, in _new_conn
    raise NewConnectionError(
urllib3.exceptions.NewConnectionError: <urllib3.connection.HTTPSConnection object at 0x7fd91ea215b0>: Failed to establish a new connection: [Errno -2] Name or service not known

During handling of the above exception, another exception occurred:

Traceback (most recent call last):
  File "/opt/hostedtoolcache/Python/3.8.17/x64/lib/python3.8/site-packages/requests/adapters.py", line 486, in send
    resp = conn.urlopen(
  File "/opt/hostedtoolcache/Python/3.8.17/x64/lib/python3.8/site-packages/urllib3/connectionpool.py", line 798, in urlopen
    retries = retries.increment(
  File "/opt/hostedtoolcache/Python/3.8.17/x64/lib/python3.8/site-packages/urllib3/util/retry.py", line 592, in increment
    raise MaxRetryError(_pool, url, error or ResponseError(cause))
urllib3.exceptions.MaxRetryError: HTTPSConnectionPool(host='retro-backend.stabl.finance', port=443): Max retries exceeded with url: /api/v1/fusions (Caused by NewConnectionError('<urllib3.connection.HTTPSConnection object at 0x7fd91ea215b0>: Failed to establish a new connection: [Errno -2] Name or service not known'))

During handling of the above exception, another exception occurred:

Traceback (most recent call last):
  File "id_data.py", line 26, in <module>
    response = requests.get(url=fusion_api)
  File "/opt/hostedtoolcache/Python/3.8.17/x64/lib/python3.8/site-packages/requests/api.py", line 73, in get
    return request("get", url, params=params, **kwargs)
  File "/opt/hostedtoolcache/Python/3.8.17/x64/lib/python3.8/site-packages/requests/api.py", line 59, in request
    return session.request(method=method, url=url, **kwargs)
  File "/opt/hostedtoolcache/Python/3.8.17/x64/lib/python3.8/site-packages/requests/sessions.py", line 589, in request
    resp = self.send(prep, **send_kwargs)
  File "/opt/hostedtoolcache/Python/3.8.17/x64/lib/python3.8/site-packages/requests/sessions.py", line 703, in send
    r = adapter.send(request, **kwargs)
  File "/opt/hostedtoolcache/Python/3.8.17/x64/lib/python3.8/site-packages/requests/adapters.py", line 519, in send
    raise ConnectionError(e, request=request)
requests.exceptions.ConnectionError: HTTPSConnectionPool(host='retro-backend.stabl.finance', port=443): Max retries exceeded with url: /api/v1/fusions (Caused by NewConnectionError('<urllib3.connection.HTTPSConnection object at 0x7fd91ea215b0>: Failed to establish a new connection: [Errno -2] Name or service not known'))
[2023-08-03 07:15:01,512] 	INFO 	79 	day_data.py 	<module>() 	Day Data Fusion Started
[2023-08-03 07:15:03,700] 	INFO 	126 	day_data.py 	<module>() 	Day Data Fusion Ended
[2023-08-03 07:15:04,911] 	INFO 	123 	pair_data.py 	<module>() 	Pair Data Fusion Started
[2023-08-03 07:15:16,854] 	INFO 	187 	pair_data.py 	<module>() 	Pair Data Fusion Ended
[2023-08-03 07:15:17,832] 	INFO 	37 	bribe_data.py 	<module>() 	Bribe Data Started
[2023-08-03 07:16:16,367] 	ERROR 	153 	bribe_data.py 	<module>() 	Error occurred during Bribe Data process. Error: HTTPSConnectionPool(host='retro-backend.stabl.finance', port=443): Max retries exceeded with url: /api/v1/assets (Caused by NewConnectionError('<urllib3.connection.HTTPSConnection object at 0x7fb0be16f670>: Failed to establish a new connection: [Errno -2] Name or service not known'))
Traceback (most recent call last):
  File "/opt/hostedtoolcache/Python/3.8.17/x64/lib/python3.8/site-packages/urllib3/connection.py", line 174, in _new_conn
    conn = connection.create_connection(
  File "/opt/hostedtoolcache/Python/3.8.17/x64/lib/python3.8/site-packages/urllib3/util/connection.py", line 72, in create_connection
    for res in socket.getaddrinfo(host, port, family, socket.SOCK_STREAM):
  File "/opt/hostedtoolcache/Python/3.8.17/x64/lib/python3.8/socket.py", line 918, in getaddrinfo
    for res in _socket.getaddrinfo(host, port, family, type, proto, flags):
socket.gaierror: [Errno -2] Name or service not known

During handling of the above exception, another exception occurred:

Traceback (most recent call last):
  File "/opt/hostedtoolcache/Python/3.8.17/x64/lib/python3.8/site-packages/urllib3/connectionpool.py", line 714, in urlopen
    httplib_response = self._make_request(
  File "/opt/hostedtoolcache/Python/3.8.17/x64/lib/python3.8/site-packages/urllib3/connectionpool.py", line 403, in _make_request
    self._validate_conn(conn)
  File "/opt/hostedtoolcache/Python/3.8.17/x64/lib/python3.8/site-packages/urllib3/connectionpool.py", line 1053, in _validate_conn
    conn.connect()
  File "/opt/hostedtoolcache/Python/3.8.17/x64/lib/python3.8/site-packages/urllib3/connection.py", line 363, in connect
    self.sock = conn = self._new_conn()
  File "/opt/hostedtoolcache/Python/3.8.17/x64/lib/python3.8/site-packages/urllib3/connection.py", line 186, in _new_conn
    raise NewConnectionError(
urllib3.exceptions.NewConnectionError: <urllib3.connection.HTTPSConnection object at 0x7fb0be16f670>: Failed to establish a new connection: [Errno -2] Name or service not known

During handling of the above exception, another exception occurred:

Traceback (most recent call last):
  File "/opt/hostedtoolcache/Python/3.8.17/x64/lib/python3.8/site-packages/requests/adapters.py", line 486, in send
    resp = conn.urlopen(
  File "/opt/hostedtoolcache/Python/3.8.17/x64/lib/python3.8/site-packages/urllib3/connectionpool.py", line 798, in urlopen
    retries = retries.increment(
  File "/opt/hostedtoolcache/Python/3.8.17/x64/lib/python3.8/site-packages/urllib3/util/retry.py", line 592, in increment
    raise MaxRetryError(_pool, url, error or ResponseError(cause))
urllib3.exceptions.MaxRetryError: HTTPSConnectionPool(host='retro-backend.stabl.finance', port=443): Max retries exceeded with url: /api/v1/assets (Caused by NewConnectionError('<urllib3.connection.HTTPSConnection object at 0x7fb0be16f670>: Failed to establish a new connection: [Errno -2] Name or service not known'))

During handling of the above exception, another exception occurred:

Traceback (most recent call last):
  File "bribe_data.py", line 93, in <module>
    response = requests.get(price_api)
  File "/opt/hostedtoolcache/Python/3.8.17/x64/lib/python3.8/site-packages/requests/api.py", line 73, in get
    return request("get", url, params=params, **kwargs)
  File "/opt/hostedtoolcache/Python/3.8.17/x64/lib/python3.8/site-packages/requests/api.py", line 59, in request
    return session.request(method=method, url=url, **kwargs)
  File "/opt/hostedtoolcache/Python/3.8.17/x64/lib/python3.8/site-packages/requests/sessions.py", line 589, in request
    resp = self.send(prep, **send_kwargs)
  File "/opt/hostedtoolcache/Python/3.8.17/x64/lib/python3.8/site-packages/requests/sessions.py", line 703, in send
    r = adapter.send(request, **kwargs)
  File "/opt/hostedtoolcache/Python/3.8.17/x64/lib/python3.8/site-packages/requests/adapters.py", line 519, in send
    raise ConnectionError(e, request=request)
requests.exceptions.ConnectionError: HTTPSConnectionPool(host='retro-backend.stabl.finance', port=443): Max retries exceeded with url: /api/v1/assets (Caused by NewConnectionError('<urllib3.connection.HTTPSConnection object at 0x7fb0be16f670>: Failed to establish a new connection: [Errno -2] Name or service not known'))
[2023-08-03 07:16:17,337] 	INFO 	37 	fee_data.py 	<module>() 	Fee Data Started
[2023-08-03 07:17:07,117] 	ERROR 	153 	fee_data.py 	<module>() 	Error occurred during Fee Data process. Error: 'address'
Traceback (most recent call last):
  File "/opt/hostedtoolcache/Python/3.8.17/x64/lib/python3.8/site-packages/pandas/core/indexes/base.py", line 3802, in get_loc
    return self._engine.get_loc(casted_key)
  File "pandas/_libs/index.pyx", line 138, in pandas._libs.index.IndexEngine.get_loc
  File "pandas/_libs/index.pyx", line 165, in pandas._libs.index.IndexEngine.get_loc
  File "pandas/_libs/hashtable_class_helper.pxi", line 5745, in pandas._libs.hashtable.PyObjectHashTable.get_item
  File "pandas/_libs/hashtable_class_helper.pxi", line 5753, in pandas._libs.hashtable.PyObjectHashTable.get_item
KeyError: 'address'

The above exception was the direct cause of the following exception:

Traceback (most recent call last):
  File "fee_data.py", line 90, in <module>
    fee_df["address"] = fee_df["address"].apply(str.lower)
  File "/opt/hostedtoolcache/Python/3.8.17/x64/lib/python3.8/site-packages/pandas/core/frame.py", line 3807, in __getitem__
    indexer = self.columns.get_loc(key)
  File "/opt/hostedtoolcache/Python/3.8.17/x64/lib/python3.8/site-packages/pandas/core/indexes/base.py", line 3804, in get_loc
    raise KeyError(key) from err
KeyError: 'address'
[2023-08-03 07:17:08,102] 	INFO 	30 	revenue_data.py 	<module>() 	Revenue Data Started
[2023-08-03 07:17:10,754] 	ERROR 	175 	revenue_data.py 	<module>() 	Error occurred during Revenue Data process. Error: HTTPSConnectionPool(host='retro-backend.stabl.finance', port=443): Max retries exceeded with url: /api/v1/assets (Caused by NewConnectionError('<urllib3.connection.HTTPSConnection object at 0x7fec0d3dd6d0>: Failed to establish a new connection: [Errno -2] Name or service not known'))
Traceback (most recent call last):
  File "/opt/hostedtoolcache/Python/3.8.17/x64/lib/python3.8/site-packages/urllib3/connection.py", line 174, in _new_conn
    conn = connection.create_connection(
  File "/opt/hostedtoolcache/Python/3.8.17/x64/lib/python3.8/site-packages/urllib3/util/connection.py", line 72, in create_connection
    for res in socket.getaddrinfo(host, port, family, socket.SOCK_STREAM):
  File "/opt/hostedtoolcache/Python/3.8.17/x64/lib/python3.8/socket.py", line 918, in getaddrinfo
    for res in _socket.getaddrinfo(host, port, family, type, proto, flags):
socket.gaierror: [Errno -2] Name or service not known

During handling of the above exception, another exception occurred:

Traceback (most recent call last):
  File "/opt/hostedtoolcache/Python/3.8.17/x64/lib/python3.8/site-packages/urllib3/connectionpool.py", line 714, in urlopen
    httplib_response = self._make_request(
  File "/opt/hostedtoolcache/Python/3.8.17/x64/lib/python3.8/site-packages/urllib3/connectionpool.py", line 403, in _make_request
    self._validate_conn(conn)
  File "/opt/hostedtoolcache/Python/3.8.17/x64/lib/python3.8/site-packages/urllib3/connectionpool.py", line 1053, in _validate_conn
    conn.connect()
  File "/opt/hostedtoolcache/Python/3.8.17/x64/lib/python3.8/site-packages/urllib3/connection.py", line 363, in connect
    self.sock = conn = self._new_conn()
  File "/opt/hostedtoolcache/Python/3.8.17/x64/lib/python3.8/site-packages/urllib3/connection.py", line 186, in _new_conn
    raise NewConnectionError(
urllib3.exceptions.NewConnectionError: <urllib3.connection.HTTPSConnection object at 0x7fec0d3dd6d0>: Failed to establish a new connection: [Errno -2] Name or service not known

During handling of the above exception, another exception occurred:

Traceback (most recent call last):
  File "/opt/hostedtoolcache/Python/3.8.17/x64/lib/python3.8/site-packages/requests/adapters.py", line 486, in send
    resp = conn.urlopen(
  File "/opt/hostedtoolcache/Python/3.8.17/x64/lib/python3.8/site-packages/urllib3/connectionpool.py", line 798, in urlopen
    retries = retries.increment(
  File "/opt/hostedtoolcache/Python/3.8.17/x64/lib/python3.8/site-packages/urllib3/util/retry.py", line 592, in increment
    raise MaxRetryError(_pool, url, error or ResponseError(cause))
urllib3.exceptions.MaxRetryError: HTTPSConnectionPool(host='retro-backend.stabl.finance', port=443): Max retries exceeded with url: /api/v1/assets (Caused by NewConnectionError('<urllib3.connection.HTTPSConnection object at 0x7fec0d3dd6d0>: Failed to establish a new connection: [Errno -2] Name or service not known'))

During handling of the above exception, another exception occurred:

Traceback (most recent call last):
  File "revenue_data.py", line 73, in <module>
    response = requests.get(price_api)
  File "/opt/hostedtoolcache/Python/3.8.17/x64/lib/python3.8/site-packages/requests/api.py", line 73, in get
    return request("get", url, params=params, **kwargs)
  File "/opt/hostedtoolcache/Python/3.8.17/x64/lib/python3.8/site-packages/requests/api.py", line 59, in request
    return session.request(method=method, url=url, **kwargs)
  File "/opt/hostedtoolcache/Python/3.8.17/x64/lib/python3.8/site-packages/requests/sessions.py", line 589, in request
    resp = self.send(prep, **send_kwargs)
  File "/opt/hostedtoolcache/Python/3.8.17/x64/lib/python3.8/site-packages/requests/sessions.py", line 703, in send
    r = adapter.send(request, **kwargs)
  File "/opt/hostedtoolcache/Python/3.8.17/x64/lib/python3.8/site-packages/requests/adapters.py", line 519, in send
    raise ConnectionError(e, request=request)
requests.exceptions.ConnectionError: HTTPSConnectionPool(host='retro-backend.stabl.finance', port=443): Max retries exceeded with url: /api/v1/assets (Caused by NewConnectionError('<urllib3.connection.HTTPSConnection object at 0x7fec0d3dd6d0>: Failed to establish a new connection: [Errno -2] Name or service not known'))
[2023-08-03 07:58:54,770] 	INFO 	20 	id_data.py 	<module>() 	ID Data Started
[2023-08-03 07:58:55,203] 	INFO 	31 	id_data.py 	<module>() 	ID Data Ended
[2023-08-03 07:58:55,805] 	INFO 	79 	day_data.py 	<module>() 	Day Data Fusion Started
[2023-08-03 07:58:58,702] 	INFO 	126 	day_data.py 	<module>() 	Day Data Fusion Ended
[2023-08-03 07:58:59,759] 	INFO 	123 	pair_data.py 	<module>() 	Pair Data Fusion Started
[2023-08-03 07:59:10,697] 	INFO 	187 	pair_data.py 	<module>() 	Pair Data Fusion Ended
[2023-08-03 07:59:11,527] 	INFO 	37 	bribe_data.py 	<module>() 	Bribe Data Started
[2023-08-03 07:59:53,367] 	INFO 	151 	bribe_data.py 	<module>() 	Bribe Data Ended
[2023-08-03 07:59:54,216] 	INFO 	37 	fee_data.py 	<module>() 	Fee Data Started
[2023-08-03 08:00:30,503] 	ERROR 	153 	fee_data.py 	<module>() 	Error occurred during Fee Data process. Error: 'address'
Traceback (most recent call last):
  File "/opt/hostedtoolcache/Python/3.8.17/x64/lib/python3.8/site-packages/pandas/core/indexes/base.py", line 3802, in get_loc
    return self._engine.get_loc(casted_key)
  File "pandas/_libs/index.pyx", line 138, in pandas._libs.index.IndexEngine.get_loc
  File "pandas/_libs/index.pyx", line 165, in pandas._libs.index.IndexEngine.get_loc
  File "pandas/_libs/hashtable_class_helper.pxi", line 5745, in pandas._libs.hashtable.PyObjectHashTable.get_item
  File "pandas/_libs/hashtable_class_helper.pxi", line 5753, in pandas._libs.hashtable.PyObjectHashTable.get_item
KeyError: 'address'

The above exception was the direct cause of the following exception:

Traceback (most recent call last):
  File "fee_data.py", line 90, in <module>
    fee_df["address"] = fee_df["address"].apply(str.lower)
  File "/opt/hostedtoolcache/Python/3.8.17/x64/lib/python3.8/site-packages/pandas/core/frame.py", line 3807, in __getitem__
    indexer = self.columns.get_loc(key)
  File "/opt/hostedtoolcache/Python/3.8.17/x64/lib/python3.8/site-packages/pandas/core/indexes/base.py", line 3804, in get_loc
    raise KeyError(key) from err
KeyError: 'address'
[2023-08-03 08:00:31,349] 	INFO 	30 	revenue_data.py 	<module>() 	Revenue Data Started
[2023-08-03 08:00:38,796] 	INFO 	173 	revenue_data.py 	<module>() 	Revenue Data Ended
[2023-08-03 08:07:24,907] 	INFO 	27 	emissions_data.py 	<module>() 	Emissions Data Started
[2023-08-03 08:07:30,914] 	INFO 	88 	emissions_data.py 	<module>() 	Emissions Data Ended
[2023-08-03 08:20:28,867] 	INFO 	20 	id_data.py 	<module>() 	ID Data Started
[2023-08-03 08:20:29,219] 	INFO 	31 	id_data.py 	<module>() 	ID Data Ended
[2023-08-03 08:20:29,816] 	INFO 	79 	day_data.py 	<module>() 	Day Data Fusion Started
[2023-08-03 08:20:32,141] 	INFO 	126 	day_data.py 	<module>() 	Day Data Fusion Ended
[2023-08-03 08:20:33,308] 	INFO 	123 	pair_data.py 	<module>() 	Pair Data Fusion Started
[2023-08-03 08:20:44,736] 	INFO 	187 	pair_data.py 	<module>() 	Pair Data Fusion Ended
[2023-08-03 08:20:45,572] 	INFO 	37 	bribe_data.py 	<module>() 	Bribe Data Started
[2023-08-03 08:21:28,836] 	INFO 	151 	bribe_data.py 	<module>() 	Bribe Data Ended
[2023-08-03 08:21:29,676] 	INFO 	37 	fee_data.py 	<module>() 	Fee Data Started
[2023-08-03 08:22:05,677] 	ERROR 	153 	fee_data.py 	<module>() 	Error occurred during Fee Data process. Error: 'address'
Traceback (most recent call last):
  File "/opt/hostedtoolcache/Python/3.8.17/x64/lib/python3.8/site-packages/pandas/core/indexes/base.py", line 3802, in get_loc
    return self._engine.get_loc(casted_key)
  File "pandas/_libs/index.pyx", line 138, in pandas._libs.index.IndexEngine.get_loc
  File "pandas/_libs/index.pyx", line 165, in pandas._libs.index.IndexEngine.get_loc
  File "pandas/_libs/hashtable_class_helper.pxi", line 5745, in pandas._libs.hashtable.PyObjectHashTable.get_item
  File "pandas/_libs/hashtable_class_helper.pxi", line 5753, in pandas._libs.hashtable.PyObjectHashTable.get_item
KeyError: 'address'

The above exception was the direct cause of the following exception:

Traceback (most recent call last):
  File "fee_data.py", line 90, in <module>
    fee_df["address"] = fee_df["address"].apply(str.lower)
  File "/opt/hostedtoolcache/Python/3.8.17/x64/lib/python3.8/site-packages/pandas/core/frame.py", line 3807, in __getitem__
    indexer = self.columns.get_loc(key)
  File "/opt/hostedtoolcache/Python/3.8.17/x64/lib/python3.8/site-packages/pandas/core/indexes/base.py", line 3804, in get_loc
    raise KeyError(key) from err
KeyError: 'address'
[2023-08-03 08:22:06,519] 	INFO 	30 	revenue_data.py 	<module>() 	Revenue Data Started
[2023-08-03 08:22:13,784] 	INFO 	173 	revenue_data.py 	<module>() 	Revenue Data Ended
[2023-08-03 09:16:16,799] 	INFO 	20 	id_data.py 	<module>() 	ID Data Started
[2023-08-03 09:16:17,329] 	INFO 	31 	id_data.py 	<module>() 	ID Data Ended
[2023-08-03 09:16:18,153] 	INFO 	79 	day_data.py 	<module>() 	Day Data Fusion Started
[2023-08-03 09:16:21,020] 	INFO 	126 	day_data.py 	<module>() 	Day Data Fusion Ended
[2023-08-03 09:16:22,411] 	INFO 	123 	pair_data.py 	<module>() 	Pair Data Fusion Started
[2023-08-03 09:16:35,342] 	INFO 	187 	pair_data.py 	<module>() 	Pair Data Fusion Ended
[2023-08-03 09:16:36,385] 	INFO 	37 	bribe_data.py 	<module>() 	Bribe Data Started
[2023-08-03 09:17:34,314] 	INFO 	151 	bribe_data.py 	<module>() 	Bribe Data Ended
[2023-08-03 09:17:35,317] 	INFO 	37 	fee_data.py 	<module>() 	Fee Data Started
[2023-08-03 09:18:28,202] 	ERROR 	153 	fee_data.py 	<module>() 	Error occurred during Fee Data process. Error: 'address'
Traceback (most recent call last):
  File "/opt/hostedtoolcache/Python/3.8.17/x64/lib/python3.8/site-packages/pandas/core/indexes/base.py", line 3802, in get_loc
    return self._engine.get_loc(casted_key)
  File "pandas/_libs/index.pyx", line 138, in pandas._libs.index.IndexEngine.get_loc
  File "pandas/_libs/index.pyx", line 165, in pandas._libs.index.IndexEngine.get_loc
  File "pandas/_libs/hashtable_class_helper.pxi", line 5745, in pandas._libs.hashtable.PyObjectHashTable.get_item
  File "pandas/_libs/hashtable_class_helper.pxi", line 5753, in pandas._libs.hashtable.PyObjectHashTable.get_item
KeyError: 'address'

The above exception was the direct cause of the following exception:

Traceback (most recent call last):
  File "fee_data.py", line 90, in <module>
    fee_df["address"] = fee_df["address"].apply(str.lower)
  File "/opt/hostedtoolcache/Python/3.8.17/x64/lib/python3.8/site-packages/pandas/core/frame.py", line 3807, in __getitem__
    indexer = self.columns.get_loc(key)
  File "/opt/hostedtoolcache/Python/3.8.17/x64/lib/python3.8/site-packages/pandas/core/indexes/base.py", line 3804, in get_loc
    raise KeyError(key) from err
KeyError: 'address'
[2023-08-03 09:18:29,309] 	INFO 	30 	revenue_data.py 	<module>() 	Revenue Data Started
[2023-08-03 09:18:37,496] 	INFO 	173 	revenue_data.py 	<module>() 	Revenue Data Ended
[2023-08-03 10:17:42,440] 	INFO 	20 	id_data.py 	<module>() 	ID Data Started
[2023-08-03 10:17:42,759] 	INFO 	31 	id_data.py 	<module>() 	ID Data Ended
[2023-08-03 10:17:43,534] 	INFO 	79 	day_data.py 	<module>() 	Day Data Fusion Started
[2023-08-03 10:17:46,144] 	INFO 	126 	day_data.py 	<module>() 	Day Data Fusion Ended
[2023-08-03 10:17:47,651] 	INFO 	123 	pair_data.py 	<module>() 	Pair Data Fusion Started
[2023-08-03 10:17:59,577] 	INFO 	187 	pair_data.py 	<module>() 	Pair Data Fusion Ended
[2023-08-03 10:18:00,681] 	INFO 	37 	bribe_data.py 	<module>() 	Bribe Data Started
[2023-08-03 10:18:44,955] 	INFO 	151 	bribe_data.py 	<module>() 	Bribe Data Ended
[2023-08-03 10:18:46,104] 	INFO 	37 	fee_data.py 	<module>() 	Fee Data Started
[2023-08-03 10:19:25,797] 	ERROR 	153 	fee_data.py 	<module>() 	Error occurred during Fee Data process. Error: 'address'
Traceback (most recent call last):
  File "/opt/hostedtoolcache/Python/3.8.17/x64/lib/python3.8/site-packages/pandas/core/indexes/base.py", line 3802, in get_loc
    return self._engine.get_loc(casted_key)
  File "pandas/_libs/index.pyx", line 138, in pandas._libs.index.IndexEngine.get_loc
  File "pandas/_libs/index.pyx", line 165, in pandas._libs.index.IndexEngine.get_loc
  File "pandas/_libs/hashtable_class_helper.pxi", line 5745, in pandas._libs.hashtable.PyObjectHashTable.get_item
  File "pandas/_libs/hashtable_class_helper.pxi", line 5753, in pandas._libs.hashtable.PyObjectHashTable.get_item
KeyError: 'address'

The above exception was the direct cause of the following exception:

Traceback (most recent call last):
  File "fee_data.py", line 90, in <module>
    fee_df["address"] = fee_df["address"].apply(str.lower)
  File "/opt/hostedtoolcache/Python/3.8.17/x64/lib/python3.8/site-packages/pandas/core/frame.py", line 3807, in __getitem__
    indexer = self.columns.get_loc(key)
  File "/opt/hostedtoolcache/Python/3.8.17/x64/lib/python3.8/site-packages/pandas/core/indexes/base.py", line 3804, in get_loc
    raise KeyError(key) from err
KeyError: 'address'
[2023-08-03 10:19:26,970] 	INFO 	30 	revenue_data.py 	<module>() 	Revenue Data Started
[2023-08-03 10:19:36,324] 	INFO 	173 	revenue_data.py 	<module>() 	Revenue Data Ended
[2023-08-03 11:58:01,089] 	INFO 	22 	pool_data.py 	<module>() 	Pool Data Started
[2023-08-03 11:58:01,090] 	ERROR 	60 	pool_data.py 	<module>() 	Error occurred during Pool Data process. Error: 'merkl_abi'
Traceback (most recent call last):
  File "pool_data.py", line 27, in <module>
    merkl_abi = config["web3"]["merkl_abi"]
KeyError: 'merkl_abi'
[2023-08-03 12:02:49,842] 	INFO 	22 	pool_data.py 	<module>() 	Pool Data Started
[2023-08-03 12:02:55,816] 	INFO 	58 	pool_data.py 	<module>() 	Pool Data Ended
[2023-08-03 12:34:26,178] 	INFO 	20 	id_data.py 	<module>() 	ID Data Started
[2023-08-03 12:34:26,906] 	INFO 	31 	id_data.py 	<module>() 	ID Data Ended
[2023-08-03 12:34:27,616] 	INFO 	79 	day_data.py 	<module>() 	Day Data Fusion Started
[2023-08-03 12:34:31,034] 	INFO 	126 	day_data.py 	<module>() 	Day Data Fusion Ended
[2023-08-03 12:34:32,308] 	INFO 	123 	pair_data.py 	<module>() 	Pair Data Fusion Started
[2023-08-03 12:34:44,911] 	INFO 	187 	pair_data.py 	<module>() 	Pair Data Fusion Ended
[2023-08-03 12:34:45,991] 	INFO 	37 	bribe_data.py 	<module>() 	Bribe Data Started
[2023-08-03 12:35:48,333] 	INFO 	151 	bribe_data.py 	<module>() 	Bribe Data Ended
[2023-08-03 12:35:49,556] 	INFO 	37 	fee_data.py 	<module>() 	Fee Data Started
[2023-08-03 12:36:44,022] 	ERROR 	153 	fee_data.py 	<module>() 	Error occurred during Fee Data process. Error: 'address'
Traceback (most recent call last):
  File "/opt/hostedtoolcache/Python/3.8.17/x64/lib/python3.8/site-packages/pandas/core/indexes/base.py", line 3802, in get_loc
    return self._engine.get_loc(casted_key)
  File "pandas/_libs/index.pyx", line 138, in pandas._libs.index.IndexEngine.get_loc
  File "pandas/_libs/index.pyx", line 165, in pandas._libs.index.IndexEngine.get_loc
  File "pandas/_libs/hashtable_class_helper.pxi", line 5745, in pandas._libs.hashtable.PyObjectHashTable.get_item
  File "pandas/_libs/hashtable_class_helper.pxi", line 5753, in pandas._libs.hashtable.PyObjectHashTable.get_item
KeyError: 'address'

The above exception was the direct cause of the following exception:

Traceback (most recent call last):
  File "fee_data.py", line 90, in <module>
    fee_df["address"] = fee_df["address"].apply(str.lower)
  File "/opt/hostedtoolcache/Python/3.8.17/x64/lib/python3.8/site-packages/pandas/core/frame.py", line 3807, in __getitem__
    indexer = self.columns.get_loc(key)
  File "/opt/hostedtoolcache/Python/3.8.17/x64/lib/python3.8/site-packages/pandas/core/indexes/base.py", line 3804, in get_loc
    raise KeyError(key) from err
KeyError: 'address'
[2023-08-03 12:36:45,154] 	INFO 	30 	revenue_data.py 	<module>() 	Revenue Data Started
[2023-08-03 12:36:54,224] 	INFO 	173 	revenue_data.py 	<module>() 	Revenue Data Ended
[2023-08-03 12:38:30,706] 	INFO 	22 	pool_data.py 	<module>() 	Pool Data Started
[2023-08-03 12:38:40,698] 	INFO 	58 	pool_data.py 	<module>() 	Pool Data Ended
[2023-08-03 13:01:06,749] 	INFO 	22 	pool_data.py 	<module>() 	Pool Data Started
[2023-08-03 13:01:12,416] 	INFO 	58 	pool_data.py 	<module>() 	Pool Data Ended
[2023-08-03 13:20:07,895] 	INFO 	20 	id_data.py 	<module>() 	ID Data Started
[2023-08-03 13:20:08,622] 	INFO 	31 	id_data.py 	<module>() 	ID Data Ended
[2023-08-03 13:20:09,410] 	INFO 	79 	day_data.py 	<module>() 	Day Data Fusion Started
[2023-08-03 13:20:12,086] 	INFO 	126 	day_data.py 	<module>() 	Day Data Fusion Ended
[2023-08-03 13:20:13,492] 	INFO 	123 	pair_data.py 	<module>() 	Pair Data Fusion Started
[2023-08-03 13:20:27,004] 	INFO 	187 	pair_data.py 	<module>() 	Pair Data Fusion Ended
[2023-08-03 13:20:28,326] 	INFO 	37 	bribe_data.py 	<module>() 	Bribe Data Started
[2023-08-03 13:21:36,828] 	INFO 	151 	bribe_data.py 	<module>() 	Bribe Data Ended
[2023-08-03 13:21:38,007] 	INFO 	37 	fee_data.py 	<module>() 	Fee Data Started
[2023-08-03 13:22:40,504] 	ERROR 	153 	fee_data.py 	<module>() 	Error occurred during Fee Data process. Error: 'address'
Traceback (most recent call last):
  File "/opt/hostedtoolcache/Python/3.8.17/x64/lib/python3.8/site-packages/pandas/core/indexes/base.py", line 3802, in get_loc
    return self._engine.get_loc(casted_key)
  File "pandas/_libs/index.pyx", line 138, in pandas._libs.index.IndexEngine.get_loc
  File "pandas/_libs/index.pyx", line 165, in pandas._libs.index.IndexEngine.get_loc
  File "pandas/_libs/hashtable_class_helper.pxi", line 5745, in pandas._libs.hashtable.PyObjectHashTable.get_item
  File "pandas/_libs/hashtable_class_helper.pxi", line 5753, in pandas._libs.hashtable.PyObjectHashTable.get_item
KeyError: 'address'

The above exception was the direct cause of the following exception:

Traceback (most recent call last):
  File "fee_data.py", line 90, in <module>
    fee_df["address"] = fee_df["address"].apply(str.lower)
  File "/opt/hostedtoolcache/Python/3.8.17/x64/lib/python3.8/site-packages/pandas/core/frame.py", line 3807, in __getitem__
    indexer = self.columns.get_loc(key)
  File "/opt/hostedtoolcache/Python/3.8.17/x64/lib/python3.8/site-packages/pandas/core/indexes/base.py", line 3804, in get_loc
    raise KeyError(key) from err
KeyError: 'address'
[2023-08-03 13:22:41,596] 	INFO 	30 	revenue_data.py 	<module>() 	Revenue Data Started
[2023-08-03 13:22:50,521] 	INFO 	173 	revenue_data.py 	<module>() 	Revenue Data Ended
[2023-08-03 13:30:40,545] 	INFO 	22 	pool_data.py 	<module>() 	Pool Data Started
[2023-08-03 13:30:49,538] 	INFO 	58 	pool_data.py 	<module>() 	Pool Data Ended
